Workbook

Sheet QTY SUMM
A1: DESCRIPTION | B1: SUBT. | C1: BASE. | D1: GRND FLR | E1: 1st FLR | F1: 2nd FLR | G1: 3rd FLR | H1: 4th FLR | I1: 5th FLR | J1: 6th FLR | K1: UPPR RF FLR | L1: TOTAL | M1: UNITS | P1: CHECKED (DRAWINGS) | Q1: VARIANCE (TAKE-OFF − CHECK) | R1: VAR %
A2: ARCHICTURAL WORKS
A4: BLOCK WALL | C4: ='BLOCK WORK'!G29 -> 548.93 | D4: ='BLOCK WORK'!O29 -> 606.945 | E4: ='BLOCK WORK'!W29 -> 437.025 | F4: ='BLOCK WORK'!AE29 -> 414.195 | G4: ='BLOCK WORK'!AM29 -> 401.565 | H4: ='BLOCK WORK'!AU29 -> 405.66 | I4: ='BLOCK WORK'!BC29 -> 637.845 | K4: ='BLOCK WORK'!BK29 -> 212.52 | L4: =SUM(B4:K4) -> 3664.685 | M4: m2 | N4: =L4*2 -> 7329.37 | P4: =L5 -> 3772.695 | Q4: =L4-P4 -> -108.01 | R4: =IF(P4=0,0,Q4/P4) -> -0.028629402
A5: Check – drawings | C5: ='BLOCK WORK'!G36 -> 516 | D5: ='BLOCK WORK'!O36 -> 639.345 | E5: ='BLOCK WORK'!W36 -> 456.495 | F5: ='BLOCK WORK'!AE36 -> 460.065 | G5: ='BLOCK WORK'!AM36 -> 411.135 | H5: ='BLOCK WORK'!AU36 -> 417.54 | I5: ='BLOCK WORK'!BC36 -> 657.645 | K5: ='BLOCK WORK'!BK36 -> 214.47 | L5: =SUM(B5:K5) -> 3772.695 | M5: m2
A6: INTERNAL PLASTERING | C6: =PLASTERING!G30 -> 2066.825 | D6: =PLASTERING!O30 -> 1006.92 | E6: =PLASTERING!W30 -> 867.45 | F6: =PLASTERING!AE30 -> 784.665 | G6: =PLASTERING!AM30 -> 765 | H6: =PLASTERING!AU30 -> 773.385 | I6: =PLASTERING!BC30 -> 1148.355 | K6: =PLASTERING!BK30 -> 291.72 | L6: =SUM(B6:K6) -> 7704.32 | M6: m2 | P6: =L7 -> 7920.34 | Q6: =L6-P6 -> -216.02 | R6: =IF(P6=0,0,Q6/P6) -> -0.027274082
A7: Check – drawings | C7: =PLASTERING!G64 -> 2000.965 | D7: =PLASTERING!O64 -> 1071.72 | E7: =PLASTERING!W64 -> 906.39 | F7: =PLASTERING!AE64 -> 876.405 | G7: =PLASTERING!AM64 -> 784.14 | H7: =PLASTERING!AU64 -> 797.145 | I7: =PLASTERING!BC64 -> 1187.955 | K7: =PLASTERING!BK64 -> 295.62 | L7: =SUM(B7:K7) -> 7920.34 | M7: m2
A8: EXTERNAL PLASTERING | C8: =PLASTERING!G58 -> 666.61 | D8: =PLASTERING!O58 -> 338.835 | E8: =PLASTERING!W58 -> 189.855 | F8: =PLASTERING!AE58 -> 182.58 | G8: =PLASTERING!AM58 -> 225.045 | H8: =PLASTERING!AU58 -> 289.485 | I8: =PLASTERING!BC58 -> 294.06 | K8: =PLASTERING!BK58 -> 162.72 | L8: =SUM(B8:K8) -> 2349.19 | M8: m2 | N8: =SUM(L6+L8) -> 10053.51 | O8: =N8-N4 -> 2724.14 | P8: =L9 -> 2349.19 | Q8: =L8-P8 -> 0 | R8: =IF(P8=0,0,Q8/P8) -> 0
A9: Check – NOT VERIFIED | C9: =PLASTERING!G69 -> 666.61 | D9: =PLASTERING!O69 -> 338.835 | E9: =PLASTERING!W69 -> 189.855 | F9: =PLASTERING!AE69 -> 182.58 | G9: =PLASTERING!AM69 -> 225.045 | H9: =PLASTERING!AU69 -> 289.485 | I9: =PLASTERING!BC69 -> 294.06 | K9: =PLASTERING!BK69 -> 162.72 | L9: =SUM(B9:K9) -> 2349.19 | M9: m2
A10: PLASTERBOARD PARTITION | F10: ='PLASTERBOARD PARTITION '!AE8 -> 315.48 | G10: ='PLASTERBOARD PARTITION '!AM8 -> 359.7 | H10: ='PLASTERBOARD PARTITION '!AU8 -> 311.85 | L10: =SUM(B10:K10) -> 987.03 | M10: m2 | P10: =L11 -> 910.14 | Q10: =L10-P10 -> 76.89 | R10: =IF(P10=0,0,Q10/P10) -> 0.084481508
A11: Check – drawings | C11: ='PLASTERBOARD PARTITION '!G12 -> 0 | D11: ='PLASTERBOARD PARTITION '!O12 -> 0 | E11: ='PLASTERBOARD PARTITION '!W12 -> 0 | F11: ='PLASTERBOARD PARTITION '!AE12 -> 312.18 | G11: ='PLASTERBOARD PARTITION '!AM12 -> 358.05 | H11: ='PLASTERBOARD PARTITION '!AU12 -> 239.91 | I11: ='PLASTERBOARD PARTITION '!BC12 -> 0 | K11: ='PLASTERBOARD PARTITION '!BK12 -> 0 | L11: =SUM(B11:K11) -> 910.14 | M11: m2
A12: CEMENT BOARD PARTITION | D12: ='CEMENT PARTITION '!O8 -> 63.9 | E12: ='CEMENT PARTITION '!W8 -> 49.5 | F12: ='CEMENT PARTITION '!AE8 -> 49.5 | G12: ='CEMENT PARTITION '!AM8 -> 52.14 | H12: ='CEMENT PARTITION '!AU8 -> 123.09 | I12: ='CEMENT PARTITION '!BC8 -> 20.46 | L12: =SUM(B12:K12) -> 358.59 | M12: m2 | P12: =L13 -> 236.25 | Q12: =L12-P12 -> 122.34 | R12: =IF(P12=0,0,Q12/P12) -> 0.51784127
A13: Check – drawings | C13: ='CEMENT PARTITION '!G12 -> 0 | D13: ='CEMENT PARTITION '!O12 -> 38.25 | E13: ='CEMENT PARTITION '!W12 -> 32.34 | F13: ='CEMENT PARTITION '!AE12 -> 18.48 | G13: ='CEMENT PARTITION '!AM12 -> 32.34 | H13: ='CEMENT PARTITION '!AU12 -> 93.72 | I13: ='CEMENT PARTITION '!BC12 -> 21.12 | K13: ='CEMENT PARTITION '!BK12 -> 0 | L13: =SUM(B13:K13) -> 236.25 | M13: m2
A14: RC SLAB RENDERED AND PAINTED | C14: ='CEILING FINISHES SCHEDULE'!C4 -> 36.4 | D14: ='CEILING FINISHES SCHEDULE'!D4 -> 1470.7 | E14: ='CEILING FINISHES SCHEDULE'!E4 -> 33.8 | F14: ='CEILING FINISHES SCHEDULE'!F4 -> 38.5 | G14: ='CEILING FINISHES SCHEDULE'!G4 -> 36.4 | H14: ='CEILING FINISHES SCHEDULE'!H4 -> 38.9 | I14: ='CEILING FINISHES SCHEDULE'!I4 -> 0 | L14: =SUM(B14:K14) -> 1654.7 | M14: m2 | P14: =L15 -> 1436.4 | Q14: =L14-P14 -> 218.3 | R14: =IF(P14=0,0,Q14/P14) -> 0.15197717
A15: Check – drawings | C15: ='CEILING FINISHES SCHEDULE'!C15 -> 1373.7 | D15: ='CEILING FINISHES SCHEDULE'!D15 -> 0 | E15: ='CEILING FINISHES SCHEDULE'!E15 -> 2.2 | F15: ='CEILING FINISHES SCHEDULE'!F15 -> 1.2 | G15: ='CEILING FINISHES SCHEDULE'!G15 -> 0 | H15: ='CEILING FINISHES SCHEDULE'!H15 -> 8.7 | I15: ='CEILING FINISHES SCHEDULE'!I15 -> 32.9 | K15: ='CEILING FINISHES SCHEDULE'!J15 -> 17.7 | L15: =SUM(B15:K15) -> 1436.4 | M15: m2
A16: PLASTEDOARD CEILING | C16: ='CEILING FINISHES SCHEDULE'!C5 -> 126 | D16: ='CEILING FINISHES SCHEDULE'!D5 -> 0 | E16: ='CEILING FINISHES SCHEDULE'!E5 -> 41.5 | F16: ='CEILING FINISHES SCHEDULE'!F5 -> 53.4 | G16: ='CEILING FINISHES SCHEDULE'!G5 -> 8.4 | H16: ='CEILING FINISHES SCHEDULE'!H5 -> 48.5 | I16: ='CEILING FINISHES SCHEDULE'!I5 -> 480.1 | L16: =SUM(B16:K16) -> 757.9 | M16: m2 | N16: 757.9 | P16: =L17 -> 720 | Q16: =L16-P16 -> 37.9 | R16: =IF(P16=0,0,Q16/P16) -> 0.052638889
A17: Check – drawings | C17: ='CEILING FINISHES SCHEDULE'!C16 -> 0 | D17: ='CEILING FINISHES SCHEDULE'!D16 -> 109.4 | E17: ='CEILING FINISHES SCHEDULE'!E16 -> 40.3 | F17: ='CEILING FINISHES SCHEDULE'!F16 -> 57.3 | G17: ='CEILING FINISHES SCHEDULE'!G16 -> 40.5 | H17: ='CEILING FINISHES SCHEDULE'!H16 -> 53.4 | I17: ='CEILING FINISHES SCHEDULE'!I16 -> 419.1 | K17: ='CEILING FINISHES SCHEDULE'!J16 -> 0 | L17: =SUM(B17:K17) -> 720 | M17: m2
A18: WAFFLE CEILING | C18: ='CEILING FINISHES SCHEDULE'!C6 -> 0 | D18: ='CEILING FINISHES SCHEDULE'!D6 -> 0 | E18: ='CEILING FINISHES SCHEDULE'!E6 -> 0 | F18: ='CEILING FINISHES SCHEDULE'!F6 -> 0 | G18: ='CEILING FINISHES SCHEDULE'!G6 -> 0 | H18: ='CEILING FINISHES SCHEDULE'!H6 -> 0 | I18: ='CEILING FINISHES SCHEDULE'!I6 -> 48.2 | L18: =SUM(B18:K18) -> 48.2 | M18: m2 | P18: =L19 -> 47.3 | Q18: =L18-P18 -> 0.9 | R18: =IF(P18=0,0,Q18/P18) -> 0.019027484
A19: Check – drawings | C19: ='CEILING FINISHES SCHEDULE'!C17 -> 0 | D19: ='CEILING FINISHES SCHEDULE'!D17 -> 0 | E19: ='CEILING FINISHES SCHEDULE'!E17 -> 0 | F19: ='CEILING FINISHES SCHEDULE'!F17 -> 0 | G19: ='CEILING FINISHES SCHEDULE'!G17 -> 0 | H19: ='CEILING FINISHES SCHEDULE'!H17 -> 0 | I19: ='CEILING FINISHES SCHEDULE'!I17 -> 47.3 | K19: ='CEILING FINISHES SCHEDULE'!J17 -> 0 | L19: =SUM(B19:K19) -> 47.3 | M19: m2
A20: CEMENT BOARD CEILING | C20: ='CEILING FINISHES SCHEDULE'!C7 -> 32.8 | D20: ='CEILING FINISHES SCHEDULE'!D7 -> 16.2 | E20: ='CEILING FINISHES SCHEDULE'!E7 -> 31.6 | F20: ='CEILING FINISHES SCHEDULE'!F7 -> 32.4 | G20: ='CEILING FINISHES SCHEDULE'!G7 -> 32.9 | H20: ='CEILING FINISHES SCHEDULE'!H7 -> 32.7 | I20: ='CEILING FINISHES SCHEDULE'!I7 -> 46.2 | L20: =SUM(B20:K20) -> 224.8 | M20: m2 | P20: =L21 -> 224.9 | Q20: =L20-P20 -> -0.1 | R20: =IF(P20=0,0,Q20/P20) -> -0.00044464206
A21: Check – drawings | C21: ='CEILING FINISHES SCHEDULE'!C18 -> 15.7 | D21: ='CEILING FINISHES SCHEDULE'!D18 -> 32.8 | E21: ='CEILING FINISHES SCHEDULE'!E18 -> 32.7 | F21: ='CEILING FINISHES SCHEDULE'!F18 -> 32.7 | G21: ='CEILING FINISHES SCHEDULE'!G18 -> 32.7 | H21: ='CEILING FINISHES SCHEDULE'!H18 -> 32.8 | I21: ='CEILING FINISHES SCHEDULE'!I18 -> 45.5 | K21: ='CEILING FINISHES SCHEDULE'!J18 -> 0 | L21: =SUM(B21:K21) -> 224.9 | M21: m2
A22: BAFFLE CEILING | C22: ='CEILING FINISHES SCHEDULE'!C8 -> 0 | D22: ='CEILING FINISHES SCHEDULE'!D8 -> 0 | E22: ='CEILING FINISHES SCHEDULE'!E8 -> 0 | F22: ='CEILING FINISHES SCHEDULE'!F8 -> 0 | G22: ='CEILING FINISHES SCHEDULE'!G8 -> 0 | H22: ='CEILING FINISHES SCHEDULE'!H8 -> 0 | I22: ='CEILING FINISHES SCHEDULE'!I8 -> 0 | L22: =SUM(B22:K22) -> 0 | M22: m2 | P22: =L23 -> 11.6 | Q22: =L22-P22 -> -11.6 | R22: =IF(P22=0,0,Q22/P22) -> -1
A23: Check – drawings | C23: ='CEILING FINISHES SCHEDULE'!C19 -> 0 | D23: ='CEILING FINISHES SCHEDULE'!D19 -> 11.6 | E23: ='CEILING FINISHES SCHEDULE'!E19 -> 0 | F23: ='CEILING FINISHES SCHEDULE'!F19 -> 0 | G23: ='CEILING FINISHES SCHEDULE'!G19 -> 0 | H23: ='CEILING FINISHES SCHEDULE'!H19 -> 0 | I23: ='CEILING FINISHES SCHEDULE'!I19 -> 0 | K23: ='CEILING FINISHES SCHEDULE'!J19 -> 0 | L23: =SUM(B23:K23) -> 11.6 | M23: m2
A24: 600 X 600mm acoustic ceiling | C24: ='CEILING FINISHES SCHEDULE'!C9 -> 215 | D24: ='CEILING FINISHES SCHEDULE'!D9 -> 0 | E24: ='CEILING FINISHES SCHEDULE'!E9 -> 415.2 | F24: ='CEILING FINISHES SCHEDULE'!F9 -> 420.1 | G24: ='CEILING FINISHES SCHEDULE'!G9 -> 424 | H24: ='CEILING FINISHES SCHEDULE'!H9 -> 411.9 | I24: ='CEILING FINISHES SCHEDULE'!I9 -> 0 | L24: =SUM(B24:K24) -> 1886.2 | M24: m2 | P24: =L25 -> 1849.6 | Q24: =L24-P24 -> 36.6 | R24: =IF(P24=0,0,Q24/P24) -> 0.019788062
A25: Check – drawings | C25: ='CEILING FINISHES SCHEDULE'!C20 -> 0 | D25: ='CEILING FINISHES SCHEDULE'!D20 -> 179.6 | E25: ='CEILING FINISHES SCHEDULE'!E20 -> 417.5 | F25: ='CEILING FINISHES SCHEDULE'!F20 -> 418.6 | G25: ='CEILING FINISHES SCHEDULE'!G20 -> 418.5 | H25: ='CEILING FINISHES SCHEDULE'!H20 -> 415.4 | I25: ='CEILING FINISHES SCHEDULE'!I20 -> 0 | K25: ='CEILING FINISHES SCHEDULE'!J20 -> 0 | L25: =SUM(B25:K25) -> 1849.6 | M25: m2
A26: ALUMINUM PANEL CEILING | C26: ='CEILING FINISHES SCHEDULE'!C10 -> 230 | D26: ='CEILING FINISHES SCHEDULE'!D10 -> 0 | E26: ='CEILING FINISHES SCHEDULE'!E10 -> 0 | F26: ='CEILING FINISHES SCHEDULE'!F10 -> 0 | G26: ='CEILING FINISHES SCHEDULE'!G10 -> 0 | H26: ='CEILING FINISHES SCHEDULE'!H10 -> 0 | I26: ='CEILING FINISHES SCHEDULE'!I10 -> 0 | L26: =SUM(B26:K26) -> 230 | M26: m2 | P26: =L27 -> 317.5 | Q26: =L26-P26 -> -87.5 | R26: =IF(P26=0,0,Q26/P26) -> -0.27559055
A27: Check – drawings | C27: ='CEILING FINISHES SCHEDULE'!C21 -> 0 | D27: ='CEILING FINISHES SCHEDULE'!D21 -> 317.5 | E27: ='CEILING FINISHES SCHEDULE'!E21 -> 0 | F27: ='CEILING FINISHES SCHEDULE'!F21 -> 0 | G27: ='CEILING FINISHES SCHEDULE'!G21 -> 0 | H27: ='CEILING FINISHES SCHEDULE'!H21 -> 0 | I27: ='CEILING FINISHES SCHEDULE'!I21 -> 0 | K27: ='CEILING FINISHES SCHEDULE'!J21 -> 0 | L27: =SUM(B27:K27) -> 317.5 | M27: m2
A29: Check rows (shaded) link to the CHECK blocks in each trade sheet. Sources and findings: see DRAWING CHECK sheet.
A30: CONCRETE WORKS
A31: BLINDING
A32: FOUNDATION
A33: COLUMN BASE
A34: SLAB
A35: BEAMS
A36: COLUMNS
A37: WATER TANK
A38: SHEAR WALL
A39: LIFT WALL
A40: RETAINING WALL
... A85: MASONRY
L99: =SUM(L1:L98)-SUM(L5,L7,L9,L11,L13,L15,L17,L19,L21,L23,L25,L27) -> 19865.615

Sheet DRAWING CHECK
A1: DRAWING CHECK — INDEPENDENT TAKE-OFF FROM ARCHITECTURAL DRAWINGS (Spektra Global WD, Rev 02, Aug 2026)
A2: Measured from the vector geometry of the issued PDF (60 sheets). Scale verified from gridlines: 8,100 mm bay = 110.3 pt on every sheet (73.44 mm per PDF point). Blue figures are measured inputs; everything else is a formula.
A4: A. WALL LENGTHS (m) | C4: BASEMENT | D4: GROUND FLR | E4: 1st FLR | F4: 2nd FLR | G4: 3rd FLR | H4: 4th FLR | I4: 5th FLR | J4: ROOFTOP | K4: TOTAL | L4: SOURCE / METHOD
A5: BLK | B5: 150mm block wall — gross length measured through door/window openings | C5: 121.8 | D5: 157.3 | E5: 154.1 | F5: 161.2 | G5: 143.9 | H5: 152.7 | I5: 219.9 | J5: 145.5 | K5: =SUM(C5:J5) -> 1256.4 | L5: Plans A008–A015. Wall = pair of black lines 150 mm apart carrying the block hatch; door/window gaps between collinear wall ends bridged; column (concrete) gaps not bridged. Tolerance about ±5%.
A6: BLKNET | B6: 150mm block wall — net length (solid wall only, for information) | C6: 114.2 | D6: 118.1 | E6: 126 | F6: 128.8 | G6: 107 | H6: 123.6 | I6: 191.7 | J6: 142.8 | K6: =SUM(C6:J6) -> 1052.2 | L6: As above, without bridging openings.
A7: PB | B7: Plasterboard partition (red) — length | C7: 0 | D7: 0 | E7: 0 | F7: 94.6 | G7: 108.5 | H7: 72.7 | I7: 0 | J7: 0 | K7: =SUM(C7:J7) -> 275.8 | L7: Half the red wall linework (both faces) on A011–A013, excluding the dashed red section-marker lines and hatch ticks.
A8: CB | B8: Cement board partition (green) — length | C8: 0 | D8: 8.5 | E8: 9.8 | F8: 5.6 | G8: 9.8 | H8: 28.4 | I8: 6.4 | J8: 0 | K8: =SUM(C8:J8) -> 68.5 | L8: Half the green linework (both faces); these are mainly the WC cubicle partitions.
A10: B. CEILING AREAS (m²) | C10: BASEMENT | D10: GROUND FLR | E10: 1st FLR | F10: 2nd FLR | G10: 3rd FLR | H10: 4th FLR | I10: 5th FLR | J10: ROOFTOP | K10: TOTAL | L10: SOURCE / METHOD
A11: CF1 | B11: RC slab rendered and painted | C11: 1373.7 | D11: 0 | E11: 2.2 | F11: 1.2 | G11: 0 | H11: 8.7 | I11: 32.9 | J11: 17.7 | K11: =SUM(C11:J11) -> 1436.4 | L11: Speckle hatch, light density. Basement = car park soffit (A067). Stair soffits are NOT hatched on the RCPs, so they are not included.
A12: CF2 | B12: Plasterboard ceiling | C12: 0 | D12: 109.4 | E12: 40.3 | F12: 57.3 | G12: 40.5 | H12: 53.4 | I12: 419.1 | J12: 0 | K12: =SUM(C12:J12) -> 720 | L12: Dense speckle hatch. On 1st–4th floors this includes the perimeter bulkhead band around the CF7 grid. 5th floor excludes 22.6 m² of waffle cells.
A13: CF3 | B13: Waffle ceiling | C13: 0 | D13: 0 | E13: 0 | F13: 0 | G13: 0 | H13: 0 | I13: 47.3 | J13: 0 | K13: =SUM(C13:J13) -> 47.3 | L13: 5th floor (A073): 4 waffle zones measured as rectangles: 17.1 + 12.9 + 8.65 + 8.65.
A14: CF5 | B14: Cement board ceiling | C14: 15.7 | D14: 32.8 | E14: 32.7 | F14: 32.7 | G14: 32.7 | H14: 32.8 | I14: 45.5 | J14: 0 | K14: =SUM(C14:J14) -> 224.9 | L14: Red diagonal hatch: WCs, lobbies, PWD.
A15: CF6 | B15: Baffle ceiling | C15: 0 | D15: 11.6 | E15: 0 | F15: 0 | G15: 0 | H15: 0 | I15: 0 | J15: 0 | K15: =SUM(C15:J15) -> 11.6 | L15: Ground floor (A068): triangular baffle zone at the reception/stair void.
A16: CF7 | B16: 600 x 600mm acoustic ceiling | C16: 0 | D16: 179.6 | E16: 417.5 | F16: 418.6 | G16: 418.5 | H16: 415.4 | I16: 0 | J16: 0 | K16: =SUM(C16:J16) -> 1849.6 | L16: Magenta 600 grid, measured inside the CF2 perimeter band.
A17: CF8 | B17: CnC dark bronze aluminium panel ceiling | C17: 0 | D17: 317.5 | E17: 0 | F17: 0 | G17: 0 | H17: 0 | I17: 0 | J17: 0 | K17: =SUM(C17:J17) -> 317.5 | L17: Ground floor (A068): blue-hatched soffit band 125.0 + X-pattern panel zone over the drop-off 192.5 (labelled CF8).
B18: TOTAL | C18: =SUM(C11:C17) -> 1389.4 | D18: =SUM(D11:D17) -> 650.9 | E18: =SUM(E11:E17) -> 492.7 | F18: =SUM(F11:F17) -> 509.8 | G18: =SUM(G11:G17) -> 491.7 | H18: =SUM(H11:H17) -> 510.3 | I18: =SUM(I11:I17) -> 544.8 | J18: =SUM(J11:J17) -> 17.7 | K18: =SUM(K11:K17) -> 4607.3
A20: C. FINDINGS ON THE TAKE-OFF
A21: 1 | B21: CEILINGS — the BASEMENT and GROUND FLOOR ceiling sheets are swapped. "BASEMENT CEILING LAYOUT" holds the ground-floor rooms (A068: lettable office 173, reception, entrance terrace), and "GROUND FLOOR CEILING LAYOUT" holds the basement car park (A067). Every ceiling row in QTY SUMM therefore has columns C and D reversed. The check below is mapped correctly.
A22: 2 | B22: CEILINGS, ground floor — CF8 aluminium panel measures 317.5 m² against 230 in the take-off. The X-pattern CF8 zone over the drop-off (192.5 m²) appears to be missing. CF6 baffle ceiling (11.6 m²) is shown on A068 but taken as zero.
A23: 3 | B23: CEILINGS — basement CF1 measures 1,373.7 m² against 1,470.7 in the take-off (−97 m²). The take-off figure looks like a gross area that includes the cores, lifts and stairs.
A24: 4 | B24: CEILINGS — the 1st–4th floor CF1 "Staircase" items (33.8–38.9 m² per floor) are not hatched on any RCP. Keep them only if the stair soffits are to be rendered and painted.
A25: 5 | B25: CEILINGS — the 3rd floor CF2 perimeter band (40.5 m²) is taken as only 8.4. On the 5th floor, CF2 measures 419.1 against 480.1, and the CF1 balcony/terrace edge strips (32.9 m²) are missing.
A26: 6 | B26: BLOCKWORK — gross lengths agree to within about ±6% on six floors. The 2nd floor is 9% higher on drawing (161.2 vs 147.3 m) and the basement 6% lower (121.8 vs 129.2 m). Re-measure those two floors.
A27: 7 | B27: BLOCKWORK — every door on each floor is deducted from blockwork, including doors that sit in plasterboard partitions (2nd–4th floor offices), while no openings are deducted from plasterboard. This understates blockwork and overstates plasterboard.
A28: 8 | B28: HEIGHTS — floor-to-floor heights are used (3.30 typical, 4.50 GF, 4.45 basement). Section A-A (A016) shows a 250 mm slab, so the clear height to soffit is 3.05 m typical. Blockwork, plastering and partitions are overstated by about 7–8% (more where walls run under beams). The check keeps the take-off heights so that only the lengths are compared.
A29: 9 | B29: PLASTERBOARD — 2nd and 3rd floors agree (94.6 vs 95.6 m; 108.5 vs 109.0 m). The 4th floor is 72.7 m on drawing against 94.5 m in the take-off (+21.8 m).
A30: 10 | B30: CEMENT BOARD — about 5–9 m too long per floor on GF–4th (for example the 1st floor is 9.8 m on drawing against 15.0). These are WC cubicle partitions measured at full storey height; confirm the specified height.
A31: 11 | B31: EXTERNAL PLASTERING — the external girth is not independently measured, because the laser-cut mesh and curtain wall surround the block envelope in plan. The check carries the take-off figure and is marked NOT VERIFIED. The basement external plaster (149.8 m × 4.45 m) needs querying: the basement perimeter is below-ground concrete retaining wall (waterproofing, not render).
A32: 12 | B32: INTERNAL PLASTERING — the check adjusts the take-off girth by twice the block length variance (both faces). The concrete wall and column faces included in the take-off girth are carried unchanged.
A33: 13 | B33: WORKBOOK — QTY SUMM!L99 sums unlike items (m² of all trades). N16 is hard-coded (757.9). Column J "6th FLR" is unused: the building is basement + GF + 5 floors + rooftop. The CEMENT PARTITION sheet headings read "PLASTERBOARD PARTITION".

Sheet CEILING FINISHES SCHEDULE
A1: CEILING FINISHES SCHEDULE — AREAS BY FLOOR (m²)
A3: CODE | B3: CEILING FINISH | C3: BASEMENT | D3: GROUND FLR | E3: 1st FLR | F3: 2nd FLR | G3: 3rd FLR | H3: 4th FLR | I3: 5th FLR | J3: TOTAL | K3: UNIT
A4: CF1 | B4: RC slab rendered and painted | C4: ='BASEMENT CEILING LAYOUT'!E16 -> 36.4 | D4: ='GROUND FLOOR CEILING LAYOUT'!E16 -> 1470.7 | E4: ='FIRST FLOOR CEILING LAYOUT '!E21 -> 33.8 | F4: ='SECOND FLOOR CEILING LAYOUT '!E21 -> 38.5 | G4: ='THIRD FLOOR CEILING LAYOUT '!E21 -> 36.4 | H4: ='FOURTH FLOOR CEILING LAYOUT '!E21 -> 38.9 | I4: ='FIFTH FLOOR CEILING LAYOUT'!E40 -> 0 | J4: =SUM(C4:I4) -> 1654.7 | K4: m2
A5: CF2 | B5: Plasterboard ceiling | C5: ='BASEMENT CEILING LAYOUT'!K16 -> 126 | D5: ='GROUND FLOOR CEILING LAYOUT'!K16 -> 0 | E5: ='FIRST FLOOR CEILING LAYOUT '!K21 -> 41.5 | F5: ='SECOND FLOOR CEILING LAYOUT '!K21 -> 53.4 | G5: ='THIRD FLOOR CEILING LAYOUT '!K21 -> 8.4 | H5: ='FOURTH FLOOR CEILING LAYOUT '!K21 -> 48.5 | I5: ='FIFTH FLOOR CEILING LAYOUT'!K40 -> 480.1 | J5: =SUM(C5:I5) -> 757.9 | K5: m2
A6: CF3 | B6: Waffle ceiling | C6: ='BASEMENT CEILING LAYOUT'!Q16 -> 0 | D6: ='GROUND FLOOR CEILING LAYOUT'!Q16 -> 0 | E6: ='FIRST FLOOR CEILING LAYOUT '!Q21 -> 0 | F6: ='SECOND FLOOR CEILING LAYOUT '!Q21 -> 0 | G6: ='THIRD FLOOR CEILING LAYOUT '!Q21 -> 0 | H6: ='FOURTH FLOOR CEILING LAYOUT '!Q21 -> 0 | I6: ='FIFTH FLOOR CEILING LAYOUT'!Q40 -> 48.2 | J6: =SUM(C6:I6) -> 48.2 | K6: m2
A7: CF5 | B7: Cement board ceiling | C7: ='BASEMENT CEILING LAYOUT'!W16 -> 32.8 | D7: ='GROUND FLOOR CEILING LAYOUT'!W16 -> 16.2 | E7: ='FIRST FLOOR CEILING LAYOUT '!W21 -> 31.6 | F7: ='SECOND FLOOR CEILING LAYOUT '!W21 -> 32.4 | G7: ='THIRD FLOOR CEILING LAYOUT '!W21 -> 32.9 | H7: ='FOURTH FLOOR CEILING LAYOUT '!W21 -> 32.7 | I7: ='FIFTH FLOOR CEILING LAYOUT'!W40 -> 46.2 | J7: =SUM(C7:I7) -> 224.8 | K7: m2
A8: CF6 | B8: Baffle ceiling | C8: ='BASEMENT CEILING LAYOUT'!AC16 -> 0 | D8: ='GROUND FLOOR CEILING LAYOUT'!AC16 -> 0 | E8: ='FIRST FLOOR CEILING LAYOUT '!AC21 -> 0 | F8: ='SECOND FLOOR CEILING LAYOUT '!AC21 -> 0 | G8: ='THIRD FLOOR CEILING LAYOUT '!AC21 -> 0 | H8: ='FOURTH FLOOR CEILING LAYOUT '!AC21 -> 0 | I8: ='FIFTH FLOOR CEILING LAYOUT'!AC40 -> 0 | J8: =SUM(C8:I8) -> 0 | K8: m2
A9: CF7 | B9: 600 x 600mm acoustic ceiling | C9: ='BASEMENT CEILING LAYOUT'!AI16 -> 215 | D9: ='GROUND FLOOR CEILING LAYOUT'!AI16 -> 0 | E9: ='FIRST FLOOR CEILING LAYOUT '!AI21 -> 415.2 | F9: ='SECOND FLOOR CEILING LAYOUT '!AI21 -> 420.1 | G9: ='THIRD FLOOR CEILING LAYOUT '!AI21 -> 424 | H9: ='FOURTH FLOOR CEILING LAYOUT '!AI21 -> 411.9 | I9: ='FIFTH FLOOR CEILING LAYOUT'!AI40 -> 0 | J9: =SUM(C9:I9) -> 1886.2 | K9: m2
A10: CF8 | B10: CnC dark bronze metallic powder-coated aluminium panel ceiling | C10: ='BASEMENT CEILING LAYOUT'!AO16 -> 230 | D10: ='GROUND FLOOR CEILING LAYOUT'!AO16 -> 0 | E10: ='FIRST FLOOR CEILING LAYOUT '!AO21 -> 0 | F10: ='SECOND FLOOR CEILING LAYOUT '!AO21 -> 0 | G10: ='THIRD FLOOR CEILING LAYOUT '!AO21 -> 0 | H10: ='FOURTH FLOOR CEILING LAYOUT '!AO21 -> 0 | I10: ='FIFTH FLOOR CEILING LAYOUT'!AO40 -> 0 | J10: =SUM(C10:I10) -> 230 | K10: m2
A11: TOTAL | C11: =SUM(C4:C10) -> 640.2 | D11: =SUM(D4:D10) -> 1486.9 | E11: =SUM(E4:E10) -> 522.1 | F11: =SUM(F4:F10) -> 544.4 | G11: =SUM(G4:G10) -> 501.7 | H11: =SUM(H4:H10) -> 532 | I11: =SUM(I4:I10) -> 574.5 | J11: =SUM(C11:I11) -> 4801.8 | K11: m2
A13: CHECK — CEILING AREAS FROM REFLECTED CEILING PLANS A067–A074 (m²)
A14: CODE | B14: CEILING FINISH | C14: BASEMENT | D14: GROUND FLR | E14: 1st FLR | F14: 2nd FLR | G14: 3rd FLR | H14: 4th FLR | I14: 5th FLR | J14: ROOFTOP | K14: TOTAL | L14: UNIT
A15: =A4 -> CF1 | B15: =B4 -> RC slab rendered and painted | C15: ='DRAWING CHECK'!C11 -> 1373.7 | D15: ='DRAWING CHECK'!D11 -> 0 | E15: ='DRAWING CHECK'!E11 -> 2.2 | F15: ='DRAWING CHECK'!F11 -> 1.2 | G15: ='DRAWING CHECK'!G11 -> 0 | H15: ='DRAWING CHECK'!H11 -> 8.7 | I15: ='DRAWING CHECK'!I11 -> 32.9 | J15: ='DRAWING CHECK'!J11 -> 17.7 | K15: =SUM(C15:J15) -> 1436.4 | L15: m2
A16: =A5 -> CF2 | B16: =B5 -> Plasterboard ceiling | C16: ='DRAWING CHECK'!C12 -> 0 | D16: ='DRAWING CHECK'!D12 -> 109.4 | E16: ='DRAWING CHECK'!E12 -> 40.3 | F16: ='DRAWING CHECK'!F12 -> 57.3 | G16: ='DRAWING CHECK'!G12 -> 40.5 | H16: ='DRAWING CHECK'!H12 -> 53.4 | I16: ='DRAWING CHECK'!I12 -> 419.1 | J16: ='DRAWING CHECK'!J12 -> 0 | K16: =SUM(C16:J16) -> 720 | L16: m2
A17: =A6 -> CF3 | B17: =B6 -> Waffle ceiling | C17: ='DRAWING CHECK'!C13 -> 0 | D17: ='DRAWING CHECK'!D13 -> 0 | E17: ='DRAWING CHECK'!E13 -> 0 | F17: ='DRAWING CHECK'!F13 -> 0 | G17: ='DRAWING CHECK'!G13 -> 0 | H17: ='DRAWING CHECK'!H13 -> 0 | I17: ='DRAWING CHECK'!I13 -> 47.3 | J17: ='DRAWING CHECK'!J13 -> 0 | K17: =SUM(C17:J17) -> 47.3 | L17: m2
A18: =A7 -> CF5 | B18: =B7 -> Cement board ceiling | C18: ='DRAWING CHECK'!C14 -> 15.7 | D18: ='DRAWING CHECK'!D14 -> 32.8 | E18: ='DRAWING CHECK'!E14 -> 32.7 | F18: ='DRAWING CHECK'!F14 -> 32.7 | G18: ='DRAWING CHECK'!G14 -> 32.7 | H18: ='DRAWING CHECK'!H14 -> 32.8 | I18: ='DRAWING CHECK'!I14 -> 45.5 | J18: ='DRAWING CHECK'!J14 -> 0 | K18: =SUM(C18:J18) -> 224.9 | L18: m2
A19: =A8 -> CF6 | B19: =B8 -> Baffle ceiling | C19: ='DRAWING CHECK'!C15 -> 0 | D19: ='DRAWING CHECK'!D15 -> 11.6 | E19: ='DRAWING CHECK'!E15 -> 0 | F19: ='DRAWING CHECK'!F15 -> 0 | G19: ='DRAWING CHECK'!G15 -> 0 | H19: ='DRAWING CHECK'!H15 -> 0 | I19: ='DRAWING CHECK'!I15 -> 0 | J19: ='DRAWING CHECK'!J15 -> 0 | K19: =SUM(C19:J19) -> 11.6 | L19: m2
A20: =A9 -> CF7 | B20: =B9 -> 600 x 600mm acoustic ceiling | C20: ='DRAWING CHECK'!C16 -> 0 | D20: ='DRAWING CHECK'!D16 -> 179.6 | E20: ='DRAWING CHECK'!E16 -> 417.5 | F20: ='DRAWING CHECK'!F16 -> 418.6 | G20: ='DRAWING CHECK'!G16 -> 418.5 | H20: ='DRAWING CHECK'!H16 -> 415.4 | I20: ='DRAWING CHECK'!I16 -> 0 | J20: ='DRAWING CHECK'!J16 -> 0 | K20: =SUM(C20:J20) -> 1849.6 | L20: m2
A21: =A10 -> CF8 | B21: =B10 -> CnC dark bronze metallic powder-coated aluminium panel ceiling | C21: ='DRAWING CHECK'!C17 -> 0 | D21: ='DRAWING CHECK'!D17 -> 317.5 | E21: ='DRAWING CHECK'!E17 -> 0 | F21: ='DRAWING CHECK'!F17 -> 0 | G21: ='DRAWING CHECK'!G17 -> 0 | H21: ='DRAWING CHECK'!H17 -> 0 | I21: ='DRAWING CHECK'!I17 -> 0 | J21: ='DRAWING CHECK'!J17 -> 0 | K21: =SUM(C21:J21) -> 317.5 | L21: m2
A22: TOTAL | C22: =SUM(C15:C21) -> 1389.4 | D22: =SUM(D15:D21) -> 650.9 | E22: =SUM(E15:E21) -> 492.7 | F22: =SUM(F15:F21) -> 509.8 | G22: =SUM(G15:G21) -> 491.7 | H22: =SUM(H15:H21) -> 510.3 | I22: =SUM(I15:I21) -> 544.8 | J22: =SUM(J15:J21) -> 17.7 | K22: =SUM(K15:K21) -> 4607.3
A24: VARIANCE — TAKE-OFF (rows 4–10, as linked) minus CHECK (rows 15–21). Note: the take-off BASEMENT/GROUND columns are swapped (see DRAWING CHECK finding 1).
A25: CODE | B25: CEILING FINISH | C25: BASEMENT | D25: GROUND FLR | E25: 1st FLR | F25: 2nd FLR | G25: 3rd FLR | H25: 4th FLR | I25: 5th FLR | J25: ROOFTOP | K25: TOTAL | L25: UNIT
A26: =A4 -> CF1 | B26: =B4 -> RC slab rendered and painted | C26: =C4-C15 -> -1337.3 | D26: =D4-D15 -> 1470.7 | E26: =E4-E15 -> 31.6 | F26: =F4-F15 -> 37.3 | G26: =G4-G15 -> 36.4 | H26: =H4-H15 -> 30.2 | I26: =I4-I15 -> -32.9 | J26: =0-J15 -> -17.7 | K26: =J4-K15 -> 218.3 | L26: m2
A27: =A5 -> CF2 | B27: =B5 -> Plasterboard ceiling | C27: =C5-C16 -> 126 | D27: =D5-D16 -> -109.4 | E27: =E5-E16 -> 1.2 | F27: =F5-F16 -> -3.9 | G27: =G5-G16 -> -32.1 | H27: =H5-H16 -> -4.9 | I27: =I5-I16 -> 61 | J27: =0-J16 -> 0 | K27: =J5-K16 -> 37.9 | L27: m2
A28: =A6 -> CF3 | B28: =B6 -> Waffle ceiling | C28: =C6-C17 -> 0 | D28: =D6-D17 -> 0 | E28: =E6-E17 -> 0 | F28: =F6-F17 -> 0 | G28: =G6-G17 -> 0 | H28: =H6-H17 -> 0 | I28: =I6-I17 -> 0.9 | J28: =0-J17 -> 0 | K28: =J6-K17 -> 0.9 | L28: m2
A29: =A7 -> CF5 | B29: =B7 -> Cement board ceiling | C29: =C7-C18 -> 17.1 | D29: =D7-D18 -> -16.6 | E29: =E7-E18 -> -1.1 | F29: =F7-F18 -> -0.3 | G29: =G7-G18 -> 0.2 | H29: =H7-H18 -> -0.1 | I29: =I7-I18 -> 0.7 | J29: =0-J18 -> 0 | K29: =J7-K18 -> -0.1 | L29: m2
A30: =A8 -> CF6 | B30: =B8 -> Baffle ceiling | C30: =C8-C19 -> 0 | D30: =D8-D19 -> -11.6 | E30: =E8-E19 -> 0 | F30: =F8-F19 -> 0 | G30: =G8-G19 -> 0 | H30: =H8-H19 -> 0 | I30: =I8-I19 -> 0 | J30: =0-J19 -> 0 | K30: =J8-K19 -> -11.6 | L30: m2
A31: =A9 -> CF7 | B31: =B9 -> 600 x 600mm acoustic ceiling | C31: =C9-C20 -> 215 | D31: =D9-D20 -> -179.6 | E31: =E9-E20 -> -2.3 | F31: =F9-F20 -> 1.5 | G31: =G9-G20 -> 5.5 | H31: =H9-H20 -> -3.5 | I31: =I9-I20 -> 0 | J31: =0-J20 -> 0 | K31: =J9-K20 -> 36.6 | L31: m2
A32: =A10 -> CF8 | B32: =B10 -> CnC dark bronze metallic powder-coated aluminium panel ceiling | C32: =C10-C21 -> 230 | D32: =D10-D21 -> -317.5 | E32: =E10-E21 -> 0 | F32: =F10-F21 -> 0 | G32: =G10-G21 -> 0 | H32: =H10-H21 -> 0 | I32: =I10-I21 -> 0 | J32: =0-J21 -> 0 | K32: =J10-K21 -> -87.5 | L32: m2

Sheet BLOCK WORK
A1: BASEMENT BLOCK WALL | I1: GROUND FLOOR BLOCKWORK | Q1: FIRST FLOOR BLOCKWORK | Y1: SECOND FLOOR BLOCKWORK | AG1: THIRD FLOOR BLOCKWORK | AO1: FOURTH FLOOR BLOCKWORK | AW1: FIFTH FLOOR BLOCKWORK | BE1: ROOFTOP FLOOR BLOCKWORK
A2: ITEM | B2: DESCRIPTION | C2: NO. | D2: LENG. | E2: HEIGHT | F2: PERIMETER OF OPENING | G2: AREA | I2: ITEM | J2: DESCRIPTION | K2: NO. | L2: LENG. | M2: HEIGHT | N2: PERIMETER OF OPENING | O2: AREA | Q2: ITEM | R2: DESCRIPTION | S2: NO. | T2: LENG. | U2: HEIGHT | V2: PERIMETER OF OPENING | W2: AREA | Y2: ITEM | Z2: DESCRIPTION | AA2: NO. | AB2: LENG. | AC2: HEIGHT | AD2: PERIMETER OF OPENING | AE2: AREA | AG2: ITEM | AH2: DESCRIPTION | AI2: NO. | AJ2: LENG. | AK2: HEIGHT | AL2: PERIMETER OF OPENING | AM2: AREA | AO2: ITEM | AP2: DESCRIPTION | AQ2: NO. | AR2: LENG. | AS2: HEIGHT | AT2: PERIMETER OF OPENING | AU2: AREA | AW2: ITEM | AX2: DESCRIPTION | AY2: NO. | AZ2: LENG. | BA2: HEIGHT | BB2: PERIMETER OF OPENING | BC2: AREA | BE2: ITEM | BF2: DESCRIPTION | BG2: NO. | BH2: LENG. | BI2: HEIGHT | BJ2: PERIMETER OF OPENING | BK2: AREA
A4: A | B4: 150mm block wall | C4: 1 | D4: 129.2 | E4: 4.45 | G4: =C4*D4*E4 -> 574.94 | I4: A | J4: 150mm block wall | K4: 1 | L4: 150.1 | M4: 4.5 | O4: =K4*L4*M4 -> 675.45 | Q4: A | R4: 150mm block wall | S4: 1 | T4: 148.2 | U4: 3.3 | W4: =S4*T4*U4 -> 489.06 | Y4: A | Z4: 150mm block wall | AA4: 1 | AB4: 147.3 | AC4: 3.3 | AE4: =AA4*AB4*AC4 -> 486.09 | AG4: A | AH4: 150mm block wall | AI4: 1 | AJ4: 141 | AK4: 3.3 | AM4: =AI4*AJ4*AK4 -> 465.3 | AO4: A | AP4: 150mm block wall | AQ4: 1 | AR4: 149.1 | AS4: 3.3 | AU4: =AQ4*AR4*AS4 -> 492.03 | AW4: A | AX4: 150mm block wall | AY4: 1 | AZ4: 213.9 | BA4: 3.3 | BC4: =AY4*AZ4*BA4 -> 705.87 | BE4: A | BF4: 150mm block wall | BG4: 1 | BH4: 144.2 | BI4: 1.5 | BK4: =BG4*BH4*BI4 -> 216.3
G6: =G4 -> 574.94 | O6: =O4 -> 675.45 | W6: =W4 -> 489.06 | AE6: =AE4 -> 486.09 | AM6: =AM4 -> 465.3 | AU6: =AU4 -> 492.03 | BC6: =BC4 -> 705.87 | BK6: =BK4 -> 216.3
B8: Ddt window | J8: Ddt window | R8: Ddt window | Z8: Ddt window | AH8: Ddt window | AP8: Ddt window | AX8: Ddt window | BF8: Ddt window
A9: B | B9: W1 | C9: 3 | D9: 1.6 | E9: 1 | F9: =2*(D9+E9)*C9 -> 15.6 | G9: =C9*D9*E9 -> 4.8 | I9: B | J9: W2 | K9: 4 | L9: ='WINDOWS AND DOORS SCHEDULE'!D6 -> 2.5 | M9: ='WINDOWS AND DOORS SCHEDULE'!E6 -> 0.75 | N9: =2*(L9+M9)*K9 -> 26 | O9: =K9*L9*M9 -> 7.5 | Q9: B | R9: W2 | S9: 4 | T9: ='WINDOWS AND DOORS SCHEDULE'!D6 -> 2.5 | U9: ='WINDOWS AND DOORS SCHEDULE'!E6 -> 0.75 | V9: =2*(T9+U9)*S9 -> 26 | W9: =S9*T9*U9 -> 7.5 | Y9: B | Z9: W2 | AA9: 6 | AB9: ='WINDOWS AND DOORS SCHEDULE'!D6 -> 2.5 | AC9: ='WINDOWS AND DOORS SCHEDULE'!E6 -> 0.75 | AD9: =2*(AB9+AC9)*AA9 -> 39 | AE9: =AA9*AB9*AC9 -> 11.25 | AG9: B | AH9: W2 | AI9: 4 | AJ9: ='WINDOWS AND DOORS SCHEDULE'!D6 -> 2.5 | AK9: ='WINDOWS AND DOORS SCHEDULE'!E6 -> 0.75 | AL9: =2*(AJ9+AK9)*AI9 -> 26 | AM9: =AI9*AJ9*AK9 -> 7.5 | AO9: B | AP9: W2 | AQ9: 4 | AR9: ='WINDOWS AND DOORS SCHEDULE'!D6 -> 2.5 | AS9: ='WINDOWS AND DOORS SCHEDULE'!E6 -> 0.75 | AT9: =2*(AR9+AS9)*AQ9 -> 26 | AU9: =AQ9*AR9*AS9 -> 7.5 | AW9: B | AX9: W2 | AY9: 4 | AZ9: ='WINDOWS AND DOORS SCHEDULE'!D6 -> 2.5 | BA9: ='WINDOWS AND DOORS SCHEDULE'!E6 -> 0.75 | BB9: =2*(AZ9+BA9)*AY9 -> 26 | BC9: =AY9*AZ9*BA9 -> 7.5
J10: W3 | K10: 3 | L10: ='WINDOWS AND DOORS SCHEDULE'!D7 -> 1.6 | M10: ='WINDOWS AND DOORS SCHEDULE'!E7 -> 3 | N10: =2*(L10+M10)*K10 -> 27.6 | O10: =K10*L10*M10 -> 14.4 | R10: W4 | S10: 2 | T10: ='WINDOWS AND DOORS SCHEDULE'!D8 -> 1.5 | U10: ='WINDOWS AND DOORS SCHEDULE'!E8 -> 1.2 | V10: =2*(T10+U10)*S10 -> 10.8 | W10: =S10*T10*U10 -> 3.6 | Z10: W4 | AA10: 2 | AB10: ='WINDOWS AND DOORS SCHEDULE'!D8 -> 1.5 | AC10: ='WINDOWS AND DOORS SCHEDULE'!E8 -> 1.2 | AD10: =2*(AB10+AC10)*AA10 -> 10.8 | AE10: =AA10*AB10*AC10 -> 3.6 | AH10: W4 | AI10: 2 | AJ10: ='WINDOWS AND DOORS SCHEDULE'!D8 -> 1.5 | AK10: ='WINDOWS AND DOORS SCHEDULE'!E8 -> 1.2 | AL10: =2*(AJ10+AK10)*AI10 -> 10.8 | AM10: =AI10*AJ10*AK10 -> 3.6 | AP10: W4 | AQ10: 2 | AR10: ='WINDOWS AND DOORS SCHEDULE'!D8 -> 1.5 | AS10: ='WINDOWS AND DOORS SCHEDULE'!E8 -> 1.2 | AT10: =2*(AR10+AS10)*AQ10 -> 10.8 | AU10: =AQ10*AR10*AS10 -> 3.6 | AX10: W4 | AY10: 1 | AZ10: ='WINDOWS AND DOORS SCHEDULE'!D8 -> 1.5 | BA10: ='WINDOWS AND DOORS SCHEDULE'!E8 -> 1.2 | BB10: =2*(AZ10+BA10)*AY10 -> 5.4 | BC10: =AY10*AZ10*BA10 -> 1.8
J11: W4 | K11: 2 | L11: ='WINDOWS AND DOORS SCHEDULE'!D8 -> 1.5 | M11: ='WINDOWS AND DOORS SCHEDULE'!E8 -> 1.2 | N11: =2*(L11+M11)*K11 -> 10.8 | O11: =K11*L11*M11 -> 3.6 | R11: W5 | S11: 2 | T11: ='WINDOWS AND DOORS SCHEDULE'!D9 -> 0.9 | U11: ='WINDOWS AND DOORS SCHEDULE'!E9 -> 2 | V11: =2*(T11+U11)*S11 -> 11.6 | W11: =S11*T11*U11 -> 3.6 | Z11: W5 | AA11: 2 | AB11: ='WINDOWS AND DOORS SCHEDULE'!D9 -> 0.9 | AC11: ='WINDOWS AND DOORS SCHEDULE'!E9 -> 2 | AD11: =2*(AB11+AC11)*AA11 -> 11.6 | AE11: =AA11*AB11*AC11 -> 3.6 | AH11: W5 | AI11: 2 | AJ11: ='WINDOWS AND DOORS SCHEDULE'!D9 -> 0.9 | AK11: ='WINDOWS AND DOORS SCHEDULE'!E9 -> 2 | AL11: =2*(AJ11+AK11)*AI11 -> 11.6 | AM11: =AI11*AJ11*AK11 -> 3.6 | AP11: W5 | AQ11: 2 | AR11: ='WINDOWS AND DOORS SCHEDULE'!D9 -> 0.9 | AS11: ='WINDOWS AND DOORS SCHEDULE'!E9 -> 2 | AT11: =2*(AR11+AS11)*AQ11 -> 11.6 | AU11: =AQ11*AR11*AS11 -> 3.6 | AX11: W5 | AY11: 5 | AZ11: ='WINDOWS AND DOORS SCHEDULE'!D9 -> 0.9 | BA11: ='WINDOWS AND DOORS SCHEDULE'!E9 -> 2 | BB11: =2*(AZ11+BA11)*AY11 -> 29 | BC11: =AY11*AZ11*BA11 -> 9
J12: W7 | K12: 1 | L12: ='WINDOWS AND DOORS SCHEDULE'!D11 -> 1.2 | M12: ='WINDOWS AND DOORS SCHEDULE'!E11 -> 0.75 | N12: =2*(L12+M12)*K12 -> 3.9 | O12: =K12*L12*M12 -> 0.9 | R12: W7 | S12: 1 | T12: ='WINDOWS AND DOORS SCHEDULE'!D11 -> 1.2 | U12: ='WINDOWS AND DOORS SCHEDULE'!E11 -> 0.75 | V12: =2*(T12+U12)*S12 -> 3.9 | W12: =S12*T12*U12 -> 0.9 | Z12: W7 | AA12: 1 | AB12: ='WINDOWS AND DOORS SCHEDULE'!D11 -> 1.2 | AC12: ='WINDOWS AND DOORS SCHEDULE'!E11 -> 0.75 | AD12: =2*(AB12+AC12)*AA12 -> 3.9 | AE12: =AA12*AB12*AC12 -> 0.9 | AH12: W7 | AI12: 1 | AJ12: ='WINDOWS AND DOORS SCHEDULE'!D11 -> 1.2 | AK12: ='WINDOWS AND DOORS SCHEDULE'!E11 -> 0.75 | AL12: =2*(AJ12+AK12)*AI12 -> 3.9 | AM12: =AI12*AJ12*AK12 -> 0.9 | AP12: W8 | AQ12: 4 | AR12: ='WINDOWS AND DOORS SCHEDULE'!D12 -> 1.8 | AS12: ='WINDOWS AND DOORS SCHEDULE'!E12 -> 1 | AT12: =2*(AR12+AS12)*AQ12 -> 22.4 | AU12: =AQ12*AR12*AS12 -> 7.2 | AX12: W7 | AY12: 1 | AZ12: ='WINDOWS AND DOORS SCHEDULE'!D11 -> 1.2 | BA12: ='WINDOWS AND DOORS SCHEDULE'!E11 -> 0.75 | BB12: =2*(AZ12+BA12)*AY12 -> 3.9 | BC12: =AY12*AZ12*BA12 -> 0.9
Z13: W8 | AA13: 3 | AB13: ='WINDOWS AND DOORS SCHEDULE'!D12 -> 1.8 | AC13: ='WINDOWS AND DOORS SCHEDULE'!E12 -> 1 | AD13: =2*(AB13+AC13)*AA13 -> 16.8 | AE13: =AA13*AB13*AC13 -> 5.4 | AH13: W8 | AI13: 3 | AJ13: ='WINDOWS AND DOORS SCHEDULE'!D12 -> 1.8 | AK13: ='WINDOWS AND DOORS SCHEDULE'!E12 -> 1 | AL13: =2*(AJ13+AK13)*AI13 -> 16.8 | AM13: =AI13*AJ13*AK13 -> 5.4
B15: Total window | F15: =F9 -> 15.6 | G15: =G9 -> 4.8 | J15: Total window | N15: =SUM(N9:N14) -> 68.3 | O15: =SUM(O9:O14) -> 26.4 | R15: Total window | V15: =SUM(V9:V14) -> 52.3 | W15: =SUM(W9:W14) -> 15.6 | Z15: Total window | AD15: =SUM(AD8:AD14) -> 82.1 | AE15: =SUM(AE9:AE13) -> 24.75 | AH15: Total window | AL15: =SUM(AL9:AL13) -> 69.1 | AM15: =SUM(AM9:AM13) -> 21 | AP15: Total window | AT15: =SUM(AT9:AT14) -> 70.8 | AU15: =SUM(AU9:AU14) -> 21.9 | AX15: Total window | BB15: =SUM(BB9:BB14) -> 64.3 | BC15: =SUM(BC9:BC14) -> 19.2 | BF15: Total window | BK15: =SUM(BK14:BK14) -> 0
B16: Ddt door | J16: Ddt door | R16: Ddt door | Z16: Ddt door | AH16: Ddt door | AX16: Ddt door | BF16: Ddt door
A17: C | B17: D2 | C17: 4 | D17: ='WINDOWS AND DOORS SCHEDULE'!L6 -> 0.9 | E17: ='WINDOWS AND DOORS SCHEDULE'!M6 -> 2.1 | F17: =2*(D17+E17)*C17 -> 24 | G17: =C17*D17*E17 -> 7.56 | I17: C | J17: D1 | K17: 3 | L17: ='WINDOWS AND DOORS SCHEDULE'!L5 -> 1.2 | M17: ='WINDOWS AND DOORS SCHEDULE'!M5 -> 2.1 | N17: =2*(L17+M17)*K17 -> 19.8 | O17: =K17*L17*M17 -> 7.56 | Q17: C | R17: D1 | S17: 3 | T17: ='WINDOWS AND DOORS SCHEDULE'!L5 -> 1.2 | U17: ='WINDOWS AND DOORS SCHEDULE'!M5 -> 2.1 | V17: =2*(T17+U17)*S17 -> 19.8 | W17: =S17*T17*U17 -> 7.56 | Y17: C | Z17: D1 | AA17: 3 | AB17: ='WINDOWS AND DOORS SCHEDULE'!L5 -> 1.2 | AC17: ='WINDOWS AND DOORS SCHEDULE'!M5 -> 2.1 | AD17: =2*(AB17+AC17)*AA17 -> 19.8 | AE17: =AA17*AB17*AC17 -> 7.56 | AG17: C | AH17: D1 | AI17: 2 | AJ17: ='WINDOWS AND DOORS SCHEDULE'!L5 -> 1.2 | AK17: ='WINDOWS AND DOORS SCHEDULE'!M5 -> 2.1 | AL17: =2*(AJ17+AK17)*AI17 -> 13.2 | AM17: =AI17*AJ17*AK17 -> 5.04 | AP17: Ddt door | AW17: C | AX17: D1 | AY17: 2 | AZ17: ='WINDOWS AND DOORS SCHEDULE'!L5 -> 1.2 | BA17: ='WINDOWS AND DOORS SCHEDULE'!M5 -> 2.1 | BB17: =2*(AZ17+BA17)*AY17 -> 13.2 | BC17: =AY17*AZ17*BA17 -> 5.04 | BE17: C | BF17: D8 | BG17: 1 | BH17: ='WINDOWS AND DOORS SCHEDULE'!L12 -> 1.8 | BI17: ='WINDOWS AND DOORS SCHEDULE'!M12 -> 2.1 | BJ17: =2*(BH17+BI17)*BG17 -> 7.8 | BK17: =BG17*BH17*BI17 -> 3.78
A18: D | B18: D3 | C18: 8 | D18: ='WINDOWS AND DOORS SCHEDULE'!L7 -> 0.75 | E18: ='WINDOWS AND DOORS SCHEDULE'!M7 -> 2.1 | F18: =2*(D18+E18)*C18 -> 45.6 | G18: =C18*D18*E18 -> 12.6 | I18: D | J18: D2 | K18: 3 | L18: ='WINDOWS AND DOORS SCHEDULE'!L6 -> 0.9 | M18: ='WINDOWS AND DOORS SCHEDULE'!M6 -> 2.1 | N18: =2*(L18+M18)*K18 -> 18 | O18: =K18*L18*M18 -> 5.67 | Q18: D | R18: D2 | S18: 4 | T18: ='WINDOWS AND DOORS SCHEDULE'!L6 -> 0.9 | U18: ='WINDOWS AND DOORS SCHEDULE'!M6 -> 2.1 | V18: =2*(T18+U18)*S18 -> 24 | W18: =S18*T18*U18 -> 7.56 | Y18: D | Z18: D2 | AA18: 8 | AB18: ='WINDOWS AND DOORS SCHEDULE'!L6 -> 0.9 | AC18: ='WINDOWS AND DOORS SCHEDULE'!M6 -> 2.1 | AD18: =2*(AB18+AC18)*AA18 -> 48 | AE18: =AA18*AB18*AC18 -> 15.12 | AG18: D | AH18: D2 | AI18: 3 | AJ18: ='WINDOWS AND DOORS SCHEDULE'!L6 -> 0.9 | AK18: ='WINDOWS AND DOORS SCHEDULE'!M6 -> 2.1 | AL18: =2*(AJ18+AK18)*AI18 -> 18 | AM18: =AI18*AJ18*AK18 -> 5.67 | AO18: C | AP18: D1 | AQ18: 2 | AR18: ='WINDOWS AND DOORS SCHEDULE'!L5 -> 1.2 | AS18: ='WINDOWS AND DOORS SCHEDULE'!M5 -> 2.1 | AT18: =2*(AR18+AS18)*AQ18 -> 13.2 | AU18: =AQ18*AR18*AS18 -> 5.04 | AW18: D | AX18: D2 | AY18: 13 | AZ18: ='WINDOWS AND DOORS SCHEDULE'!L6 -> 0.9 | BA18: ='WINDOWS AND DOORS SCHEDULE'!M6 -> 2.1 | BB18: =2*(AZ18+BA18)*AY18 -> 78 | BC18: =AY18*AZ18*BA18 -> 24.57
A19: E | B19: D4 | C19: 1 | D19: ='WINDOWS AND DOORS SCHEDULE'!L8 -> 0.5 | E19: ='WINDOWS AND DOORS SCHEDULE'!M8 -> 2.1 | F19: =2*(D19+E19)*C19 -> 5.2 | G19: =C19*D19*E19 -> 1.05 | I19: E | J19: D3 | K19: 11 | L19: ='WINDOWS AND DOORS SCHEDULE'!L7 -> 0.75 | M19: ='WINDOWS AND DOORS SCHEDULE'!M7 -> 2.1 | N19: =2*(L19+M19)*K19 -> 62.7 | O19: =K19*L19*M19 -> 17.325 | Q19: E | R19: D3 | S19: 11 | T19: ='WINDOWS AND DOORS SCHEDULE'!L7 -> 0.75 | U19: ='WINDOWS AND DOORS SCHEDULE'!M7 -> 2.1 | V19: =2*(T19+U19)*S19 -> 62.7 | W19: =S19*T19*U19 -> 17.325 | Y19: E | Z19: D3 | AA19: 13 | AB19: ='WINDOWS AND DOORS SCHEDULE'!L7 -> 0.75 | AC19: ='WINDOWS AND DOORS SCHEDULE'!M7 -> 2.1 | AD19: =2*(AB19+AC19)*AA19 -> 74.1 | AE19: =AA19*AB19*AC19 -> 20.475 | AG19: E | AH19: D3 | AI19: 13 | AJ19: ='WINDOWS AND DOORS SCHEDULE'!L7 -> 0.75 | AK19: ='WINDOWS AND DOORS SCHEDULE'!M7 -> 2.1 | AL19: =2*(AJ19+AK19)*AI19 -> 74.1 | AM19: =AI19*AJ19*AK19 -> 20.475 | AO19: D | AP19: D2 | AQ19: 14 | AR19: ='WINDOWS AND DOORS SCHEDULE'!L6 -> 0.9 | AS19: ='WINDOWS AND DOORS SCHEDULE'!M6 -> 2.1 | AT19: =2*(AR19+AS19)*AQ19 -> 84 | AU19: =AQ19*AR19*AS19 -> 26.46 | AW19: E | AX19: D3 | AY19: 5 | AZ19: ='WINDOWS AND DOORS SCHEDULE'!L7 -> 0.75 | BA19: ='WINDOWS AND DOORS SCHEDULE'!M7 -> 2.1 | BB19: =2*(AZ19+BA19)*AY19 -> 28.5 | BC19: =AY19*AZ19*BA19 -> 7.875
I20: F | J20: D4 | K20: 3 | L20: ='WINDOWS AND DOORS SCHEDULE'!L8 -> 0.5 | M20: ='WINDOWS AND DOORS SCHEDULE'!M8 -> 2.1 | N20: =2*(L20+M20)*K20 -> 15.6 | O20: =K20*L20*M20 -> 3.15 | Q20: F | R20: D4 | S20: 2 | T20: ='WINDOWS AND DOORS SCHEDULE'!L8 -> 0.5 | U20: ='WINDOWS AND DOORS SCHEDULE'!M8 -> 2.1 | V20: =2*(T20+U20)*S20 -> 10.4 | W20: =S20*T20*U20 -> 2.1 | Y20: F | Z20: D4 | AA20: 2 | AB20: ='WINDOWS AND DOORS SCHEDULE'!L8 -> 0.5 | AC20: ='WINDOWS AND DOORS SCHEDULE'!M8 -> 2.1 | AD20: =2*(AB20+AC20)*AA20 -> 10.4 | AE20: =AA20*AB20*AC20 -> 2.1 | AG20: F | AH20: D4 | AI20: 2 | AJ20: ='WINDOWS AND DOORS SCHEDULE'!L8 -> 0.5 | AK20: ='WINDOWS AND DOORS SCHEDULE'!M8 -> 2.1 | AL20: =2*(AJ20+AK20)*AI20 -> 10.4 | AM20: =AI20*AJ20*AK20 -> 2.1 | AO20: E | AP20: D3 | AQ20: 16 | AR20: ='WINDOWS AND DOORS SCHEDULE'!L7 -> 0.75 | AS20: ='WINDOWS AND DOORS SCHEDULE'!M7 -> 2.1 | AT20: =2*(AR20+AS20)*AQ20 -> 91.2 | AU20: =AQ20*AR20*AS20 -> 25.2 | AW20: F | AX20: D4 | AY20: 1 | AZ20: ='WINDOWS AND DOORS SCHEDULE'!L8 -> 0.5 | BA20: ='WINDOWS AND DOORS SCHEDULE'!M8 -> 2.1 | BB20: =2*(AZ20+BA20)*AY20 -> 5.2 | BC20: =AY20*AZ20*BA20 -> 1.05
I21: G | J21: D7 | K21: 2 | L21: ='WINDOWS AND DOORS SCHEDULE'!L11 -> 2 | M21: ='WINDOWS AND DOORS SCHEDULE'!M11 -> 2.1 | N21: =2*(L21+M21)*K21 -> 16.4 | O21: =K21*L21*M21 -> 8.4 | Q21: G | R21: D6 | S21: 1 | T21: ='WINDOWS AND DOORS SCHEDULE'!L10 -> 0.9 | U21: ='WINDOWS AND DOORS SCHEDULE'!M10 -> 2.1 | V21: =2*(T21+U21)*S21 -> 6 | W21: =S21*T21*U21 -> 1.89 | Y21: G | Z21: D6 | AA21: 1 | AB21: ='WINDOWS AND DOORS SCHEDULE'!L10 -> 0.9 | AC21: ='WINDOWS AND DOORS SCHEDULE'!M10 -> 2.1 | AD21: =2*(AB21+AC21)*AA21 -> 6 | AE21: =AA21*AB21*AC21 -> 1.89 | AG21: G | AH21: D6 | AI21: 1 | AJ21: ='WINDOWS AND DOORS SCHEDULE'!L10 -> 0.9 | AK21: ='WINDOWS AND DOORS SCHEDULE'!M10 -> 2.1 | AL21: =2*(AJ21+AK21)*AI21 -> 6 | AM21: =AI21*AJ21*AK21 -> 1.89 | AO21: F | AP21: D4 | AQ21: 2 | AR21: ='WINDOWS AND DOORS SCHEDULE'!L8 -> 0.5 | AS21: ='WINDOWS AND DOORS SCHEDULE'!M8 -> 2.1 | AT21: =2*(AR21+AS21)*AQ21 -> 10.4 | AU21: =AQ21*AR21*AS21 -> 2.1 | AW21: G | AX21: D5 | AY21: 1 | AZ21: ='WINDOWS AND DOORS SCHEDULE'!L9 -> 4 | BA21: ='WINDOWS AND DOORS SCHEDULE'!M9 -> 2.1 | BB21: =2*(AZ21+BA21)*AY21 -> 12.2 | BC21: =AY21*AZ21*BA21 -> 8.4
AG22: H | AH22: D8 | AI22: 2 | AJ22: ='WINDOWS AND DOORS SCHEDULE'!L12 -> 1.8 | AK22: ='WINDOWS AND DOORS SCHEDULE'!M12 -> 2.1 | AL22: =2*(AJ22+AK22)*AI22 -> 15.6 | AM22: =AI22*AJ22*AK22 -> 7.56 | AO22: G | AP22: D6 | AQ22: 1 | AR22: ='WINDOWS AND DOORS SCHEDULE'!L10 -> 0.9 | AS22: ='WINDOWS AND DOORS SCHEDULE'!M10 -> 2.1 | AT22: =2*(AR22+AS22)*AQ22 -> 6 | AU22: =AQ22*AR22*AS22 -> 1.89 | AW22: H | AX22: D6 | AY22: 1 | AZ22: ='WINDOWS AND DOORS SCHEDULE'!L10 -> 0.9 | BA22: ='WINDOWS AND DOORS SCHEDULE'!M10 -> 2.1 | BB22: =2*(AZ22+BA22)*AY22 -> 6 | BC22: =AY22*AZ22*BA22 -> 1.89
AO23: H | AP23: D8 | AQ23: 1 | AR23: ='WINDOWS AND DOORS SCHEDULE'!L12 -> 1.8 | AS23: ='WINDOWS AND DOORS SCHEDULE'!M12 -> 2.1 | AT23: =2*(AR23+AS23)*AQ23 -> 7.8 | AU23: =AQ23*AR23*AS23 -> 3.78
B24: Toal Doors | F24: =SUM(F17:F23) -> 74.8 | G24: =SUM(G17:G23) -> 21.21 | J24: Toal Doors | N24: =SUM(N17:N23) -> 132.5 | O24: =SUM(O17:O23) -> 42.105 | R24: Toal Doors | V24: =SUM(V17:V23) -> 122.9 | W24: =SUM(W17:W23) -> 36.435 | Z24: Toal Doors | AD24: =SUM(AD17:AD23) -> 158.3 | AE24: =SUM(AE17:AE23) -> 47.145 | AH24: Toal Doors | AL24: =SUM(AL17:AL23) -> 137.3 | AM24: =SUM(AM17:AM23) -> 42.735 | AP24: Toal Doors | AT24: =SUM(AT18:AT23) -> 212.6 | AU24: =SUM(AU18:AU23) -> 64.47 | AX24: Toal Doors | BB24: =SUM(BB17:BB23) -> 143.1 | BC24: =SUM(BC17:BC23) -> 48.825 | BF24: Toal Doors | BJ24: =SUM(BJ17:BJ23) -> 7.8 | BK24: =SUM(BK17:BK23) -> 3.78
G29: =G6-(G15+G24) -> 548.93 | O29: =O6-(O15+O24) -> 606.945 | W29: =W6-(W15+W24) -> 437.025 | AE29: =AE6-(AE15+AE24) -> 414.195 | AM29: =AM6-(AM15+AM24) -> 401.565 | AU29: =AU6-(AU15+AU24) -> 405.66 | BC29: =BC6-(BC15+BC24) -> 637.845 | BK29: =BK6-(BK15+BK24) -> 212.52
G31: =G29*2 -> 1097.86 | O31: =O29*2 -> 1213.89
A33: CHECK | B33: DRAWING CHECK | I33: CHECK | J33: DRAWING CHECK | Q33: CHECK | R33: DRAWING CHECK | Y33: CHECK | Z33: DRAWING CHECK | AG33: CHECK | AH33: DRAWING CHECK | AO33: CHECK | AP33: DRAWING CHECK | AW33: CHECK | AX33: DRAWING CHECK | BE33: CHECK | BF33: DRAWING CHECK
B34: 150mm block wall (drawing, gross) | C34: 1 | D34: ='DRAWING CHECK'!C5 -> 121.8 | E34: =E4 -> 4.45 | G34: =C34*D34*E34 -> 542.01 | J34: 150mm block wall (drawing, gross) | K34: 1 | L34: ='DRAWING CHECK'!D5 -> 157.3 | M34: =M4 -> 4.5 | O34: =K34*L34*M34 -> 707.85 | R34: 150mm block wall (drawing, gross) | S34: 1 | T34: ='DRAWING CHECK'!E5 -> 154.1 | U34: =U4 -> 3.3 | W34: =S34*T34*U34 -> 508.53 | Z34: 150mm block wall (drawing, gross) | AA34: 1 | AB34: ='DRAWING CHECK'!F5 -> 161.2 | AC34: =AC4 -> 3.3 | AE34: =AA34*AB34*AC34 -> 531.96 | AH34: 150mm block wall (drawing, gross) | AI34: 1 | AJ34: ='DRAWING CHECK'!G5 -> 143.9 | AK34: =AK4 -> 3.3 | AM34: =AI34*AJ34*AK34 -> 474.87 | AP34: 150mm block wall (drawing, gross) | AQ34: 1 | AR34: ='DRAWING CHECK'!H5 -> 152.7 | AS34: =AS4 -> 3.3 | AU34: =AQ34*AR34*AS34 -> 503.91 | AX34: 150mm block wall (drawing, gross) | AY34: 1 | AZ34: ='DRAWING CHECK'!I5 -> 219.9 | BA34: =BA4 -> 3.3 | BC34: =AY34*AZ34*BA34 -> 725.67 | BF34: 150mm block wall (drawing, gross) | BG34: 1 | BH34: ='DRAWING CHECK'!J5 -> 145.5 | BI34: =BI4 -> 1.5 | BK34: =BG34*BH34*BI34 -> 218.25
B35: Ddt openings (as above) | G35: =G15+G24 -> 26.01 | J35: Ddt openings (as above) | O35: =O15+O24 -> 68.505 | R35: Ddt openings (as above) | W35: =W15+W24 -> 52.035 | Z35: Ddt openings (as above) | AE35: =AE15+AE24 -> 71.895 | AH35: Ddt openings (as above) | AM35: =AM15+AM24 -> 63.735 | AP35: Ddt openings (as above) | AU35: =AU15+AU24 -> 86.37 | AX35: Ddt openings (as above) | BC35: =BC15+BC24 -> 68.025 | BF35: Ddt openings (as above) | BK35: =BK15+BK24 -> 3.78
B36: Checked net area | G36: =G34-G35 -> 516 | J36: Checked net area | O36: =O34-O35 -> 639.345 | R36: Checked net area | W36: =W34-W35 -> 456.495 | Z36: Checked net area | AE36: =AE34-AE35 -> 460.065 | AH36: Checked net area | AM36: =AM34-AM35 -> 411.135 | AP36: Checked net area | AU36: =AU34-AU35 -> 417.54 | AX36: Checked net area | BC36: =BC34-BC35 -> 657.645 | BF36: Checked net area | BK36: =BK34-BK35 -> 214.47
B37: Take-off net area (row 29) | G37: =G29 -> 548.93 | J37: Take-off net area (row 29) | O37: =O29 -> 606.945 | R37: Take-off net area (row 29) | W37: =W29 -> 437.025 | Z37: Take-off net area (row 29) | AE37: =AE29 -> 414.195 | AH37: Take-off net area (row 29) | AM37: =AM29 -> 401.565 | AP37: Take-off net area (row 29) | AU37: =AU29 -> 405.66 | AX37: Take-off net area (row 29) | BC37: =BC29 -> 637.845 | BF37: Take-off net area (row 29) | BK37: =BK29 -> 212.52
B38: Variance (take-off − check) | G38: =G37-G36 -> 32.93 | J38: Variance (take-off − check) | O38: =O37-O36 -> -32.4 | R38: Variance (take-off − check) | W38: =W37-W36 -> -19.47 | Z38: Variance (take-off − check) | AE38: =AE37-AE36 -> -45.87 | AH38: Variance (take-off − check) | AM38: =AM37-AM36 -> -9.57 | AP38: Variance (take-off − check) | AU38: =AU37-AU36 -> -11.88 | AX38: Variance (take-off − check) | BC38: =BC37-BC36 -> -19.8 | BF38: Variance (take-off − check) | BK38: =BK37-BK36 -> -1.95
B39: Variance % | G39: =IF(G36=0,0,G38/G36) -> 0.063817829 | J39: Variance % | O39: =IF(O36=0,0,O38/O36) -> -0.050676865 | R39: Variance % | W39: =IF(W36=0,0,W38/W36) -> -0.04265107 | Z39: Variance % | AE39: =IF(AE36=0,0,AE38/AE36) -> -0.099703303 | AH39: Variance % | AM39: =IF(AM36=0,0,AM38/AM36) -> -0.023277026 | AP39: Variance % | AU39: =IF(AU36=0,0,AU38/AU36) -> -0.028452364 | AX39: Variance % | BC39: =IF(BC36=0,0,BC38/BC36) -> -0.030107429 | BF39: Variance % | BK39: =IF(BK36=0,0,BK38/BK36) -> -0.0090921807

Sheet PLASTERING
A1: BASEMENT PLASTERING | I1: GROUND FLOOR PLASTERING | Q1: FIRST FLOOR PLASTERING | Y1: SECOND FLOOR PLASTERING | AG1: THIRD FLOOR PLASTERING | AO1: FOURTH FLOOR PLASTERING | AW1: FIFTH FLOOR PLASTERING | BE1: ROOFTOP FLOOR PLASTERING
A2: ITEM | B2: DESCRIPTION | C2: NO. | D2: LENG. | E2: HEIGHT | F2: PERIMETER OF OPENING | G2: AREA | I2: ITEM | J2: DESCRIPTION | K2: NO. | L2: LENG. | M2: HEIGHT | N2: PERIMETER OF OPENING | O2: AREA | Q2: ITEM | R2: DESCRIPTION | S2: NO. | T2: LENG. | U2: HEIGHT | V2: PERIMETER OF OPENING | W2: AREA | Y2: ITEM | Z2: DESCRIPTION | AA2: NO. | AB2: LENG. | AC2: HEIGHT | AD2: PERIMETER OF OPENING | AE2: AREA | AG2: ITEM | AH2: DESCRIPTION | AI2: NO. | AJ2: LENG. | AK2: HEIGHT | AL2: PERIMETER OF OPENING | AM2: AREA | AO2: ITEM | AP2: DESCRIPTION | AQ2: NO. | AR2: LENG. | AS2: HEIGHT | AT2: PERIMETER OF OPENING | AU2: AREA | AW2: ITEM | AX2: DESCRIPTION | AY2: NO. | AZ2: LENG. | BA2: HEIGHT | BB2: PERIMETER OF OPENING | BC2: AREA | BE2: ITEM | BF2: DESCRIPTION | BG2: NO. | BH2: LENG. | BI2: HEIGHT | BJ2: PERIMETER OF OPENING | BK2: AREA
A3: INTERNAL PLASTERING | I3: INTERNAL PLASTERING | Q3: INTERNAL PLASTERING | Y3: INTERNAL PLASTERING | AG3: INTERNAL PLASTERING | AO3: INTERNAL PLASTERING | AW3: INTERNAL PLASTERING | BE3: INTERNAL PLASTERING
A5: A | B5: Internal Plastering | C5: 1 | D5: 470.3 | E5: 4.45 | G5: =C5*D5*E5 -> 2092.835 | I5: A | J5: Internal Plastering | K5: 1 | L5: 239.4 | M5: 4.5 | O5: =K5*L5*M5 -> 1077.3 | Q5: A | R5: 150mm block wall | S5: 1 | T5: 279.2 | U5: 3.3 | W5: =S5*T5*U5 -> 921.36 | Y5: A | Z5: 150mm block wall | AA5: 1 | AB5: 258.8 | AC5: 3.3 | AE5: =AA5*AB5*AC5 -> 854.04 | AG5: A | AH5: 150mm block wall | AI5: 1 | AJ5: 251.7 | AK5: 3.3 | AM5: =AI5*AJ5*AK5 -> 830.61 | AO5: A | AP5: 150mm block wall | AQ5: 1 | AR5: 261.1 | AS5: 3.3 | AU5: =AQ5*AR5*AS5 -> 861.63 | AW5: A | AX5: 150mm block wall | AY5: 1 | AZ5: 368.6 | BA5: 3.3 | BC5: =AY5*AZ5*BA5 -> 1216.38 | BE5: A | BF5: 150mm block wall | BG5: 1 | BH5: 197 | BI5: 1.5 | BK5: =BG5*BH5*BI5 -> 295.5
G7: =G5 -> 2092.835 | O7: =O5 -> 1077.3 | W7: =W5 -> 921.36 | AE7: =AE5 -> 854.04 | AM7: =AM5 -> 830.61 | AU7: =AU5 -> 861.63 | BC7: =BC5 -> 1216.38 | BK7: =BK5 -> 295.5
B9: Ddt window | J9: Ddt window | R9: Ddt window | Z9: Ddt window | AH9: Ddt window | AP9: Ddt window | AX9: Ddt window | BF9: Ddt window
A10: B | B10: W1 | C10: 3 | D10: 1.6 | E10: 1 | F10: =2*(D10+E10)*C10 -> 15.6 | G10: =C10*D10*E10 -> 4.8 | I10: B | J10: W2 | K10: 5 | L10: ='WINDOWS AND DOORS SCHEDULE'!D6 -> 2.5 | M10: ='WINDOWS AND DOORS SCHEDULE'!E6 -> 0.75 | N10: =2*(L10+M10)*K10 -> 32.5 | O10: =K10*L10*M10 -> 9.375 | Q10: B | R10: W2 | S10: 5 | T10: ='WINDOWS AND DOORS SCHEDULE'!D6 -> 2.5 | U10: ='WINDOWS AND DOORS SCHEDULE'!E6 -> 0.75 | V10: =2*(T10+U10)*S10 -> 32.5 | W10: =S10*T10*U10 -> 9.375 | Y10: B | Z10: W2 | AA10: 6 | AB10: ='WINDOWS AND DOORS SCHEDULE'!D6 -> 2.5 | AC10: ='WINDOWS AND DOORS SCHEDULE'!E6 -> 0.75 | AD10: =2*(AB10+AC10)*AA10 -> 39 | AE10: =AA10*AB10*AC10 -> 11.25 | AG10: B | AH10: W2 | AI10: 5 | AJ10: ='WINDOWS AND DOORS SCHEDULE'!D6 -> 2.5 | AK10: ='WINDOWS AND DOORS SCHEDULE'!E6 -> 0.75 | AL10: =2*(AJ10+AK10)*AI10 -> 32.5 | AM10: =AI10*AJ10*AK10 -> 9.375 | AO10: B | AP10: W2 | AQ10: 5 | AR10: ='WINDOWS AND DOORS SCHEDULE'!D6 -> 2.5 | AS10: ='WINDOWS AND DOORS SCHEDULE'!E6 -> 0.75 | AT10: =2*(AR10+AS10)*AQ10 -> 32.5 | AU10: =AQ10*AR10*AS10 -> 9.375 | AW10: B | AX10: W2 | AY10: 4 | AZ10: ='WINDOWS AND DOORS SCHEDULE'!D6 -> 2.5 | BA10: ='WINDOWS AND DOORS SCHEDULE'!E6 -> 0.75 | BB10: =2*(AZ10+BA10)*AY10 -> 26 | BC10: =AY10*AZ10*BA10 -> 7.5
J11: W3 | K11: 3 | L11: ='WINDOWS AND DOORS SCHEDULE'!D7 -> 1.6 | M11: ='WINDOWS AND DOORS SCHEDULE'!E7 -> 3 | N11: =2*(L11+M11)*K11 -> 27.6 | O11: =K11*L11*M11 -> 14.4 | R11: W4 | S11: 2 | T11: ='WINDOWS AND DOORS SCHEDULE'!D8 -> 1.5 | U11: ='WINDOWS AND DOORS SCHEDULE'!E8 -> 1.2 | V11: =2*(T11+U11)*S11 -> 10.8 | W11: =S11*T11*U11 -> 3.6 | Z11: W4 | AA11: 2 | AB11: ='WINDOWS AND DOORS SCHEDULE'!D8 -> 1.5 | AC11: ='WINDOWS AND DOORS SCHEDULE'!E8 -> 1.2 | AD11: =2*(AB11+AC11)*AA11 -> 10.8 | AE11: =AA11*AB11*AC11 -> 3.6 | AH11: W4 | AI11: 2 | AJ11: ='WINDOWS AND DOORS SCHEDULE'!D8 -> 1.5 | AK11: ='WINDOWS AND DOORS SCHEDULE'!E8 -> 1.2 | AL11: =2*(AJ11+AK11)*AI11 -> 10.8 | AM11: =AI11*AJ11*AK11 -> 3.6 | AP11: W4 | AQ11: 2 | AR11: ='WINDOWS AND DOORS SCHEDULE'!D8 -> 1.5 | AS11: ='WINDOWS AND DOORS SCHEDULE'!E8 -> 1.2 | AT11: =2*(AR11+AS11)*AQ11 -> 10.8 | AU11: =AQ11*AR11*AS11 -> 3.6 | AX11: W4 | AY11: 1 | AZ11: ='WINDOWS AND DOORS SCHEDULE'!D8 -> 1.5 | BA11: ='WINDOWS AND DOORS SCHEDULE'!E8 -> 1.2 | BB11: =2*(AZ11+BA11)*AY11 -> 5.4 | BC11: =AY11*AZ11*BA11 -> 1.8
J12: W4 | K12: 2 | L12: ='WINDOWS AND DOORS SCHEDULE'!D8 -> 1.5 | M12: ='WINDOWS AND DOORS SCHEDULE'!E8 -> 1.2 | N12: =2*(L12+M12)*K12 -> 10.8 | O12: =K12*L12*M12 -> 3.6 | R12: W5 | S12: 2 | T12: ='WINDOWS AND DOORS SCHEDULE'!D9 -> 0.9 | U12: ='WINDOWS AND DOORS SCHEDULE'!E9 -> 2 | V12: =2*(T12+U12)*S12 -> 11.6 | W12: =S12*T12*U12 -> 3.6 | Z12: W5 | AA12: 2 | AB12: ='WINDOWS AND DOORS SCHEDULE'!D9 -> 0.9 | AC12: ='WINDOWS AND DOORS SCHEDULE'!E9 -> 2 | AD12: =2*(AB12+AC12)*AA12 -> 11.6 | AE12: =AA12*AB12*AC12 -> 3.6 | AH12: W5 | AI12: 2 | AJ12: ='WINDOWS AND DOORS SCHEDULE'!D9 -> 0.9 | AK12: ='WINDOWS AND DOORS SCHEDULE'!E9 -> 2 | AL12: =2*(AJ12+AK12)*AI12 -> 11.6 | AM12: =AI12*AJ12*AK12 -> 3.6 | AP12: W5 | AQ12: 2 | AR12: ='WINDOWS AND DOORS SCHEDULE'!D9 -> 0.9 | AS12: ='WINDOWS AND DOORS SCHEDULE'!E9 -> 2 | AT12: =2*(AR12+AS12)*AQ12 -> 11.6 | AU12: =AQ12*AR12*AS12 -> 3.6 | AX12: W5 | AY12: 5 | AZ12: ='WINDOWS AND DOORS SCHEDULE'!D9 -> 0.9 | BA12: ='WINDOWS AND DOORS SCHEDULE'!E9 -> 2 | BB12: =2*(AZ12+BA12)*AY12 -> 29 | BC12: =AY12*AZ12*BA12 -> 9
J13: W7 | K13: 1 | L13: ='WINDOWS AND DOORS SCHEDULE'!D11 -> 1.2 | M13: ='WINDOWS AND DOORS SCHEDULE'!E11 -> 0.75 | N13: =2*(L13+M13)*K13 -> 3.9 | O13: =K13*L13*M13 -> 0.9 | R13: W7 | S13: 1 | T13: ='WINDOWS AND DOORS SCHEDULE'!D11 -> 1.2 | U13: ='WINDOWS AND DOORS SCHEDULE'!E11 -> 0.75 | V13: =2*(T13+U13)*S13 -> 3.9 | W13: =S13*T13*U13 -> 0.9 | Z13: W7 | AA13: 1 | AB13: ='WINDOWS AND DOORS SCHEDULE'!D11 -> 1.2 | AC13: ='WINDOWS AND DOORS SCHEDULE'!E11 -> 0.75 | AD13: =2*(AB13+AC13)*AA13 -> 3.9 | AE13: =AA13*AB13*AC13 -> 0.9 | AH13: W7 | AI13: 1 | AJ13: ='WINDOWS AND DOORS SCHEDULE'!D11 -> 1.2 | AK13: ='WINDOWS AND DOORS SCHEDULE'!E11 -> 0.75 | AL13: =2*(AJ13+AK13)*AI13 -> 3.9 | AM13: =AI13*AJ13*AK13 -> 0.9 | AP13: W8 | AQ13: 4 | AR13: ='WINDOWS AND DOORS SCHEDULE'!D12 -> 1.8 | AS13: ='WINDOWS AND DOORS SCHEDULE'!E12 -> 1 | AT13: =2*(AR13+AS13)*AQ13 -> 22.4 | AU13: =AQ13*AR13*AS13 -> 7.2 | AX13: W7 | AY13: 1 | AZ13: ='WINDOWS AND DOORS SCHEDULE'!D11 -> 1.2 | BA13: ='WINDOWS AND DOORS SCHEDULE'!E11 -> 0.75 | BB13: =2*(AZ13+BA13)*AY13 -> 3.9 | BC13: =AY13*AZ13*BA13 -> 0.9
Z14: W8 | AA14: 3 | AB14: ='WINDOWS AND DOORS SCHEDULE'!D12 -> 1.8 | AC14: ='WINDOWS AND DOORS SCHEDULE'!E12 -> 1 | AD14: =2*(AB14+AC14)*AA14 -> 16.8 | AE14: =AA14*AB14*AC14 -> 5.4 | AH14: W8 | AI14: 3 | AJ14: ='WINDOWS AND DOORS SCHEDULE'!D12 -> 1.8 | AK14: ='WINDOWS AND DOORS SCHEDULE'!E12 -> 1 | AL14: =2*(AJ14+AK14)*AI14 -> 16.8 | AM14: =AI14*AJ14*AK14 -> 5.4
B16: Total window | F16: =F10 -> 15.6 | G16: =G10 -> 4.8 | J16: Total window | N16: =SUM(N10:N15) -> 74.8 | O16: =SUM(O10:O15) -> 28.275 | R16: Total window | V16: =SUM(V10:V15) -> 58.8 | W16: =SUM(W10:W15) -> 17.475 | Z16: Total window | AD16: =SUM(AD9:AD15) -> 82.1 | AE16: =SUM(AE10:AE14) -> 24.75 | AH16: Total window | AL16: =SUM(AL10:AL14) -> 75.6 | AM16: =SUM(AM10:AM14) -> 22.875 | AP16: Total window | AT16: =SUM(AT10:AT15) -> 77.3 | AU16: =SUM(AU10:AU15) -> 23.775 | AX16: Total window | BB16: =SUM(BB10:BB15) -> 64.3 | BC16: =SUM(BC10:BC15) -> 19.2 | BF16: Total window | BK16: =SUM(BK15:BK15) -> 0
B17: Ddt door | J17: Ddt door | R17: Ddt door | Z17: Ddt door | AH17: Ddt door | AX17: Ddt door | BF17: Ddt door
A18: C | B18: D2 | C18: 4 | D18: ='WINDOWS AND DOORS SCHEDULE'!L6 -> 0.9 | E18: ='WINDOWS AND DOORS SCHEDULE'!M6 -> 2.1 | F18: =2*(D18+E18)*C18 -> 24 | G18: =C18*D18*E18 -> 7.56 | I18: C | J18: D1 | K18: 3 | L18: ='WINDOWS AND DOORS SCHEDULE'!L5 -> 1.2 | M18: ='WINDOWS AND DOORS SCHEDULE'!M5 -> 2.1 | N18: =2*(L18+M18)*K18 -> 19.8 | O18: =K18*L18*M18 -> 7.56 | Q18: C | R18: D1 | S18: 3 | T18: ='WINDOWS AND DOORS SCHEDULE'!L5 -> 1.2 | U18: ='WINDOWS AND DOORS SCHEDULE'!M5 -> 2.1 | V18: =2*(T18+U18)*S18 -> 19.8 | W18: =S18*T18*U18 -> 7.56 | Y18: C | Z18: D1 | AA18: 2 | AB18: ='WINDOWS AND DOORS SCHEDULE'!L5 -> 1.2 | AC18: ='WINDOWS AND DOORS SCHEDULE'!M5 -> 2.1 | AD18: =2*(AB18+AC18)*AA18 -> 13.2 | AE18: =AA18*AB18*AC18 -> 5.04 | AG18: C | AH18: D1 | AI18: 2 | AJ18: ='WINDOWS AND DOORS SCHEDULE'!L5 -> 1.2 | AK18: ='WINDOWS AND DOORS SCHEDULE'!M5 -> 2.1 | AL18: =2*(AJ18+AK18)*AI18 -> 13.2 | AM18: =AI18*AJ18*AK18 -> 5.04 | AP18: Ddt door | AW18: C | AX18: D1 | AY18: 2 | AZ18: ='WINDOWS AND DOORS SCHEDULE'!L5 -> 1.2 | BA18: ='WINDOWS AND DOORS SCHEDULE'!M5 -> 2.1 | BB18: =2*(AZ18+BA18)*AY18 -> 13.2 | BC18: =AY18*AZ18*BA18 -> 5.04 | BE18: C | BF18: D8 | BG18: 1 | BH18: ='WINDOWS AND DOORS SCHEDULE'!L12 -> 1.8 | BI18: ='WINDOWS AND DOORS SCHEDULE'!M12 -> 2.1 | BJ18: =2*(BH18+BI18)*BG18 -> 7.8 | BK18: =BG18*BH18*BI18 -> 3.78
A19: D | B19: D3 | C19: 8 | D19: ='WINDOWS AND DOORS SCHEDULE'!L7 -> 0.75 | E19: ='WINDOWS AND DOORS SCHEDULE'!M7 -> 2.1 | F19: =2*(D19+E19)*C19 -> 45.6 | G19: =C19*D19*E19 -> 12.6 | I19: D | J19: D2 | K19: 3 | L19: ='WINDOWS AND DOORS SCHEDULE'!L6 -> 0.9 | M19: ='WINDOWS AND DOORS SCHEDULE'!M6 -> 2.1 | N19: =2*(L19+M19)*K19 -> 18 | O19: =K19*L19*M19 -> 5.67 | Q19: D | R19: D2 | S19: 4 | T19: ='WINDOWS AND DOORS SCHEDULE'!L6 -> 0.9 | U19: ='WINDOWS AND DOORS SCHEDULE'!M6 -> 2.1 | V19: =2*(T19+U19)*S19 -> 24 | W19: =S19*T19*U19 -> 7.56 | Y19: D | Z19: D2 | AA19: 8 | AB19: ='WINDOWS AND DOORS SCHEDULE'!L6 -> 0.9 | AC19: ='WINDOWS AND DOORS SCHEDULE'!M6 -> 2.1 | AD19: =2*(AB19+AC19)*AA19 -> 48 | AE19: =AA19*AB19*AC19 -> 15.12 | AG19: D | AH19: D2 | AI19: 3 | AJ19: ='WINDOWS AND DOORS SCHEDULE'!L6 -> 0.9 | AK19: ='WINDOWS AND DOORS SCHEDULE'!M6 -> 2.1 | AL19: =2*(AJ19+AK19)*AI19 -> 18 | AM19: =AI19*AJ19*AK19 -> 5.67 | AO19: C | AP19: D1 | AQ19: 2 | AR19: ='WINDOWS AND DOORS SCHEDULE'!L5 -> 1.2 | AS19: ='WINDOWS AND DOORS SCHEDULE'!M5 -> 2.1 | AT19: =2*(AR19+AS19)*AQ19 -> 13.2 | AU19: =AQ19*AR19*AS19 -> 5.04 | AW19: D | AX19: D2 | AY19: 13 | AZ19: ='WINDOWS AND DOORS SCHEDULE'!L6 -> 0.9 | BA19: ='WINDOWS AND DOORS SCHEDULE'!M6 -> 2.1 | BB19: =2*(AZ19+BA19)*AY19 -> 78 | BC19: =AY19*AZ19*BA19 -> 24.57
A20: E | B20: D4 | C20: 1 | D20: ='WINDOWS AND DOORS SCHEDULE'!L8 -> 0.5 | E20: ='WINDOWS AND DOORS SCHEDULE'!M8 -> 2.1 | F20: =2*(D20+E20)*C20 -> 5.2 | G20: =C20*D20*E20 -> 1.05 | I20: E | J20: D3 | K20: 11 | L20: ='WINDOWS AND DOORS SCHEDULE'!L7 -> 0.75 | M20: ='WINDOWS AND DOORS SCHEDULE'!M7 -> 2.1 | N20: =2*(L20+M20)*K20 -> 62.7 | O20: =K20*L20*M20 -> 17.325 | Q20: E | R20: D3 | S20: 11 | T20: ='WINDOWS AND DOORS SCHEDULE'!L7 -> 0.75 | U20: ='WINDOWS AND DOORS SCHEDULE'!M7 -> 2.1 | V20: =2*(T20+U20)*S20 -> 62.7 | W20: =S20*T20*U20 -> 17.325 | Y20: E | Z20: D3 | AA20: 13 | AB20: ='WINDOWS AND DOORS SCHEDULE'!L7 -> 0.75 | AC20: ='WINDOWS AND DOORS SCHEDULE'!M7 -> 2.1 | AD20: =2*(AB20+AC20)*AA20 -> 74.1 | AE20: =AA20*AB20*AC20 -> 20.475 | AG20: E | AH20: D3 | AI20: 13 | AJ20: ='WINDOWS AND DOORS SCHEDULE'!L7 -> 0.75 | AK20: ='WINDOWS AND DOORS SCHEDULE'!M7 -> 2.1 | AL20: =2*(AJ20+AK20)*AI20 -> 74.1 | AM20: =AI20*AJ20*AK20 -> 20.475 | AO20: D | AP20: D2 | AQ20: 14 | AR20: ='WINDOWS AND DOORS SCHEDULE'!L6 -> 0.9 | AS20: ='WINDOWS AND DOORS SCHEDULE'!M6 -> 2.1 | AT20: =2*(AR20+AS20)*AQ20 -> 84 | AU20: =AQ20*AR20*AS20 -> 26.46 | AW20: E | AX20: D3 | AY20: 5 | AZ20: ='WINDOWS AND DOORS SCHEDULE'!L7 -> 0.75 | BA20: ='WINDOWS AND DOORS SCHEDULE'!M7 -> 2.1 | BB20: =2*(AZ20+BA20)*AY20 -> 28.5 | BC20: =AY20*AZ20*BA20 -> 7.875
I21: F | J21: D4 | K21: 3 | L21: ='WINDOWS AND DOORS SCHEDULE'!L8 -> 0.5 | M21: ='WINDOWS AND DOORS SCHEDULE'!M8 -> 2.1 | N21: =2*(L21+M21)*K21 -> 15.6 | O21: =K21*L21*M21 -> 3.15 | Q21: F | R21: D4 | S21: 2 | T21: ='WINDOWS AND DOORS SCHEDULE'!L8 -> 0.5 | U21: ='WINDOWS AND DOORS SCHEDULE'!M8 -> 2.1 | V21: =2*(T21+U21)*S21 -> 10.4 | W21: =S21*T21*U21 -> 2.1 | Y21: F | Z21: D4 | AA21: 2 | AB21: ='WINDOWS AND DOORS SCHEDULE'!L8 -> 0.5 | AC21: ='WINDOWS AND DOORS SCHEDULE'!M8 -> 2.1 | AD21: =2*(AB21+AC21)*AA21 -> 10.4 | AE21: =AA21*AB21*AC21 -> 2.1 | AG21: F | AH21: D4 | AI21: 2 | AJ21: ='WINDOWS AND DOORS SCHEDULE'!L8 -> 0.5 | AK21: ='WINDOWS AND DOORS SCHEDULE'!M8 -> 2.1 | AL21: =2*(AJ21+AK21)*AI21 -> 10.4 | AM21: =AI21*AJ21*AK21 -> 2.1 | AO21: E | AP21: D3 | AQ21: 16 | AR21: ='WINDOWS AND DOORS SCHEDULE'!L7 -> 0.75 | AS21: ='WINDOWS AND DOORS SCHEDULE'!M7 -> 2.1 | AT21: =2*(AR21+AS21)*AQ21 -> 91.2 | AU21: =AQ21*AR21*AS21 -> 25.2 | AW21: F | AX21: D4 | AY21: 1 | AZ21: ='WINDOWS AND DOORS SCHEDULE'!L8 -> 0.5 | BA21: ='WINDOWS AND DOORS SCHEDULE'!M8 -> 2.1 | BB21: =2*(AZ21+BA21)*AY21 -> 5.2 | BC21: =AY21*AZ21*BA21 -> 1.05
