Workbook

Sheet SUBSTUCTURE BILL
A1: PROPOSED 6 STOREY OFFICE BUILDING WITH 1 LEVEL BASEMENT – PRIORITY HOUSE, NORTH RIDGE, ACCRA
A2: Client: Priority Insurance Company Ltd. Structural: ESPCo, drawings ESPCo/PI/6SB-1B/2026/SDD/001 (Aug 2026, Rev 001). BILL No.1 SUBSTRUCTURE (ALL PROVISIONAL) – to basement top (ground floor) slab
A3: DRAFT FOR REVIEW – quantities subject to the queries listed on the QUERIES sheet; rates to be inserted (yellow).
B5: DESCRIPTION | C5: QTY | D5: UNIT | E5: RATE | F5: AMOUNT GH¢
B6: D GROUNDWORK | F6: =F44 -> 0
B7: E IN-SITU CONCRETE | F7: =F94 -> 0
B8: F MASONRY | F8: =F100 -> 0
B9: J WATERPROOFING | F9: =F113 -> 0
B10: PROVISIONAL SUMS & CONTINGENCY | F10: =F122 -> 0
B11: SUB-TOTAL SUBSTRUCTURE (carried to General Summary) | F11: =SUM(F6:F10) -> 0
B14: D GROUNDWORK
B15: D20 Excavating and filling
B16: Site preparation
A17: A | B17: Clear site of all vegetation, debris and existing surface obstructions; dispose off site | C17: =calculations!G5 -> 1619 | D17: m2 | F17: =IF(D17="","",IF(E17="","",E17*C17))
A18: B | B18: Excavate topsoil average 150 mm deep and remove from site | C18: =calculations!G6 -> 1619 | D18: m2 | F18: =IF(D18="","",IF(E18="","",E18*C18))
B19: Excavation (sloping site – depths from assumed average existing ground level; re-measure on topo survey)
A20: C | B20: Bulk excavation for basement, commencing at existing ground level, maximum depth not exceeding 4.00 m (average ~2.95 m) to formation | C20: =calculations!G8 -> 4747 | D20: m3 | F20: =IF(D20="","",IF(E20="","",E20*C20))
A21: D | B21: Excavate pits for pad and combined bases commencing at basement formation level, maximum depth not exceeding 4.00 m | C21: =calculations!G21 -> 1126 | D21: m3 | F21: =IF(D21="","",IF(E21="","",E21*C21))
A22: E | B22: Excavate trenches for retaining wall bases, strip footings and ground beams commencing at basement formation level, maximum depth not exceeding 4.00 m (RW bases 2.05 m) | C22: =calculations!G29 -> 674 | D22: m3 | F22: =IF(D22="","",IF(E22="","",E22*C22))
A23: F | B23: Extra over excavation for excavating in rock (Provisional) | C23: 50 | D23: m3 | F23: =IF(D23="","",IF(E23="","",E23*C23))
A24: G | B24: Extra over excavation for breaking out obstructions / old foundations (Provisional) | C24: 20 | D24: m3 | F24: =IF(D24="","",IF(E24="","",E24*C24))
A25: H | B25: Working space allowance to excavations for retaining walls (outside face) | C25: =calculations!G32 -> 617 | D25: m2 | F25: =IF(D25="","",IF(E25="","",E25*C25))
B26: Earthwork support
A27: J | B27: Earthwork support to faces of basement excavation, maximum depth 4.00–6.00 m, distance between opposing faces exceeding 4.00 m | C27: =calculations!G33 -> 812 | D27: m2 | F27: =IF(D27="","",IF(E27="","",E27*C27))
A28: K | B28: Extra over earthwork support for support adjoining existing building (Sunny FM party wall) – temporary works design by Contractor (Provisional) | C28: =ROUND(calculations!$AP$16*5,0) -> 340 | D28: m2 | F28: =IF(D28="","",IF(E28="","",E28*C28))
B29: Disposal
A30: L | B30: Remove surplus excavated material from site to a tip provided by the Contractor | C30: =calculations!G36 -> 5320 | D30: m3 | F30: =IF(D30="","",IF(E30="","",E30*C30))
A31: M | B31: Keep excavations free from ground and surface water (dewatering) – S-001 Concrete note 3 | D31: Item | F31: =IF(D31="","",IF(E31="","",E31*C31))
B32: Filling
A33: N | B33: Filling to excavations with approved hardcore material graded per S-001 note 4, compacted in layers to 95% MDD at OMC | C33: =calculations!G35 -> 1227 | D33: m3 | F33: =IF(D33="","",IF(E33="","",E33*C33))
A34: P | B34: Hardcore bed under basement slab, thickness assumed 150 mm (not stated), compacted to 95% MDD | C34: =calculations!G37 -> 231 | D34: m3 | F34: =IF(D34="","",IF(E34="","",E34*C34))
A35: Q | B35: 0–40 crushed rock filling to soft spots / overdig beneath foundations, compacted to 98% MDD (Provisional) | C35: 30 | D35: m3 | F35: =IF(D35="","",IF(E35="","",E35*C35))
B36: Surface treatments
A37: R | B37: Level and compact bottoms of excavations to receive blinding | C37: =calculations!G38 -> 761 | D37: m2 | F37: =IF(D37="","",IF(E37="","",E37*C37))
A38: S | B38: Level and compact basement formation | C38: =calculations!G40 -> 1540 | D38: m2 | F38: =IF(D38="","",IF(E38="","",E38*C38))
A39: T | B39: Blind surface of hardcore with sand and compact | C39: =calculations!G39 -> 1540 | D39: m2 | F39: =IF(D39="","",IF(E39="","",E39*C39))
B40: Sundries
A41: U | B41: Allow for condition (dilapidation) survey of adjoining Sunny FM building and neighbouring properties before and after works | D41: Item | F41: =IF(D41="","",IF(E41="","",E41*C41))
A42: V | B42: Allow for monitoring of adjoining structures and excavation movement during basement works | D42: Item | F42: =IF(D42="","",IF(E42="","",E42*C42))
B44: D GROUNDWORK – Carried to Collection | F44: =SUM(F16:F43) -> 0
...

Sheet calculations
A1: EXCAVATION & FILLING | I1: SUB CONCRETE (m³) | Q1: FORMWORK | Y1: REINFORCEMENT (kg) | AG1: WATERPROOFING & SUNDRIES | AO1: KEY INPUTS & ASSUMPTIONS (yellow = assumed, confirm)
A3: DESCRIPTION | B3: DRAWING REF / NOTE | C3: Nr | D3: len | E3: width | F3: Ht/Dp | G3: m³ / m² | I3: DESCRIPTION | J3: DRAWING REF / NOTE | K3: Nr | L3: len | M3: width | N3: thk/ht | O3: m³ | Q3: DESCRIPTION | R3: DRAWING REF / NOTE | S3: NR | T3: LEN | U3: GIRTH/W | V3: HT | W3: m² / m | Y3: ELEMENT | Z3: BAR MARK / NOTE | AA3: DIA | AB3: No. (total) | AC3: LENGTH m | AD3: kg/m | AE3: kg | AG3: DESCRIPTION | AH3: DRAWING REF / NOTE | AI3: Nr | AJ3: L | AK3: H/W | AL3: - | AM3: qty | AO3: Average existing ground level over basement footprint (m, rel. GF ±0.000) | AP3: -1.05 | AQ3: ASSUMED. No topographic survey issued (arch. A093/A094 missing). Mean of retained ground implied by RW Type A (top of wall −2.10 on grids A & 6) and RW Type B (retains to ±0.000 on grids 1(H–J), J, 6(H–J)). Replace with level-grid average from topo survey.
A4: Site preparation (m²) | I4: Blinding GEN2 C12/15, 50 mm | Q4: Foundations | Y4: COLUMNS (base to GF) | AG4: Tanking / membranes (m²) | AO4: Top of basement slab (m) | AP4: -3.7 | AQ4: S-006 Basement GA CFL −3700; column details S-039–041 "BASEMENT −3700". (RW details S-005 show −3600 – see query.)
A5: Clear site of vegetation / debris | B5: Site area A002 | C5: 1 | D5: =$AP$11 -> 1619 | E5: 1 | G5: =ROUND(C5*D5*E5,0) -> 1619 | I5: Blinding under F1 (C1, E/3) | J5: S-001/002 F1 4600×4600 (meas.), 1100 thk | K5: 1 | L5: 4.6 | M5: 4.6 | N5: =$AP$10 -> 0.05 | O5: =ROUND(K5*L5*M5*N5,2) -> 1.06 | Q5: Sides of F1 (C1, E/3) | R5: S-001/002 F1 4600×4600 (meas.), 1100 thk | S5: 1 | T5: 9.2 | U5: 2 | V5: 1.1 | W5: =ROUND(S5*T5*U5*V5,2) -> 20.24 | Y5: C1 ×6 (S-039–043) | Z5: H2501 – 16/col × 6 | AA5: 25 | AB5: 96 | AC5: 5.95 | AD5: =ROUND(AA5^2/162.162,3) -> 3.854 | AE5: =ROUND(AB5*AC5*AD5,1) -> 2201.4 | AG5: Approved waterproofing to RW Type A external face | AH5: S-005; base underside −6.00 to top −2.10 | AI5: 1 | AJ5: =$AP$16 -> 68 | AK5: 3.9 | AM5: =ROUND(AI5*AJ5*AK5,0) -> 265 | AO5: Basement slab thickness (m) | AP5: 0.15 | AQ5: S-006: 150 mm non-suspended slab with BRC A252 (column details show 200 – query).
A6: Excavate topsoil avg 150 mm | B6: Note: site area | C6: 1 | D6: =$AP$11 -> 1619 | E6: 1 | G6: =ROUND(C6*D6*E6,0) -> 1619 | I6: Blinding under F1 (C1, E/5) | J6: S-001/002 F1 4400×4400 (meas.), 1100 thk | K6: 1 | L6: 4.4 | M6: 4.4 | N6: =$AP$10 -> 0.05 | O6: =ROUND(K6*L6*M6*N6,2) -> 0.97 | Q6: Sides of F1 (C1, E/5) | R6: S-001/002 F1 4400×4400 (meas.), 1100 thk | S6: 1 | T6: 8.8 | U6: 2 | V6: 1.1 | W6: =ROUND(S6*T6*U6*V6,2) -> 19.36 | Y6: C1 ×6 (S-039–043) | Z6: H2502 – 16/col × 6 | AA6: 25 | AB6: 96 | AC6: 6.1 | AD6: =ROUND(AA6^2/162.162,3) -> 3.854 | AE6: =ROUND(AB6*AC6*AD6,1) -> 2256.9 | AG6: Approved waterproofing to RW Type B external face | AH6: S-005; −6.00 to ±0.00 | AI6: 1 | AJ6: =$AP$17 -> 55.4 | AK6: 6 | AM6: =ROUND(AI6*AJ6*AK6,0) -> 332 | AO6: Hardcore bed thickness under basement slab (m) | AP6: 0.15 | AQ6: ASSUMED. General notes S-001 specify hardcore grading but no thickness.
A7: Bulk excavation for basement (m³) | I7: Blinding under F2 (C4/C1, grid 2 C,D,E) | J7: S-002 F2 4400×4400, 1100 thk; 3 No. | K7: 3 | L7: 4.4 | M7: 4.4 | N7: =$AP$10 -> 0.05 | O7: =ROUND(K7*L7*M7*N7,2) -> 2.9 | Q7: Sides of F2 (C4/C1, grid 2 C,D,E) | R7: S-002 F2 4400×4400, 1100 thk; 3 No. | S7: 3 | T7: 8.8 | U7: 2 | V7: 1.1 | W7: =ROUND(S7*T7*U7*V7,2) -> 58.08 | Y7: C1 ×6 (S-039–043) | Z7: H1001 – 64/col × 6 | AA7: 10 | AB7: 384 | AC7: 1.88 | AD7: =ROUND(AA7^2/162.162,3) -> 0.617 | AE7: =ROUND(AB7*AC7*AD7,1) -> 445.4 | AG7: DPM under basement slab (gauge by specialist) | AH7: S-001 misc. note 4 | AI7: 1 | AJ7: =$AP$14 -> 1540.1225 | AK7: 1 | AM7: =ROUND(AI7*AJ7*AK7,0) -> 1540 | AO7: Basement formation level (m) | AP7: =AP4-AP5-AP6 -> -4 | AQ7: Note: top of slab − slab − hardcore.
A8: Basement bulk excavation, EGL to formation | B8: Area to RW outer face; depth = EGL − formation | C8: 1 | D8: =$AP$13 -> 1609.2725 | E8: 1 | F8: =$AP$3-$AP$7 -> 2.95 | G8: =ROUND(C8*D8*E8*F8,0) -> 4747 | I8: Blinding under F4 (C1 ×2, F/5a–5) | J8: S-001 F4 7050×4200 (meas.), 1100 thk | K8: 1 | L8: 7.05 | M8: 4.2 | N8: =$AP$10 -> 0.05 | O8: =ROUND(K8*L8*M8*N8,2) -> 1.48 | Q8: Sides of F4 (C1 ×2, F/5a–5) | R8: S-001 F4 7050×4200 (meas.), 1100 thk | S8: 1 | T8: 11.25 | U8: 2 | V8: 1.1 | W8: =ROUND(S8*T8*U8*V8,2) -> 24.75 | Y8: C1 ×6 (S-039–043) | Z8: H1002 – 192/col × 6 | AA8: 10 | AB8: 1152 | AC8: 1.32 | AD8: =ROUND(AA8^2/162.162,3) -> 0.617 | AE8: =ROUND(AB8*AC8*AD8,1) -> 938.2 | AG8: BRC A252 mesh to basement slab | AH8: S-006 | AI8: 1 | AJ8: =$AP$14 -> 1540.1225 | AK8: 1 | AM8: =ROUND(AI8*AJ8*AK8,0) -> 1540 | AO8: Top of pad foundations (m) | AP8: -6.3 | AQ8: S-039–041 column elevations: 2600 from basement level −3700 to top of base.
A9: Excavation below formation – pits for bases (m³) | I9: Blinding under F5 (W2 + C3) | J9: S-001 F5 L-shaped, 30.20 m² (meas.), 1100 thk | K9: 1 | L9: 30.2 | M9: 1 | N9: =$AP$10 -> 0.05 | O9: =ROUND(K9*L9*M9*N9,2) -> 1.51 | Q9: Sides of F5 (W2 + C3) (perimeter scaled from area) | R9: S-001 F5 L-shaped, 30.20 m² (meas.), 1100 thk | S9: 1 | T9: =4*SQRT(K25*L25) -> 21.981811 | U9: 1 | V9: 1.1 | W9: =ROUND(S9*T9*U9*V9,2) -> 24.18 | Y9: C3 ×1 (S-039–043) | Z9: H2506 – 16/col × 1 | AA9: 25 | AB9: 16 | AC9: 5.575 | AD9: =ROUND(AA9^2/162.162,3) -> 3.854 | AE9: =ROUND(AB9*AC9*AD9,1) -> 343.8 | AG9: Water stops & joints (m) | AO9: Underside of RW base (m) | AP9: -6 | AQ9: S-005: basement −3600 − 2000 − 400 base.
A10: Pit for F1 (C1, E/3) | B10: S-001/002 F1 4600×4600 (meas.), 1100 thk | C10: 1 | D10: 4.6 | E10: 4.6 | F10: =$AP$7-($AP$8-1.1-$AP$10) -> 3.45 | G10: =ROUND(C10*D10*E10*F10,1) -> 73 | I10: Blinding under F6 (W1) | J10: S-001 F6 4000×5700 (meas.), 600 thk | K10: 1 | L10: 4 | M10: 5.7 | N10: =$AP$10 -> 0.05 | O10: =ROUND(K10*L10*M10*N10,2) -> 1.14 | Q10: Sides of F6 (W1) | R10: S-001 F6 4000×5700 (meas.), 600 thk | S10: 1 | T10: 9.7 | U10: 2 | V10: 0.6 | W10: =ROUND(S10*T10*U10*V10,2) -> 11.64 | Y10: C3 ×1 (S-039–043) | Z10: H2502 – 16/col × 1 | AA10: 25 | AB10: 16 | AC10: 6.1 | AD10: =ROUND(AA10^2/162.162,3) -> 3.854 | AE10: =ROUND(AB10*AC10*AD10,1) -> 376.2 | AG10: PVC water stop at RW kicker joint | AH10: S-005 | AI10: 1 | AJ10: =$AP$16+$AP$17 -> 123.4 | AK10: 1 | AM10: =ROUND(AI10*AJ10*AK10,0) -> 123 | AO10: Blinding thickness (m) | AP10: 0.05 | AQ10: Blinding GEN2 C12/15 (S-001 note 5); 50 mm standard.
A11: Pit for F1 (C1, E/5) | B11: S-001/002 F1 4400×4400 (meas.), 1100 thk | C11: 1 | D11: 4.4 | E11: 4.4 | F11: =$AP$7-($AP$8-1.1-$AP$10) -> 3.45 | G11: =ROUND(C11*D11*E11*F11,1) -> 66.8 | I11: Blinding under F7 (W3) | J11: S-002 F7 3000×4500, 600 thk | K11: 1 | L11: 3 | M11: 4.5 | N11: =$AP$10 -> 0.05 | O11: =ROUND(K11*L11*M11*N11,2) -> 0.68 | Q11: Sides of F7 (W3) | R11: S-002 F7 3000×4500, 600 thk | S11: 1 | T11: 7.5 | U11: 2 | V11: 0.6 | W11: =ROUND(S11*T11*U11*V11,2) -> 9 | Y11: C3 ×1 (S-039–043) | Z11: H1006 – 54/col × 1 | AA11: 10 | AB11: 54 | AC11: 2.08 | AD11: =ROUND(AA11^2/162.162,3) -> 0.617 | AE11: =ROUND(AB11*AC11*AD11,1) -> 69.3 | AG11: Protective coatings (m²) | AO11: Site area (m²) | AP11: 1619 | AQ11: Arch. A002 Plan of Land: 0.40 acre (0.16 ha).
A12: Pit for F2 (C4/C1, grid 2 C,D,E) | B12: S-002 F2 4400×4400, 1100 thk; 3 No. | C12: 3 | D12: 4.4 | E12: 4.4 | F12: =$AP$7-($AP$8-1.1-$AP$10) -> 3.45 | G12: =ROUND(C12*D12*E12*F12,1) -> 200.4 | I12: Blinding under F8 (lift core 2 + W4/W5) | J12: S-001 F8 combined, 56.25 m² (meas.), 600 thk | K12: 1 | L12: 56.25 | M12: 1 | N12: =$AP$10 -> 0.05 | O12: =ROUND(K12*L12*M12*N12,2) -> 2.81 | Q12: Sides of F8 (lift core 2 + W4/W5) (perimeter scaled from area) | R12: S-001 F8 combined, 56.25 m² (meas.), 600 thk | S12: 1 | T12: =4*SQRT(K28*L28) -> 30 | U12: 1 | V12: 0.6 | W12: =ROUND(S12*T12*U12*V12,2) -> 18 | Y12: C3 ×1 (S-039–043) | Z12: H1007 – 108/col × 1 | AA12: 10 | AB12: 108 | AC12: 1.17 | AD12: =ROUND(AA12^2/162.162,3) -> 0.617 | AE12: =ROUND(AB12*AC12*AD12,1) -> 78 | AG12: Bitumen emulsion to top & sides of F1 (C1, E/3) | AH12: S-001/002 F1 4600×4600 (meas.), 1100 thk | AI12: 1 | AJ12: =4.6*4.6+2*(4.6+4.6)*1.1 -> 41.4 | AK12: 1 | AM12: =ROUND(AI12*AJ12*AK12,2) -> 41.4 | AO12: NE chamfer area excluded from rectangle (m²) | AP12: 17.32 | AQ12: S-001: RW Type B diagonal 5.68 m × 6.10 m legs; triangle.
A13: Pit for F4 (C1 ×2, F/5a–5) | B13: S-001 F4 7050×4200 (meas.), 1100 thk | C13: 1 | D13: 7.05 | E13: 4.2 | F13: =$AP$7-($AP$8-1.1-$AP$10) -> 3.45 | G13: =ROUND(C13*D13*E13*F13,1) -> 102.2 | I13: Blinding under F9 (C9 + lift core 1) | J13: S-001/002 F9 combined, 41.98 m² (meas.), 600 thk | K13: 1 | L13: 41.98 | M13: 1 | N13: =$AP$10 -> 0.05 | O13: =ROUND(K13*L13*M13*N13,2) -> 2.1 | Q13: Sides of F9 (C9 + lift core 1) (perimeter scaled from area) | R13: S-001/002 F9 combined, 41.98 m² (meas.), 600 thk | S13: 1 | T13: =4*SQRT(K29*L29) -> 25.91679 | U13: 1 | V13: 0.6 | W13: =ROUND(S13*T13*U13*V13,2) -> 15.55 | Y13: C3 ×1 (S-039–043) | Z13: H1008 – 54/col × 1 | AA13: 10 | AB13: 54 | AC13: 1.18 | AD13: =ROUND(AA13^2/162.162,3) -> 0.617 | AE13: =ROUND(AB13*AC13*AD13,1) -> 39.3 | AG13: Bitumen emulsion to top & sides of F1 (C1, E/5) | AH13: S-001/002 F1 4400×4400 (meas.), 1100 thk | AI13: 1 | AJ13: =4.4*4.4+2*(4.4+4.4)*1.1 -> 38.72 | AK13: 1 | AM13: =ROUND(AI13*AJ13*AK13,2) -> 38.72 | AO13: Basement plan area to outer face of RW (m²) | AP13: =(53.65+0.3)*(29.85+0.3)-AP12 -> 1609.2725 | AQ13: Grid A–J 53.65 m × grid 1–6 29.85 m (S-001) + 150 mm each side to outer face of 300 RW.
A14: Pit for F5 (W2 + C3) | B14: S-001 F5 L-shaped, 30.20 m² (meas.), 1100 thk | C14: 1 | D14: 30.2 | E14: 1 | F14: =$AP$7-($AP$8-1.1-$AP$10) -> 3.45 | G14: =ROUND(C14*D14*E14*F14,1) -> 104.2 | I14: Blinding under F3 (C6 ×7, C7 ×1) | J14: S-001 F3 2400×2400, 400 thk; 8 No. | K14: 8 | L14: 2.4 | M14: 2.4 | N14: =$AP$10 -> 0.05 | O14: =ROUND(K14*L14*M14*N14,2) -> 2.3 | Q14: Sides of F3 (C6 ×7, C7 ×1) | R14: S-001 F3 2400×2400, 400 thk; 8 No. | S14: 8 | T14: 4.8 | U14: 2 | V14: 0.4 | W14: =ROUND(S14*T14*U14*V14,2) -> 30.72 | Y14: C3 ×1 (S-039–043) | Z14: H1009 – 54/col × 1 | AA14: 10 | AB14: 54 | AC14: 1.18 | AD14: =ROUND(AA14^2/162.162,3) -> 0.617 | AE14: =ROUND(AB14*AC14*AD14,1) -> 39.3 | AG14: Bitumen emulsion to top & sides of F2 (C4/C1, grid 2 C,D,E) | AH14: S-002 F2 4400×4400, 1100 thk; 3 No. | AI14: 3 | AJ14: =4.4*4.4+2*(4.4+4.4)*1.1 -> 38.72 | AK14: 1 | AM14: =ROUND(AI14*AJ14*AK14,2) -> 116.16 | AO14: Basement slab area (m²) | AP14: =(53.65-0.3)*(29.85-0.3)-AP12-5*2.75-2*2.65 -> 1540.1225 | AQ14: Inside faces of RW less lift core 1 (5.00×2.75) and core 2 (2.00×2.65) footprints (S-003).
A15: Pit for F6 (W1) | B15: S-001 F6 4000×5700 (meas.), 600 thk | C15: 1 | D15: 4 | E15: 5.7 | F15: =$AP$7-($AP$8-0.6-$AP$10) -> 2.95 | G15: =ROUND(C15*D15*E15*F15,1) -> 67.3 | I15: Blinding under F10/F11 (C8 ×5, C10A, C10B, C10 ×2 grid 1) | J15: S-001/002 1500×1500, 400 thk; 9 No. | K15: 9 | L15: 1.5 | M15: 1.5 | N15: =$AP$10 -> 0.05 | O15: =ROUND(K15*L15*M15*N15,2) -> 1.01 | Q15: Sides of F10/F11 (C8 ×5, C10A, C10B, C10 ×2 grid 1) | R15: S-001/002 1500×1500, 400 thk; 9 No. | S15: 9 | T15: 3 | U15: 2 | V15: 0.4 | W15: =ROUND(S15*T15*U15*V15,2) -> 21.6 | Y15: C4 ×1 (S-039–043) | Z15: H2506 – 16/col × 1 | AA15: 25 | AB15: 16 | AC15: 5.575 | AD15: =ROUND(AA15^2/162.162,3) -> 3.854 | AE15: =ROUND(AB15*AC15*AD15,1) -> 343.8 | AG15: Bitumen emulsion to top & sides of F4 (C1 ×2, F/5a–5) | AH15: S-001 F4 7050×4200 (meas.), 1100 thk | AI15: 1 | AJ15: =7.05*4.2+2*(7.05+4.2)*1.1 -> 54.36 | AK15: 1 | AM15: =ROUND(AI15*AJ15*AK15,2) -> 54.36 | AO15: Working space allowance width (m) | AP15: 0.6 | AQ15: ASSUMED standard 600 mm outside RW for formwork/tanking.
A16: Pit for F7 (W3) | B16: S-002 F7 3000×4500, 600 thk | C16: 1 | D16: 3 | E16: 4.5 | F16: =$AP$7-($AP$8-0.6-$AP$10) -> 2.95 | G16: =ROUND(C16*D16*E16*F16,1) -> 39.8 | I16: Blinding under RW bases (A + B) | J16: S-005 base 2500 wide | K16: 1 | L16: =$AP$16+$AP$17 -> 123.4 | M16: =$AP$20 -> 2.5 | N16: =$AP$10 -> 0.05 | O16: =ROUND(K16*L16*M16*N16,2) -> 15.43 | Q16: TOTAL SIDES OF BASES (m²) | W16: =ROUND(SUM(W5:W15),0) -> 253 | Y16: C4 ×1 (S-039–043) | Z16: H2502 – 16/col × 1 | AA16: 25 | AB16: 16 | AC16: 6.1 | AD16: =ROUND(AA16^2/162.162,3) -> 3.854 | AE16: =ROUND(AB16*AC16*AD16,1) -> 376.2 | AG16: Bitumen emulsion to top & sides of F5 (W2 + C3) | AH16: S-001 F5 L-shaped, 30.20 m² (meas.), 1100 thk | AI16: 1 | AJ16: =K25*L25+4*SQRT(K25*L25)*1.1 -> 54.379992 | AK16: 1 | AM16: =ROUND(AI16*AJ16*AK16,2) -> 54.38 | AO16: RW Type A length (m) | AP16: 68 | AQ16: S-005 "LENGTH = 68 m" (grids A and 6 A–H).
A17: Pit for F8 (lift core 2 + W4/W5) | B17: S-001 F8 combined, 56.25 m² (meas.), 600 thk | C17: 1 | D17: 56.25 | E17: 1 | F17: =$AP$7-($AP$8-0.6-$AP$10) -> 2.95 | G17: =ROUND(C17*D17*E17*F17,1) -> 165.9 | I17: Blinding under strip footings | J17: S-001 450 wide | K17: 1 | L17: =$AP$22 -> 207 | M17: 0.45 | N17: =$AP$10 -> 0.05 | O17: =ROUND(K17*L17*M17*N17,2) -> 4.66 | Y17: C4 ×1 (S-039–043) | Z17: H1001 – 44/col × 1 | AA17: 10 | AB17: 44 | AC17: 1.88 | AD17: =ROUND(AA17^2/162.162,3) -> 0.617 | AE17: =ROUND(AB17*AC17*AD17,1) -> 51 | AG17: Bitumen emulsion to top & sides of F6 (W1) | AH17: S-001 F6 4000×5700 (meas.), 600 thk | AI17: 1 | AJ17: =4*5.7+2*(4+5.7)*0.6 -> 34.44 | AK17: 1 | AM17: =ROUND(AI17*AJ17*AK17,2) -> 34.44 | AO17: RW Type B length (m) | AP17: 55.4 | AQ17: S-005 "LENGTH = 55.4 m" (measured on S-004 ≈ 56.2 m – query).
A18: Pit for F9 (C9 + lift core 1) | B18: S-001/002 F9 combined, 41.98 m² (meas.), 600 thk | C18: 1 | D18: 41.98 | E18: 1 | F18: =$AP$7-($AP$8-0.6-$AP$10) -> 2.95 | G18: =ROUND(C18*D18*E18*F18,1) -> 123.8 | I18: TOTAL BLINDING | O18: =ROUND(SUM(O5:O17),1) -> 38.1 | Q18: Edges of RW bases 400 high (both edges) | R18: S-005 | S18: 1 | T18: =$AP$16+$AP$17 -> 123.4 | U18: 2 | V18: =$AP$21 -> 0.4 | W18: =ROUND(S18*T18*U18*V18,2) -> 98.72 | Y18: C4 ×1 (S-039–043) | Z18: H1002 – 132/col × 1 | AA18: 10 | AB18: 132 | AC18: 1.32 | AD18: =ROUND(AA18^2/162.162,3) -> 0.617 | AE18: =ROUND(AB18*AC18*AD18,1) -> 107.5 | AG18: Bitumen emulsion to top & sides of F7 (W3) | AH18: S-002 F7 3000×4500, 600 thk | AI18: 1 | AJ18: =3*4.5+2*(3+4.5)*0.6 -> 22.5 | AK18: 1 | AM18: =ROUND(AI18*AJ18*AK18,2) -> 22.5 | AO18: RW Type A wall height above base (m) | AP18: 3.65 | AQ18: S-005: 2000 + 150 + 1500.
A19: Pit for F3 (C6 ×7, C7 ×1) | B19: S-001 F3 2400×2400, 400 thk; 8 No. | C19: 8 | D19: 2.4 | E19: 2.4 | F19: =$AP$7-($AP$8-0.4-$AP$10) -> 2.75 | G19: =ROUND(C19*D19*E19*F19,1) -> 126.7 | Q19: Sides of strip footings 225 high | R19: S-001 | S19: 1 | T19: =$AP$22 -> 207 | U19: 2 | V19: 0.225 | W19: =ROUND(S19*T19*U19*V19,2) -> 93.15 | Y19: C6 ×7 (S-039–043) | Z19: H2001 – 8/col × 7 | AA19: 20 | AB19: 56 | AC19: 5.575 | AD19: =ROUND(AA19^2/162.162,3) -> 2.467 | AE19: =ROUND(AB19*AC19*AD19,1) -> 770.2 | AG19: Bitumen emulsion to top & sides of F8 (lift core 2 + W4/W5) | AH19: S-001 F8 combined, 56.25 m² (meas.), 600 thk | AI19: 1 | AJ19: =K28*L28+4*SQRT(K28*L28)*0.6 -> 74.25 | AK19: 1 | AM19: =ROUND(AI19*AJ19*AK19,2) -> 74.25 | AO19: RW Type B wall height above base to GF slab soffit (m) | AP19: 5.625 | AQ19: S-005: 2000 + 150 + 3475 (225 GF slab measured with slab).
A20: Pit for F10/F11 (C8 ×5, C10A, C10B, C10 ×2 grid 1) | B20: S-001/002 1500×1500, 400 thk; 9 No. | C20: 9 | D20: 1.5 | E20: 1.5 | F20: =$AP$7-($AP$8-0.4-$AP$10) -> 2.75 | G20: =ROUND(C20*D20*E20*F20,1) -> 55.7 | I20: Isolated / combined pad foundations C25/30 | Q20: TOTAL SIDES OF RW BASES & STRIPS (m²) | W20: =ROUND(SUM(W18:W19),0) -> 192 | Y20: C6 ×7 (S-039–043) | Z20: H2002 – 8/col × 7 | AA20: 20 | AB20: 56 | AC20: 2.825 | AD20: =ROUND(AA20^2/162.162,3) -> 2.467 | AE20: =ROUND(AB20*AC20*AD20,1) -> 390.3 | AG20: Bitumen emulsion to top & sides of F9 (C9 + lift core 1) | AH20: S-001/002 F9 combined, 41.98 m² (meas.), 600 thk | AI20: 1 | AJ20: =K29*L29+4*SQRT(K29*L29)*0.6 -> 57.530074 | AK20: 1 | AM20: =ROUND(AI20*AJ20*AK20,2) -> 57.53 | AO20: RW base width (m) | AP20: 2.5 | AQ20: S-005.
A21: TOTAL PIT EXCAVATION | G21: =ROUND(SUM(G10:G20),0) -> 1126 | I21: Pad F1 (C1, E/3) | J21: S-001/002 F1 4600×4600 (meas.), 1100 thk | K21: 1 | L21: 4.6 | M21: 4.6 | N21: 1.1 | O21: =ROUND(K21*L21*M21*N21,2) -> 23.28 | Y21: C6 ×7 (S-039–043) | Z21: H1010 – 56/col × 7 | AA21: 10 | AB21: 392 | AC21: 1.08 | AD21: =ROUND(AA21^2/162.162,3) -> 0.617 | AE21: =ROUND(AB21*AC21*AD21,1) -> 261.2 | AG21: Bitumen emulsion to top & sides of F3 (C6 ×7, C7 ×1) | AH21: S-001 F3 2400×2400, 400 thk; 8 No. | AI21: 8 | AJ21: =2.4*2.4+2*(2.4+2.4)*0.4 -> 9.6 | AK21: 1 | AM21: =ROUND(AI21*AJ21*AK21,2) -> 76.8 | AO21: RW base thickness (m) | AP21: 0.4 | AQ21: S-005; "400 mm THICKNESS" labels S-001.
I22: Pad F1 (C1, E/5) | J22: S-001/002 F1 4400×4400 (meas.), 1100 thk | K22: 1 | L22: 4.4 | M22: 4.4 | N22: 1.1 | O22: =ROUND(K22*L22*M22*N22,2) -> 21.3 | Q22: Walls (vertical) | Y22: C6 ×7 (S-039–043) | Z22: H1011 – 112/col × 7 | AA22: 10 | AB22: 784 | AC22: 0.68 | AD22: =ROUND(AA22^2/162.162,3) -> 0.617 | AE22: =ROUND(AB22*AC22*AD22,1) -> 328.9 | AG22: Bitumen emulsion to top & sides of F10/F11 (C8 ×5, C10A, C10B, C10 ×2 grid 1) | AH22: S-001/002 1500×1500, 400 thk; 9 No. | AI22: 9 | AJ22: =1.5*1.5+2*(1.5+1.5)*0.4 -> 4.65 | AK22: 1 | AM22: =ROUND(AI22*AJ22*AK22,2) -> 41.85 | AO22: Strip footing length net between bases (m) | AP22: 207 | AQ22: S-001 "strip footing 450x225" measured on plan, net of pads/RW bases.
A23: Excavation below formation – trenches (m³) | I23: Pad F2 (C4/C1, grid 2 C,D,E) | J23: S-002 F2 4400×4400, 1100 thk; 3 No. | K23: 3 | L23: 4.4 | M23: 4.4 | N23: 1.1 | O23: =ROUND(K23*L23*M23*N23,2) -> 63.89 | Q23: RW Type A both faces | R23: S-005 | S23: 1 | T23: =$AP$16-10*0.7 -> 61 | U23: 2 | V23: =$AP$18 -> 3.65 | W23: =ROUND(S23*T23*U23*V23,2) -> 445.3 | Y23: C7 ×1 (S-039–043) | Z23: H2001 – 8/col × 1 | AA23: 20 | AB23: 8 | AC23: 5.575 | AD23: =ROUND(AA23^2/162.162,3) -> 2.467 | AE23: =ROUND(AB23*AC23*AD23,1) -> 110 | AG23: Bitumen emulsion to RW bases (top heel + edges) | AI23: 1 | AJ23: =$AP$16+$AP$17 -> 123.4 | AK23: =$AP$20-0.3+2*$AP$21 -> 3 | AM23: =ROUND(AI23*AJ23*AK23,2) -> 370.2 | AO23: Perimeter of basement excavation for earthwork support (m) | AP23: =AP16+AP17+38.95 -> 162.35 | AQ23: RW A + RW B + grid 1 A–H (no RW shown – query).
A24: Trench for RW Type A base | B24: S-005 | C24: 1 | D24: =$AP$16 -> 68 | E24: =$AP$20 -> 2.5 | F24: =$AP$7-($AP$9-$AP$10) -> 2.05 | G24: =ROUND(C24*D24*E24*F24,1) -> 348.5 | I24: Pad F4 (C1 ×2, F/5a–5) | J24: S-001 F4 7050×4200 (meas.), 1100 thk | K24: 1 | L24: 7.05 | M24: 4.2 | N24: 1.1 | O24: =ROUND(K24*L24*M24*N24,2) -> 32.57 | Q24: RW Type B both faces | R24: S-005 | S24: 1 | T24: =$AP$17 -> 55.4 | U24: 2 | V24: =$AP$19 -> 5.625 | W24: =ROUND(S24*T24*U24*V24,2) -> 623.25 | Y24: C7 ×1 (S-039–043) | Z24: H2003 – 8/col × 1 | AA24: 20 | AB24: 8 | AC24: 6.075 | AD24: =ROUND(AA24^2/162.162,3) -> 2.467 | AE24: =ROUND(AB24*AC24*AD24,1) -> 119.9 | AG24: Bitumen emulsion to strip footings | AI24: 1 | AJ24: =$AP$22 -> 207 | AK24: =0.45+2*0.225 -> 0.9 | AM24: =ROUND(AI24*AJ24*AK24,2) -> 186.3
A25: Trench for RW Type B base | B25: S-005 | C25: 1 | D25: =$AP$17 -> 55.4 | E25: =$AP$20 -> 2.5 | F25: =$AP$7-($AP$9-$AP$10) -> 2.05 | G25: =ROUND(C25*D25*E25*F25,1) -> 283.9 | I25: Pad F5 (W2 + C3) | J25: S-001 F5 L-shaped, 30.20 m² (meas.), 1100 thk | K25: 1 | L25: 30.2 | M25: 1 | N25: 1.1 | O25: =ROUND(K25*L25*M25*N25,2) -> 33.22 | Q25: Lift core 1 faces (outer 15.50 + inner 17.00 m) | R25: S-003 | S25: 1 | T25: 32.5 | U25: 1 | V25: 6.9 | W25: =ROUND(S25*T25*U25*V25,2) -> 224.25 | Y25: C7 ×1 (S-039–043) | Z25: H1010 – 56/col × 1 | AA25: 10 | AB25: 56 | AC25: 1.08 | AD25: =ROUND(AA25^2/162.162,3) -> 0.617 | AE25: =ROUND(AB25*AC25*AD25,1) -> 37.3 | AG25: Bitumen emulsion to columns below formation | AI25: 1 | AJ25: =K50*2*(L50+M50)+K51*2*(L51+M51)+K52*2*(L52+M52)+K53*2*(L53+M53)+K54*2*(L54+M54)+K55*2*(L55+M55)+K56*2*(L56+M56)+K57*2*(L57+M57)+K58*2*(L58+M58)+K59*2*(L59+M59) -> 61 | AK25: =$AP$7-$AP$8 -> 2.3 | AM25: =ROUND(AI25*AJ25*AK25,2) -> 140.3
A26: Trench for strip footings (assumed at formation) | B26: S-001 – level to confirm | C26: 1 | D26: =$AP$22 -> 207 | E26: 0.45 | F26: =0.225+$AP$10 -> 0.275 | G26: =ROUND(C26*D26*E26*F26,1) -> 25.6 | I26: Pad F6 (W1) | J26: S-001 F6 4000×5700 (meas.), 600 thk | K26: 1 | L26: 4 | M26: 5.7 | N26: 0.6 | O26: =ROUND(K26*L26*M26*N26,2) -> 13.68 | Q26: Lift core 2 faces (outer 9.30 + inner 7.70 m) | R26: S-003 | S26: 1 | T26: 17 | U26: 1 | V26: 6.9 | W26: =ROUND(S26*T26*U26*V26,2) -> 117.3 | Y26: C7 ×1 (S-039–043) | Z26: H1011 – 112/col × 1 | AA26: 10 | AB26: 112 | AC26: 0.68 | AD26: =ROUND(AA26^2/162.162,3) -> 0.617 | AE26: =ROUND(AB26*AC26*AD26,1) -> 47 | AG26: TOTAL BITUMEN EMULSION (m²) | AM26: =ROUND(SUM(AM12:AM25),0) -> 1309
A27: Trench for ground beams 300×200 downstand | B27: S-006 | C27: 1 | D27: 406 | E27: 0.2 | F27: 0.15 | G27: =ROUND(C27*D27*E27*F27,1) -> 12.2 | I27: Pad F7 (W3) | J27: S-002 F7 3000×4500, 600 thk | K27: 1 | L27: 3 | M27: 4.5 | N27: 0.6 | O27: =ROUND(K27*L27*M27*N27,2) -> 8.1 | Q27: W4 300 thk faces + ends | R27: S-003: 200+2200+2850+200 = 5.45 m | S27: 1 | T27: =2*5.45+2*0.3 -> 11.5 | U27: 1 | V27: 6.9 | W27: =ROUND(S27*T27*U27*V27,2) -> 79.35 | Y27: C8 ×5 (S-039–043) | Z27: H2001 – 8/col × 5 | AA27: 20 | AB27: 40 | AC27: 5.575 | AD27: =ROUND(AA27^2/162.162,3) -> 2.467 | AE27: =ROUND(AB27*AC27*AD27,1) -> 550.1
A28: Trench for ground beam 600×200 downstand | B28: S-006 | C28: 1 | D28: 38.6 | E28: 0.2 | F28: 0.45 | G28: =ROUND(C28*D28*E28*F28,1) -> 3.5 | I28: Pad F8 (lift core 2 + W4/W5) | J28: S-001 F8 combined, 56.25 m² (meas.), 600 thk | K28: 1 | L28: 56.25 | M28: 1 | N28: 0.6 | O28: =ROUND(K28*L28*M28*N28,2) -> 33.75 | Q28: W5 300 thk faces + ends | R28: S-003: 5.45 m | S28: 1 | T28: =2*5.45+2*0.3 -> 11.5 | U28: 1 | V28: 6.9 | W28: =ROUND(S28*T28*U28*V28,2) -> 79.35 | Y28: C8 ×5 (S-039–043) | Z28: H2002 – 8/col × 5 | AA28: 20 | AB28: 40 | AC28: 2.825 | AD28: =ROUND(AA28^2/162.162,3) -> 2.467 | AE28: =ROUND(AB28*AC28*AD28,1) -> 278.8 | AG28: Kickers (m)
A29: TOTAL TRENCH EXCAVATION | G29: =ROUND(SUM(G24:G28),0) -> 674 | I29: Pad F9 (C9 + lift core 1) | J29: S-001/002 F9 combined, 41.98 m² (meas.), 600 thk | K29: 1 | L29: 41.98 | M29: 1 | N29: 0.6 | O29: =ROUND(K29*L29*M29*N29,2) -> 25.19 | Q29: W1 300 thk faces + ends | R29: S-003: 150+1750+250 = 2.15 m | S29: 1 | T29: =2*2.15+2*0.3 -> 4.9 | U29: 1 | V29: 6.9 | W29: =ROUND(S29*T29*U29*V29,2) -> 33.81 | Y29: C8 ×5 (S-039–043) | Z29: H1012 – 56/col × 5 | AA29: 10 | AB29: 280 | AC29: 1.08 | AD29: =ROUND(AA29^2/162.162,3) -> 0.617 | AE29: =ROUND(AB29*AC29*AD29,1) -> 186.6 | AG29: 75 mm kicker to RW | AH29: S-005 | AI29: 1 | AJ29: =$AP$16+$AP$17 -> 123.4 | AK29: 1 | AM29: =ROUND(AI29*AJ29*AK29,0) -> 123
I30: Pad F3 (C6 ×7, C7 ×1) | J30: S-001 F3 2400×2400, 400 thk; 8 No. | K30: 8 | L30: 2.4 | M30: 2.4 | N30: 0.4 | O30: =ROUND(K30*L30*M30*N30,2) -> 18.43 | Q30: W2 300 thk faces + ends | R30: S-003: 150+1900+250 = 2.30 m | S30: 1 | T30: =2*2.3+2*0.3 -> 5.2 | U30: 1 | V30: 6.9 | W30: =ROUND(S30*T30*U30*V30,2) -> 35.88 | Y30: C8 ×5 (S-039–043) | Z30: H1013 – 112/col × 5 | AA30: 10 | AB30: 560 | AC30: 0.68 | AD30: =ROUND(AA30^2/162.162,3) -> 0.617 | AE30: =ROUND(AB30*AC30*AD30,1) -> 235
A31: Working space & support | I31: Pad F10/F11 (C8 ×5, C10A, C10B, C10 ×2 grid 1) | J31: S-001/002 1500×1500, 400 thk; 9 No. | K31: 9 | L31: 1.5 | M31: 1.5 | N31: 0.4 | O31: =ROUND(K31*L31*M31*N31,2) -> 8.1 | Q31: W3 300 thk faces + ends | R31: S-001 scaled ≈1.85 m (dim. not given – query); top +0.45 | S31: 1 | T31: =2*1.85+2*0.3 -> 4.3 | U31: 1 | V31: 6.75 | W31: =ROUND(S31*T31*U31*V31,2) -> 29.03 | Y31: C9 ×1 (S-039–043) | Z31: H2506 – 16/col × 1 | AA31: 25 | AB31: 16 | AC31: 5.575 | AD31: =ROUND(AA31^2/162.162,3) -> 3.854 | AE31: =ROUND(AB31*AC31*AD31,1) -> 343.8
A32: Working space allowance to RW outer face (m²) | B32: RW length × depth EGL to RW formation | C32: 1 | D32: =$AP$16+$AP$17 -> 123.4 | E32: 1 | F32: =$AP$3-($AP$9-$AP$10) -> 5 | G32: =ROUND(C32*D32*E32*F32,0) -> 617 | I32: TOTAL PAD CONCRETE | O32: =ROUND(SUM(O21:O31),1) -> 281.5 | Q32: TOTAL WALL FORMWORK (m²) | W32: =ROUND(SUM(W23:W31),0) -> 1668 | Y32: C9 ×1 (S-039–043) | Z32: H2502 – 16/col × 1 | AA32: 25 | AB32: 16 | AC32: 6.1 | AD32: =ROUND(AA32^2/162.162,3) -> 3.854 | AE32: =ROUND(AB32*AC32*AD32,1) -> 376.2
A33: Earthwork support to basement perimeter, max depth >4 m (m²) | B33: Perimeter × depth EGL to RW formation | C33: 1 | D33: =$AP$23 -> 162.35 | E33: 1 | F33: =$AP$3-($AP$9-$AP$10) -> 5 | G33: =ROUND(C33*D33*E33*F33,0) -> 812 | Y33: C9 ×1 (S-039–043) | Z33: H1001 – 44/col × 1 | AA33: 10 | AB33: 44 | AC33: 1.88 | AD33: =ROUND(AA33^2/162.162,3) -> 0.617 | AE33: =ROUND(AB33*AC33*AD33,1) -> 51
A34: Filling, disposal, hardcore | I34: Base count (check = 28: 6×C1/C4/C9/C3 group pads + 8 F3 + 9 F10/F11) | O34: =K21+K22+K23+K24+K25+K26+K27+K28+K29+K30+K31 -> 28 | Q34: Columns | Y34: C9 ×1 (S-039–043) | Z34: H1002 – 132/col × 1 | AA34: 10 | AB34: 132 | AC34: 1.32 | AD34: =ROUND(AA34^2/162.162,3) -> 0.617 | AE34: =ROUND(AB34*AC34*AD34,1) -> 107.5
A35: Filling to excavation (pits & trenches) – selected/hardcore fill 95% MDD | B35: Note: pits + trenches − concrete below formation | C35: 1 | G35: =ROUND(G21+G29-(O18+O32+O39+O42+O113+O75),0) -> 1227 | Q35: Sides of C1 500×500 (GF +750) | R35: S-039 6 No.; −6.300 to +0.525 | S35: 6 | T35: =2*(0.5+0.5) -> 2 | U35: 1 | V35: 6.825 | W35: =ROUND(S35*T35*U35*V35,2) -> 81.9 | Y35: C10 ×10 (S-039–043) | Z35: H2001 – 12/col × 10 | AA35: 20 | AB35: 120 | AC35: 5.575 | AD35: =ROUND(AA35^2/162.162,3) -> 2.467 | AE35: =ROUND(AB35*AC35*AD35,1) -> 1650.4
A36: Disposal of surplus excavated material off site | B36: Note: bulk + pits + trenches − filling | C36: 1 | G36: =ROUND(G8+G21+G29-G35,0) -> 5320 | I36: Retaining wall bases & strip footings C25/30 | Q36: Sides of C3 800×300 (GF +000) | R36: S-039 1 No.; −6.300 to −0.225 | S36: 1 | T36: =2*(0.8+0.3) -> 2.2 | U36: 1 | V36: 6.075 | W36: =ROUND(S36*T36*U36*V36,2) -> 13.37 | Y36: C10 ×10 (S-039–043) | Z36: H2002 – 12/col × 10 | AA36: 20 | AB36: 120 | AC36: 2.825 | AD36: =ROUND(AA36^2/162.162,3) -> 2.467 | AE36: =ROUND(AB36*AC36*AD36,1) -> 836.3
A37: Hardcore bed under basement slab | B37: Basement slab area × assumed thickness | C37: 1 | D37: =$AP$14 -> 1540.1225 | E37: 1 | F37: =$AP$6 -> 0.15 | G37: =ROUND(C37*D37*E37*F37,0) -> 231 | I37: RW Type A base | J37: S-005 2500×400 | K37: 1 | L37: =$AP$16 -> 68 | M37: =$AP$20 -> 2.5 | N37: =$AP$21 -> 0.4 | O37: =ROUND(K37*L37*M37*N37,2) -> 68 | Q37: Sides of C4 500×500 (GF +750) | R37: S-040 1 No. | S37: 1 | T37: =2*(0.5+0.5) -> 2 | U37: 1 | V37: 6.825 | W37: =ROUND(S37*T37*U37*V37,2) -> 13.65 | Y37: C10 ×10 (S-039–043) | Z37: H1014 – 56/col × 10 | AA37: 10 | AB37: 560 | AC37: 1.88 | AD37: =ROUND(AA37^2/162.162,3) -> 0.617 | AE37: =ROUND(AB37*AC37*AD37,1) -> 649.6
A38: Compact bottoms of excavation (m²) | B38: Pits + RW trenches + strip trenches plan | C38: 1 | G38: =ROUND(C10*D10*E10+C11*D11*E11+C12*D12*E12+C13*D13*E13+C14*D14*E14+C15*D15*E15+C16*D16*E16+C17*D17*E17+C18*D18*E18+C19*D19*E19+C20*D20*E20+($AP$16+$AP$17)*$AP$20+$AP$22*0.45,0) -> 761 | I38: RW Type B base | J38: S-005 2500×400 | K38: 1 | L38: =$AP$17 -> 55.4 | M38: =$AP$20 -> 2.5 | N38: =$AP$21 -> 0.4 | O38: =ROUND(K38*L38*M38*N38,2) -> 55.4 | Q38: Sides of C6 400×400 (GF +000) | R38: S-040 7 No. | S38: 7 | T38: =2*(0.4+0.4) -> 1.6 | U38: 1 | V38: 6.075 | W38: =ROUND(S38*T38*U38*V38,2) -> 68.04 | Y38: C10 ×10 (S-039–043) | Z38: H1015 – 56/col × 10 | AA38: 10 | AB38: 560 | AC38: 1.37 | AD38: =ROUND(AA38^2/162.162,3) -> 0.617 | AE38: =ROUND(AB38*AC38*AD38,1) -> 473.4
A39: Compact surface of hardcore (m²) | B39: Note: basement slab area | C39: 1 | D39: =$AP$14 -> 1540.1225 | E39: 1 | G39: =ROUND(C39*D39*E39,0) -> 1540 | I39: TOTAL RW BASES | O39: =ROUND(SUM(O37:O38),1) -> 123.4 | Q39: Sides of C7 400×400 (GF +000) | R39: S-040 1 No. | S39: 1 | T39: =2*(0.4+0.4) -> 1.6 | U39: 1 | V39: 6.075 | W39: =ROUND(S39*T39*U39*V39,2) -> 9.72 | Y39: C10 ×10 (S-039–043) | Z39: H1016 – 56/col × 10 | AA39: 10 | AB39: 560 | AC39: 1.06 | AD39: =ROUND(AA39^2/162.162,3) -> 0.617 | AE39: =ROUND(AB39*AC39*AD39,1) -> 366.3
A40: Level and compact basement formation (m²) | B40: Note: basement slab area | C40: 1 | D40: =$AP$14 -> 1540.1225 | E40: 1 | G40: =ROUND(C40*D40*E40,0) -> 1540 | Q40: Sides of C8 300×300 (GF +000) | R40: S-041 5 No. | S40: 5 | T40: =2*(0.3+0.3) -> 1.2 | U40: 1 | V40: 6.075 | W40: =ROUND(S40*T40*U40*V40,2) -> 36.45 | Y40: C10A ×1 (S-039–043) | Z40: H2003 – 12/col × 1 | AA40: 20 | AB40: 12 | AC40: 5.575 | AD40: =ROUND(AA40^2/162.162,3) -> 2.467 | AE40: =ROUND(AB40*AC40*AD40,1) -> 165
A41: Reconciliation checks | I41: Strip footings 450×225 | J41: S-001 (level/detail not given – query) | K41: 1 | L41: =$AP$22 -> 207 | M41: 0.45 | N41: 0.225 | O41: =ROUND(K41*L41*M41*N41,2) -> 20.96 | Q41: Sides of C9 500×500 (GF +750) | R41: S-041 1 No. | S41: 1 | T41: =2*(0.5+0.5) -> 2 | U41: 1 | V41: 6.825 | W41: =ROUND(S41*T41*U41*V41,2) -> 13.65 | Y41: C10A ×1 (S-039–043) | Z41: H1014 – 24/col × 1 | AA41: 10 | AB41: 24 | AC41: 1.88 | AD41: =ROUND(AA41^2/162.162,3) -> 0.617 | AE41: =ROUND(AB41*AC41*AD41,1) -> 27.8
...

Sheet QUERIES
A1: QS QUERIES ON STRUCTURAL DRAWINGS – PRIORITY HOUSE (ESPCo, Aug 2026, Rev 001)
A3: No. | B3: QUERY | C3: EFFECT ON THIS BoQ / ASSUMPTION MADE
A4: A. SITE, LEVELS & SETTING OUT
A5: 1 | B5: No topographic survey or existing ground levels are issued with the structural set (architectural sheets A093 "Topo levels on block plan" and A094 "Topo on basement level" are listed but missing). The site is sloping; excavation depths cannot be fixed. Issue a levelled grid survey related to the GF ±0.000 datum and state that datum relative to MSL. | C5: Bulk excavation, earthwork support and disposal are priced on an ASSUMED average EGL of −1.05 m (calculations AP3).
A6: 2 | B6: Structural grid 1–6 totals 29,850 mm (5150/2850/3550/2500/3550/2200/2850/7200) but the architectural grid totals 29,500 mm (5150/2950/3450/2525/3575/2175/2825/6850). Bay 5–6 differs by 350 mm. Confirm which governs. | C6: Basement plan area and slab areas follow the structural grid.
A7: 3 | B7: Basement level is −3600 on the retaining wall details (S-005) but −3700 on the basement GA (CFL −3700/−3550) and on all column elevations. Confirm the structural level and the 150 mm step between CFL −3700 and −3550 zones (no detail). | C7: −3.700 adopted.
A8: 4 | B8: Founding levels conflict: column elevations give top of base 2,600 below basement level (−6.300), while the RW base top is 2,000 below −3,600 (−5.600). Confirm formation levels for pads and RW bases and confirm they satisfy the geotechnical report (not issued). | C8: Pads measured to −6.300 top; RW base underside −6.000.
A9: 5 | B9: Plot is 0.16 ha (1,619 m²) and the basement footprint to outer face of walls is ~1,609 m². Excavation is effectively boundary-to-boundary up to ~5 m deep. No temporary works, embedded retaining wall (sheet/secant/contiguous piles), propping or underpinning is shown. | C9: Earthwork support measured + provisional sum for temporary works.
A10: B. PARTY WALL – SUNNY FM (45 Hilla Limann Avenue)
A11: 6 | B11: Confirm which boundary is shared with Sunny FM (west grid A or south grid 6 – both are RW Type A). Provide the foundation type/depth of the Sunny FM building; a 6 m deep excavation at the party line will undermine shallow footings. | C11: Item for dilapidation survey and monitoring included.
A12: 7 | B12: RW Type A is detailed as a cantilever wall with a 2,500 mm base and backfill on the retained side. On the party side there is no space to excavate for the base heel/backfill/working space. Confirm the base projects inward only, and the construction sequence (bottom-up vs. embedded wall). | C12: Working space measured to both RW types – omit on party side if embedded wall adopted.
A13: 8 | B13: RW Type A rises only 1,500 mm above basement level (top −2.100). Confirm what forms the external wall from −2.100 to GF on grids A and 6 between the C10 columns (the architectural basement plan shows a full-height concrete wall), and confirm retained ground levels there. | C13: Nothing measured above −2.100 except C10 columns.
A14: 9 | B14: Grid 1 (A–H, north) has no retaining wall or wall footing – only 450×225 strip footings and F10/F11 pads. The architectural plan shows a concrete wall along grid 1. Confirm ground level on the north side and the wall/retaining provision required. | C14: Not measured.
A15: C. FOUNDATIONS
A16: 10 | B16: No foundation details or reinforcement schedules for pads F1–F12 (only plan sizes from setting-out and thickness labels). Issue base sections, bar schedules and starter details. | C16: Steel measured as a PROVISIONAL 90 kg/m³ allowance.
A17: 11 | B17: F1 at E/5 measures 4,400×4,400 on plan whereas F1 at E/3 is dimensioned 4,600×4,500 and measures 4,600×4,600. Confirm F1 sizes. Confirm sizes of F4, F5 (L-shaped), F8 and F9 (combined with lift cores) – not fully dimensioned. | C17: Measured from drawing geometry.
A18: 12 | B18: "Strip footing 450x225" runs on all grid lines between bases: no section, founding level, reinforcement or purpose is given (pads are ~2.3 m deeper than basement formation). Confirm level and detail. | C18: Measured at basement formation level; if at base level add ~210 m³ excavation.
A19: 13 | B19: F12 is marked under C10 columns within the RW base band: confirm whether F12 is a separate pad/thickening or simply the 400 mm RW base. | C19: Treated as RW base.
A20: 14 | B20: Geotechnical report (325 kN/m² allowable bearing) and groundwater level are not issued. Confirm presence of rock and groundwater; dewatering requirement (S-001 concrete note 3). | C20: Rock EO and dewatering included provisionally.
A21: 15 | B21: Notes refer to C25/30 "raft foundations" but the design is pads/combined bases. Confirm concrete grade for foundations and walls (C30/37 for ductile walls).
A22: D. RETAINING WALLS
A23: 16 | B23: No bending schedule for retaining walls; base reinforcement is not labelled; corner detail bars (H16@200, H1610@200) not scheduled. | C23: Steel PROVISIONAL 110 kg/m³.
A24: 17 | B24: Stated lengths: Type A 68 m, Type B 55.4 m. Type B measures ≈56.2 m on S-004 (9.42 + 8.33 diagonal + 23.39 + 15.10). Confirm. | C24: Stated lengths used.
A25: 18 | B25: Waterproofing is "approved water proofing material" – specify the system (membrane type, protection board, drainage), the basement grade (BS 8102 Grade 2/3) and the water stop type at kicker and slab/wall joints.
A26: E. BASEMENT SLAB & GROUND BEAMS
A27: 19 | B27: Basement slab is 150 mm non-suspended (S-006) but column details show 200 mm. Confirm thickness, hardcore thickness (not stated) and DPM gauge ("consult specialist"). | C27: 150 slab + 150 hardcore assumed.
A28: 20 | B28: Ground beam schedule uses R (round mild steel) bars – conflicts with the high-tensile specification. Quantities (85 No. R12 ×9 m ×2 marks, 808 R10 links @225) do not match ~445 m of 300×200/600×200 beams measured (~1,980 links required). Re-issue schedule. | C28: Measured as scheduled – will be under-measured.
A29: 21 | B29: Lift pits (cores 1 and 2) – no pit depth, base, walls or waterproofing detail. | C29: Provisional sum.
A30: F. COLUMNS & WALLS
A31: 22 | B31: Column schedule totals inconsistent with "No. THUS": C6 (7 No.) H1010 total 336 (=6×56), H2001/H2002 total 16 (should be 56); C8 (5 No.) H1013 total 518 (=7×74), H2001/H2002 total 16 (should be 40); C3 H1007 No. each 484 vs total 446; C10A (1 No.) H1014 each 24 vs total 560, H1015/H1016 total 560; C10B is not scheduled (12-H2004 on elevation). C6/C7/C8 link counts on elevations (2× per set = 112) differ from schedule each (74). | C31: Measured from elevation call-outs × No. thus.
A32: 23 | B32: Wall schedules list bar marks H1201/H1202 with diameter 16 mm. Confirm diameter (12 or 16). | C32: Measured as 16 mm per schedule.
A33: 24 | B33: Wall W3 length not dimensioned on S-003 (scaled ≈1.85 m); W4/W5 drawn 300 thick but labelled near "200 mm thick wall" – confirm thicknesses.
A34: 25 | B34: C2 and C5 start at ground floor on 1200×600 / 975×500 / 750×500 beams (transfer). Confirm the transfer beam design.
A35: G. GROUND FLOOR (BASEMENT TOP) SLAB
A36: 26 | B36: No beam reinforcement details/schedules for any GF beam (1350×300, 1200×600, 975×300/500, 750×500/300, 600×300, upstands 600×200/750×200). Confirm notation is depth × width. | C36: Steel PROVISIONAL 180 kg/m³.
A37: 27 | B37: Slab openings (ramp, stairs, lifts, steps) are not dimensioned on the slab drawings; the curved 750×200 upstand around the stair void is not dimensioned. | C37: Voids taken provisionally (ramp 20.82×7.20; stairs/lifts 69.5 m²).
A38: 28 | B38: GF slab bending schedule (LVL +000) bar H1218 "varies 2750–12000" – issue individual lengths. | C38: Mean length 7.375 m used.
A39: 29 | B39: Ramp from basement to ground and Staircase Type 3 (basement–GF): ramp structure not detailed; confirm whether the external ramp (rows 5–6) is suspended or on grade. | C39: Provisional sum.
A40: H. DOCUMENT CONTROL
A41: 30 | B41: Drawings are titled Aug 2026, Rev 001, stamped "Issued for construction", signed 30-09-2026 while submitted "for permit". Confirm status; revision notes are blank.
