Workbook

Sheet Cover Page 
A1: aq
B11: PROPOSED BILLS OF QUANTITIES FOR KANESHIE BLOCK N REDEVELOPMENT
F23: DATE:9/30/2026

Sheet GEN SUMMARY
A1: PROJECT: BLOCK N REDEVELOPMENT
A2: LOCATION: KANESHIE
A3: CLIENT: STATE HOUSING LIMITED
A4: ='Cover Page '!F23 -> DATE:9/30/2026
A5: ITEM | B5: GENERAL SUMMARY | D5: GHC
A7: A | B7: PRELIMINARIES AND GENERAL ITEMS | D7: ='PRELIMS & GEN. ITEMS'!F41 -> 6123000
A9: B | B9: SUBSTRUCTURE (ALL PROVISIONAL) | D9: =SUBSTRUCTURE!F19 -> 13010013
A11: C | B11: GROUND FLOOR (INCL. M1 PARKING LEVEL) | D11: ='GROUND FLR '!F25 -> 4201917.1
A13: D | B13: FIRST FLOOR (INCL. M2 PARKING LEVEL) | D13: ='1ST FLR '!F25 -> 4073182.1
A15: E | B15: SECOND FLOOR (INCL. MEZZANINE PARKING LEVEL) | D15: ='2ND FLR'!F25 -> 4870821.8
A17: F | B17: THIRD FLOOR | D17: ='3RD FLR'!F25 -> 5599162.8
A19: G | B19: FOURTH FLOOR | D19: ='4TH FLR '!F25 -> 5197425.6
A21: H | B21: FIFTH FLOOR | D21: ='5TH FLR '!F25 -> 5106769.7
A23: J | B23: SIXTH FLOOR | D23: ='6TH FLR '!F25 -> 5180255.7
A25: K | B25: SEVENTH FLOOR | D25: ='7TH FLR '!F25 -> 5124646.8
A27: L | B27: EIGHTH FLOOR | D27: ='8TH FLR '!F25 -> 5120461.9
A29: M | B29: NINTH FLOOR | D29: ='9TH FLR '!F27 -> 4768520
A31: N | B31: TENTH FLOOR | D31: ='10TH FLR '!F25 -> 3957995
A33: P | B33: ELEVENTH LEVEL - ROOF TOP TERRACE | D33: ='11TH FLR'!F27 -> 3142285.2
A35: Q | B35: TWELFTH LEVEL - ROOF LEVEL & LIFT CORE | D35: ='12TH FLR '!F19 -> 656113.1
A37: R | B37: LIFTS AND PROVISIONAL SUMS | D37: ='LIFTS & PS'!F17 -> 8770000
B38: SUB - TOTAL (1) | C38: GHC | D38: =SUM(D6:D37) -> 84902569
B41: ADD: STATUTORY LEVIES AND TAXES | C41: 0.2 | D41: =D38*C41 -> 16980514
B43: TOTAL COST OF THE WORKS | C43: GHC | D43: =D41+D38 -> 1.0188308e+08

Sheet PRELIMS & GEN. ITEMS
A2: ='GEN SUMMARY'!A1 -> PROJECT: BLOCK N REDEVELOPMENT
A3: ='GEN SUMMARY'!A2 -> LOCATION: KANESHIE
A4: ='GEN SUMMARY'!A3 -> CLIENT: STATE HOUSING LIMITED
A5: ='GEN SUMMARY'!A4 -> DATE:9/30/2026
B7: BILL NO.1- PRELIMINARIES BILL AND GENERAL CONDITIONS
A8: ITEM | B8: DESCRIPTION | C8: QTY | D8: UNIT | E8: RATE | F8: AMOUNT GHS
B10: SUMMARY
B12: COLLECTION
B13: Page 2 | F13: =F74 -> 0
B15: Page 3 | F15: =F106 -> 0
B17: Page 4 | F17: =F137 -> 910000
B19: Page 5 | F19: =F163 -> 245000
B21: Page 6 | F21: =F186 -> 0
B23: Page 7 | F23: =F216 -> 3000000
B25: Page 8 | F25: =F241 -> 801000
B27: Page 9 | F27: =F268 -> 650000
B29: Page 10 | F29: =F295 -> 60000
B31: Page 11 | F31: =F325 -> 282000
B33: Page 12 | F33: =F355 -> 90000
B35: Page 13 | F35: =F370 -> 25000
B37: Page 14 | F37: =F379 -> 60000
B41: PRELIMINARIES AND GENERAL ITEMS | F41: =SUM(F13:F39) -> 6123000
B42: TOTAL CARRIED TO GENERAL SUMMARY
A43: A | B43: Generally
B44: The contractor shall be deemed to have allowed against each item a rate which complies with all the requirements of the “Preliminaries”. All unpriced preliminaries items shall be deemed to have been included in the general pricing of the works. All item containing “Preliminaries” shall apply to the whole of the works The contractor shall be deemed to have allowed against each item or in his rates of complying with all the requirements of the “Preliminaries”. All item containing “Preliminaries” shall apply to the whole of the works
A46: B | B46: Names of Parties
B47: The names of parties referred to in these Bills of Quantities and in the Conditions of Contract are as follows:-
B48: ENTERPRISE LIFE COMPANY LIMITED
A50: C | B50: ALL DRAWINGS
B51: The drawings used for the preparation of the bills of quantities are scheduled at the Appendix
A53: D | B53: Format of Bills of Quantities
B54: Major portions of this Bills of Quantities have been prepared in accordance with the "Standard Method of Measurement of Building Works", Seventh (7th) Edition (metric) Revised SMM7R (metric) dated July 1998 issued by the Royal Institution of Chartered Surveyors (R.I.C.S.) and the building Employers Confederation (B.E.C.) both of the United Kingdom. However, departures from this method of measurement (see General Notes on Method of Measurement) have been effected to reduce the number of measured Labour items and also to simplify certain other measured items. The Contractor must allow for this departures in his/her pricing so that his/her tender figure shall represent the total cost of all items of works involved in the project. No claim for extra payment will be entertained on the ground that method of the measurement adopted does not comply with the said Standard Method of Measurement.
A56: E | B56: Prohibition of Use
B57: The quantities given in the Bills of Quantities are not intended for ordering of materials/components. Quantities for use in ordering materials/components must be calculated by the Contractor by measurement on site or from contract drawings.
A59: F | B59: Site Location
B60: The Site is located at: Accra in the Greater Accra Region The Contractor is to visit and examine the site and satisfy himself as to the site conditions and facilities for obtaining special materials and shall obtain generally his own information on all matters affecting the execution of the Works.
A62: G | B62: Overtime
B63: The Contractor shall be held to have made all enquiries as to the source of his labour and to have made all provisions in his tender for every cost to him of providing and maintaining the labour force necessary to complete the contract including all extra and additional works in the contract Time, including all overtime and weekend working which he considers he shall require and supervisory cost associated therewith. No extra will be allowed on the contract Sum for this Clause.
A65: H | B65: Definition of Abbreviations
B66: Abbreviations have been used in the Bills of Quantities for the units of measurement and the Contractor should take due notice of the under-mentioned:
...

Sheet SUBSTRUCTURE
A1: ='PRELIMS & GEN. ITEMS'!A2 -> PROJECT: BLOCK N REDEVELOPMENT
A2: ='PRELIMS & GEN. ITEMS'!A3 -> LOCATION: KANESHIE
A3: ='PRELIMS & GEN. ITEMS'!A4 -> CLIENT: STATE HOUSING LIMITED
A4: ='PRELIMS & GEN. ITEMS'!A5 -> DATE:9/30/2026
A5: ITEM | B5: DESCRIPTION | C5: QTY | D5: UNIT | E5: RATE | F5: AMOUNT - GHC | G5: Measurement basis / calculation
B7: MAIN BUILDING
B9: SUBSTRUCTURE (ALL PROVISIONAL)
B11: BILL SUMMARY
A13: A | B13: D GROUNDWORK (D20 EXCAVATION AND FILLING) | F13: =F44 -> 3070047
A15: B | B15: E IN SITU CONCRETE | F15: =F84 -> 9896922.7
A17: C | B17: BLOCK WORK | F17: =F93 -> 43043
B19: =B9 -> SUBSTRUCTURE (ALL PROVISIONAL) | E19: GHC | F19: =SUM(F13:F18) -> 13010013
B20: To Bill General Summary
B23: BILL NR. 2 - SUBSTRUCTURE
B25: D GROUNDWORK (D20 EXCAVATION AND FILLING)
B27: Site Preparation
A28: A | B28: Clear site of all vegetation, grub up their roots and dispose-off (Block N plot and Parking-22 forecourt) | C28: =40.85*38.27+35.2*20.9 -> 2299.0095 | D28: m2 | E28: =RATES!$D$7 -> 15 | F28: =C28*E28 -> 34485.143 | G28: 40.85*38.27+35.2*20.9
A30: B | B30: Excavate oversite to remove vegetable soil average 150mm deep and deposit on site for re-use average 50m from excavation | C30: =(41.0+2*2.0)*(36.0+2*2.0) -> 1800 | D30: m2 | E30: =RATES!$D$8 -> 28 | F30: =C30*E30 -> 50400 | G30: (41.0+2*2.0)*(36.0+2*2.0)
A32: C | B32: Excavate raft foundation to reduce levels maximum depth 4.00m | C32: =(45.0*40.0)*4.0 -> 7200 | D32: m3 | E32: =RATES!$D$9 -> 85 | F32: =C32*E32 -> 612000 | G32: (45.0*40.0)*4.0
A34: D | B34: Fill to make up levels over raft average 1000mm thick with waterproof external membrane and high strength biaxial geogrid; compacted | C34: =41.0*36.0*1.0-(69.445*0.25*1.0)-(13.294*1.0) -> 1445.3447 | D34: m3 | E34: =RATES!$D$10 -> 220 | F34: =C34*E34 -> 317975.84 | G34: 41.0*36.0*1.0-(69.445*0.25*1.0)-(13.294*1.0)
A36: E | B36: Fill to make up levels below raft 1700mm thick with 300mm thick compacted crushed rock layers between geogrid layers until formation level is reached | C36: =(45.0*40.0)*1.7 -> 3060 | D36: m3 | E36: =RATES!$D$11 -> 480 | F36: =C36*E36 -> 1468800 | G36: (45.0*40.0)*1.7
A38: F | B38: Backfill and compact selected excavated material around foundations | C38: =((45.0*40.0)-(41.0*36.0))*(4.0-1.7) -> 745.2 | D38: m3 | E38: =RATES!$D$12 -> 60 | F38: =C38*E38 -> 44712 | G38: ((45.0*40.0)-(41.0*36.0))*(4.0-1.7)
A40: G | B40: Load up surplus excavated material and remove from site | C40: =(45.0*40.0)*4.0-((45.0*40.0)-(41.0*36.0))*(4.0-1.7) -> 6454.8 | D40: m3 | E40: =RATES!$D$13 -> 75 | F40: =C40*E40 -> 484110 | G40: (45.0*40.0)*4.0-((45.0*40.0)-(41.0*36.0))*(4.0-1.7)
A42: H | B42: Approved imported granular material hardcore filling to make up levels: depositing and compacting in layers 150mm maximum thickness | C42: =41.0*36.0*0.15 -> 221.4 | D42: m3 | E42: =RATES!$D$14 -> 260 | F42: =C42*E42 -> 57564 | G42: 41.0*36.0*0.15
B44: =B25 -> D GROUNDWORK (D20 EXCAVATION AND FILLING) | F44: =SUM(F27:F43) -> 3070047
B45: Carried to Bill Summary
B48: E IN SITU CONCRETE
B50: E10 Plain in-situ concrete (1:4:8 - 38mm aggregate) as described in:
A51: A | B51: Blinding 100mm thick under raft | C51: =41.0*36.0*0.10 -> 147.6 | D51: m3 | E51: =RATES!$D$15 -> 1650 | F51: =C51*E51 -> 243540 | G51: 41.0*36.0*0.10
A53: B | B53: 150mm thick bed | C53: =41.0*36.0*0.15 -> 221.4 | D53: m3 | E53: =RATES!$D$16 -> 2150 | F53: =C53*E53 -> 476010 | G53: 41.0*36.0*0.15
B55: Vibrated in-situ concrete C40 as described in:
A56: C | B56: Concrete walls (raft to ground floor) | C56: =(22.05+21.825+25.57)*0.25*1.3 -> 22.569625 | D56: m3 | E56: =RATES!$D$20 -> 2750 | F56: =C56*E56 -> 62066.469 | G56: (22.05+21.825+25.57)*0.25*1.3
A58: D | B58: Concrete in raft 1300mm thick | C58: =41.0*36.0*1.3 -> 1918.8 | D58: m3 | E58: =RATES!$D$19 -> 2550 | F58: =C58*E58 -> 4892940 | G58: 41.0*36.0*1.3
A60: E | B60: Concrete in columns (raft to ground floor) | C60: =5*0.75*0.5*1.3+1*0.75*0.5*1.3+2*0.75*0.5*1.3+1*0.75*0.5*1.3+3*1.2*0.3*1.3+6*1.2*0.3*1.3+1*1.2*0.3*1.3+15*1.2*0.3*1.3+1*(2.85*0.25+0.825*0.25)*1.3 -> 17.281875 | D60: m3 | E60: =RATES!$D$21 -> 2800 | F60: =C60*E60 -> 48389.25 | G60: 5*0.75*0.5*1.3+1*0.75*0.5*1.3+2*0.75*0.5*1.3+1*0.75*0.5*1.3+3*1.2*0.3*1.3+6*1.2*0.3*1.3+1*1.2*0.3*1.3+15*1.2*0.3*1.3+1*(2.85*0.25+0.825*0.25)*1.3
B62: E30 REINFORCEMENT - High tensile yield round bar reinforcement (standard):
A63: F | B63: 20mm diameter in raft | C63: =2.466 -> 2.466 | D63: t | E63: =RATES!$D$32 -> 19000 | F63: =C63*E63 -> 46854 | G63: 2.466
A65: G | B65: 25mm diameter in raft | C65: =184.672 -> 184.672 | D65: t | E65: =RATES!$D$33 -> 19000 | F65: =C65*E65 -> 3508768 | G65: 184.672
A67: H | B67: 10mm diameter links to columns & walls (raft to ground floor) | C67: =3.252+0.517+0.260 -> 4.029 | D67: t | E67: =RATES!$D$29 -> 20500 | F67: =C67*E67 -> 82594.5 | G67: 3.252+0.517+0.260
A69: J | B69: 12mm diameter to walls (raft to ground floor) | C69: =0.863+0.390 -> 1.253 | D69: t | E69: =RATES!$D$30 -> 20000 | F69: =C69*E69 -> 25060 | G69: 0.863+0.390
A71: K | B71: 25mm diameter to columns & walls (raft to ground floor) | C71: =6.531+9.840+4.935 -> 21.306 | D71: t | E71: =RATES!$D$33 -> 19000 | F71: =C71*E71 -> 404814 | G71: 6.531+9.840+4.935
...

Sheet GROUND FLR 
A1: ='PRELIMS & GEN. ITEMS'!A2 -> PROJECT: BLOCK N REDEVELOPMENT
A2: ='PRELIMS & GEN. ITEMS'!A3 -> LOCATION: KANESHIE
A3: ='PRELIMS & GEN. ITEMS'!A4 -> CLIENT: STATE HOUSING LIMITED
A4: ='PRELIMS & GEN. ITEMS'!A5 -> DATE:9/30/2026
A5: ITEM | B5: DESCRIPTION | C5: QTY | D5: UNIT | E5: RATE | F5: AMOUNT - GHC | G5: Measurement basis / calculation
B7: MAIN BUILDING
B9: GROUND FLOOR (INCL. M1 PARKING LEVEL 1B)
B11: BILL SUMMARY
A13: A | B13: ELEMENT NO. 1: IN SITU CONCRETE/LARGE PRECAST CONCRETE | F13: =F92 -> 2969324.3
A15: B | B15: ELEMENT NO. 2: MASONRY | F15: =F103 -> 209940.8
A17: C | B17: ELEMENT NO. 4: WINDOWS/DOORS | F17: =F166 -> 412711.9
A19: D | B19: ELEMENT NO. 5: FLOOR FINISHES | F19: =F189 -> 311872.36
A21: E | B21: ELEMENT NO. 6: WALL FINISHES | F21: =F206 -> 157798.45
A23: F | B23: ELEMENT NO. 7: PAINTING AND DECORATING | F23: =F229 -> 140269.25
B25: =B9 -> GROUND FLOOR (INCL. M1 PARKING LEVEL 1B) | E25: GHC | F25: =SUM(F13:F24) -> 4201917.1
B26: To Bill General Summary
B29: BILL NR. 3 - GROUND FLOOR
B31: ELEMENT NO. 1: IN SITU CONCRETE/LARGE PRECAST CONCRETE
B33: Vibrated in-situ concrete C40 as described in:
A34: A | B34: Suspended slab 250mm thick | C34: =689.1*0.25 -> 172.275 | D34: m3 | E34: =RATES!$D$22 -> 2650 | F34: =C34*E34 -> 456528.75 | G34: 689.1*0.25
A36: B | B36: Beams (downstands below slab) | C36: =67.8*0.3*0.35 -> 7.119 | D36: m3 | E36: =RATES!$D$23 -> 2700 | F36: =C36*E36 -> 19221.3 | G36: 67.8*0.3*0.35
A38: C | B38: Columns | C38: =5*0.75*0.5*3.6+1*0.75*0.5*3.6+2*0.75*0.5*3.6+1*0.75*0.5*1.95+1*0.75*0.5*2.45+3*1.2*0.3*3.6+6*1.2*0.3*3.6+1*1.2*0.3*3.6+15*1.2*0.3*1.95+15*1.2*0.3*2.45+1*(2.85*0.25+0.825*0.25)*3.6 -> 52.4775 | D38: m3 | E38: =RATES!$D$21 -> 2800 | F38: =C38*E38 -> 146937 | G38: 5*0.75*0.5*3.6+1*0.75*0.5*3.6+2*0.75*0.5*3.6+1*0.75*0.5*1.95+1*0.75*0.5*2.45+3*1.2*0.3*3.6+6*1.2*0.3*3.6+1*1.2*0.3*3.6+15*1.2*0.3*1.95+15*1.2*0.3*2.45+1*(2.85*0.25+0.825*0.25)*3.6
A40: D | B40: Concrete wall - shear walls to main & emergency stair cores, 250mm thick | C40: =22.05*3.6*0.25+25.57*2.25*0.25+25.57*2.45*0.25 -> 49.88975 | D40: m3 | E40: =RATES!$D$20 -> 2750 | F40: =C40*E40 -> 137196.81 | G40: 22.05*3.6*0.25+25.57*2.25*0.25+25.57*2.45*0.25
A42: E | B42: Concrete wall - lift walls, 250mm thick | C42: =21.825*3.6*0.25 -> 19.6425 | D42: m3 | E42: =RATES!$D$20 -> 2750 | F42: =C42*E42 -> 54016.875 | G42: 21.825*3.6*0.25
A44: F | B44: Stairs | C44: =(2.966*3.85/3.3+2.625)+(2.966*2.5/3.3+2.625)+(2.966*2.7/3.3+2.625) -> 16.00903 | D44: m3 | E44: =RATES!$D$24 -> 2850 | F44: =C44*E44 -> 45625.736 | G44: (2.966*3.85/3.3+2.625)+(2.966*2.5/3.3+2.625)+(2.966*2.7/3.3+2.625)
A46: G | B46: Lintels 150 x 225mm over door and window openings | C46: =(1*(1.8+0.3)+6*(0.9+0.3)+1*(0.9+0.3)+1*(3.2+0.3)+6*(0.75+0.3)+2*(0.7+0.3)+3*(1+0.3)+2*(0.9+0.3)+3*(1.8+0.3)+2*(1.8+0.3)+2*(2.4+0.3)+1*(5.05+0.3)+2*(4.2+0.3)+1*(3.6+0.3)+1*(1.8+0.3)+1*(1.8+0.3)+1*(3.5+0.3)+3*(3.6+0.3)+2*(2.4+0.3)+2*(2.1+0.3)+4*(0.9+0.3)+1*(0.75+0.3))*0.15*0.225 -> 3.324375 | D46: m3 | E46: =RATES!$D$25 -> 2600 | F46: =C46*E46 -> 8643.375 | G46: (1*(1.8+0.3)+6*(0.9+0.3)+1*(0.9+0.3)+1*(3.2+0.3)+6*(0.75+0.3)+2*(0.7+0.3)+3*(1+0.3)+2*(0.9+0.3)+3*(1.8+0.3)+2*(1.8+0.3)+2*(2.4+0.3)+1*(5.05+0.3)+2*(4.2+0.3)+1*(3.6+0.3)+1*(1.8+0.3)+1*(1.8+0.3)+1*(3.5+0.3)+3*(3.6+0.3)+2*(2.4+0.3)+2*(2.1+0.3)+4*(0.9...
B48: E20 FORMWORK - Formwork as described to:
A49: H | B49: Soffits of suspended slab | C49: =689.1 -> 689.1 | D49: m2 | E49: =RATES!$D$38 -> 170 | F49: =C49*E49 -> 117147 | G49: 689.1
A51: J | B51: Edges of suspended slab 250mm high | C51: =238.4 -> 238.4 | D51: m | E51: =RATES!$D$40 -> 65 | F51: =C51*E51 -> 15496 | G51: 238.4
A53: K | B53: Sides and soffits of beams | C53: =67.8*(2*0.35+0.3) -> 67.8 | D53: m2 | E53: =RATES!$D$39 -> 200 | F53: =C53*E53 -> 13560 | G53: 67.8*(2*0.35+0.3)
A55: L | B55: Columns | C55: =5*2*(0.75+0.5)*3.6+1*2*(0.75+0.5)*3.6+2*2*(0.75+0.5)*3.6+1*2*(0.75+0.5)*1.95+1*2*(0.75+0.5)*2.45+3*2*(1.2+0.3)*3.6+6*2*(1.2+0.3)*3.6+1*2*(1.2+0.3)*3.6+15*2*(1.2+0.3)*1.95+15*2*(1.2+0.3)*2.45+1*2*(2.85+1.075)*3.6 -> 417.26 | D55: m2 | E55: =RATES!$D$37 -> 190 | F55: =C55*E55 -> 79279.4 | G55: 5*2*(0.75+0.5)*3.6+1*2*(0.75+0.5)*3.6+2*2*(0.75+0.5)*3.6+1*2*(0.75+0.5)*1.95+1*2*(0.75+0.5)*2.45+3*2*(1.2+0.3)*3.6+6*2*(1.2+0.3)*3.6+1*2*(1.2+0.3)*3.6+15*2*(1.2+0.3)*1.95+15*2*(1.2+0.3)*2.45+1*2*(2.85+1.075)*3.6
A57: M | B57: Concrete wall (both faces) | C57: =2*22.05*3.6+2*21.825*3.6+2*25.57*2.25+2*25.57*2.45 -> 556.258 | D57: m2 | E57: =RATES!$D$36 -> 185 | F57: =C57*E57 -> 102907.73 | G57: 2*22.05*3.6+2*21.825*3.6+2*25.57*2.25+2*25.57*2.45
A59: N | B59: Soffits of stair flights, landings and risers | C59: =(2*3.424*1.8+15.0+22*0.15*1.8)+(2*3.424*1.8+15.0+22*0.15*1.8)+(2*3.424*1.8+15.0+22*0.15*1.8) -> 99.7992 | D59: m2 | E59: =RATES!$D$42 -> 230 | F59: =C59*E59 -> 22953.816 | G59: (2*3.424*1.8+15.0+22*0.15*1.8)+(2*3.424*1.8+15.0+22*0.15*1.8)+(2*3.424*1.8+15.0+22*0.15*1.8)
A61: P | B61: Side and soffits of lintel / coping | C61: =(1*(1.8+0.3)+6*(0.9+0.3)+1*(0.9+0.3)+1*(3.2+0.3)+6*(0.75+0.3)+2*(0.7+0.3)+3*(1+0.3)+2*(0.9+0.3)+3*(1.8+0.3)+2*(1.8+0.3)+2*(2.4+0.3)+1*(5.05+0.3)+2*(4.2+0.3)+1*(3.6+0.3)+1*(1.8+0.3)+1*(1.8+0.3)+1*(3.5+0.3)+3*(3.6+0.3)+2*(2.4+0.3)+2*(2.1+0.3)+4*(0.9+0.3)+1*(0.75+0.3))*(2*0.225+0.15) -> 59.1 | D61: m2 | E61: =RATES!$D$43 -> 180 | F61: =C61*E61 -> 10638 | G61: (1*(1.8+0.3)+6*(0.9+0.3)+1*(0.9+0.3)+1*(3.2+0.3)+6*(0.75+0.3)+2*(0.7+0.3)+3*(1+0.3)+2*(0.9+0.3)+3*(1.8+0.3)+2*(1.8+0.3)+2*(2.4+0.3)+1*(5.05+0.3)+2*(4.2+0.3)+1*(3.6+0.3)+1*(1.8+0.3)+1*(1.8+0.3)+1*(3.5+0.3)+3*(3.6+0.3)+2*(2.4+0.3)+2*(2.1+0.3)+4*(0.9...
B63: E30 REINFORCEMENT - High tensile yield round bar reinforcement (standard) to BS 4449:
A64: Q | B64: 10mm diameter in columns | C64: =4.372+1.656 -> 6.028 | D64: t | E64: =RATES!$D$29 -> 20500 | F64: =C64*E64 -> 123574 | G64: 4.372+1.656
A66: R | B66: 20mm diameter in columns | C66: =0.599 -> 0.599 | D66: t | E66: =RATES!$D$32 -> 19000 | F66: =C66*E66 -> 11381 | G66: 0.599
A68: S | B68: 25mm diameter in columns | C68: =10.083+4.303 -> 14.386 | D68: t | E68: =RATES!$D$33 -> 19000 | F68: =C68*E68 -> 273334 | G68: 10.083+4.303
A70: T | B70: 10mm diameter in beams (links) | C70: =1.126 -> 1.126 | D70: t | E70: =RATES!$D$29 -> 20500 | F70: =C70*E70 -> 23083 | G70: 1.126
A72: U | B72: 16mm diameter in beams | C72: =0.576 -> 0.576 | D72: t | E72: =RATES!$D$31 -> 19500 | F72: =C72*E72 -> 11232 | G72: 0.576
...

Sheet 1ST FLR 
A1: ='PRELIMS & GEN. ITEMS'!A2 -> PROJECT: BLOCK N REDEVELOPMENT
A2: ='PRELIMS & GEN. ITEMS'!A3 -> LOCATION: KANESHIE
A3: ='PRELIMS & GEN. ITEMS'!A4 -> CLIENT: STATE HOUSING LIMITED
A4: ='PRELIMS & GEN. ITEMS'!A5 -> DATE:9/30/2026
A5: ITEM | B5: DESCRIPTION | C5: QTY | D5: UNIT | E5: RATE | F5: AMOUNT - GHC | G5: Measurement basis / calculation
B7: MAIN BUILDING
B9: FIRST FLOOR - LEVEL 2A PARKING (INCL. M2 LEVEL 2B)
B11: BILL SUMMARY
A13: A | B13: ELEMENT NO. 1: IN SITU CONCRETE/LARGE PRECAST CONCRETE | F13: =F92 -> 3630370.6
A15: B | B15: ELEMENT NO. 2: MASONRY | F15: =F103 -> 76177.553
A17: C | B17: ELEMENT NO. 4: WINDOWS/DOORS | F17: =F112 -> 21600
A19: D | B19: ELEMENT NO. 5: FLOOR FINISHES | F19: =F131 -> 227701.44
A21: E | B21: ELEMENT NO. 6: WALL FINISHES | F21: =F142 -> 63462.63
A23: F | B23: ELEMENT NO. 7: PAINTING AND DECORATING | F23: =F157 -> 53869.883
B25: =B9 -> FIRST FLOOR - LEVEL 2A PARKING (INCL. M2 LEVEL 2B) | E25: GHC | F25: =SUM(F13:F24) -> 4073182.1
B26: To Bill General Summary
B29: BILL NR. 4 - FIRST FLOOR
B31: ELEMENT NO. 1: IN SITU CONCRETE/LARGE PRECAST CONCRETE
B33: Vibrated in-situ concrete C40 as described in:
A34: A | B34: Suspended slab 250mm thick | C34: =737.6*0.25+650.6*0.25 -> 347.05 | D34: m3 | E34: =RATES!$D$22 -> 2650 | F34: =C34*E34 -> 919682.5 | G34: 737.6*0.25+650.6*0.25
A36: B | B36: Beams (downstands below slab) | C36: =81.1*0.3*0.35+43.5*0.2*0.35+63.6*0.3*0.35 -> 18.2385 | D36: m3 | E36: =RATES!$D$23 -> 2700 | F36: =C36*E36 -> 49243.95 | G36: 81.1*0.3*0.35+43.5*0.2*0.35+63.6*0.3*0.35
A38: C | B38: Columns | C38: =5*0.75*0.5*2.45+1*0.75*0.5*2.45+2*0.75*0.5*2.45+1*0.75*0.5*2.45+3*1.2*0.3*2.45+6*1.2*0.3*2.45+1*1.2*0.3*2.45+15*1.2*0.3*2.45+1*(2.85*0.25+0.825*0.25)*2.45 -> 32.569688 | D38: m3 | E38: =RATES!$D$21 -> 2800 | F38: =C38*E38 -> 91195.125 | G38: 5*0.75*0.5*2.45+1*0.75*0.5*2.45+2*0.75*0.5*2.45+1*0.75*0.5*2.45+3*1.2*0.3*2.45+6*1.2*0.3*2.45+1*1.2*0.3*2.45+15*1.2*0.3*2.45+1*(2.85*0.25+0.825*0.25)*2.45
A40: D | B40: Concrete wall - shear walls to main & emergency stair cores, 250mm thick | C40: =22.05*2.45*0.25+25.57*2.45*0.25 -> 29.16725 | D40: m3 | E40: =RATES!$D$20 -> 2750 | F40: =C40*E40 -> 80209.938 | G40: 22.05*2.45*0.25+25.57*2.45*0.25
A42: E | B42: Concrete wall - lift walls, 250mm thick | C42: =21.825*2.45*0.25 -> 13.367813 | D42: m3 | E42: =RATES!$D$20 -> 2750 | F42: =C42*E42 -> 36761.484 | G42: 21.825*2.45*0.25
A44: F | B44: Stairs | C44: =(2.966*2.7/3.3+2.625)+(2.966*2.7/3.3+2.625) -> 10.103455 | D44: m3 | E44: =RATES!$D$24 -> 2850 | F44: =C44*E44 -> 28794.845 | G44: (2.966*2.7/3.3+2.625)+(2.966*2.7/3.3+2.625)
A46: G | B46: Lintels 150 x 225mm over door and window openings | C46: =(3*(1+0.3))*0.15*0.225 -> 0.131625 | D46: m3 | E46: =RATES!$D$25 -> 2600 | F46: =C46*E46 -> 342.225 | G46: (3*(1+0.3))*0.15*0.225
B48: E20 FORMWORK - Formwork as described to:
A49: H | B49: Soffits of suspended slab | C49: =737.6+650.6 -> 1388.2 | D49: m2 | E49: =RATES!$D$38 -> 170 | F49: =C49*E49 -> 235994 | G49: 737.6+650.6
A51: J | B51: Edges of suspended slab 250mm high | C51: =185.9+224.9 -> 410.8 | D51: m | E51: =RATES!$D$40 -> 65 | F51: =C51*E51 -> 26702 | G51: 185.9+224.9
A53: K | B53: Sides and soffits of beams | C53: =81.1*(2*0.35+0.3)+43.5*(2*0.35+0.2)+63.6*(2*0.35+0.3) -> 183.85 | D53: m2 | E53: =RATES!$D$39 -> 200 | F53: =C53*E53 -> 36770 | G53: 81.1*(2*0.35+0.3)+43.5*(2*0.35+0.2)+63.6*(2*0.35+0.3)
A55: L | B55: Columns | C55: =5*2*(0.75+0.5)*2.45+1*2*(0.75+0.5)*2.45+2*2*(0.75+0.5)*2.45+1*2*(0.75+0.5)*2.45+3*2*(1.2+0.3)*2.45+6*2*(1.2+0.3)*2.45+1*2*(1.2+0.3)*2.45+15*2*(1.2+0.3)*2.45+1*2*(2.85+1.075)*2.45 -> 258.1075 | D55: m2 | E55: =RATES!$D$37 -> 190 | F55: =C55*E55 -> 49040.425 | G55: 5*2*(0.75+0.5)*2.45+1*2*(0.75+0.5)*2.45+2*2*(0.75+0.5)*2.45+1*2*(0.75+0.5)*2.45+3*2*(1.2+0.3)*2.45+6*2*(1.2+0.3)*2.45+1*2*(1.2+0.3)*2.45+15*2*(1.2+0.3)*2.45+1*2*(2.85+1.075)*2.45
A57: M | B57: Concrete wall (both faces) | C57: =2*22.05*2.45+2*21.825*2.45+2*25.57*2.45 -> 340.2805 | D57: m2 | E57: =RATES!$D$36 -> 185 | F57: =C57*E57 -> 62951.893 | G57: 2*22.05*2.45+2*21.825*2.45+2*25.57*2.45
A59: N | B59: Soffits of stair flights, landings and risers | C59: =(2*3.424*1.8+15.0+22*0.15*1.8)+(2*3.424*1.8+15.0+22*0.15*1.8) -> 66.5328 | D59: m2 | E59: =RATES!$D$42 -> 230 | F59: =C59*E59 -> 15302.544 | G59: (2*3.424*1.8+15.0+22*0.15*1.8)+(2*3.424*1.8+15.0+22*0.15*1.8)
A61: P | B61: Side and soffits of lintel / coping | C61: =(3*(1+0.3))*(2*0.225+0.15) -> 2.34 | D61: m2 | E61: =RATES!$D$43 -> 180 | F61: =C61*E61 -> 421.2 | G61: (3*(1+0.3))*(2*0.225+0.15)
B63: E30 REINFORCEMENT - High tensile yield round bar reinforcement (standard) to BS 4449:
A64: Q | B64: 10mm diameter in columns | C64: =2.717+1.656 -> 4.373 | D64: t | E64: =RATES!$D$29 -> 20500 | F64: =C64*E64 -> 89646.5 | G64: 2.717+1.656
A66: R | B66: 20mm diameter in columns | C66: =0.462+0.154 -> 0.616 | D66: t | E66: =RATES!$D$32 -> 19000 | F66: =C66*E66 -> 11704 | G66: 0.462+0.154
A68: S | B68: 25mm diameter in columns | C68: =4.634+4.062 -> 8.696 | D68: t | E68: =RATES!$D$33 -> 19000 | F68: =C68*E68 -> 165224 | G68: 4.634+4.062
A70: T | B70: 10mm diameter in beams (links) | C70: =0.977+0.644 -> 1.621 | D70: t | E70: =RATES!$D$29 -> 20500 | F70: =C70*E70 -> 33230.5 | G70: 0.977+0.644
A72: U | B72: 16mm diameter in beams | C72: =0.763+0.460 -> 1.223 | D72: t | E72: =RATES!$D$31 -> 19500 | F72: =C72*E72 -> 23848.5 | G72: 0.763+0.460
...

Sheet 2ND FLR
A1: ='PRELIMS & GEN. ITEMS'!A2 -> PROJECT: BLOCK N REDEVELOPMENT
A2: ='PRELIMS & GEN. ITEMS'!A3 -> LOCATION: KANESHIE
A3: ='PRELIMS & GEN. ITEMS'!A4 -> CLIENT: STATE HOUSING LIMITED
A4: ='PRELIMS & GEN. ITEMS'!A5 -> DATE:9/30/2026
A5: ITEM | B5: DESCRIPTION | C5: QTY | D5: UNIT | E5: RATE | F5: AMOUNT - GHC | G5: Measurement basis / calculation
B7: MAIN BUILDING
B9: SECOND FLOOR - LEVEL 3A PARKING (INCL. MEZZANINE LEVEL 3B)
B11: BILL SUMMARY
A13: A | B13: ELEMENT NO. 1: IN SITU CONCRETE/LARGE PRECAST CONCRETE | F13: =F92 -> 4005497.4
A15: B | B15: ELEMENT NO. 2: MASONRY | F15: =F103 -> 175769.91
A17: C | B17: ELEMENT NO. 4: WINDOWS/DOORS | F17: =F112 -> 43200
A19: D | B19: ELEMENT NO. 5: FLOOR FINISHES | F19: =F131 -> 370064.94
A21: E | B21: ELEMENT NO. 6: WALL FINISHES | F21: =F142 -> 158847.63
A23: F | B23: ELEMENT NO. 7: PAINTING AND DECORATING | F23: =F157 -> 117441.9
B25: =B9 -> SECOND FLOOR - LEVEL 3A PARKING (INCL. MEZZANINE LEVEL 3B) | E25: GHC | F25: =SUM(F13:F24) -> 4870821.8
B26: To Bill General Summary
B29: BILL NR. 5 - SECOND FLOOR
B31: ELEMENT NO. 1: IN SITU CONCRETE/LARGE PRECAST CONCRETE
B33: Vibrated in-situ concrete C40 as described in:
A34: A | B34: Suspended slab 250mm thick | C34: =737.5*0.25+554.9*0.25 -> 323.1 | D34: m3 | E34: =RATES!$D$22 -> 2650 | F34: =C34*E34 -> 856215 | G34: 737.5*0.25+554.9*0.25
A36: B | B36: Beams (downstands below slab) | C36: =79.9*0.3*0.35+43*0.2*0.35+64.3*0.3*0.35 -> 18.151 | D36: m3 | E36: =RATES!$D$23 -> 2700 | F36: =C36*E36 -> 49007.7 | G36: 79.9*0.3*0.35+43*0.2*0.35+64.3*0.3*0.35
A38: C | B38: Columns | C38: =5*0.75*0.5*3.8+1*0.75*0.5*3.8+2*0.75*0.5*3.8+1*0.75*0.5*2.75+3*1.2*0.3*3.8+6*1.2*0.3*3.8+1*1.2*0.3*3.8+15*1.2*0.3*2.75+1*(2.85*0.25+0.825*0.25)*3.8 -> 44.4525 | D38: m3 | E38: =RATES!$D$21 -> 2800 | F38: =C38*E38 -> 124467 | G38: 5*0.75*0.5*3.8+1*0.75*0.5*3.8+2*0.75*0.5*3.8+1*0.75*0.5*2.75+3*1.2*0.3*3.8+6*1.2*0.3*3.8+1*1.2*0.3*3.8+15*1.2*0.3*2.75+1*(2.85*0.25+0.825*0.25)*3.8
A40: D | B40: Concrete wall - shear walls to main & emergency stair cores, 250mm thick | C40: =22.05*3.8*0.25+25.57*2.75*0.25 -> 38.526875 | D40: m3 | E40: =RATES!$D$20 -> 2750 | F40: =C40*E40 -> 105948.91 | G40: 22.05*3.8*0.25+25.57*2.75*0.25
A42: E | B42: Concrete wall - lift walls, 250mm thick | C42: =21.825*3.8*0.25 -> 20.73375 | D42: m3 | E42: =RATES!$D$20 -> 2750 | F42: =C42*E42 -> 57017.812 | G42: 21.825*3.8*0.25
A44: F | B44: Stairs | C44: =(2.966*4.05/3.3+2.625)+(2.966*3/3.3+2.625) -> 11.586455 | D44: m3 | E44: =RATES!$D$24 -> 2850 | F44: =C44*E44 -> 33021.395 | G44: (2.966*4.05/3.3+2.625)+(2.966*3/3.3+2.625)
A46: G | B46: Lintels 150 x 225mm over door and window openings | C46: =(3*(1+0.3))*0.15*0.225+(3*(1+0.3))*0.15*0.225 -> 0.26325 | D46: m3 | E46: =RATES!$D$25 -> 2600 | F46: =C46*E46 -> 684.45 | G46: (3*(1+0.3))*0.15*0.225+(3*(1+0.3))*0.15*0.225
B48: E20 FORMWORK - Formwork as described to:
A49: H | B49: Soffits of suspended slab | C49: =737.5+554.9 -> 1292.4 | D49: m2 | E49: =RATES!$D$38 -> 170 | F49: =C49*E49 -> 219708 | G49: 737.5+554.9
A51: J | B51: Edges of suspended slab 250mm high | C51: =186.5+216.4 -> 402.9 | D51: m | E51: =RATES!$D$40 -> 65 | F51: =C51*E51 -> 26188.5 | G51: 186.5+216.4
A53: K | B53: Sides and soffits of beams | C53: =79.9*(2*0.35+0.3)+43*(2*0.35+0.2)+64.3*(2*0.35+0.3) -> 182.9 | D53: m2 | E53: =RATES!$D$39 -> 200 | F53: =C53*E53 -> 36580 | G53: 79.9*(2*0.35+0.3)+43*(2*0.35+0.2)+64.3*(2*0.35+0.3)
A55: L | B55: Columns | C55: =5*2*(0.75+0.5)*3.8+1*2*(0.75+0.5)*3.8+2*2*(0.75+0.5)*3.8+1*2*(0.75+0.5)*2.75+3*2*(1.2+0.3)*3.8+6*2*(1.2+0.3)*3.8+1*2*(1.2+0.3)*3.8+15*2*(1.2+0.3)*2.75+1*2*(2.85+1.075)*3.8 -> 350.455 | D55: m2 | E55: =RATES!$D$37 -> 190 | F55: =C55*E55 -> 66586.45 | G55: 5*2*(0.75+0.5)*3.8+1*2*(0.75+0.5)*3.8+2*2*(0.75+0.5)*3.8+1*2*(0.75+0.5)*2.75+3*2*(1.2+0.3)*3.8+6*2*(1.2+0.3)*3.8+1*2*(1.2+0.3)*3.8+15*2*(1.2+0.3)*2.75+1*2*(2.85+1.075)*3.8
A57: M | B57: Concrete wall (both faces) | C57: =2*22.05*3.8+2*21.825*3.8+2*25.57*2.75 -> 474.085 | D57: m2 | E57: =RATES!$D$36 -> 185 | F57: =C57*E57 -> 87705.725 | G57: 2*22.05*3.8+2*21.825*3.8+2*25.57*2.75
A59: N | B59: Soffits of stair flights, landings and risers | C59: =(2*3.424*1.8+15.0+22*0.15*1.8)+(2*3.424*1.8+15.0+22*0.15*1.8) -> 66.5328 | D59: m2 | E59: =RATES!$D$42 -> 230 | F59: =C59*E59 -> 15302.544 | G59: (2*3.424*1.8+15.0+22*0.15*1.8)+(2*3.424*1.8+15.0+22*0.15*1.8)
A61: P | B61: Side and soffits of lintel / coping | C61: =(3*(1+0.3))*(2*0.225+0.15)+(3*(1+0.3))*(2*0.225+0.15) -> 4.68 | D61: m2 | E61: =RATES!$D$43 -> 180 | F61: =C61*E61 -> 842.4 | G61: (3*(1+0.3))*(2*0.225+0.15)+(3*(1+0.3))*(2*0.225+0.15)
B63: E30 REINFORCEMENT - High tensile yield round bar reinforcement (standard) to BS 4449:
A64: Q | B64: 10mm diameter in columns | C64: =3.239+1.656 -> 4.895 | D64: t | E64: =RATES!$D$29 -> 20500 | F64: =C64*E64 -> 100347.5 | G64: 3.239+1.656
A66: R | B66: 20mm diameter in columns | C66: =0.622+3.166 -> 3.788 | D66: t | E66: =RATES!$D$32 -> 19000 | F66: =C66*E66 -> 71972 | G66: 0.622+3.166
A68: S | B68: 25mm diameter in columns | C68: =6.238 -> 6.238 | D68: t | E68: =RATES!$D$33 -> 19000 | F68: =C68*E68 -> 118522 | G68: 6.238
A70: T | B70: 10mm diameter in beams (links) | C70: =0.902+0.579 -> 1.481 | D70: t | E70: =RATES!$D$29 -> 20500 | F70: =C70*E70 -> 30360.5 | G70: 0.902+0.579
A72: U | B72: 16mm diameter in beams | C72: =0.740+0.406 -> 1.146 | D72: t | E72: =RATES!$D$31 -> 19500 | F72: =C72*E72 -> 22347 | G72: 0.740+0.406
...

Sheet 3RD FLR
A1: ='PRELIMS & GEN. ITEMS'!A2 -> PROJECT: BLOCK N REDEVELOPMENT
A2: ='PRELIMS & GEN. ITEMS'!A3 -> LOCATION: KANESHIE
A3: ='PRELIMS & GEN. ITEMS'!A4 -> CLIENT: STATE HOUSING LIMITED
A4: ='PRELIMS & GEN. ITEMS'!A5 -> DATE:9/30/2026
A5: ITEM | B5: DESCRIPTION | C5: QTY | D5: UNIT | E5: RATE | F5: AMOUNT - GHC | G5: Measurement basis / calculation
B7: MAIN BUILDING
B9: THIRD FLOOR
B11: BILL SUMMARY
A13: A | B13: ELEMENT NO. 1: IN SITU CONCRETE/LARGE PRECAST CONCRETE | F13: =F90 -> 3579714.6
A15: B | B15: ELEMENT NO. 2: MASONRY | F15: =F101 -> 420081.85
A17: C | B17: ELEMENT NO. 4: WINDOWS/DOORS | F17: =F190 -> 704364.25
A19: D | B19: ELEMENT NO. 5: FLOOR FINISHES | F19: =F211 -> 385700.14
A21: E | B21: ELEMENT NO. 6: WALL FINISHES | F21: =F228 -> 315809.63
A23: F | B23: ELEMENT NO. 7: PAINTING AND DECORATING | F23: =F249 -> 193492.32
B25: =B9 -> THIRD FLOOR | E25: GHC | F25: =SUM(F13:F24) -> 5599162.8
B26: To Bill General Summary
B29: BILL NR. 6 - THIRD FLOOR
B31: ELEMENT NO. 1: IN SITU CONCRETE/LARGE PRECAST CONCRETE
B33: Vibrated in-situ concrete C40 as described in:
A34: A | B34: Suspended slab 250mm thick | C34: =1273.9*0.25 -> 318.475 | D34: m3 | E34: =RATES!$D$22 -> 2650 | F34: =C34*E34 -> 843958.75 | G34: 1273.9*0.25
A36: B | B36: Beams (downstands below slab) | C36: =97.4*0.3*0.35+33.1*0.2*0.35 -> 12.544 | D36: m3 | E36: =RATES!$D$23 -> 2700 | F36: =C36*E36 -> 33868.8 | G36: 97.4*0.3*0.35+33.1*0.2*0.35
A38: C | B38: Columns | C38: =5*0.75*0.5*3.05+1*0.75*0.5*3.05+2*0.75*0.5*3.05+1*0.75*0.5*3.05+3*1.2*0.3*3.05+6*1.2*0.3*3.05+1*1.2*0.3*3.05+15*1.2*0.3*3.05+1*(2.85*0.25+0.825*0.25)*3.05 -> 40.545937 | D38: m3 | E38: =RATES!$D$21 -> 2800 | F38: =C38*E38 -> 113528.62 | G38: 5*0.75*0.5*3.05+1*0.75*0.5*3.05+2*0.75*0.5*3.05+1*0.75*0.5*3.05+3*1.2*0.3*3.05+6*1.2*0.3*3.05+1*1.2*0.3*3.05+15*1.2*0.3*3.05+1*(2.85*0.25+0.825*0.25)*3.05
A40: D | B40: Concrete wall - shear walls to main & emergency stair cores, 250mm thick | C40: =22.05*3.05*0.25+25.57*3.05*0.25 -> 36.31025 | D40: m3 | E40: =RATES!$D$20 -> 2750 | F40: =C40*E40 -> 99853.187 | G40: 22.05*3.05*0.25+25.57*3.05*0.25
A42: E | B42: Concrete wall - lift walls, 250mm thick | C42: =21.825*3.05*0.25 -> 16.641562 | D42: m3 | E42: =RATES!$D$20 -> 2750 | F42: =C42*E42 -> 45764.297 | G42: 21.825*3.05*0.25
A44: F | B44: Stairs | C44: =(2.966*3.3/3.3+2.625)+(2.966*3.3/3.3+2.625) -> 11.182 | D44: m3 | E44: =RATES!$D$24 -> 2850 | F44: =C44*E44 -> 31868.7 | G44: (2.966*3.3/3.3+2.625)+(2.966*3.3/3.3+2.625)
A46: G | B46: Lintels 150 x 225mm over door and window openings | C46: =(10*(1+0.3)+19*(0.9+0.3)+21*(0.75+0.3)+2*(0.7+0.3)+3*(1.2+0.3)+3*(1+0.3)+3*(1+0.3)+2*(0.9+0.3)+1*(1.5+0.3)+3*(0.9+0.3)+5*(0.75+0.3)+1*(0.45+0.3)+3*(0.6+0.3)+1*(3+0.3)+4*(1.6+0.3)+3*(1.3+0.3)+5*(1.8+0.3)+1*(1.2+0.3)+7*(1.8+0.3)+13*(0.9+0.3)+2*(1.8+0.3)+4*(1.2+0.3)+10*(1.2+0.3)+1*(1.2+0.3)+8*(1.5+0.3)+4*(1.5+0.3)+1*(2.4+0.3)+1*(3+0.3)+4*(1.8+0.3)+1*(0.75+0.3)+1*(1.45+0.3)+12*(0.9+0.3)+5*(0.75+0.3)+1*(0.6+0.3)+1*(1.2+0.3))*0.15*0.225 -> 7.90425 | D46: m3 | E46: =RATES!$D$25 -> 2600 | F46: =C46*E46 -> 20551.05 | G46: (10*(1+0.3)+19*(0.9+0.3)+21*(0.75+0.3)+2*(0.7+0.3)+3*(1.2+0.3)+3*(1+0.3)+3*(1+0.3)+2*(0.9+0.3)+1*(1.5+0.3)+3*(0.9+0.3)+5*(0.75+0.3)+1*(0.45+0.3)+3*(0.6+0.3)+1*(3+0.3)+4*(1.6+0.3)+3*(1.3+0.3)+5*(1.8+0.3)+1*(1.2+0.3)+7*(1.8+0.3)+13*(0.9+0.3)+2*(1.8+...
B48: E20 FORMWORK - Formwork as described to:
A49: H | B49: Soffits of suspended slab | C49: =1273.9 -> 1273.9 | D49: m2 | E49: =RATES!$D$38 -> 170 | F49: =C49*E49 -> 216563 | G49: 1273.9
A51: J | B51: Edges of suspended slab 250mm high | C51: =232.4 -> 232.4 | D51: m | E51: =RATES!$D$40 -> 65 | F51: =C51*E51 -> 15106 | G51: 232.4
A53: K | B53: Sides and soffits of beams | C53: =97.4*(2*0.35+0.3)+33.1*(2*0.35+0.2) -> 127.19 | D53: m2 | E53: =RATES!$D$39 -> 200 | F53: =C53*E53 -> 25438 | G53: 97.4*(2*0.35+0.3)+33.1*(2*0.35+0.2)
A55: L | B55: Columns | C55: =5*2*(0.75+0.5)*3.05+1*2*(0.75+0.5)*3.05+2*2*(0.75+0.5)*3.05+1*2*(0.75+0.5)*3.05+3*2*(1.2+0.3)*3.05+6*2*(1.2+0.3)*3.05+1*2*(1.2+0.3)*3.05+15*2*(1.2+0.3)*3.05+1*2*(2.85+1.075)*3.05 -> 321.3175 | D55: m2 | E55: =RATES!$D$37 -> 190 | F55: =C55*E55 -> 61050.325 | G55: 5*2*(0.75+0.5)*3.05+1*2*(0.75+0.5)*3.05+2*2*(0.75+0.5)*3.05+1*2*(0.75+0.5)*3.05+3*2*(1.2+0.3)*3.05+6*2*(1.2+0.3)*3.05+1*2*(1.2+0.3)*3.05+15*2*(1.2+0.3)*3.05+1*2*(2.85+1.075)*3.05
A57: M | B57: Concrete wall (both faces) | C57: =2*22.05*3.05+2*21.825*3.05+2*25.57*3.05 -> 423.6145 | D57: m2 | E57: =RATES!$D$36 -> 185 | F57: =C57*E57 -> 78368.683 | G57: 2*22.05*3.05+2*21.825*3.05+2*25.57*3.05
A59: N | B59: Soffits of stair flights, landings and risers | C59: =(2*3.424*1.8+15.0+22*0.15*1.8)+(2*3.424*1.8+15.0+22*0.15*1.8) -> 66.5328 | D59: m2 | E59: =RATES!$D$42 -> 230 | F59: =C59*E59 -> 15302.544 | G59: (2*3.424*1.8+15.0+22*0.15*1.8)+(2*3.424*1.8+15.0+22*0.15*1.8)
A61: P | B61: Side and soffits of lintel / coping | C61: =(10*(1+0.3)+19*(0.9+0.3)+21*(0.75+0.3)+2*(0.7+0.3)+3*(1.2+0.3)+3*(1+0.3)+3*(1+0.3)+2*(0.9+0.3)+1*(1.5+0.3)+3*(0.9+0.3)+5*(0.75+0.3)+1*(0.45+0.3)+3*(0.6+0.3)+1*(3+0.3)+4*(1.6+0.3)+3*(1.3+0.3)+5*(1.8+0.3)+1*(1.2+0.3)+7*(1.8+0.3)+13*(0.9+0.3)+2*(1.8+0.3)+4*(1.2+0.3)+10*(1.2+0.3)+1*(1.2+0.3)+8*(1.5+0.3)+4*(1.5+0.3)+1*(2.4+0.3)+1*(3+0.3)+4*(1.8+0.3)+1*(0.75+0.3)+1*(1.45+0.3)+12*(0.9+0.3)+5*(0.75+0.3)+1*(0.6+0.3)+1*(1.2+0.3))*(2*0.225+0.15) -> 140.52 | D61: m2 | E61: =RATES!$D$43 -> 180 | F61: =C61*E61 -> 25293.6 | G61: (10*(1+0.3)+19*(0.9+0.3)+21*(0.75+0.3)+2*(0.7+0.3)+3*(1.2+0.3)+3*(1+0.3)+3*(1+0.3)+2*(0.9+0.3)+1*(1.5+0.3)+3*(0.9+0.3)+5*(0.75+0.3)+1*(0.45+0.3)+3*(0.6+0.3)+1*(3+0.3)+4*(1.6+0.3)+3*(1.3+0.3)+5*(1.8+0.3)+1*(1.2+0.3)+7*(1.8+0.3)+13*(0.9+0.3)+2*(1.8+...
B63: E30 REINFORCEMENT - High tensile yield round bar reinforcement (standard) to BS 4449:
A64: Q | B64: 10mm diameter in columns | C64: =4.551 -> 4.551 | D64: t | E64: =RATES!$D$29 -> 20500 | F64: =C64*E64 -> 93295.5 | G64: 4.551
A66: R | B66: 20mm diameter in columns | C66: =7.133 -> 7.133 | D66: t | E66: =RATES!$D$32 -> 19000 | F66: =C66*E66 -> 135527 | G66: 7.133
A68: S | B68: 10mm diameter in beams (links) | C68: =1.164 -> 1.164 | D68: t | E68: =RATES!$D$29 -> 20500 | F68: =C68*E68 -> 23862 | G68: 1.164
A70: T | B70: 16mm diameter in beams | C70: =1.003 -> 1.003 | D70: t | E70: =RATES!$D$31 -> 19500 | F70: =C70*E70 -> 19558.5 | G70: 1.003
A72: U | B72: 20mm diameter in beams | C72: =2.162 -> 2.162 | D72: t | E72: =RATES!$D$32 -> 19000 | F72: =C72*E72 -> 41078 | G72: 2.162
...

Sheet 4TH FLR 
A1: ='PRELIMS & GEN. ITEMS'!A2 -> PROJECT: BLOCK N REDEVELOPMENT
A2: ='PRELIMS & GEN. ITEMS'!A3 -> LOCATION: KANESHIE
A3: ='PRELIMS & GEN. ITEMS'!A4 -> CLIENT: STATE HOUSING LIMITED
A4: ='PRELIMS & GEN. ITEMS'!A5 -> DATE:9/30/2026
A5: ITEM | B5: DESCRIPTION | C5: QTY | D5: UNIT | E5: RATE | F5: AMOUNT - GHC | G5: Measurement basis / calculation
B7: MAIN BUILDING
B9: FOURTH FLOOR
B11: BILL SUMMARY
A13: A | B13: ELEMENT NO. 1: IN SITU CONCRETE/LARGE PRECAST CONCRETE | F13: =F92 -> 3356708.8
A15: B | B15: ELEMENT NO. 2: MASONRY | F15: =F103 -> 385904.19
A17: C | B17: ELEMENT NO. 4: WINDOWS/DOORS | F17: =F192 -> 624892.6
A19: D | B19: ELEMENT NO. 5: FLOOR FINISHES | F19: =F213 -> 344765.54
A21: E | B21: ELEMENT NO. 6: WALL FINISHES | F21: =F230 -> 304843.68
A23: F | B23: ELEMENT NO. 7: PAINTING AND DECORATING | F23: =F251 -> 180310.77
B25: =B9 -> FOURTH FLOOR | E25: GHC | F25: =SUM(F13:F24) -> 5197425.6
B26: To Bill General Summary
B29: BILL NR. 7 - FOURTH FLOOR
B31: ELEMENT NO. 1: IN SITU CONCRETE/LARGE PRECAST CONCRETE
B33: Vibrated in-situ concrete C40 as described in:
A34: A | B34: Suspended slab 250mm thick | C34: =1134.6*0.25 -> 283.65 | D34: m3 | E34: =RATES!$D$22 -> 2650 | F34: =C34*E34 -> 751672.5 | G34: 1134.6*0.25
A36: B | B36: Beams (downstands below slab) | C36: =166.8*0.3*0.35+33.1*0.2*0.35 -> 19.831 | D36: m3 | E36: =RATES!$D$23 -> 2700 | F36: =C36*E36 -> 53543.7 | G36: 166.8*0.3*0.35+33.1*0.2*0.35
A38: C | B38: Columns | C38: =5*0.75*0.5*3.05+1*0.75*0.5*3.05+2*0.75*0.5*3.05+1*0.75*0.5*3.05+3*1.2*0.3*3.05+6*1.2*0.3*3.05+1*1.2*0.3*3.05+15*1.2*0.3*3.05+1*(2.85*0.25+0.825*0.25)*3.05 -> 40.545937 | D38: m3 | E38: =RATES!$D$21 -> 2800 | F38: =C38*E38 -> 113528.62 | G38: 5*0.75*0.5*3.05+1*0.75*0.5*3.05+2*0.75*0.5*3.05+1*0.75*0.5*3.05+3*1.2*0.3*3.05+6*1.2*0.3*3.05+1*1.2*0.3*3.05+15*1.2*0.3*3.05+1*(2.85*0.25+0.825*0.25)*3.05
A40: D | B40: Concrete wall - shear walls to main & emergency stair cores, 250mm thick | C40: =22.05*3.05*0.25+25.57*3.05*0.25 -> 36.31025 | D40: m3 | E40: =RATES!$D$20 -> 2750 | F40: =C40*E40 -> 99853.187 | G40: 22.05*3.05*0.25+25.57*3.05*0.25
A42: E | B42: Concrete wall - lift walls, 250mm thick | C42: =21.825*3.05*0.25 -> 16.641562 | D42: m3 | E42: =RATES!$D$20 -> 2750 | F42: =C42*E42 -> 45764.297 | G42: 21.825*3.05*0.25
A44: F | B44: Stairs | C44: =(2.966*3.3/3.3+2.625)+(2.966*3.3/3.3+2.625) -> 11.182 | D44: m3 | E44: =RATES!$D$24 -> 2850 | F44: =C44*E44 -> 31868.7 | G44: (2.966*3.3/3.3+2.625)+(2.966*3.3/3.3+2.625)
A46: G | B46: Lintels 150 x 225mm over door and window openings | C46: =(8*(1+0.3)+15*(0.9+0.3)+22*(0.75+0.3)+1*(0.7+0.3)+3*(1.2+0.3)+3*(1+0.3)+3*(1+0.3)+2*(0.9+0.3)+1*(1.5+0.3)+3*(0.9+0.3)+5*(0.75+0.3)+1*(0.45+0.3)+3*(0.6+0.3)+1*(3+0.3)+4*(1.6+0.3)+2*(1.3+0.3)+4*(1.8+0.3)+1*(1.2+0.3)+6*(1.8+0.3)+10*(0.9+0.3)+2*(1.8+0.3)+3*(1.2+0.3)+8*(1.2+0.3)+1*(1.2+0.3)+7*(1.5+0.3)+4*(1.5+0.3)+1*(2.4+0.3)+1*(3+0.3)+3*(1.8+0.3)+1*(0.75+0.3)+1*(1.45+0.3)+13*(0.9+0.3)+5*(0.75+0.3)+2*(0.6+0.3)+2*(1.2+0.3))*0.15*0.225 -> 7.1769375 | D46: m3 | E46: =RATES!$D$25 -> 2600 | F46: =C46*E46 -> 18660.038 | G46: (8*(1+0.3)+15*(0.9+0.3)+22*(0.75+0.3)+1*(0.7+0.3)+3*(1.2+0.3)+3*(1+0.3)+3*(1+0.3)+2*(0.9+0.3)+1*(1.5+0.3)+3*(0.9+0.3)+5*(0.75+0.3)+1*(0.45+0.3)+3*(0.6+0.3)+1*(3+0.3)+4*(1.6+0.3)+2*(1.3+0.3)+4*(1.8+0.3)+1*(1.2+0.3)+6*(1.8+0.3)+10*(0.9+0.3)+2*(1.8+0...
B48: E20 FORMWORK - Formwork as described to:
A49: H | B49: Soffits of suspended slab | C49: =1134.6 -> 1134.6 | D49: m2 | E49: =RATES!$D$38 -> 170 | F49: =C49*E49 -> 192882 | G49: 1134.6
A51: J | B51: Edges of suspended slab 250mm high | C51: =294.6 -> 294.6 | D51: m | E51: =RATES!$D$40 -> 65 | F51: =C51*E51 -> 19149 | G51: 294.6
A53: K | B53: Sides and soffits of beams | C53: =166.8*(2*0.35+0.3)+33.1*(2*0.35+0.2) -> 196.59 | D53: m2 | E53: =RATES!$D$39 -> 200 | F53: =C53*E53 -> 39318 | G53: 166.8*(2*0.35+0.3)+33.1*(2*0.35+0.2)
A55: L | B55: Columns | C55: =5*2*(0.75+0.5)*3.05+1*2*(0.75+0.5)*3.05+2*2*(0.75+0.5)*3.05+1*2*(0.75+0.5)*3.05+3*2*(1.2+0.3)*3.05+6*2*(1.2+0.3)*3.05+1*2*(1.2+0.3)*3.05+15*2*(1.2+0.3)*3.05+1*2*(2.85+1.075)*3.05 -> 321.3175 | D55: m2 | E55: =RATES!$D$37 -> 190 | F55: =C55*E55 -> 61050.325 | G55: 5*2*(0.75+0.5)*3.05+1*2*(0.75+0.5)*3.05+2*2*(0.75+0.5)*3.05+1*2*(0.75+0.5)*3.05+3*2*(1.2+0.3)*3.05+6*2*(1.2+0.3)*3.05+1*2*(1.2+0.3)*3.05+15*2*(1.2+0.3)*3.05+1*2*(2.85+1.075)*3.05
A57: M | B57: Concrete wall (both faces) | C57: =2*22.05*3.05+2*21.825*3.05+2*25.57*3.05 -> 423.6145 | D57: m2 | E57: =RATES!$D$36 -> 185 | F57: =C57*E57 -> 78368.683 | G57: 2*22.05*3.05+2*21.825*3.05+2*25.57*3.05
A59: N | B59: Soffits of stair flights, landings and risers | C59: =(2*3.424*1.8+15.0+22*0.15*1.8)+(2*3.424*1.8+15.0+22*0.15*1.8) -> 66.5328 | D59: m2 | E59: =RATES!$D$42 -> 230 | F59: =C59*E59 -> 15302.544 | G59: (2*3.424*1.8+15.0+22*0.15*1.8)+(2*3.424*1.8+15.0+22*0.15*1.8)
A61: P | B61: Side and soffits of lintel / coping | C61: =(8*(1+0.3)+15*(0.9+0.3)+22*(0.75+0.3)+1*(0.7+0.3)+3*(1.2+0.3)+3*(1+0.3)+3*(1+0.3)+2*(0.9+0.3)+1*(1.5+0.3)+3*(0.9+0.3)+5*(0.75+0.3)+1*(0.45+0.3)+3*(0.6+0.3)+1*(3+0.3)+4*(1.6+0.3)+2*(1.3+0.3)+4*(1.8+0.3)+1*(1.2+0.3)+6*(1.8+0.3)+10*(0.9+0.3)+2*(1.8+0.3)+3*(1.2+0.3)+8*(1.2+0.3)+1*(1.2+0.3)+7*(1.5+0.3)+4*(1.5+0.3)+1*(2.4+0.3)+1*(3+0.3)+3*(1.8+0.3)+1*(0.75+0.3)+1*(1.45+0.3)+13*(0.9+0.3)+5*(0.75+0.3)+2*(0.6+0.3)+2*(1.2+0.3))*(2*0.225+0.15) -> 127.59 | D61: m2 | E61: =RATES!$D$43 -> 180 | F61: =C61*E61 -> 22966.2 | G61: (8*(1+0.3)+15*(0.9+0.3)+22*(0.75+0.3)+1*(0.7+0.3)+3*(1.2+0.3)+3*(1+0.3)+3*(1+0.3)+2*(0.9+0.3)+1*(1.5+0.3)+3*(0.9+0.3)+5*(0.75+0.3)+1*(0.45+0.3)+3*(0.6+0.3)+1*(3+0.3)+4*(1.6+0.3)+2*(1.3+0.3)+4*(1.8+0.3)+1*(1.2+0.3)+6*(1.8+0.3)+10*(0.9+0.3)+2*(1.8+0...
B63: E30 REINFORCEMENT - High tensile yield round bar reinforcement (standard) to BS 4449:
A64: Q | B64: 10mm diameter in columns | C64: =4.551 -> 4.551 | D64: t | E64: =RATES!$D$29 -> 20500 | F64: =C64*E64 -> 93295.5 | G64: 4.551
A66: R | B66: 20mm diameter in columns | C66: =7.133 -> 7.133 | D66: t | E66: =RATES!$D$32 -> 19000 | F66: =C66*E66 -> 135527 | G66: 7.133
A68: S | B68: 10mm diameter in beams (links) | C68: =1.806 -> 1.806 | D68: t | E68: =RATES!$D$29 -> 20500 | F68: =C68*E68 -> 37023 | G68: 1.806
A70: T | B70: 16mm diameter in beams | C70: =1.248 -> 1.248 | D70: t | E70: =RATES!$D$31 -> 19500 | F70: =C70*E70 -> 24336 | G70: 1.248
A72: U | B72: 20mm diameter in beams | C72: =2.135 -> 2.135 | D72: t | E72: =RATES!$D$32 -> 19000 | F72: =C72*E72 -> 40565 | G72: 2.135
...

Sheet 5TH FLR 
A1: ='PRELIMS & GEN. ITEMS'!A2 -> PROJECT: BLOCK N REDEVELOPMENT
A2: ='PRELIMS & GEN. ITEMS'!A3 -> LOCATION: KANESHIE
A3: ='PRELIMS & GEN. ITEMS'!A4 -> CLIENT: STATE HOUSING LIMITED
A4: ='PRELIMS & GEN. ITEMS'!A5 -> DATE:9/30/2026
A5: ITEM | B5: DESCRIPTION | C5: QTY | D5: UNIT | E5: RATE | F5: AMOUNT - GHC | G5: Measurement basis / calculation
B7: MAIN BUILDING
B9: FIFTH FLOOR
B11: BILL SUMMARY
A13: A | B13: ELEMENT NO. 1: IN SITU CONCRETE/LARGE PRECAST CONCRETE | F13: =F90 -> 3312876.5
A15: B | B15: ELEMENT NO. 2: MASONRY | F15: =F101 -> 378588.89
A17: C | B17: ELEMENT NO. 4: WINDOWS/DOORS | F17: =F190 -> 577390.45
A19: D | B19: ELEMENT NO. 5: FLOOR FINISHES | F19: =F211 -> 341125.34
A21: E | B21: ELEMENT NO. 6: WALL FINISHES | F21: =F228 -> 309236.25
A23: F | B23: ELEMENT NO. 7: PAINTING AND DECORATING | F23: =F249 -> 187552.29
B25: =B9 -> FIFTH FLOOR | E25: GHC | F25: =SUM(F13:F24) -> 5106769.7
B26: To Bill General Summary
B29: BILL NR. 8 - FIFTH FLOOR
B31: ELEMENT NO. 1: IN SITU CONCRETE/LARGE PRECAST CONCRETE
B33: Vibrated in-situ concrete C40 as described in:
A34: A | B34: Suspended slab 250mm thick | C34: =1134.6*0.25 -> 283.65 | D34: m3 | E34: =RATES!$D$22 -> 2650 | F34: =C34*E34 -> 751672.5 | G34: 1134.6*0.25
A36: B | B36: Beams (downstands below slab) | C36: =166.8*0.3*0.35+33.1*0.2*0.35 -> 19.831 | D36: m3 | E36: =RATES!$D$23 -> 2700 | F36: =C36*E36 -> 53543.7 | G36: 166.8*0.3*0.35+33.1*0.2*0.35
A38: C | B38: Columns | C38: =5*0.75*0.5*3.05+1*0.75*0.5*3.05+2*0.75*0.5*3.05+1*0.75*0.5*3.05+3*1.2*0.3*3.05+6*1.2*0.3*3.05+1*1.2*0.3*3.05+15*1.2*0.3*3.05+1*(2.85*0.25+0.825*0.25)*3.05 -> 40.545937 | D38: m3 | E38: =RATES!$D$21 -> 2800 | F38: =C38*E38 -> 113528.62 | G38: 5*0.75*0.5*3.05+1*0.75*0.5*3.05+2*0.75*0.5*3.05+1*0.75*0.5*3.05+3*1.2*0.3*3.05+6*1.2*0.3*3.05+1*1.2*0.3*3.05+15*1.2*0.3*3.05+1*(2.85*0.25+0.825*0.25)*3.05
A40: D | B40: Concrete wall - shear walls to main & emergency stair cores, 250mm thick | C40: =22.05*3.05*0.25+25.57*3.05*0.25 -> 36.31025 | D40: m3 | E40: =RATES!$D$20 -> 2750 | F40: =C40*E40 -> 99853.187 | G40: 22.05*3.05*0.25+25.57*3.05*0.25
A42: E | B42: Concrete wall - lift walls, 250mm thick | C42: =21.825*3.05*0.25 -> 16.641562 | D42: m3 | E42: =RATES!$D$20 -> 2750 | F42: =C42*E42 -> 45764.297 | G42: 21.825*3.05*0.25
A44: F | B44: Stairs | C44: =(2.966*3.3/3.3+2.625)+(2.966*3.3/3.3+2.625) -> 11.182 | D44: m3 | E44: =RATES!$D$24 -> 2850 | F44: =C44*E44 -> 31868.7 | G44: (2.966*3.3/3.3+2.625)+(2.966*3.3/3.3+2.625)
A46: G | B46: Lintels 150 x 225mm over door and window openings | C46: =(7*(1+0.3)+15*(0.9+0.3)+20*(0.75+0.3)+1*(0.7+0.3)+3*(1.2+0.3)+3*(1+0.3)+3*(1+0.3)+1*(0.9+0.3)+1*(1.5+0.3)+2*(0.9+0.3)+5*(0.75+0.3)+1*(0.45+0.3)+3*(0.6+0.3)+1*(3+0.3)+3*(1.6+0.3)+2*(1.3+0.3)+4*(1.8+0.3)+1*(1.2+0.3)+6*(1.8+0.3)+10*(0.9+0.3)+1*(1.8+0.3)+3*(1.2+0.3)+8*(1.2+0.3)+1*(1.2+0.3)+6*(1.5+0.3)+3*(1.5+0.3)+1*(2.4+0.3)+1*(3+0.3)+3*(1.8+0.3)+1*(0.75+0.3)+1*(1.45+0.3)+12*(0.9+0.3)+4*(0.75+0.3)+1*(0.6+0.3)+1*(1.2+0.3))*0.15*0.225 -> 6.56775 | D46: m3 | E46: =RATES!$D$25 -> 2600 | F46: =C46*E46 -> 17076.15 | G46: (7*(1+0.3)+15*(0.9+0.3)+20*(0.75+0.3)+1*(0.7+0.3)+3*(1.2+0.3)+3*(1+0.3)+3*(1+0.3)+1*(0.9+0.3)+1*(1.5+0.3)+2*(0.9+0.3)+5*(0.75+0.3)+1*(0.45+0.3)+3*(0.6+0.3)+1*(3+0.3)+3*(1.6+0.3)+2*(1.3+0.3)+4*(1.8+0.3)+1*(1.2+0.3)+6*(1.8+0.3)+10*(0.9+0.3)+1*(1.8+0...
B48: E20 FORMWORK - Formwork as described to:
A49: H | B49: Soffits of suspended slab | C49: =1134.6 -> 1134.6 | D49: m2 | E49: =RATES!$D$38 -> 170 | F49: =C49*E49 -> 192882 | G49: 1134.6
A51: J | B51: Edges of suspended slab 250mm high | C51: =294.6 -> 294.6 | D51: m | E51: =RATES!$D$40 -> 65 | F51: =C51*E51 -> 19149 | G51: 294.6
A53: K | B53: Sides and soffits of beams | C53: =166.8*(2*0.35+0.3)+33.1*(2*0.35+0.2) -> 196.59 | D53: m2 | E53: =RATES!$D$39 -> 200 | F53: =C53*E53 -> 39318 | G53: 166.8*(2*0.35+0.3)+33.1*(2*0.35+0.2)
A55: L | B55: Columns | C55: =5*2*(0.75+0.5)*3.05+1*2*(0.75+0.5)*3.05+2*2*(0.75+0.5)*3.05+1*2*(0.75+0.5)*3.05+3*2*(1.2+0.3)*3.05+6*2*(1.2+0.3)*3.05+1*2*(1.2+0.3)*3.05+15*2*(1.2+0.3)*3.05+1*2*(2.85+1.075)*3.05 -> 321.3175 | D55: m2 | E55: =RATES!$D$37 -> 190 | F55: =C55*E55 -> 61050.325 | G55: 5*2*(0.75+0.5)*3.05+1*2*(0.75+0.5)*3.05+2*2*(0.75+0.5)*3.05+1*2*(0.75+0.5)*3.05+3*2*(1.2+0.3)*3.05+6*2*(1.2+0.3)*3.05+1*2*(1.2+0.3)*3.05+15*2*(1.2+0.3)*3.05+1*2*(2.85+1.075)*3.05
A57: M | B57: Concrete wall (both faces) | C57: =2*22.05*3.05+2*21.825*3.05+2*25.57*3.05 -> 423.6145 | D57: m2 | E57: =RATES!$D$36 -> 185 | F57: =C57*E57 -> 78368.683 | G57: 2*22.05*3.05+2*21.825*3.05+2*25.57*3.05
A59: N | B59: Soffits of stair flights, landings and risers | C59: =(2*3.424*1.8+15.0+22*0.15*1.8)+(2*3.424*1.8+15.0+22*0.15*1.8) -> 66.5328 | D59: m2 | E59: =RATES!$D$42 -> 230 | F59: =C59*E59 -> 15302.544 | G59: (2*3.424*1.8+15.0+22*0.15*1.8)+(2*3.424*1.8+15.0+22*0.15*1.8)
A61: P | B61: Side and soffits of lintel / coping | C61: =(7*(1+0.3)+15*(0.9+0.3)+20*(0.75+0.3)+1*(0.7+0.3)+3*(1.2+0.3)+3*(1+0.3)+3*(1+0.3)+1*(0.9+0.3)+1*(1.5+0.3)+2*(0.9+0.3)+5*(0.75+0.3)+1*(0.45+0.3)+3*(0.6+0.3)+1*(3+0.3)+3*(1.6+0.3)+2*(1.3+0.3)+4*(1.8+0.3)+1*(1.2+0.3)+6*(1.8+0.3)+10*(0.9+0.3)+1*(1.8+0.3)+3*(1.2+0.3)+8*(1.2+0.3)+1*(1.2+0.3)+6*(1.5+0.3)+3*(1.5+0.3)+1*(2.4+0.3)+1*(3+0.3)+3*(1.8+0.3)+1*(0.75+0.3)+1*(1.45+0.3)+12*(0.9+0.3)+4*(0.75+0.3)+1*(0.6+0.3)+1*(1.2+0.3))*(2*0.225+0.15) -> 116.76 | D61: m2 | E61: =RATES!$D$43 -> 180 | F61: =C61*E61 -> 21016.8 | G61: (7*(1+0.3)+15*(0.9+0.3)+20*(0.75+0.3)+1*(0.7+0.3)+3*(1.2+0.3)+3*(1+0.3)+3*(1+0.3)+1*(0.9+0.3)+1*(1.5+0.3)+2*(0.9+0.3)+5*(0.75+0.3)+1*(0.45+0.3)+3*(0.6+0.3)+1*(3+0.3)+3*(1.6+0.3)+2*(1.3+0.3)+4*(1.8+0.3)+1*(1.2+0.3)+6*(1.8+0.3)+10*(0.9+0.3)+1*(1.8+0...
B63: E30 REINFORCEMENT - High tensile yield round bar reinforcement (standard) to BS 4449:
A64: Q | B64: 10mm diameter in columns | C64: =4.551 -> 4.551 | D64: t | E64: =RATES!$D$29 -> 20500 | F64: =C64*E64 -> 93295.5 | G64: 4.551
A66: R | B66: 20mm diameter in columns | C66: =7.133 -> 7.133 | D66: t | E66: =RATES!$D$32 -> 19000 | F66: =C66*E66 -> 135527 | G66: 7.133
A68: S | B68: 10mm diameter in beams (links) | C68: =1.806 -> 1.806 | D68: t | E68: =RATES!$D$29 -> 20500 | F68: =C68*E68 -> 37023 | G68: 1.806
A70: T | B70: 16mm diameter in beams | C70: =1.248 -> 1.248 | D70: t | E70: =RATES!$D$31 -> 19500 | F70: =C70*E70 -> 24336 | G70: 1.248
A72: U | B72: 20mm diameter in beams | C72: =2.135 -> 2.135 | D72: t | E72: =RATES!$D$32 -> 19000 | F72: =C72*E72 -> 40565 | G72: 2.135
...

Sheet 6TH FLR  
A1: ='PRELIMS & GEN. ITEMS'!A2 -> PROJECT: BLOCK N REDEVELOPMENT
A2: ='PRELIMS & GEN. ITEMS'!A3 -> LOCATION: KANESHIE
A3: ='PRELIMS & GEN. ITEMS'!A4 -> CLIENT: STATE HOUSING LIMITED
A4: ='PRELIMS & GEN. ITEMS'!A5 -> DATE:9/30/2026
A5: ITEM | B5: DESCRIPTION | C5: QTY | D5: UNIT | E5: RATE | F5: AMOUNT - GHC | G5: Measurement basis / calculation
B7: MAIN BUILDING
B9: SIXTH FLOOR
B11: BILL SUMMARY
A13: A | B13: ELEMENT NO. 1: IN SITU CONCRETE/LARGE PRECAST CONCRETE | F13: =F90 -> 3315382.1
A15: B | B15: ELEMENT NO. 2: MASONRY | F15: =F101 -> 394834.26
A17: C | B17: ELEMENT NO. 4: WINDOWS/DOORS | F17: =F190 -> 608377.15
A19: D | B19: ELEMENT NO. 5: FLOOR FINISHES | F19: =F211 -> 349083.24
A21: E | B21: ELEMENT NO. 6: WALL FINISHES | F21: =F228 -> 321670.38
A23: F | B23: ELEMENT NO. 7: PAINTING AND DECORATING | F23: =F249 -> 190908.58
B25: =B9 -> SIXTH FLOOR | E25: GHC | F25: =SUM(F13:F24) -> 5180255.7
B26: To Bill General Summary
B29: BILL NR. 9 - SIXTH FLOOR
B31: ELEMENT NO. 1: IN SITU CONCRETE/LARGE PRECAST CONCRETE
B33: Vibrated in-situ concrete C40 as described in:
A34: A | B34: Suspended slab 250mm thick | C34: =1134.6*0.25 -> 283.65 | D34: m3 | E34: =RATES!$D$22 -> 2650 | F34: =C34*E34 -> 751672.5 | G34: 1134.6*0.25
A36: B | B36: Beams (downstands below slab) | C36: =166.8*0.3*0.35+33.1*0.2*0.35 -> 19.831 | D36: m3 | E36: =RATES!$D$23 -> 2700 | F36: =C36*E36 -> 53543.7 | G36: 166.8*0.3*0.35+33.1*0.2*0.35
A38: C | B38: Columns | C38: =5*0.75*0.5*3.05+1*0.75*0.5*3.05+2*0.75*0.5*3.05+1*0.75*0.5*3.05+3*1.2*0.3*3.05+6*1.2*0.3*3.05+1*1.2*0.3*3.05+15*1.2*0.3*3.05+1*(2.85*0.25+0.825*0.25)*3.05 -> 40.545937 | D38: m3 | E38: =RATES!$D$21 -> 2800 | F38: =C38*E38 -> 113528.62 | G38: 5*0.75*0.5*3.05+1*0.75*0.5*3.05+2*0.75*0.5*3.05+1*0.75*0.5*3.05+3*1.2*0.3*3.05+6*1.2*0.3*3.05+1*1.2*0.3*3.05+15*1.2*0.3*3.05+1*(2.85*0.25+0.825*0.25)*3.05
A40: D | B40: Concrete wall - shear walls to main & emergency stair cores, 250mm thick | C40: =22.05*3.05*0.25+25.57*3.05*0.25 -> 36.31025 | D40: m3 | E40: =RATES!$D$20 -> 2750 | F40: =C40*E40 -> 99853.187 | G40: 22.05*3.05*0.25+25.57*3.05*0.25
A42: E | B42: Concrete wall - lift walls, 250mm thick | C42: =21.825*3.05*0.25 -> 16.641562 | D42: m3 | E42: =RATES!$D$20 -> 2750 | F42: =C42*E42 -> 45764.297 | G42: 21.825*3.05*0.25
A44: F | B44: Stairs | C44: =(2.966*3.3/3.3+2.625)+(2.966*3.3/3.3+2.625) -> 11.182 | D44: m3 | E44: =RATES!$D$24 -> 2850 | F44: =C44*E44 -> 31868.7 | G44: (2.966*3.3/3.3+2.625)+(2.966*3.3/3.3+2.625)
A46: G | B46: Lintels 150 x 225mm over door and window openings | C46: =(8*(1+0.3)+15*(0.9+0.3)+21*(0.75+0.3)+1*(0.7+0.3)+3*(1.2+0.3)+3*(1+0.3)+3*(1+0.3)+1*(0.9+0.3)+1*(1.5+0.3)+2*(0.9+0.3)+5*(0.75+0.3)+1*(0.45+0.3)+3*(0.6+0.3)+1*(3+0.3)+4*(1.6+0.3)+2*(1.3+0.3)+4*(1.8+0.3)+1*(1.2+0.3)+6*(1.8+0.3)+10*(0.9+0.3)+2*(1.8+0.3)+3*(1.2+0.3)+8*(1.2+0.3)+1*(1.2+0.3)+6*(1.5+0.3)+4*(1.5+0.3)+1*(2.4+0.3)+1*(3+0.3)+3*(1.8+0.3)+1*(0.75+0.3)+1*(1.45+0.3)+13*(0.9+0.3)+5*(0.75+0.3)+2*(0.6+0.3)+2*(1.2+0.3))*0.15*0.225 -> 6.99975 | D46: m3 | E46: =RATES!$D$25 -> 2600 | F46: =C46*E46 -> 18199.35 | G46: (8*(1+0.3)+15*(0.9+0.3)+21*(0.75+0.3)+1*(0.7+0.3)+3*(1.2+0.3)+3*(1+0.3)+3*(1+0.3)+1*(0.9+0.3)+1*(1.5+0.3)+2*(0.9+0.3)+5*(0.75+0.3)+1*(0.45+0.3)+3*(0.6+0.3)+1*(3+0.3)+4*(1.6+0.3)+2*(1.3+0.3)+4*(1.8+0.3)+1*(1.2+0.3)+6*(1.8+0.3)+10*(0.9+0.3)+2*(1.8+0...
B48: E20 FORMWORK - Formwork as described to:
A49: H | B49: Soffits of suspended slab | C49: =1134.6 -> 1134.6 | D49: m2 | E49: =RATES!$D$38 -> 170 | F49: =C49*E49 -> 192882 | G49: 1134.6
A51: J | B51: Edges of suspended slab 250mm high | C51: =294.6 -> 294.6 | D51: m | E51: =RATES!$D$40 -> 65 | F51: =C51*E51 -> 19149 | G51: 294.6
A53: K | B53: Sides and soffits of beams | C53: =166.8*(2*0.35+0.3)+33.1*(2*0.35+0.2) -> 196.59 | D53: m2 | E53: =RATES!$D$39 -> 200 | F53: =C53*E53 -> 39318 | G53: 166.8*(2*0.35+0.3)+33.1*(2*0.35+0.2)
A55: L | B55: Columns | C55: =5*2*(0.75+0.5)*3.05+1*2*(0.75+0.5)*3.05+2*2*(0.75+0.5)*3.05+1*2*(0.75+0.5)*3.05+3*2*(1.2+0.3)*3.05+6*2*(1.2+0.3)*3.05+1*2*(1.2+0.3)*3.05+15*2*(1.2+0.3)*3.05+1*2*(2.85+1.075)*3.05 -> 321.3175 | D55: m2 | E55: =RATES!$D$37 -> 190 | F55: =C55*E55 -> 61050.325 | G55: 5*2*(0.75+0.5)*3.05+1*2*(0.75+0.5)*3.05+2*2*(0.75+0.5)*3.05+1*2*(0.75+0.5)*3.05+3*2*(1.2+0.3)*3.05+6*2*(1.2+0.3)*3.05+1*2*(1.2+0.3)*3.05+15*2*(1.2+0.3)*3.05+1*2*(2.85+1.075)*3.05
A57: M | B57: Concrete wall (both faces) | C57: =2*22.05*3.05+2*21.825*3.05+2*25.57*3.05 -> 423.6145 | D57: m2 | E57: =RATES!$D$36 -> 185 | F57: =C57*E57 -> 78368.683 | G57: 2*22.05*3.05+2*21.825*3.05+2*25.57*3.05
A59: N | B59: Soffits of stair flights, landings and risers | C59: =(2*3.424*1.8+15.0+22*0.15*1.8)+(2*3.424*1.8+15.0+22*0.15*1.8) -> 66.5328 | D59: m2 | E59: =RATES!$D$42 -> 230 | F59: =C59*E59 -> 15302.544 | G59: (2*3.424*1.8+15.0+22*0.15*1.8)+(2*3.424*1.8+15.0+22*0.15*1.8)
A61: P | B61: Side and soffits of lintel / coping | C61: =(8*(1+0.3)+15*(0.9+0.3)+21*(0.75+0.3)+1*(0.7+0.3)+3*(1.2+0.3)+3*(1+0.3)+3*(1+0.3)+1*(0.9+0.3)+1*(1.5+0.3)+2*(0.9+0.3)+5*(0.75+0.3)+1*(0.45+0.3)+3*(0.6+0.3)+1*(3+0.3)+4*(1.6+0.3)+2*(1.3+0.3)+4*(1.8+0.3)+1*(1.2+0.3)+6*(1.8+0.3)+10*(0.9+0.3)+2*(1.8+0.3)+3*(1.2+0.3)+8*(1.2+0.3)+1*(1.2+0.3)+6*(1.5+0.3)+4*(1.5+0.3)+1*(2.4+0.3)+1*(3+0.3)+3*(1.8+0.3)+1*(0.75+0.3)+1*(1.45+0.3)+13*(0.9+0.3)+5*(0.75+0.3)+2*(0.6+0.3)+2*(1.2+0.3))*(2*0.225+0.15) -> 124.44 | D61: m2 | E61: =RATES!$D$43 -> 180 | F61: =C61*E61 -> 22399.2 | G61: (8*(1+0.3)+15*(0.9+0.3)+21*(0.75+0.3)+1*(0.7+0.3)+3*(1.2+0.3)+3*(1+0.3)+3*(1+0.3)+1*(0.9+0.3)+1*(1.5+0.3)+2*(0.9+0.3)+5*(0.75+0.3)+1*(0.45+0.3)+3*(0.6+0.3)+1*(3+0.3)+4*(1.6+0.3)+2*(1.3+0.3)+4*(1.8+0.3)+1*(1.2+0.3)+6*(1.8+0.3)+10*(0.9+0.3)+2*(1.8+0...
B63: E30 REINFORCEMENT - High tensile yield round bar reinforcement (standard) to BS 4449:
A64: Q | B64: 10mm diameter in columns | C64: =4.551 -> 4.551 | D64: t | E64: =RATES!$D$29 -> 20500 | F64: =C64*E64 -> 93295.5 | G64: 4.551
A66: R | B66: 20mm diameter in columns | C66: =7.133 -> 7.133 | D66: t | E66: =RATES!$D$32 -> 19000 | F66: =C66*E66 -> 135527 | G66: 7.133
A68: S | B68: 10mm diameter in beams (links) | C68: =1.806 -> 1.806 | D68: t | E68: =RATES!$D$29 -> 20500 | F68: =C68*E68 -> 37023 | G68: 1.806
A70: T | B70: 16mm diameter in beams | C70: =1.248 -> 1.248 | D70: t | E70: =RATES!$D$31 -> 19500 | F70: =C70*E70 -> 24336 | G70: 1.248
A72: U | B72: 20mm diameter in beams | C72: =2.135 -> 2.135 | D72: t | E72: =RATES!$D$32 -> 19000 | F72: =C72*E72 -> 40565 | G72: 2.135
...

Sheet 7TH FLR   
A1: ='PRELIMS & GEN. ITEMS'!A2 -> PROJECT: BLOCK N REDEVELOPMENT
A2: ='PRELIMS & GEN. ITEMS'!A3 -> LOCATION: KANESHIE
A3: ='PRELIMS & GEN. ITEMS'!A4 -> CLIENT: STATE HOUSING LIMITED
A4: ='PRELIMS & GEN. ITEMS'!A5 -> DATE:9/30/2026
A5: ITEM | B5: DESCRIPTION | C5: QTY | D5: UNIT | E5: RATE | F5: AMOUNT - GHC | G5: Measurement basis / calculation
B7: MAIN BUILDING
B9: SEVENTH FLOOR
B11: BILL SUMMARY
A13: A | B13: ELEMENT NO. 1: IN SITU CONCRETE/LARGE PRECAST CONCRETE | F13: =F90 -> 3313248.4
A15: B | B15: ELEMENT NO. 2: MASONRY | F15: =F101 -> 381266.88
A17: C | B17: ELEMENT NO. 4: WINDOWS/DOORS | F17: =F190 -> 584032.95
A19: D | B19: ELEMENT NO. 5: FLOOR FINISHES | F19: =F211 -> 345672.24
A21: E | B21: ELEMENT NO. 6: WALL FINISHES | F21: =F228 -> 312099.76
A23: F | B23: ELEMENT NO. 7: PAINTING AND DECORATING | F23: =F249 -> 188326.49
B25: =B9 -> SEVENTH FLOOR | E25: GHC | F25: =SUM(F13:F24) -> 5124646.8
B26: To Bill General Summary
B29: BILL NR. 10 - SEVENTH FLOOR
B31: ELEMENT NO. 1: IN SITU CONCRETE/LARGE PRECAST CONCRETE
B33: Vibrated in-situ concrete C40 as described in:
A34: A | B34: Suspended slab 250mm thick | C34: =1134.6*0.25 -> 283.65 | D34: m3 | E34: =RATES!$D$22 -> 2650 | F34: =C34*E34 -> 751672.5 | G34: 1134.6*0.25
A36: B | B36: Beams (downstands below slab) | C36: =166.8*0.3*0.35+33.1*0.2*0.35 -> 19.831 | D36: m3 | E36: =RATES!$D$23 -> 2700 | F36: =C36*E36 -> 53543.7 | G36: 166.8*0.3*0.35+33.1*0.2*0.35
A38: C | B38: Columns | C38: =5*0.75*0.5*3.05+1*0.75*0.5*3.05+2*0.75*0.5*3.05+1*0.75*0.5*3.05+3*1.2*0.3*3.05+6*1.2*0.3*3.05+1*1.2*0.3*3.05+15*1.2*0.3*3.05+1*(2.85*0.25+0.825*0.25)*3.05 -> 40.545937 | D38: m3 | E38: =RATES!$D$21 -> 2800 | F38: =C38*E38 -> 113528.62 | G38: 5*0.75*0.5*3.05+1*0.75*0.5*3.05+2*0.75*0.5*3.05+1*0.75*0.5*3.05+3*1.2*0.3*3.05+6*1.2*0.3*3.05+1*1.2*0.3*3.05+15*1.2*0.3*3.05+1*(2.85*0.25+0.825*0.25)*3.05
A40: D | B40: Concrete wall - shear walls to main & emergency stair cores, 250mm thick | C40: =22.05*3.05*0.25+25.57*3.05*0.25 -> 36.31025 | D40: m3 | E40: =RATES!$D$20 -> 2750 | F40: =C40*E40 -> 99853.187 | G40: 22.05*3.05*0.25+25.57*3.05*0.25
A42: E | B42: Concrete wall - lift walls, 250mm thick | C42: =21.825*3.05*0.25 -> 16.641562 | D42: m3 | E42: =RATES!$D$20 -> 2750 | F42: =C42*E42 -> 45764.297 | G42: 21.825*3.05*0.25
A44: F | B44: Stairs | C44: =(2.966*3.3/3.3+2.625)+(2.966*3.3/3.3+2.625) -> 11.182 | D44: m3 | E44: =RATES!$D$24 -> 2850 | F44: =C44*E44 -> 31868.7 | G44: (2.966*3.3/3.3+2.625)+(2.966*3.3/3.3+2.625)
A46: G | B46: Lintels 150 x 225mm over door and window openings | C46: =(8*(1+0.3)+15*(0.9+0.3)+20*(0.75+0.3)+1*(0.7+0.3)+3*(1.2+0.3)+3*(1+0.3)+2*(1+0.3)+1*(0.9+0.3)+1*(1.5+0.3)+2*(0.9+0.3)+4*(0.75+0.3)+1*(0.45+0.3)+3*(0.6+0.3)+1*(3+0.3)+4*(1.6+0.3)+2*(1.3+0.3)+4*(1.8+0.3)+1*(1.2+0.3)+6*(1.8+0.3)+10*(0.9+0.3)+1*(1.8+0.3)+3*(1.2+0.3)+8*(1.2+0.3)+1*(1.2+0.3)+6*(1.5+0.3)+3*(1.5+0.3)+1*(2.4+0.3)+1*(3+0.3)+3*(1.8+0.3)+1*(0.75+0.3)+1*(1.45+0.3)+12*(0.9+0.3)+5*(0.75+0.3)+1*(0.6+0.3)+1*(1.2+0.3))*0.15*0.225 -> 6.631875 | D46: m3 | E46: =RATES!$D$25 -> 2600 | F46: =C46*E46 -> 17242.875 | G46: (8*(1+0.3)+15*(0.9+0.3)+20*(0.75+0.3)+1*(0.7+0.3)+3*(1.2+0.3)+3*(1+0.3)+2*(1+0.3)+1*(0.9+0.3)+1*(1.5+0.3)+2*(0.9+0.3)+4*(0.75+0.3)+1*(0.45+0.3)+3*(0.6+0.3)+1*(3+0.3)+4*(1.6+0.3)+2*(1.3+0.3)+4*(1.8+0.3)+1*(1.2+0.3)+6*(1.8+0.3)+10*(0.9+0.3)+1*(1.8+0...
B48: E20 FORMWORK - Formwork as described to:
A49: H | B49: Soffits of suspended slab | C49: =1134.6 -> 1134.6 | D49: m2 | E49: =RATES!$D$38 -> 170 | F49: =C49*E49 -> 192882 | G49: 1134.6
A51: J | B51: Edges of suspended slab 250mm high | C51: =294.6 -> 294.6 | D51: m | E51: =RATES!$D$40 -> 65 | F51: =C51*E51 -> 19149 | G51: 294.6
A53: K | B53: Sides and soffits of beams | C53: =166.8*(2*0.35+0.3)+33.1*(2*0.35+0.2) -> 196.59 | D53: m2 | E53: =RATES!$D$39 -> 200 | F53: =C53*E53 -> 39318 | G53: 166.8*(2*0.35+0.3)+33.1*(2*0.35+0.2)
A55: L | B55: Columns | C55: =5*2*(0.75+0.5)*3.05+1*2*(0.75+0.5)*3.05+2*2*(0.75+0.5)*3.05+1*2*(0.75+0.5)*3.05+3*2*(1.2+0.3)*3.05+6*2*(1.2+0.3)*3.05+1*2*(1.2+0.3)*3.05+15*2*(1.2+0.3)*3.05+1*2*(2.85+1.075)*3.05 -> 321.3175 | D55: m2 | E55: =RATES!$D$37 -> 190 | F55: =C55*E55 -> 61050.325 | G55: 5*2*(0.75+0.5)*3.05+1*2*(0.75+0.5)*3.05+2*2*(0.75+0.5)*3.05+1*2*(0.75+0.5)*3.05+3*2*(1.2+0.3)*3.05+6*2*(1.2+0.3)*3.05+1*2*(1.2+0.3)*3.05+15*2*(1.2+0.3)*3.05+1*2*(2.85+1.075)*3.05
A57: M | B57: Concrete wall (both faces) | C57: =2*22.05*3.05+2*21.825*3.05+2*25.57*3.05 -> 423.6145 | D57: m2 | E57: =RATES!$D$36 -> 185 | F57: =C57*E57 -> 78368.683 | G57: 2*22.05*3.05+2*21.825*3.05+2*25.57*3.05
A59: N | B59: Soffits of stair flights, landings and risers | C59: =(2*3.424*1.8+15.0+22*0.15*1.8)+(2*3.424*1.8+15.0+22*0.15*1.8) -> 66.5328 | D59: m2 | E59: =RATES!$D$42 -> 230 | F59: =C59*E59 -> 15302.544 | G59: (2*3.424*1.8+15.0+22*0.15*1.8)+(2*3.424*1.8+15.0+22*0.15*1.8)
A61: P | B61: Side and soffits of lintel / coping | C61: =(8*(1+0.3)+15*(0.9+0.3)+20*(0.75+0.3)+1*(0.7+0.3)+3*(1.2+0.3)+3*(1+0.3)+2*(1+0.3)+1*(0.9+0.3)+1*(1.5+0.3)+2*(0.9+0.3)+4*(0.75+0.3)+1*(0.45+0.3)+3*(0.6+0.3)+1*(3+0.3)+4*(1.6+0.3)+2*(1.3+0.3)+4*(1.8+0.3)+1*(1.2+0.3)+6*(1.8+0.3)+10*(0.9+0.3)+1*(1.8+0.3)+3*(1.2+0.3)+8*(1.2+0.3)+1*(1.2+0.3)+6*(1.5+0.3)+3*(1.5+0.3)+1*(2.4+0.3)+1*(3+0.3)+3*(1.8+0.3)+1*(0.75+0.3)+1*(1.45+0.3)+12*(0.9+0.3)+5*(0.75+0.3)+1*(0.6+0.3)+1*(1.2+0.3))*(2*0.225+0.15) -> 117.9 | D61: m2 | E61: =RATES!$D$43 -> 180 | F61: =C61*E61 -> 21222 | G61: (8*(1+0.3)+15*(0.9+0.3)+20*(0.75+0.3)+1*(0.7+0.3)+3*(1.2+0.3)+3*(1+0.3)+2*(1+0.3)+1*(0.9+0.3)+1*(1.5+0.3)+2*(0.9+0.3)+4*(0.75+0.3)+1*(0.45+0.3)+3*(0.6+0.3)+1*(3+0.3)+4*(1.6+0.3)+2*(1.3+0.3)+4*(1.8+0.3)+1*(1.2+0.3)+6*(1.8+0.3)+10*(0.9+0.3)+1*(1.8+0...
B63: E30 REINFORCEMENT - High tensile yield round bar reinforcement (standard) to BS 4449:
