Workbook

Sheet Cover Page 
A1: aq
B11: PROPOSED BILLS OF QUANTITIES FOR KANESHIE BLOCK N REDEVELOPMENT
F23: DATE:9/30/2026

Sheet GEN SUMMARY
A1: PROJECT: BLOCK N REDEVELOPMENT
A2: LOCATION: KANESHIE
A3: CLIENT: STATE HOUSING LIMITED
A4: ='Cover Page '!F23 -> DATE:9/30/2026
A5: ITEM | B5: GENERAL SUMMARY | D5: GHC
A7: A | B7: PRELIMINARIES AND GENERAL ITEMS | D7: ='PRELIMS & GEN. ITEMS'!F40 -> 6123000
A9: B | B9: SUBSTRUCTURE (ALL PROVISIONAL) | D9: =SUBSTRUCTURE!F19 -> 11462308
A11: C | B11: GROUND FLOOR (INCL. M1 PARKING LEVEL) | D11: ='GROUND FLR '!F25 -> 3564210.3
A13: D | B13: FIRST FLOOR (INCL. M2 PARKING LEVEL) | D13: ='1ST FLR '!F25 -> 3329563.1
A15: E | B15: SECOND FLOOR (INCL. MEZZANINE PARKING LEVEL) | D15: ='2ND FLR'!F25 -> 4022915.7
A17: F | B17: THIRD FLOOR | D17: ='3RD FLR'!F25 -> 4846104.7
A19: G | B19: FOURTH FLOOR | D19: ='4TH FLR '!F25 -> 4493131.5
A21: H | B21: FIFTH FLOOR | D21: ='5TH FLR '!F25 -> 4413966.8
A23: J | B23: SIXTH FLOOR | D23: ='6TH FLR '!F25 -> 4486311.7
A25: K | B25: SEVENTH FLOOR | D25: ='7TH FLR '!F25 -> 4431733.9
A27: L | B27: EIGHTH FLOOR | D27: ='8TH FLR '!F25 -> 4427887.7
A29: M | B29: NINTH FLOOR | D29: ='9TH FLR '!F27 -> 4096981.5
A31: N | B31: TENTH FLOOR | D31: ='10TH FLR '!F25 -> 3426769.9
A33: P | B33: ELEVENTH LEVEL - ROOF TOP TERRACE | D33: ='11TH FLR'!F27 -> 2622767.4
A35: Q | B35: TWELFTH LEVEL - ROOF LEVEL & LIFT CORE | D35: ='12TH FLR '!F19 -> 532030.67
A37: R | B37: LIFTS AND PROVISIONAL SUMS | D37: ='LIFTS & PS'!F17 -> 4354000
B39: SUB - TOTAL (1) | C39: GHC | D39: =SUM(D6:D37) -> 70633683
B42: ADD: STATUTORY LEVIES AND TAXES | C42: 0.2 | D42: =D39*C42 -> 14126737
B44: TOTAL COST OF THE WORKS | C44: GHC | D44: =D42+D39 -> 84760419

Sheet PRELIMS & GEN. ITEMS
A1: ='GEN SUMMARY'!A1 -> PROJECT: BLOCK N REDEVELOPMENT
A2: ='GEN SUMMARY'!A2 -> LOCATION: KANESHIE
A3: ='GEN SUMMARY'!A3 -> CLIENT: STATE HOUSING LIMITED
A4: ='GEN SUMMARY'!A4 -> DATE:9/30/2026
B6: BILL NO.1- PRELIMINARIES BILL AND GENERAL CONDITIONS
A7: ITEM | B7: DESCRIPTION | C7: QTY | D7: UNIT | E7: RATE | F7: AMOUNT GHS
B9: SUMMARY
B11: COLLECTION
B12: Page 2 | F12: =F73 -> 0
B14: Page 3 | F14: =F105 -> 0
B16: Page 4 | F16: =F136 -> 910000
B18: Page 5 | F18: =F162 -> 245000
B20: Page 6 | F20: =F185 -> 0
B22: Page 7 | F22: =F215 -> 3000000
B24: Page 8 | F24: =F240 -> 801000
B26: Page 9 | F26: =F267 -> 650000
B28: Page 10 | F28: =F294 -> 60000
B30: Page 11 | F30: =F324 -> 282000
B32: Page 12 | F32: =F354 -> 90000
B34: Page 13 | F34: =F369 -> 25000
B36: Page 14 | F36: =F378 -> 60000
B40: PRELIMINARIES AND GENERAL ITEMS | F40: =SUM(F12:F38) -> 6123000
B41: TOTAL CARRIED TO GENERAL SUMMARY
A42: A | B42: Generally
B43: The contractor shall be deemed to have allowed against each item a rate which complies with all the requirements of the “Preliminaries”. All unpriced preliminaries items shall be deemed to have been included in the general pricing of the works. All item containing “Preliminaries” shall apply to the whole of the works The contractor shall be deemed to have allowed against each item or in his rates of complying with all the requirements of the “Preliminaries”. All item containing “Preliminaries” shall apply to the whole of the works
A45: B | B45: Names of Parties
B46: The names of parties referred to in these Bills of Quantities and in the Conditions of Contract are as follows:-
B47: ENTERPRISE LIFE COMPANY LIMITED
A49: C | B49: ALL DRAWINGS
B50: The drawings used for the preparation of the bills of quantities are scheduled at the Appendix
A52: D | B52: Format of Bills of Quantities
B53: Major portions of this Bills of Quantities have been prepared in accordance with the "Standard Method of Measurement of Building Works", Seventh (7th) Edition (metric) Revised SMM7R (metric) dated July 1998 issued by the Royal Institution of Chartered Surveyors (R.I.C.S.) and the building Employers Confederation (B.E.C.) both of the United Kingdom. However, departures from this method of measurement (see General Notes on Method of Measurement) have been effected to reduce the number of measured Labour items and also to simplify certain other measured items. The Contractor must allow for this departures in his/her pricing so that his/her tender figure shall represent the total cost of all items of works involved in the project. No claim for extra payment will be entertained on the ground that method of the measurement adopted does not comply with the said Standard Method of Measurement.
A55: E | B55: Prohibition of Use
B56: The quantities given in the Bills of Quantities are not intended for ordering of materials/components. Quantities for use in ordering materials/components must be calculated by the Contractor by measurement on site or from contract drawings.
A58: F | B58: Site Location
B59: The Site is located at: Accra in the Greater Accra Region The Contractor is to visit and examine the site and satisfy himself as to the site conditions and facilities for obtaining special materials and shall obtain generally his own information on all matters affecting the execution of the Works.
A61: G | B61: Overtime
B62: The Contractor shall be held to have made all enquiries as to the source of his labour and to have made all provisions in his tender for every cost to him of providing and maintaining the labour force necessary to complete the contract including all extra and additional works in the contract Time, including all overtime and weekend working which he considers he shall require and supervisory cost associated therewith. No extra will be allowed on the contract Sum for this Clause.
A64: H | B64: Definition of Abbreviations
B65: Abbreviations have been used in the Bills of Quantities for the units of measurement and the Contractor should take due notice of the under-mentioned:
...

Sheet SUBSTRUCTURE
A1: ='PRELIMS & GEN. ITEMS'!A1 -> PROJECT: BLOCK N REDEVELOPMENT
A2: ='PRELIMS & GEN. ITEMS'!A2 -> LOCATION: KANESHIE
A3: ='PRELIMS & GEN. ITEMS'!A3 -> CLIENT: STATE HOUSING LIMITED
A4: ='PRELIMS & GEN. ITEMS'!A4 -> DATE:9/30/2026
A5: ITEM | B5: DESCRIPTION | C5: QTY | D5: UNIT | E5: RATE | F5: AMOUNT - GHC | G5: Measurement basis / calculation
B7: MAIN BUILDING
B9: SUBSTRUCTURE (ALL PROVISIONAL)
B11: BILL SUMMARY
A13: A | B13: D GROUNDWORK (D20 EXCAVATION AND FILLING) | F13: =F43 -> 3068497.2
A15: B | B15: E IN SITU CONCRETE | F15: =F83 -> 8350767.6
A17: C | B17: BLOCK WORK | F17: =F92 -> 43043
B19: =B9 -> SUBSTRUCTURE (ALL PROVISIONAL) | E19: GHC | F19: =SUM(F13:F18) -> 11462308
B20: To Bill General Summary
B23: BILL NR. 2 - SUBSTRUCTURE
B25: D GROUNDWORK (D20 EXCAVATION AND FILLING)
B26: Site Preparation
A27: A | B27: Clear site of all vegetation, grub up their roots and dispose-off (Block N plot and Parking-22 forecourt) | C27: =TAKEOFF!$H$29 -> 2299.0095 | D27: m2 | E27: =RATES!$D$7 -> 15 | F27: =C27*E27 -> 34485.143 | G27: 40.85*38.27+35.2*20.9
A29: B | B29: Excavate oversite to remove vegetable soil average 150mm deep and deposit on site for re-use average 50m from excavation | C29: =TAKEOFF!$H$32 -> 1800 | D29: m2 | E29: =RATES!$D$8 -> 28 | F29: =C29*E29 -> 50400 | G29: (41.0+2*2.0)*(36.0+2*2.0)
A31: C | B31: Excavate raft foundation to reduce levels maximum depth 4.00m | C31: =TAKEOFF!$H$35 -> 7200 | D31: m3 | E31: =RATES!$D$9 -> 85 | F31: =C31*E31 -> 612000 | G31: (45.0*40.0)*4.0
A33: D | B33: Fill to make up levels over raft average 1000mm thick with waterproof external membrane and high strength biaxial geogrid; compacted | C33: =TAKEOFF!$H$40 -> 1445.3447 | D33: m3 | E33: =RATES!$D$10 -> 220 | F33: =C33*E33 -> 317975.84 | G33: 41.0*36.0*1.0-(69.445*0.25*1.0)-(13.294*1.0)
A35: E | B35: Fill to make up levels below raft 1700mm thick with 300mm thick compacted crushed rock layers between geogrid layers until formation level is reached | C35: =TAKEOFF!$H$43 -> 3060 | D35: m3 | E35: =RATES!$D$11 -> 480 | F35: =C35*E35 -> 1468800 | G35: (45.0*40.0)*1.7
A37: F | B37: Backfill and compact selected excavated material around foundations | C37: =TAKEOFF!$H$47 -> 745.2 | D37: m3 | E37: =RATES!$D$12 -> 60 | F37: =C37*E37 -> 44712 | G37: ((45.0*40.0)-(41.0*36.0))*(4.0-1.7)
A39: G | B39: Load up surplus excavated material and remove from site | C39: =TAKEOFF!$H$52 -> 6454.8 | D39: m3 | E39: =RATES!$D$13 -> 75 | F39: =C39*E39 -> 484110 | G39: (45.0*40.0)*4.0-((45.0*40.0)-(41.0*36.0))*(4.0-1.7)
A41: H | B41: Approved imported granular material hardcore filling to make up levels: depositing and compacting in layers 150mm maximum thickness | C41: =TAKEOFF!$H$55 -> 221.4 | D41: m3 | E41: =RATES!$D$14 -> 253 | F41: =C41*E41 -> 56014.2 | G41: 41.0*36.0*0.15
B43: =B25 -> D GROUNDWORK (D20 EXCAVATION AND FILLING) | F43: =SUM(F26:F42) -> 3068497.2
B44: Carried to Bill Summary
B47: E IN SITU CONCRETE
B49: E10 Plain in-situ concrete (1:4:8 - 38mm aggregate) as described in:
A50: A | B50: Blinding 100mm thick under raft | C50: =TAKEOFF!$H$60 -> 147.6 | D50: m3 | E50: =RATES!$D$15 -> 1650 | F50: =C50*E50 -> 243540 | G50: 41.0*36.0*0.10
A52: B | B52: 150mm thick bed | C52: =TAKEOFF!$H$63 -> 221.4 | D52: m3 | E52: =RATES!$D$16 -> 1925 | F52: =C52*E52 -> 426195 | G52: 41.0*36.0*0.15
B54: Vibrated in-situ concrete C40 as described in:
A55: C | B55: Concrete walls (raft to ground floor) | C55: =TAKEOFF!$H$69 -> 22.569625 | D55: m3 | E55: =RATES!$D$20 -> 2310 | F55: =C55*E55 -> 52135.834 | G55: (22.05+21.825+25.57)*0.25*1.3
A57: D | B57: Concrete in raft 1300mm thick | C57: =TAKEOFF!$H$72 -> 1918.8 | D57: m3 | E57: =RATES!$D$19 -> 2310 | F57: =C57*E57 -> 4432428 | G57: 41.0*36.0*1.3
A59: E | B59: Concrete in columns (raft to ground floor) | C59: =TAKEOFF!$H$83 -> 17.281875 | D59: m3 | E59: =RATES!$D$21 -> 2310 | F59: =C59*E59 -> 39921.131 | G59: 5*0.75*0.5*1.3+1*0.75*0.5*1.3+2*0.75*0.5*1.3+1*0.75*0.5*1.3+3*1.2*0.3*1.3+6*1.2*0.3*1.3+1*1.2*0.3*1.3+15*1.2*0.3*1.3+1*(2.85*0.25+0.825*0.25)*1.3
B61: E30 REINFORCEMENT - High tensile yield round bar reinforcement (standard):
A62: F | B62: 20mm diameter in raft | C62: =TAKEOFF!$H$87 -> 2.466 | D62: t | E62: =RATES!$D$32 -> 14300 | F62: =C62*E62 -> 35263.8 | G62: 2.466
A64: G | B64: 25mm diameter in raft | C64: =TAKEOFF!$H$90 -> 184.672 | D64: t | E64: =RATES!$D$33 -> 14300 | F64: =C64*E64 -> 2640809.6 | G64: 184.672
A66: H | B66: 10mm diameter links to columns & walls (raft to ground floor) | C66: =TAKEOFF!$H$95 -> 4.029 | D66: t | E66: =RATES!$D$29 -> 14300 | F66: =C66*E66 -> 57614.7 | G66: 3.252+0.517+0.260
A68: J | B68: 12mm diameter to walls (raft to ground floor) | C68: =TAKEOFF!$H$99 -> 1.253 | D68: t | E68: =RATES!$D$30 -> 14300 | F68: =C68*E68 -> 17917.9 | G68: 0.863+0.390
A70: K | B70: 25mm diameter to columns & walls (raft to ground floor) | C70: =TAKEOFF!$H$104 -> 21.306 | D70: t | E70: =RATES!$D$33 -> 14300 | F70: =C70*E70 -> 304675.8 | G70: 6.531+9.840+4.935
...

Sheet GROUND FLR 
A1: ='PRELIMS & GEN. ITEMS'!A1 -> PROJECT: BLOCK N REDEVELOPMENT
A2: ='PRELIMS & GEN. ITEMS'!A2 -> LOCATION: KANESHIE
A3: ='PRELIMS & GEN. ITEMS'!A3 -> CLIENT: STATE HOUSING LIMITED
A4: ='PRELIMS & GEN. ITEMS'!A4 -> DATE:9/30/2026
A5: ITEM | B5: DESCRIPTION | C5: QTY | D5: UNIT | E5: RATE | F5: AMOUNT - GHC | G5: Measurement basis / calculation
B7: MAIN BUILDING
B9: GROUND FLOOR (INCL. M1 PARKING LEVEL 1B)
B11: BILL SUMMARY
A13: A | B13: ELEMENT NO. 1: IN SITU CONCRETE/LARGE PRECAST CONCRETE | F13: =F92 -> 2337940.4
A15: B | B15: ELEMENT NO. 2: MASONRY | F15: =F103 -> 209940.8
A17: C | B17: ELEMENT NO. 4: WINDOWS/DOORS | F17: =F169 -> 406389.1
A19: D | B19: ELEMENT NO. 5: FLOOR FINISHES | F19: =F192 -> 311872.36
A21: E | B21: ELEMENT NO. 6: WALL FINISHES | F21: =F209 -> 157798.45
A23: F | B23: ELEMENT NO. 7: PAINTING AND DECORATING | F23: =F231 -> 140269.25
B25: =B9 -> GROUND FLOOR (INCL. M1 PARKING LEVEL 1B) | E25: GHC | F25: =SUM(F13:F24) -> 3564210.3
B26: To Bill General Summary
B29: BILL NR. 3 - GROUND FLOOR
B31: ELEMENT NO. 1: IN SITU CONCRETE/LARGE PRECAST CONCRETE
B33: Vibrated in-situ concrete C40 as described in:
A34: A | B34: Suspended slab 250mm thick | C34: =TAKEOFF!$H$143 -> 172.275 | D34: m3 | E34: =RATES!$D$22 -> 2310 | F34: =C34*E34 -> 397955.25 | G34: 689.1*0.25
A36: B | B36: Beams (downstands below slab) | C36: =TAKEOFF!$H$146 -> 7.119 | D36: m3 | E36: =RATES!$D$23 -> 2310 | F36: =C36*E36 -> 16444.89 | G36: 67.8*0.3*0.35
A38: C | B38: Columns | C38: =TAKEOFF!$H$159 -> 52.4775 | D38: m3 | E38: =RATES!$D$21 -> 2310 | F38: =C38*E38 -> 121223.02 | G38: 5*0.75*0.5*3.6+1*0.75*0.5*3.6+2*0.75*0.5*3.6+1*0.75*0.5*1.95+1*0.75*0.5*2.45+3*1.2*0.3*3.6+6*1.2*0.3*3.6+1*1.2*0.3*3.6+15*1.2*0.3*1.95+15*1.2*0.3*2.45+1*(2.85*0.25+0.825*0.25)*3.6
A40: D | B40: Concrete wall - shear walls to main & emergency stair cores, 250mm thick | C40: =TAKEOFF!$H$164 -> 49.88975 | D40: m3 | E40: =RATES!$D$20 -> 2310 | F40: =C40*E40 -> 115245.32 | G40: 22.05*3.6*0.25+25.57*2.25*0.25+25.57*2.45*0.25
A42: E | B42: Concrete wall - lift walls, 250mm thick | C42: =TAKEOFF!$H$167 -> 19.6425 | D42: m3 | E42: =RATES!$D$20 -> 2310 | F42: =C42*E42 -> 45374.175 | G42: 21.825*3.6*0.25
A44: F | B44: Stairs | C44: =TAKEOFF!$H$175 -> 16.00903 | D44: m3 | E44: =RATES!$D$24 -> 2310 | F44: =C44*E44 -> 36980.86 | G44: (2.966*3.85/3.3+2.625)+(2.966*2.5/3.3+2.625)+(2.966*2.7/3.3+2.625)
A46: G | B46: Lintels 150 x 225mm over door and window openings | C46: =TAKEOFF!$H$199 -> 3.324375 | D46: m3 | E46: =RATES!$D$25 -> 1925 | F46: =C46*E46 -> 6399.4219 | G46: (1*(1.8+0.3)+6*(0.9+0.3)+1*(0.9+0.3)+1*(3.2+0.3)+6*(0.75+0.3)+2*(0.7+0.3)+3*(1+0.3)+2*(0.9+0.3)+3*(1.8+0.3)+2*(1.8+0.3)+2*(2.4+0.3)+1*(5.05+0.3)+2*(4.2+0.3)+1*(3.6+0.3)+1*(1.8+0.3)+1*(1.8+0.3)+1*(3.5+0.3)+3*(3.6+0.3)+2*(2.4+0.3)+2*(2.1+0.3)+4*(0.9...
B48: E20 FORMWORK - Formwork as described to:
A49: H | B49: Soffits of suspended slab | C49: =TAKEOFF!$H$203 -> 689.1 | D49: m2 | E49: =RATES!$D$38 -> 165 | F49: =C49*E49 -> 113701.5 | G49: 689.1
A51: J | B51: Edges of suspended slab 250mm high | C51: =TAKEOFF!$H$206 -> 238.4 | D51: m | E51: =RATES!$D$40 -> 65 | F51: =C51*E51 -> 15496 | G51: 238.4
A53: K | B53: Sides and soffits of beams | C53: =TAKEOFF!$H$209 -> 67.8 | D53: m2 | E53: =RATES!$D$39 -> 165 | F53: =C53*E53 -> 11187 | G53: 67.8*(2*0.35+0.3)
A55: L | B55: Columns | C55: =TAKEOFF!$H$222 -> 417.26 | D55: m2 | E55: =RATES!$D$37 -> 165 | F55: =C55*E55 -> 68847.9 | G55: 5*2*(0.75+0.5)*3.6+1*2*(0.75+0.5)*3.6+2*2*(0.75+0.5)*3.6+1*2*(0.75+0.5)*1.95+1*2*(0.75+0.5)*2.45+3*2*(1.2+0.3)*3.6+6*2*(1.2+0.3)*3.6+1*2*(1.2+0.3)*3.6+15*2*(1.2+0.3)*1.95+15*2*(1.2+0.3)*2.45+1*2*(2.85+1.075)*3.6
A57: M | B57: Concrete wall (both faces) | C57: =TAKEOFF!$H$228 -> 556.258 | D57: m2 | E57: =RATES!$D$36 -> 165 | F57: =C57*E57 -> 91782.57 | G57: 2*22.05*3.6+2*21.825*3.6+2*25.57*2.25+2*25.57*2.45
A59: N | B59: Soffits of stair flights, landings and risers | C59: =TAKEOFF!$H$239 -> 99.7992 | D59: m2 | E59: =RATES!$D$42 -> 165 | F59: =C59*E59 -> 16466.868 | G59: (2*3.424*1.8+15.0+22*0.15*1.8)+(2*3.424*1.8+15.0+22*0.15*1.8)+(2*3.424*1.8+15.0+22*0.15*1.8)
A61: P | B61: Side and soffits of lintel / coping | C61: =TAKEOFF!$H$263 -> 59.1 | D61: m2 | E61: =RATES!$D$43 -> 165 | F61: =C61*E61 -> 9751.5 | G61: (1*(1.8+0.3)+6*(0.9+0.3)+1*(0.9+0.3)+1*(3.2+0.3)+6*(0.75+0.3)+2*(0.7+0.3)+3*(1+0.3)+2*(0.9+0.3)+3*(1.8+0.3)+2*(1.8+0.3)+2*(2.4+0.3)+1*(5.05+0.3)+2*(4.2+0.3)+1*(3.6+0.3)+1*(1.8+0.3)+1*(1.8+0.3)+1*(3.5+0.3)+3*(3.6+0.3)+2*(2.4+0.3)+2*(2.1+0.3)+4*(0.9...
B63: E30 REINFORCEMENT - High tensile yield round bar reinforcement (standard) to BS 4449:
A64: Q | B64: 10mm diameter in columns | C64: =TAKEOFF!$H$268 -> 6.028 | D64: t | E64: =RATES!$D$29 -> 14300 | F64: =C64*E64 -> 86200.4 | G64: 4.372+1.656
A66: R | B66: 20mm diameter in columns | C66: =TAKEOFF!$H$271 -> 0.599 | D66: t | E66: =RATES!$D$32 -> 14300 | F66: =C66*E66 -> 8565.7 | G66: 0.599
A68: S | B68: 25mm diameter in columns | C68: =TAKEOFF!$H$275 -> 14.386 | D68: t | E68: =RATES!$D$33 -> 14300 | F68: =C68*E68 -> 205719.8 | G68: 10.083+4.303
A70: T | B70: 10mm diameter in beams (links) | C70: =TAKEOFF!$H$278 -> 1.126 | D70: t | E70: =RATES!$D$29 -> 14300 | F70: =C70*E70 -> 16101.8 | G70: 1.126
A72: U | B72: 16mm diameter in beams | C72: =TAKEOFF!$H$281 -> 0.576 | D72: t | E72: =RATES!$D$31 -> 14300 | F72: =C72*E72 -> 8236.8 | G72: 0.576
...

Sheet 1ST FLR 
A1: ='PRELIMS & GEN. ITEMS'!A1 -> PROJECT: BLOCK N REDEVELOPMENT
A2: ='PRELIMS & GEN. ITEMS'!A2 -> LOCATION: KANESHIE
A3: ='PRELIMS & GEN. ITEMS'!A3 -> CLIENT: STATE HOUSING LIMITED
A4: ='PRELIMS & GEN. ITEMS'!A4 -> DATE:9/30/2026
A5: ITEM | B5: DESCRIPTION | C5: QTY | D5: UNIT | E5: RATE | F5: AMOUNT - GHC | G5: Measurement basis / calculation
B7: MAIN BUILDING
B9: FIRST FLOOR - LEVEL 2A PARKING (INCL. M2 LEVEL 2B)
B11: BILL SUMMARY
A13: A | B13: ELEMENT NO. 1: IN SITU CONCRETE/LARGE PRECAST CONCRETE | F13: =F93 -> 2886751.5
A15: B | B15: ELEMENT NO. 2: MASONRY | F15: =F104 -> 76177.553
A17: C | B17: ELEMENT NO. 4: WINDOWS/DOORS | F17: =F113 -> 21600
A19: D | B19: ELEMENT NO. 5: FLOOR FINISHES | F19: =F131 -> 227701.44
A21: E | B21: ELEMENT NO. 6: WALL FINISHES | F21: =F141 -> 63462.63
A23: F | B23: ELEMENT NO. 7: PAINTING AND DECORATING | F23: =F156 -> 53869.883
B25: =B9 -> FIRST FLOOR - LEVEL 2A PARKING (INCL. M2 LEVEL 2B) | E25: GHC | F25: =SUM(F13:F24) -> 3329563.1
B26: To Bill General Summary
B28: BILL NR. 4 - FIRST FLOOR
B30: ELEMENT NO. 1: IN SITU CONCRETE/LARGE PRECAST CONCRETE
B32: Vibrated in-situ concrete C40 as described in:
A33: A | B33: Suspended slab 250mm thick | C33: =TAKEOFF!$H$658 -> 347.05 | D33: m3 | E33: =RATES!$D$22 -> 2310 | F33: =C33*E33 -> 801685.5 | G33: 737.6*0.25+650.6*0.25
A35: B | B35: Beams (downstands below slab) | C35: =TAKEOFF!$H$663 -> 18.2385 | D35: m3 | E35: =RATES!$D$23 -> 2310 | F35: =C35*E35 -> 42130.935 | G35: 81.1*0.3*0.35+43.5*0.2*0.35+63.6*0.3*0.35
A37: C | B37: Columns | C37: =TAKEOFF!$H$674 -> 32.569688 | D37: m3 | E37: =RATES!$D$21 -> 2310 | F37: =C37*E37 -> 75235.978 | G37: 5*0.75*0.5*2.45+1*0.75*0.5*2.45+2*0.75*0.5*2.45+1*0.75*0.5*2.45+3*1.2*0.3*2.45+6*1.2*0.3*2.45+1*1.2*0.3*2.45+15*1.2*0.3*2.45+1*(2.85*0.25+0.825*0.25)*2.45
A39: D | B39: Concrete wall - shear walls to main & emergency stair cores, 250mm thick | C39: =TAKEOFF!$H$678 -> 29.16725 | D39: m3 | E39: =RATES!$D$20 -> 2310 | F39: =C39*E39 -> 67376.348 | G39: 22.05*2.45*0.25+25.57*2.45*0.25
A41: E | B41: Concrete wall - lift walls, 250mm thick | C41: =TAKEOFF!$H$681 -> 13.367813 | D41: m3 | E41: =RATES!$D$20 -> 2310 | F41: =C41*E41 -> 30879.647 | G41: 21.825*2.45*0.25
A43: F | B43: Stairs | C43: =TAKEOFF!$H$687 -> 10.103455 | D43: m3 | E43: =RATES!$D$24 -> 2310 | F43: =C43*E43 -> 23338.98 | G43: (2.966*2.7/3.3+2.625)+(2.966*2.7/3.3+2.625)
A45: G | B45: Lintels 150 x 225mm over door and window openings | C45: =TAKEOFF!$H$690 -> 0.131625 | D45: m3 | E45: =RATES!$D$25 -> 1925 | F45: =C45*E45 -> 253.37813 | G45: (3*(1+0.3))*0.15*0.225
B47: E20 FORMWORK - Formwork as described to:
A48: H | B48: Soffits of suspended slab | C48: =TAKEOFF!$H$695 -> 1388.2 | D48: m2 | E48: =RATES!$D$38 -> 165 | F48: =C48*E48 -> 229053 | G48: 737.6+650.6
A50: J | B50: Edges of suspended slab 250mm high | C50: =TAKEOFF!$H$699 -> 410.8 | D50: m | E50: =RATES!$D$40 -> 65 | F50: =C50*E50 -> 26702 | G50: 185.9+224.9
A52: K | B52: Sides and soffits of beams | C52: =TAKEOFF!$H$704 -> 183.85 | D52: m2 | E52: =RATES!$D$39 -> 165 | F52: =C52*E52 -> 30335.25 | G52: 81.1*(2*0.35+0.3)+43.5*(2*0.35+0.2)+63.6*(2*0.35+0.3)
A54: L | B54: Columns | C54: =TAKEOFF!$H$715 -> 258.1075 | D54: m2 | E54: =RATES!$D$37 -> 165 | F54: =C54*E54 -> 42587.738 | G54: 5*2*(0.75+0.5)*2.45+1*2*(0.75+0.5)*2.45+2*2*(0.75+0.5)*2.45+1*2*(0.75+0.5)*2.45+3*2*(1.2+0.3)*2.45+6*2*(1.2+0.3)*2.45+1*2*(1.2+0.3)*2.45+15*2*(1.2+0.3)*2.45+1*2*(2.85+1.075)*2.45
A56: M | B56: Concrete wall (both faces) | C56: =TAKEOFF!$H$720 -> 340.2805 | D56: m2 | E56: =RATES!$D$36 -> 165 | F56: =C56*E56 -> 56146.283 | G56: 2*22.05*2.45+2*21.825*2.45+2*25.57*2.45
A58: N | B58: Soffits of stair flights, landings and risers | C58: =TAKEOFF!$H$728 -> 66.5328 | D58: m2 | E58: =RATES!$D$42 -> 165 | F58: =C58*E58 -> 10977.912 | G58: (2*3.424*1.8+15.0+22*0.15*1.8)+(2*3.424*1.8+15.0+22*0.15*1.8)
A60: P | B60: Side and soffits of lintel / coping | C60: =TAKEOFF!$H$731 -> 2.34 | D60: m2 | E60: =RATES!$D$43 -> 165 | F60: =C60*E60 -> 386.1 | G60: (3*(1+0.3))*(2*0.225+0.15)
B64: E30 REINFORCEMENT - High tensile yield round bar reinforcement (standard) to BS 4449:
A65: Q | B65: 10mm diameter in columns | C65: =TAKEOFF!$H$736 -> 4.373 | D65: t | E65: =RATES!$D$29 -> 14300 | F65: =C65*E65 -> 62533.9 | G65: 2.717+1.656
A67: R | B67: 20mm diameter in columns | C67: =TAKEOFF!$H$740 -> 0.616 | D67: t | E67: =RATES!$D$32 -> 14300 | F67: =C67*E67 -> 8808.8 | G67: 0.462+0.154
A69: S | B69: 25mm diameter in columns | C69: =TAKEOFF!$H$744 -> 8.696 | D69: t | E69: =RATES!$D$33 -> 14300 | F69: =C69*E69 -> 124352.8 | G69: 4.634+4.062
A71: T | B71: 10mm diameter in beams (links) | C71: =TAKEOFF!$H$748 -> 1.621 | D71: t | E71: =RATES!$D$29 -> 14300 | F71: =C71*E71 -> 23180.3 | G71: 0.977+0.644
A73: U | B73: 16mm diameter in beams | C73: =TAKEOFF!$H$752 -> 1.223 | D73: t | E73: =RATES!$D$31 -> 14300 | F73: =C73*E73 -> 17488.9 | G73: 0.763+0.460
...

Sheet 2ND FLR
A1: ='PRELIMS & GEN. ITEMS'!A1 -> PROJECT: BLOCK N REDEVELOPMENT
A2: ='PRELIMS & GEN. ITEMS'!A2 -> LOCATION: KANESHIE
A3: ='PRELIMS & GEN. ITEMS'!A3 -> CLIENT: STATE HOUSING LIMITED
A4: ='PRELIMS & GEN. ITEMS'!A4 -> DATE:9/30/2026
A5: ITEM | B5: DESCRIPTION | C5: QTY | D5: UNIT | E5: RATE | F5: AMOUNT - GHC | G5: Measurement basis / calculation
B7: MAIN BUILDING
B9: SECOND FLOOR - LEVEL 3A PARKING (INCL. MEZZANINE LEVEL 3B)
B11: BILL SUMMARY
A13: A | B13: ELEMENT NO. 1: IN SITU CONCRETE/LARGE PRECAST CONCRETE | F13: =F91 -> 3157591.3
A15: B | B15: ELEMENT NO. 2: MASONRY | F15: =F102 -> 175769.91
A17: C | B17: ELEMENT NO. 4: WINDOWS/DOORS | F17: =F111 -> 43200
A19: D | B19: ELEMENT NO. 5: FLOOR FINISHES | F19: =F130 -> 370064.94
A21: E | B21: ELEMENT NO. 6: WALL FINISHES | F21: =F141 -> 158847.63
A23: F | B23: ELEMENT NO. 7: PAINTING AND DECORATING | F23: =F156 -> 117441.9
B25: =B9 -> SECOND FLOOR - LEVEL 3A PARKING (INCL. MEZZANINE LEVEL 3B) | E25: GHC | F25: =SUM(F13:F24) -> 4022915.7
B26: To Bill General Summary
B28: BILL NR. 5 - SECOND FLOOR
B30: ELEMENT NO. 1: IN SITU CONCRETE/LARGE PRECAST CONCRETE
B32: Vibrated in-situ concrete C40 as described in:
A33: A | B33: Suspended slab 250mm thick | C33: =TAKEOFF!$H$894 -> 323.1 | D33: m3 | E33: =RATES!$D$22 -> 2310 | F33: =C33*E33 -> 746361 | G33: 737.5*0.25+554.9*0.25
A35: B | B35: Beams (downstands below slab) | C35: =TAKEOFF!$H$899 -> 18.151 | D35: m3 | E35: =RATES!$D$23 -> 2310 | F35: =C35*E35 -> 41928.81 | G35: 79.9*0.3*0.35+43*0.2*0.35+64.3*0.3*0.35
A37: C | B37: Columns | C37: =TAKEOFF!$H$910 -> 44.4525 | D37: m3 | E37: =RATES!$D$21 -> 2310 | F37: =C37*E37 -> 102685.27 | G37: 5*0.75*0.5*3.8+1*0.75*0.5*3.8+2*0.75*0.5*3.8+1*0.75*0.5*2.75+3*1.2*0.3*3.8+6*1.2*0.3*3.8+1*1.2*0.3*3.8+15*1.2*0.3*2.75+1*(2.85*0.25+0.825*0.25)*3.8
A39: D | B39: Concrete wall - shear walls to main & emergency stair cores, 250mm thick | C39: =TAKEOFF!$H$914 -> 38.526875 | D39: m3 | E39: =RATES!$D$20 -> 2310 | F39: =C39*E39 -> 88997.081 | G39: 22.05*3.8*0.25+25.57*2.75*0.25
A41: E | B41: Concrete wall - lift walls, 250mm thick | C41: =TAKEOFF!$H$917 -> 20.73375 | D41: m3 | E41: =RATES!$D$20 -> 2310 | F41: =C41*E41 -> 47894.962 | G41: 21.825*3.8*0.25
A43: F | B43: Stairs | C43: =TAKEOFF!$H$923 -> 11.586455 | D43: m3 | E43: =RATES!$D$24 -> 2310 | F43: =C43*E43 -> 26764.71 | G43: (2.966*4.05/3.3+2.625)+(2.966*3/3.3+2.625)
A45: G | B45: Lintels 150 x 225mm over door and window openings | C45: =TAKEOFF!$H$927 -> 0.26325 | D45: m3 | E45: =RATES!$D$25 -> 1925 | F45: =C45*E45 -> 506.75625 | G45: (3*(1+0.3))*0.15*0.225+(3*(1+0.3))*0.15*0.225
B47: E20 FORMWORK - Formwork as described to:
A48: H | B48: Soffits of suspended slab | C48: =TAKEOFF!$H$932 -> 1292.4 | D48: m2 | E48: =RATES!$D$38 -> 165 | F48: =C48*E48 -> 213246 | G48: 737.5+554.9
A50: J | B50: Edges of suspended slab 250mm high | C50: =TAKEOFF!$H$936 -> 402.9 | D50: m | E50: =RATES!$D$40 -> 65 | F50: =C50*E50 -> 26188.5 | G50: 186.5+216.4
A52: K | B52: Sides and soffits of beams | C52: =TAKEOFF!$H$941 -> 182.9 | D52: m2 | E52: =RATES!$D$39 -> 165 | F52: =C52*E52 -> 30178.5 | G52: 79.9*(2*0.35+0.3)+43*(2*0.35+0.2)+64.3*(2*0.35+0.3)
A54: L | B54: Columns | C54: =TAKEOFF!$H$952 -> 350.455 | D54: m2 | E54: =RATES!$D$37 -> 165 | F54: =C54*E54 -> 57825.075 | G54: 5*2*(0.75+0.5)*3.8+1*2*(0.75+0.5)*3.8+2*2*(0.75+0.5)*3.8+1*2*(0.75+0.5)*2.75+3*2*(1.2+0.3)*3.8+6*2*(1.2+0.3)*3.8+1*2*(1.2+0.3)*3.8+15*2*(1.2+0.3)*2.75+1*2*(2.85+1.075)*3.8
A56: M | B56: Concrete wall (both faces) | C56: =TAKEOFF!$H$957 -> 474.085 | D56: m2 | E56: =RATES!$D$36 -> 165 | F56: =C56*E56 -> 78224.025 | G56: 2*22.05*3.8+2*21.825*3.8+2*25.57*2.75
A58: N | B58: Soffits of stair flights, landings and risers | C58: =TAKEOFF!$H$965 -> 66.5328 | D58: m2 | E58: =RATES!$D$42 -> 165 | F58: =C58*E58 -> 10977.912 | G58: (2*3.424*1.8+15.0+22*0.15*1.8)+(2*3.424*1.8+15.0+22*0.15*1.8)
A60: P | B60: Side and soffits of lintel / coping | C60: =TAKEOFF!$H$969 -> 4.68 | D60: m2 | E60: =RATES!$D$43 -> 165 | F60: =C60*E60 -> 772.2 | G60: (3*(1+0.3))*(2*0.225+0.15)+(3*(1+0.3))*(2*0.225+0.15)
B62: E30 REINFORCEMENT - High tensile yield round bar reinforcement (standard) to BS 4449:
A63: Q | B63: 10mm diameter in columns | C63: =TAKEOFF!$H$974 -> 4.895 | D63: t | E63: =RATES!$D$29 -> 14300 | F63: =C63*E63 -> 69998.5 | G63: 3.239+1.656
A65: R | B65: 20mm diameter in columns | C65: =TAKEOFF!$H$978 -> 3.788 | D65: t | E65: =RATES!$D$32 -> 14300 | F65: =C65*E65 -> 54168.4 | G65: 0.622+3.166
A67: S | B67: 25mm diameter in columns | C67: =TAKEOFF!$H$981 -> 6.238 | D67: t | E67: =RATES!$D$33 -> 14300 | F67: =C67*E67 -> 89203.4 | G67: 6.238
A69: T | B69: 10mm diameter in beams (links) | C69: =TAKEOFF!$H$985 -> 1.481 | D69: t | E69: =RATES!$D$29 -> 14300 | F69: =C69*E69 -> 21178.3 | G69: 0.902+0.579
A71: U | B71: 16mm diameter in beams | C71: =TAKEOFF!$H$989 -> 1.146 | D71: t | E71: =RATES!$D$31 -> 14300 | F71: =C71*E71 -> 16387.8 | G71: 0.740+0.406
...

Sheet 3RD FLR
A1: ='PRELIMS & GEN. ITEMS'!A1 -> PROJECT: BLOCK N REDEVELOPMENT
A2: ='PRELIMS & GEN. ITEMS'!A2 -> LOCATION: KANESHIE
A3: ='PRELIMS & GEN. ITEMS'!A3 -> CLIENT: STATE HOUSING LIMITED
A4: ='PRELIMS & GEN. ITEMS'!A4 -> DATE:9/30/2026
A5: ITEM | B5: DESCRIPTION | C5: QTY | D5: UNIT | E5: RATE | F5: AMOUNT - GHC | G5: Measurement basis / calculation
B7: MAIN BUILDING
B9: THIRD FLOOR
B11: BILL SUMMARY
A13: A | B13: ELEMENT NO. 1: IN SITU CONCRETE/LARGE PRECAST CONCRETE | F13: =F90 -> 2839785
A15: B | B15: ELEMENT NO. 2: MASONRY | F15: =F101 -> 420081.85
A17: C | B17: ELEMENT NO. 4: WINDOWS/DOORS | F17: =F190 -> 691235.75
A19: D | B19: ELEMENT NO. 5: FLOOR FINISHES | F19: =F210 -> 385700.14
A21: E | B21: ELEMENT NO. 6: WALL FINISHES | F21: =F226 -> 315809.63
A23: F | B23: ELEMENT NO. 7: PAINTING AND DECORATING | F23: =F245 -> 193492.32
B25: =B9 -> THIRD FLOOR | E25: GHC | F25: =SUM(F13:F24) -> 4846104.7
B26: To Bill General Summary
B29: BILL NR. 6 - THIRD FLOOR
B31: ELEMENT NO. 1: IN SITU CONCRETE/LARGE PRECAST CONCRETE
B33: Vibrated in-situ concrete C40 as described in:
A34: A | B34: Suspended slab 250mm thick | C34: =TAKEOFF!$H$1155 -> 318.475 | D34: m3 | E34: =RATES!$D$22 -> 2310 | F34: =C34*E34 -> 735677.25 | G34: 1273.9*0.25
A36: B | B36: Beams (downstands below slab) | C36: =TAKEOFF!$H$1159 -> 12.544 | D36: m3 | E36: =RATES!$D$23 -> 2310 | F36: =C36*E36 -> 28976.64 | G36: 97.4*0.3*0.35+33.1*0.2*0.35
A38: C | B38: Columns | C38: =TAKEOFF!$H$1170 -> 40.545937 | D38: m3 | E38: =RATES!$D$21 -> 2310 | F38: =C38*E38 -> 93661.116 | G38: 5*0.75*0.5*3.05+1*0.75*0.5*3.05+2*0.75*0.5*3.05+1*0.75*0.5*3.05+3*1.2*0.3*3.05+6*1.2*0.3*3.05+1*1.2*0.3*3.05+15*1.2*0.3*3.05+1*(2.85*0.25+0.825*0.25)*3.05
A40: D | B40: Concrete wall - shear walls to main & emergency stair cores, 250mm thick | C40: =TAKEOFF!$H$1174 -> 36.31025 | D40: m3 | E40: =RATES!$D$20 -> 2310 | F40: =C40*E40 -> 83876.677 | G40: 22.05*3.05*0.25+25.57*3.05*0.25
A42: E | B42: Concrete wall - lift walls, 250mm thick | C42: =TAKEOFF!$H$1177 -> 16.641562 | D42: m3 | E42: =RATES!$D$20 -> 2310 | F42: =C42*E42 -> 38442.009 | G42: 21.825*3.05*0.25
A44: F | B44: Stairs | C44: =TAKEOFF!$H$1183 -> 11.182 | D44: m3 | E44: =RATES!$D$24 -> 2310 | F44: =C44*E44 -> 25830.42 | G44: (2.966*3.3/3.3+2.625)+(2.966*3.3/3.3+2.625)
A46: G | B46: Lintels 150 x 225mm over door and window openings | C46: =TAKEOFF!$H$1220 -> 7.90425 | D46: m3 | E46: =RATES!$D$25 -> 1925 | F46: =C46*E46 -> 15215.681 | G46: (10*(1+0.3)+19*(0.9+0.3)+21*(0.75+0.3)+2*(0.7+0.3)+3*(1.2+0.3)+3*(1+0.3)+3*(1+0.3)+2*(0.9+0.3)+1*(1.5+0.3)+3*(0.9+0.3)+5*(0.75+0.3)+1*(0.45+0.3)+3*(0.6+0.3)+1*(3+0.3)+4*(1.6+0.3)+3*(1.3+0.3)+5*(1.8+0.3)+1*(1.2+0.3)+7*(1.8+0.3)+13*(0.9+0.3)+2*(1.8+...
B48: E20 FORMWORK - Formwork as described to:
A49: H | B49: Soffits of suspended slab | C49: =TAKEOFF!$H$1224 -> 1273.9 | D49: m2 | E49: =RATES!$D$38 -> 165 | F49: =C49*E49 -> 210193.5 | G49: 1273.9
A51: J | B51: Edges of suspended slab 250mm high | C51: =TAKEOFF!$H$1227 -> 232.4 | D51: m | E51: =RATES!$D$40 -> 65 | F51: =C51*E51 -> 15106 | G51: 232.4
A53: K | B53: Sides and soffits of beams | C53: =TAKEOFF!$H$1231 -> 127.19 | D53: m2 | E53: =RATES!$D$39 -> 165 | F53: =C53*E53 -> 20986.35 | G53: 97.4*(2*0.35+0.3)+33.1*(2*0.35+0.2)
A55: L | B55: Columns | C55: =TAKEOFF!$H$1242 -> 321.3175 | D55: m2 | E55: =RATES!$D$37 -> 165 | F55: =C55*E55 -> 53017.387 | G55: 5*2*(0.75+0.5)*3.05+1*2*(0.75+0.5)*3.05+2*2*(0.75+0.5)*3.05+1*2*(0.75+0.5)*3.05+3*2*(1.2+0.3)*3.05+6*2*(1.2+0.3)*3.05+1*2*(1.2+0.3)*3.05+15*2*(1.2+0.3)*3.05+1*2*(2.85+1.075)*3.05
A57: M | B57: Concrete wall (both faces) | C57: =TAKEOFF!$H$1247 -> 423.6145 | D57: m2 | E57: =RATES!$D$36 -> 165 | F57: =C57*E57 -> 69896.393 | G57: 2*22.05*3.05+2*21.825*3.05+2*25.57*3.05
A59: N | B59: Soffits of stair flights, landings and risers | C59: =TAKEOFF!$H$1255 -> 66.5328 | D59: m2 | E59: =RATES!$D$42 -> 165 | F59: =C59*E59 -> 10977.912 | G59: (2*3.424*1.8+15.0+22*0.15*1.8)+(2*3.424*1.8+15.0+22*0.15*1.8)
A61: P | B61: Side and soffits of lintel / coping | C61: =TAKEOFF!$H$1292 -> 140.52 | D61: m2 | E61: =RATES!$D$43 -> 165 | F61: =C61*E61 -> 23185.8 | G61: (10*(1+0.3)+19*(0.9+0.3)+21*(0.75+0.3)+2*(0.7+0.3)+3*(1.2+0.3)+3*(1+0.3)+3*(1+0.3)+2*(0.9+0.3)+1*(1.5+0.3)+3*(0.9+0.3)+5*(0.75+0.3)+1*(0.45+0.3)+3*(0.6+0.3)+1*(3+0.3)+4*(1.6+0.3)+3*(1.3+0.3)+5*(1.8+0.3)+1*(1.2+0.3)+7*(1.8+0.3)+13*(0.9+0.3)+2*(1.8+...
B63: E30 REINFORCEMENT - High tensile yield round bar reinforcement (standard) to BS 4449:
A64: Q | B64: 10mm diameter in columns | C64: =TAKEOFF!$H$1296 -> 4.551 | D64: t | E64: =RATES!$D$29 -> 14300 | F64: =C64*E64 -> 65079.3 | G64: 4.551
A66: R | B66: 20mm diameter in columns | C66: =TAKEOFF!$H$1299 -> 7.133 | D66: t | E66: =RATES!$D$32 -> 14300 | F66: =C66*E66 -> 102001.9 | G66: 7.133
A68: S | B68: 10mm diameter in beams (links) | C68: =TAKEOFF!$H$1302 -> 1.164 | D68: t | E68: =RATES!$D$29 -> 14300 | F68: =C68*E68 -> 16645.2 | G68: 1.164
A70: T | B70: 16mm diameter in beams | C70: =TAKEOFF!$H$1305 -> 1.003 | D70: t | E70: =RATES!$D$31 -> 14300 | F70: =C70*E70 -> 14342.9 | G70: 1.003
A72: U | B72: 20mm diameter in beams | C72: =TAKEOFF!$H$1308 -> 2.162 | D72: t | E72: =RATES!$D$32 -> 14300 | F72: =C72*E72 -> 30916.6 | G72: 2.162
...

Sheet 4TH FLR 
A1: ='PRELIMS & GEN. ITEMS'!A1 -> PROJECT: BLOCK N REDEVELOPMENT
A2: ='PRELIMS & GEN. ITEMS'!A2 -> LOCATION: KANESHIE
A3: ='PRELIMS & GEN. ITEMS'!A3 -> CLIENT: STATE HOUSING LIMITED
A4: ='PRELIMS & GEN. ITEMS'!A4 -> DATE:9/30/2026
A5: ITEM | B5: DESCRIPTION | C5: QTY | D5: UNIT | E5: RATE | F5: AMOUNT - GHC | G5: Measurement basis / calculation
B7: MAIN BUILDING
B9: FOURTH FLOOR
B11: BILL SUMMARY
A13: A | B13: ELEMENT NO. 1: IN SITU CONCRETE/LARGE PRECAST CONCRETE | F13: =F92 -> 2663932.8
A15: B | B15: ELEMENT NO. 2: MASONRY | F15: =F103 -> 385904.19
A17: C | B17: ELEMENT NO. 4: WINDOWS/DOORS | F17: =F193 -> 613374.5
A19: D | B19: ELEMENT NO. 5: FLOOR FINISHES | F19: =F213 -> 344765.54
A21: E | B21: ELEMENT NO. 6: WALL FINISHES | F21: =F229 -> 304843.68
A23: F | B23: ELEMENT NO. 7: PAINTING AND DECORATING | F23: =F249 -> 180310.77
B25: =B9 -> FOURTH FLOOR | E25: GHC | F25: =SUM(F13:F24) -> 4493131.5
B26: To Bill General Summary
B29: BILL NR. 7 - FOURTH FLOOR
B31: ELEMENT NO. 1: IN SITU CONCRETE/LARGE PRECAST CONCRETE
B33: Vibrated in-situ concrete C40 as described in:
A34: A | B34: Suspended slab 250mm thick | C34: =TAKEOFF!$H$1766 -> 283.65 | D34: m3 | E34: =RATES!$D$22 -> 2310 | F34: =C34*E34 -> 655231.5 | G34: 1134.6*0.25
A36: B | B36: Beams (downstands below slab) | C36: =TAKEOFF!$H$1770 -> 19.831 | D36: m3 | E36: =RATES!$D$23 -> 2310 | F36: =C36*E36 -> 45809.61 | G36: 166.8*0.3*0.35+33.1*0.2*0.35
A38: C | B38: Columns | C38: =TAKEOFF!$H$1781 -> 40.545937 | D38: m3 | E38: =RATES!$D$21 -> 2310 | F38: =C38*E38 -> 93661.116 | G38: 5*0.75*0.5*3.05+1*0.75*0.5*3.05+2*0.75*0.5*3.05+1*0.75*0.5*3.05+3*1.2*0.3*3.05+6*1.2*0.3*3.05+1*1.2*0.3*3.05+15*1.2*0.3*3.05+1*(2.85*0.25+0.825*0.25)*3.05
A40: D | B40: Concrete wall - shear walls to main & emergency stair cores, 250mm thick | C40: =TAKEOFF!$H$1785 -> 36.31025 | D40: m3 | E40: =RATES!$D$20 -> 2310 | F40: =C40*E40 -> 83876.677 | G40: 22.05*3.05*0.25+25.57*3.05*0.25
A42: E | B42: Concrete wall - lift walls, 250mm thick | C42: =TAKEOFF!$H$1788 -> 16.641562 | D42: m3 | E42: =RATES!$D$20 -> 2310 | F42: =C42*E42 -> 38442.009 | G42: 21.825*3.05*0.25
A44: F | B44: Stairs | C44: =TAKEOFF!$H$1794 -> 11.182 | D44: m3 | E44: =RATES!$D$24 -> 2310 | F44: =C44*E44 -> 25830.42 | G44: (2.966*3.3/3.3+2.625)+(2.966*3.3/3.3+2.625)
A46: G | B46: Lintels 150 x 225mm over door and window openings | C46: =TAKEOFF!$H$1831 -> 7.1769375 | D46: m3 | E46: =RATES!$D$25 -> 1925 | F46: =C46*E46 -> 13815.605 | G46: (8*(1+0.3)+15*(0.9+0.3)+22*(0.75+0.3)+1*(0.7+0.3)+3*(1.2+0.3)+3*(1+0.3)+3*(1+0.3)+2*(0.9+0.3)+1*(1.5+0.3)+3*(0.9+0.3)+5*(0.75+0.3)+1*(0.45+0.3)+3*(0.6+0.3)+1*(3+0.3)+4*(1.6+0.3)+2*(1.3+0.3)+4*(1.8+0.3)+1*(1.2+0.3)+6*(1.8+0.3)+10*(0.9+0.3)+2*(1.8+0...
B48: E20 FORMWORK - Formwork as described to:
A49: H | B49: Soffits of suspended slab | C49: =TAKEOFF!$H$1835 -> 1134.6 | D49: m2 | E49: =RATES!$D$38 -> 165 | F49: =C49*E49 -> 187209 | G49: 1134.6
A51: J | B51: Edges of suspended slab 250mm high | C51: =TAKEOFF!$H$1838 -> 294.6 | D51: m | E51: =RATES!$D$40 -> 65 | F51: =C51*E51 -> 19149 | G51: 294.6
A53: K | B53: Sides and soffits of beams | C53: =TAKEOFF!$H$1842 -> 196.59 | D53: m2 | E53: =RATES!$D$39 -> 165 | F53: =C53*E53 -> 32437.35 | G53: 166.8*(2*0.35+0.3)+33.1*(2*0.35+0.2)
A55: L | B55: Columns | C55: =TAKEOFF!$H$1853 -> 321.3175 | D55: m2 | E55: =RATES!$D$37 -> 165 | F55: =C55*E55 -> 53017.387 | G55: 5*2*(0.75+0.5)*3.05+1*2*(0.75+0.5)*3.05+2*2*(0.75+0.5)*3.05+1*2*(0.75+0.5)*3.05+3*2*(1.2+0.3)*3.05+6*2*(1.2+0.3)*3.05+1*2*(1.2+0.3)*3.05+15*2*(1.2+0.3)*3.05+1*2*(2.85+1.075)*3.05
A57: M | B57: Concrete wall (both faces) | C57: =TAKEOFF!$H$1858 -> 423.6145 | D57: m2 | E57: =RATES!$D$36 -> 165 | F57: =C57*E57 -> 69896.393 | G57: 2*22.05*3.05+2*21.825*3.05+2*25.57*3.05
A59: N | B59: Soffits of stair flights, landings and risers | C59: =TAKEOFF!$H$1866 -> 66.5328 | D59: m2 | E59: =RATES!$D$42 -> 165 | F59: =C59*E59 -> 10977.912 | G59: (2*3.424*1.8+15.0+22*0.15*1.8)+(2*3.424*1.8+15.0+22*0.15*1.8)
A61: P | B61: Side and soffits of lintel / coping | C61: =TAKEOFF!$H$1903 -> 127.59 | D61: m2 | E61: =RATES!$D$43 -> 165 | F61: =C61*E61 -> 21052.35 | G61: (8*(1+0.3)+15*(0.9+0.3)+22*(0.75+0.3)+1*(0.7+0.3)+3*(1.2+0.3)+3*(1+0.3)+3*(1+0.3)+2*(0.9+0.3)+1*(1.5+0.3)+3*(0.9+0.3)+5*(0.75+0.3)+1*(0.45+0.3)+3*(0.6+0.3)+1*(3+0.3)+4*(1.6+0.3)+2*(1.3+0.3)+4*(1.8+0.3)+1*(1.2+0.3)+6*(1.8+0.3)+10*(0.9+0.3)+2*(1.8+0...
B63: E30 REINFORCEMENT - High tensile yield round bar reinforcement (standard) to BS 4449:
A64: Q | B64: 10mm diameter in columns | C64: =TAKEOFF!$H$1907 -> 4.551 | D64: t | E64: =RATES!$D$29 -> 14300 | F64: =C64*E64 -> 65079.3 | G64: 4.551
A66: R | B66: 20mm diameter in columns | C66: =TAKEOFF!$H$1910 -> 7.133 | D66: t | E66: =RATES!$D$32 -> 14300 | F66: =C66*E66 -> 102001.9 | G66: 7.133
A68: S | B68: 10mm diameter in beams (links) | C68: =TAKEOFF!$H$1913 -> 1.806 | D68: t | E68: =RATES!$D$29 -> 14300 | F68: =C68*E68 -> 25825.8 | G68: 1.806
A70: T | B70: 16mm diameter in beams | C70: =TAKEOFF!$H$1916 -> 1.248 | D70: t | E70: =RATES!$D$31 -> 14300 | F70: =C70*E70 -> 17846.4 | G70: 1.248
A72: U | B72: 20mm diameter in beams | C72: =TAKEOFF!$H$1919 -> 2.135 | D72: t | E72: =RATES!$D$32 -> 14300 | F72: =C72*E72 -> 30530.5 | G72: 2.135
...

Sheet 5TH FLR 
A1: ='PRELIMS & GEN. ITEMS'!A1 -> PROJECT: BLOCK N REDEVELOPMENT
A2: ='PRELIMS & GEN. ITEMS'!A2 -> LOCATION: KANESHIE
A3: ='PRELIMS & GEN. ITEMS'!A3 -> CLIENT: STATE HOUSING LIMITED
A4: ='PRELIMS & GEN. ITEMS'!A4 -> DATE:9/30/2026
A5: ITEM | B5: DESCRIPTION | C5: QTY | D5: UNIT | E5: RATE | F5: AMOUNT - GHC | G5: Measurement basis / calculation
B7: MAIN BUILDING
B9: FIFTH FLOOR
B11: BILL SUMMARY
A13: A | B13: ELEMENT NO. 1: IN SITU CONCRETE/LARGE PRECAST CONCRETE | F13: =F90 -> 2630642.9
A15: B | B15: ELEMENT NO. 2: MASONRY | F15: =F101 -> 378588.89
A17: C | B17: ELEMENT NO. 4: WINDOWS/DOORS | F17: =F193 -> 566821.1
A19: D | B19: ELEMENT NO. 5: FLOOR FINISHES | F19: =F213 -> 341125.34
A21: E | B21: ELEMENT NO. 6: WALL FINISHES | F21: =F230 -> 309236.25
A23: F | B23: ELEMENT NO. 7: PAINTING AND DECORATING | F23: =F251 -> 187552.29
B25: =B9 -> FIFTH FLOOR | E25: GHC | F25: =SUM(F13:F24) -> 4413966.8
B26: To Bill General Summary
B29: BILL NR. 8 - FIFTH FLOOR
B31: ELEMENT NO. 1: IN SITU CONCRETE/LARGE PRECAST CONCRETE
B33: Vibrated in-situ concrete C40 as described in:
A34: A | B34: Suspended slab 250mm thick | C34: =TAKEOFF!$H$2379 -> 283.65 | D34: m3 | E34: =RATES!$D$22 -> 2310 | F34: =C34*E34 -> 655231.5 | G34: 1134.6*0.25
A36: B | B36: Beams (downstands below slab) | C36: =TAKEOFF!$H$2383 -> 19.831 | D36: m3 | E36: =RATES!$D$23 -> 2310 | F36: =C36*E36 -> 45809.61 | G36: 166.8*0.3*0.35+33.1*0.2*0.35
A38: C | B38: Columns | C38: =TAKEOFF!$H$2394 -> 40.545937 | D38: m3 | E38: =RATES!$D$21 -> 2310 | F38: =C38*E38 -> 93661.116 | G38: 5*0.75*0.5*3.05+1*0.75*0.5*3.05+2*0.75*0.5*3.05+1*0.75*0.5*3.05+3*1.2*0.3*3.05+6*1.2*0.3*3.05+1*1.2*0.3*3.05+15*1.2*0.3*3.05+1*(2.85*0.25+0.825*0.25)*3.05
A40: D | B40: Concrete wall - shear walls to main & emergency stair cores, 250mm thick | C40: =TAKEOFF!$H$2398 -> 36.31025 | D40: m3 | E40: =RATES!$D$20 -> 2310 | F40: =C40*E40 -> 83876.677 | G40: 22.05*3.05*0.25+25.57*3.05*0.25
A42: E | B42: Concrete wall - lift walls, 250mm thick | C42: =TAKEOFF!$H$2401 -> 16.641562 | D42: m3 | E42: =RATES!$D$20 -> 2310 | F42: =C42*E42 -> 38442.009 | G42: 21.825*3.05*0.25
A44: F | B44: Stairs | C44: =TAKEOFF!$H$2407 -> 11.182 | D44: m3 | E44: =RATES!$D$24 -> 2310 | F44: =C44*E44 -> 25830.42 | G44: (2.966*3.3/3.3+2.625)+(2.966*3.3/3.3+2.625)
A46: G | B46: Lintels 150 x 225mm over door and window openings | C46: =TAKEOFF!$H$2444 -> 6.56775 | D46: m3 | E46: =RATES!$D$25 -> 1925 | F46: =C46*E46 -> 12642.919 | G46: (7*(1+0.3)+15*(0.9+0.3)+20*(0.75+0.3)+1*(0.7+0.3)+3*(1.2+0.3)+3*(1+0.3)+3*(1+0.3)+1*(0.9+0.3)+1*(1.5+0.3)+2*(0.9+0.3)+5*(0.75+0.3)+1*(0.45+0.3)+3*(0.6+0.3)+1*(3+0.3)+3*(1.6+0.3)+2*(1.3+0.3)+4*(1.8+0.3)+1*(1.2+0.3)+6*(1.8+0.3)+10*(0.9+0.3)+1*(1.8+0...
B48: E20 FORMWORK - Formwork as described to:
A49: H | B49: Soffits of suspended slab | C49: =TAKEOFF!$H$2448 -> 1134.6 | D49: m2 | E49: =RATES!$D$38 -> 165 | F49: =C49*E49 -> 187209 | G49: 1134.6
A51: J | B51: Edges of suspended slab 250mm high | C51: =TAKEOFF!$H$2451 -> 294.6 | D51: m | E51: =RATES!$D$40 -> 65 | F51: =C51*E51 -> 19149 | G51: 294.6
A53: K | B53: Sides and soffits of beams | C53: =TAKEOFF!$H$2455 -> 196.59 | D53: m2 | E53: =RATES!$D$39 -> 165 | F53: =C53*E53 -> 32437.35 | G53: 166.8*(2*0.35+0.3)+33.1*(2*0.35+0.2)
A55: L | B55: Columns | C55: =TAKEOFF!$H$2466 -> 321.3175 | D55: m2 | E55: =RATES!$D$37 -> 165 | F55: =C55*E55 -> 53017.387 | G55: 5*2*(0.75+0.5)*3.05+1*2*(0.75+0.5)*3.05+2*2*(0.75+0.5)*3.05+1*2*(0.75+0.5)*3.05+3*2*(1.2+0.3)*3.05+6*2*(1.2+0.3)*3.05+1*2*(1.2+0.3)*3.05+15*2*(1.2+0.3)*3.05+1*2*(2.85+1.075)*3.05
A57: M | B57: Concrete wall (both faces) | C57: =TAKEOFF!$H$2471 -> 423.6145 | D57: m2 | E57: =RATES!$D$36 -> 165 | F57: =C57*E57 -> 69896.393 | G57: 2*22.05*3.05+2*21.825*3.05+2*25.57*3.05
A59: N | B59: Soffits of stair flights, landings and risers | C59: =TAKEOFF!$H$2479 -> 66.5328 | D59: m2 | E59: =RATES!$D$42 -> 165 | F59: =C59*E59 -> 10977.912 | G59: (2*3.424*1.8+15.0+22*0.15*1.8)+(2*3.424*1.8+15.0+22*0.15*1.8)
A61: P | B61: Side and soffits of lintel / coping | C61: =TAKEOFF!$H$2516 -> 116.76 | D61: m2 | E61: =RATES!$D$43 -> 165 | F61: =C61*E61 -> 19265.4 | G61: (7*(1+0.3)+15*(0.9+0.3)+20*(0.75+0.3)+1*(0.7+0.3)+3*(1.2+0.3)+3*(1+0.3)+3*(1+0.3)+1*(0.9+0.3)+1*(1.5+0.3)+2*(0.9+0.3)+5*(0.75+0.3)+1*(0.45+0.3)+3*(0.6+0.3)+1*(3+0.3)+3*(1.6+0.3)+2*(1.3+0.3)+4*(1.8+0.3)+1*(1.2+0.3)+6*(1.8+0.3)+10*(0.9+0.3)+1*(1.8+0...
B63: E30 REINFORCEMENT - High tensile yield round bar reinforcement (standard) to BS 4449:
A64: Q | B64: 10mm diameter in columns | C64: =TAKEOFF!$H$2520 -> 4.551 | D64: t | E64: =RATES!$D$29 -> 14300 | F64: =C64*E64 -> 65079.3 | G64: 4.551
A66: R | B66: 20mm diameter in columns | C66: =TAKEOFF!$H$2523 -> 7.133 | D66: t | E66: =RATES!$D$32 -> 14300 | F66: =C66*E66 -> 102001.9 | G66: 7.133
A68: S | B68: 10mm diameter in beams (links) | C68: =TAKEOFF!$H$2526 -> 1.806 | D68: t | E68: =RATES!$D$29 -> 14300 | F68: =C68*E68 -> 25825.8 | G68: 1.806
A70: T | B70: 16mm diameter in beams | C70: =TAKEOFF!$H$2529 -> 1.248 | D70: t | E70: =RATES!$D$31 -> 14300 | F70: =C70*E70 -> 17846.4 | G70: 1.248
A72: U | B72: 20mm diameter in beams | C72: =TAKEOFF!$H$2532 -> 2.135 | D72: t | E72: =RATES!$D$32 -> 14300 | F72: =C72*E72 -> 30530.5 | G72: 2.135
...

Sheet 6TH FLR  
A1: ='PRELIMS & GEN. ITEMS'!A1 -> PROJECT: BLOCK N REDEVELOPMENT
A2: ='PRELIMS & GEN. ITEMS'!A2 -> LOCATION: KANESHIE
A3: ='PRELIMS & GEN. ITEMS'!A3 -> CLIENT: STATE HOUSING LIMITED
A4: ='PRELIMS & GEN. ITEMS'!A4 -> DATE:9/30/2026
A5: ITEM | B5: DESCRIPTION | C5: QTY | D5: UNIT | E5: RATE | F5: AMOUNT - GHC | G5: Measurement basis / calculation
B7: MAIN BUILDING
B9: SIXTH FLOOR
B11: BILL SUMMARY
A13: A | B13: ELEMENT NO. 1: IN SITU CONCRETE/LARGE PRECAST CONCRETE | F13: =F90 -> 2632741.7
A15: B | B15: ELEMENT NO. 2: MASONRY | F15: =F101 -> 394834.26
A17: C | B17: ELEMENT NO. 4: WINDOWS/DOORS | F17: =F191 -> 597073.55
A19: D | B19: ELEMENT NO. 5: FLOOR FINISHES | F19: =F211 -> 349083.24
A21: E | B21: ELEMENT NO. 6: WALL FINISHES | F21: =F227 -> 321670.38
A23: F | B23: ELEMENT NO. 7: PAINTING AND DECORATING | F23: =F247 -> 190908.58
B25: =B9 -> SIXTH FLOOR | E25: GHC | F25: =SUM(F13:F24) -> 4486311.7
B26: To Bill General Summary
B29: BILL NR. 9 - SIXTH FLOOR
B31: ELEMENT NO. 1: IN SITU CONCRETE/LARGE PRECAST CONCRETE
B33: Vibrated in-situ concrete C40 as described in:
A34: A | B34: Suspended slab 250mm thick | C34: =TAKEOFF!$H$2990 -> 283.65 | D34: m3 | E34: =RATES!$D$22 -> 2310 | F34: =C34*E34 -> 655231.5 | G34: 1134.6*0.25
A36: B | B36: Beams (downstands below slab) | C36: =TAKEOFF!$H$2994 -> 19.831 | D36: m3 | E36: =RATES!$D$23 -> 2310 | F36: =C36*E36 -> 45809.61 | G36: 166.8*0.3*0.35+33.1*0.2*0.35
A38: C | B38: Columns | C38: =TAKEOFF!$H$3005 -> 40.545937 | D38: m3 | E38: =RATES!$D$21 -> 2310 | F38: =C38*E38 -> 93661.116 | G38: 5*0.75*0.5*3.05+1*0.75*0.5*3.05+2*0.75*0.5*3.05+1*0.75*0.5*3.05+3*1.2*0.3*3.05+6*1.2*0.3*3.05+1*1.2*0.3*3.05+15*1.2*0.3*3.05+1*(2.85*0.25+0.825*0.25)*3.05
A40: D | B40: Concrete wall - shear walls to main & emergency stair cores, 250mm thick | C40: =TAKEOFF!$H$3009 -> 36.31025 | D40: m3 | E40: =RATES!$D$20 -> 2310 | F40: =C40*E40 -> 83876.677 | G40: 22.05*3.05*0.25+25.57*3.05*0.25
A42: E | B42: Concrete wall - lift walls, 250mm thick | C42: =TAKEOFF!$H$3012 -> 16.641562 | D42: m3 | E42: =RATES!$D$20 -> 2310 | F42: =C42*E42 -> 38442.009 | G42: 21.825*3.05*0.25
A44: F | B44: Stairs | C44: =TAKEOFF!$H$3018 -> 11.182 | D44: m3 | E44: =RATES!$D$24 -> 2310 | F44: =C44*E44 -> 25830.42 | G44: (2.966*3.3/3.3+2.625)+(2.966*3.3/3.3+2.625)
A46: G | B46: Lintels 150 x 225mm over door and window openings | C46: =TAKEOFF!$H$3055 -> 6.99975 | D46: m3 | E46: =RATES!$D$25 -> 1925 | F46: =C46*E46 -> 13474.519 | G46: (8*(1+0.3)+15*(0.9+0.3)+21*(0.75+0.3)+1*(0.7+0.3)+3*(1.2+0.3)+3*(1+0.3)+3*(1+0.3)+1*(0.9+0.3)+1*(1.5+0.3)+2*(0.9+0.3)+5*(0.75+0.3)+1*(0.45+0.3)+3*(0.6+0.3)+1*(3+0.3)+4*(1.6+0.3)+2*(1.3+0.3)+4*(1.8+0.3)+1*(1.2+0.3)+6*(1.8+0.3)+10*(0.9+0.3)+2*(1.8+0...
B48: E20 FORMWORK - Formwork as described to:
A49: H | B49: Soffits of suspended slab | C49: =TAKEOFF!$H$3059 -> 1134.6 | D49: m2 | E49: =RATES!$D$38 -> 165 | F49: =C49*E49 -> 187209 | G49: 1134.6
A51: J | B51: Edges of suspended slab 250mm high | C51: =TAKEOFF!$H$3062 -> 294.6 | D51: m | E51: =RATES!$D$40 -> 65 | F51: =C51*E51 -> 19149 | G51: 294.6
A53: K | B53: Sides and soffits of beams | C53: =TAKEOFF!$H$3066 -> 196.59 | D53: m2 | E53: =RATES!$D$39 -> 165 | F53: =C53*E53 -> 32437.35 | G53: 166.8*(2*0.35+0.3)+33.1*(2*0.35+0.2)
A55: L | B55: Columns | C55: =TAKEOFF!$H$3077 -> 321.3175 | D55: m2 | E55: =RATES!$D$37 -> 165 | F55: =C55*E55 -> 53017.387 | G55: 5*2*(0.75+0.5)*3.05+1*2*(0.75+0.5)*3.05+2*2*(0.75+0.5)*3.05+1*2*(0.75+0.5)*3.05+3*2*(1.2+0.3)*3.05+6*2*(1.2+0.3)*3.05+1*2*(1.2+0.3)*3.05+15*2*(1.2+0.3)*3.05+1*2*(2.85+1.075)*3.05
A57: M | B57: Concrete wall (both faces) | C57: =TAKEOFF!$H$3082 -> 423.6145 | D57: m2 | E57: =RATES!$D$36 -> 165 | F57: =C57*E57 -> 69896.393 | G57: 2*22.05*3.05+2*21.825*3.05+2*25.57*3.05
A59: N | B59: Soffits of stair flights, landings and risers | C59: =TAKEOFF!$H$3090 -> 66.5328 | D59: m2 | E59: =RATES!$D$42 -> 165 | F59: =C59*E59 -> 10977.912 | G59: (2*3.424*1.8+15.0+22*0.15*1.8)+(2*3.424*1.8+15.0+22*0.15*1.8)
A61: P | B61: Side and soffits of lintel / coping | C61: =TAKEOFF!$H$3127 -> 124.44 | D61: m2 | E61: =RATES!$D$43 -> 165 | F61: =C61*E61 -> 20532.6 | G61: (8*(1+0.3)+15*(0.9+0.3)+21*(0.75+0.3)+1*(0.7+0.3)+3*(1.2+0.3)+3*(1+0.3)+3*(1+0.3)+1*(0.9+0.3)+1*(1.5+0.3)+2*(0.9+0.3)+5*(0.75+0.3)+1*(0.45+0.3)+3*(0.6+0.3)+1*(3+0.3)+4*(1.6+0.3)+2*(1.3+0.3)+4*(1.8+0.3)+1*(1.2+0.3)+6*(1.8+0.3)+10*(0.9+0.3)+2*(1.8+0...
B63: E30 REINFORCEMENT - High tensile yield round bar reinforcement (standard) to BS 4449:
A64: Q | B64: 10mm diameter in columns | C64: =TAKEOFF!$H$3131 -> 4.551 | D64: t | E64: =RATES!$D$29 -> 14300 | F64: =C64*E64 -> 65079.3 | G64: 4.551
A66: R | B66: 20mm diameter in columns | C66: =TAKEOFF!$H$3134 -> 7.133 | D66: t | E66: =RATES!$D$32 -> 14300 | F66: =C66*E66 -> 102001.9 | G66: 7.133
A68: S | B68: 10mm diameter in beams (links) | C68: =TAKEOFF!$H$3137 -> 1.806 | D68: t | E68: =RATES!$D$29 -> 14300 | F68: =C68*E68 -> 25825.8 | G68: 1.806
A70: T | B70: 16mm diameter in beams | C70: =TAKEOFF!$H$3140 -> 1.248 | D70: t | E70: =RATES!$D$31 -> 14300 | F70: =C70*E70 -> 17846.4 | G70: 1.248
A72: U | B72: 20mm diameter in beams | C72: =TAKEOFF!$H$3143 -> 2.135 | D72: t | E72: =RATES!$D$32 -> 14300 | F72: =C72*E72 -> 30530.5 | G72: 2.135
...

Sheet 7TH FLR   
A1: ='PRELIMS & GEN. ITEMS'!A1 -> PROJECT: BLOCK N REDEVELOPMENT
A2: ='PRELIMS & GEN. ITEMS'!A2 -> LOCATION: KANESHIE
A3: ='PRELIMS & GEN. ITEMS'!A3 -> CLIENT: STATE HOUSING LIMITED
A4: ='PRELIMS & GEN. ITEMS'!A4 -> DATE:9/30/2026
A5: ITEM | B5: DESCRIPTION | C5: QTY | D5: UNIT | E5: RATE | F5: AMOUNT - GHC | G5: Measurement basis / calculation
B7: MAIN BUILDING
B9: SEVENTH FLOOR
B11: BILL SUMMARY
A13: A | B13: ELEMENT NO. 1: IN SITU CONCRETE/LARGE PRECAST CONCRETE | F13: =F90 -> 2630954.4
A15: B | B15: ELEMENT NO. 2: MASONRY | F15: =F101 -> 381266.88
A17: C | B17: ELEMENT NO. 4: WINDOWS/DOORS | F17: =F191 -> 573414.1
A19: D | B19: ELEMENT NO. 5: FLOOR FINISHES | F19: =F211 -> 345672.24
A21: E | B21: ELEMENT NO. 6: WALL FINISHES | F21: =F227 -> 312099.76
A23: F | B23: ELEMENT NO. 7: PAINTING AND DECORATING | F23: =F248 -> 188326.49
B25: =B9 -> SEVENTH FLOOR | E25: GHC | F25: =SUM(F13:F24) -> 4431733.9
B26: To Bill General Summary
B29: BILL NR. 10 - SEVENTH FLOOR
B31: ELEMENT NO. 1: IN SITU CONCRETE/LARGE PRECAST CONCRETE
B33: Vibrated in-situ concrete C40 as described in:
A34: A | B34: Suspended slab 250mm thick | C34: =TAKEOFF!$H$3601 -> 283.65 | D34: m3 | E34: =RATES!$D$22 -> 2310 | F34: =C34*E34 -> 655231.5 | G34: 1134.6*0.25
A36: B | B36: Beams (downstands below slab) | C36: =TAKEOFF!$H$3605 -> 19.831 | D36: m3 | E36: =RATES!$D$23 -> 2310 | F36: =C36*E36 -> 45809.61 | G36: 166.8*0.3*0.35+33.1*0.2*0.35
A38: C | B38: Columns | C38: =TAKEOFF!$H$3616 -> 40.545937 | D38: m3 | E38: =RATES!$D$21 -> 2310 | F38: =C38*E38 -> 93661.116 | G38: 5*0.75*0.5*3.05+1*0.75*0.5*3.05+2*0.75*0.5*3.05+1*0.75*0.5*3.05+3*1.2*0.3*3.05+6*1.2*0.3*3.05+1*1.2*0.3*3.05+15*1.2*0.3*3.05+1*(2.85*0.25+0.825*0.25)*3.05
A40: D | B40: Concrete wall - shear walls to main & emergency stair cores, 250mm thick | C40: =TAKEOFF!$H$3620 -> 36.31025 | D40: m3 | E40: =RATES!$D$20 -> 2310 | F40: =C40*E40 -> 83876.677 | G40: 22.05*3.05*0.25+25.57*3.05*0.25
A42: E | B42: Concrete wall - lift walls, 250mm thick | C42: =TAKEOFF!$H$3623 -> 16.641562 | D42: m3 | E42: =RATES!$D$20 -> 2310 | F42: =C42*E42 -> 38442.009 | G42: 21.825*3.05*0.25
A44: F | B44: Stairs | C44: =TAKEOFF!$H$3629 -> 11.182 | D44: m3 | E44: =RATES!$D$24 -> 2310 | F44: =C44*E44 -> 25830.42 | G44: (2.966*3.3/3.3+2.625)+(2.966*3.3/3.3+2.625)
A46: G | B46: Lintels 150 x 225mm over door and window openings | C46: =TAKEOFF!$H$3666 -> 6.631875 | D46: m3 | E46: =RATES!$D$25 -> 1925 | F46: =C46*E46 -> 12766.359 | G46: (8*(1+0.3)+15*(0.9+0.3)+20*(0.75+0.3)+1*(0.7+0.3)+3*(1.2+0.3)+3*(1+0.3)+2*(1+0.3)+1*(0.9+0.3)+1*(1.5+0.3)+2*(0.9+0.3)+4*(0.75+0.3)+1*(0.45+0.3)+3*(0.6+0.3)+1*(3+0.3)+4*(1.6+0.3)+2*(1.3+0.3)+4*(1.8+0.3)+1*(1.2+0.3)+6*(1.8+0.3)+10*(0.9+0.3)+1*(1.8+0...
B48: E20 FORMWORK - Formwork as described to:
A49: H | B49: Soffits of suspended slab | C49: =TAKEOFF!$H$3670 -> 1134.6 | D49: m2 | E49: =RATES!$D$38 -> 165 | F49: =C49*E49 -> 187209 | G49: 1134.6
A51: J | B51: Edges of suspended slab 250mm high | C51: =TAKEOFF!$H$3673 -> 294.6 | D51: m | E51: =RATES!$D$40 -> 65 | F51: =C51*E51 -> 19149 | G51: 294.6
A53: K | B53: Sides and soffits of beams | C53: =TAKEOFF!$H$3677 -> 196.59 | D53: m2 | E53: =RATES!$D$39 -> 165 | F53: =C53*E53 -> 32437.35 | G53: 166.8*(2*0.35+0.3)+33.1*(2*0.35+0.2)
A55: L | B55: Columns | C55: =TAKEOFF!$H$3688 -> 321.3175 | D55: m2 | E55: =RATES!$D$37 -> 165 | F55: =C55*E55 -> 53017.387 | G55: 5*2*(0.75+0.5)*3.05+1*2*(0.75+0.5)*3.05+2*2*(0.75+0.5)*3.05+1*2*(0.75+0.5)*3.05+3*2*(1.2+0.3)*3.05+6*2*(1.2+0.3)*3.05+1*2*(1.2+0.3)*3.05+15*2*(1.2+0.3)*3.05+1*2*(2.85+1.075)*3.05
A57: M | B57: Concrete wall (both faces) | C57: =TAKEOFF!$H$3693 -> 423.6145 | D57: m2 | E57: =RATES!$D$36 -> 165 | F57: =C57*E57 -> 69896.393 | G57: 2*22.05*3.05+2*21.825*3.05+2*25.57*3.05
A59: N | B59: Soffits of stair flights, landings and risers | C59: =TAKEOFF!$H$3701 -> 66.5328 | D59: m2 | E59: =RATES!$D$42 -> 165 | F59: =C59*E59 -> 10977.912 | G59: (2*3.424*1.8+15.0+22*0.15*1.8)+(2*3.424*1.8+15.0+22*0.15*1.8)
A61: P | B61: Side and soffits of lintel / coping | C61: =TAKEOFF!$H$3738 -> 117.9 | D61: m2 | E61: =RATES!$D$43 -> 165 | F61: =C61*E61 -> 19453.5 | G61: (8*(1+0.3)+15*(0.9+0.3)+20*(0.75+0.3)+1*(0.7+0.3)+3*(1.2+0.3)+3*(1+0.3)+2*(1+0.3)+1*(0.9+0.3)+1*(1.5+0.3)+2*(0.9+0.3)+4*(0.75+0.3)+1*(0.45+0.3)+3*(0.6+0.3)+1*(3+0.3)+4*(1.6+0.3)+2*(1.3+0.3)+4*(1.8+0.3)+1*(1.2+0.3)+6*(1.8+0.3)+10*(0.9+0.3)+1*(1.8+0...
B63: E30 REINFORCEMENT - High tensile yield round bar reinforcement (standard) to BS 4449:
A64: Q | B64: 10mm diameter in columns | C64: =TAKEOFF!$H$3742 -> 4.551 | D64: t | E64: =RATES!$D$29 -> 14300 | F64: =C64*E64 -> 65079.3 | G64: 4.551
A66: R | B66: 20mm diameter in columns | C66: =TAKEOFF!$H$3745 -> 7.133 | D66: t | E66: =RATES!$D$32 -> 14300 | F66: =C66*E66 -> 102001.9 | G66: 7.133
A68: S | B68: 10mm diameter in beams (links) | C68: =TAKEOFF!$H$3748 -> 1.806 | D68: t | E68: =RATES!$D$29 -> 14300 | F68: =C68*E68 -> 25825.8 | G68: 1.806
A70: T | B70: 16mm diameter in beams | C70: =TAKEOFF!$H$3751 -> 1.248 | D70: t | E70: =RATES!$D$31 -> 14300 | F70: =C70*E70 -> 17846.4 | G70: 1.248
A72: U | B72: 20mm diameter in beams | C72: =TAKEOFF!$H$3754 -> 2.135 | D72: t | E72: =RATES!$D$32 -> 14300 | F72: =C72*E72 -> 30530.5 | G72: 2.135
...

Sheet 8TH FLR   
A1: ='PRELIMS & GEN. ITEMS'!A1 -> PROJECT: BLOCK N REDEVELOPMENT
A2: ='PRELIMS & GEN. ITEMS'!A2 -> LOCATION: KANESHIE
A3: ='PRELIMS & GEN. ITEMS'!A3 -> CLIENT: STATE HOUSING LIMITED
A4: ='PRELIMS & GEN. ITEMS'!A4 -> DATE:9/30/2026
A5: ITEM | B5: DESCRIPTION | C5: QTY | D5: UNIT | E5: RATE | F5: AMOUNT - GHC | G5: Measurement basis / calculation
B7: MAIN BUILDING
B9: EIGHTH FLOOR
B11: BILL SUMMARY
A13: A | B13: ELEMENT NO. 1: IN SITU CONCRETE/LARGE PRECAST CONCRETE | F13: =F94 -> 2628506.8
A15: B | B15: ELEMENT NO. 2: MASONRY | F15: =F105 -> 379547.96
A17: C | B17: ELEMENT NO. 4: WINDOWS/DOORS | F17: =F195 -> 576573.55
A19: D | B19: ELEMENT NO. 5: FLOOR FINISHES | F19: =F215 -> 345862.54
A21: E | B21: ELEMENT NO. 6: WALL FINISHES | F21: =F231 -> 311695.51
A23: F | B23: ELEMENT NO. 7: PAINTING AND DECORATING | F23: =F251 -> 185701.3
B25: =B9 -> EIGHTH FLOOR | E25: GHC | F25: =SUM(F13:F24) -> 4427887.7
B26: To Bill General Summary
B29: BILL NR. 11 - EIGHTH FLOOR
B31: ELEMENT NO. 1: IN SITU CONCRETE/LARGE PRECAST CONCRETE
B33: Vibrated in-situ concrete C40 as described in:
A34: A | B34: Suspended slab 250mm thick | C34: =TAKEOFF!$H$4212 -> 283.65 | D34: m3 | E34: =RATES!$D$22 -> 2310 | F34: =C34*E34 -> 655231.5 | G34: 1134.6*0.25
A36: B | B36: Beams (downstands below slab) | C36: =TAKEOFF!$H$4216 -> 19.831 | D36: m3 | E36: =RATES!$D$23 -> 2310 | F36: =C36*E36 -> 45809.61 | G36: 166.8*0.3*0.35+33.1*0.2*0.35
A38: C | B38: Columns | C38: =TAKEOFF!$H$4227 -> 40.545937 | D38: m3 | E38: =RATES!$D$21 -> 2310 | F38: =C38*E38 -> 93661.116 | G38: 5*0.75*0.5*3.05+1*0.75*0.5*3.05+2*0.75*0.5*3.05+1*0.75*0.5*3.05+3*1.2*0.3*3.05+6*1.2*0.3*3.05+1*1.2*0.3*3.05+15*1.2*0.3*3.05+1*(2.85*0.25+0.825*0.25)*3.05
A40: D | B40: Concrete wall - shear walls to main & emergency stair cores, 250mm thick | C40: =TAKEOFF!$H$4231 -> 36.31025 | D40: m3 | E40: =RATES!$D$20 -> 2310 | F40: =C40*E40 -> 83876.677 | G40: 22.05*3.05*0.25+25.57*3.05*0.25
A42: E | B42: Concrete wall - lift walls, 250mm thick | C42: =TAKEOFF!$H$4234 -> 16.641562 | D42: m3 | E42: =RATES!$D$20 -> 2310 | F42: =C42*E42 -> 38442.009 | G42: 21.825*3.05*0.25
A44: F | B44: Stairs | C44: =TAKEOFF!$H$4240 -> 11.182 | D44: m3 | E44: =RATES!$D$24 -> 2310 | F44: =C44*E44 -> 25830.42 | G44: (2.966*3.3/3.3+2.625)+(2.966*3.3/3.3+2.625)
A46: G | B46: Lintels 150 x 225mm over door and window openings | C46: =TAKEOFF!$H$4277 -> 6.8698125 | D46: m3 | E46: =RATES!$D$25 -> 1925 | F46: =C46*E46 -> 13224.389 | G46: (8*(1+0.3)+15*(0.9+0.3)+21*(0.75+0.3)+1*(0.7+0.3)+2*(1.2+0.3)+3*(1+0.3)+2*(1+0.3)+1*(0.9+0.3)+1*(1.5+0.3)+2*(0.9+0.3)+4*(0.75+0.3)+1*(0.45+0.3)+3*(0.6+0.3)+1*(3+0.3)+4*(1.6+0.3)+2*(1.3+0.3)+4*(1.8+0.3)+1*(1.2+0.3)+6*(1.8+0.3)+10*(0.9+0.3)+2*(1.8+0...
B48: E20 FORMWORK - Formwork as described to:
A49: H | B49: Soffits of suspended slab | C49: =TAKEOFF!$H$4281 -> 1134.6 | D49: m2 | E49: =RATES!$D$38 -> 165 | F49: =C49*E49 -> 187209 | G49: 1134.6
A51: J | B51: Edges of suspended slab 250mm high | C51: =TAKEOFF!$H$4284 -> 294.6 | D51: m | E51: =RATES!$D$40 -> 65 | F51: =C51*E51 -> 19149 | G51: 294.6
A53: K | B53: Sides and soffits of beams | C53: =TAKEOFF!$H$4288 -> 196.59 | D53: m2 | E53: =RATES!$D$39 -> 165 | F53: =C53*E53 -> 32437.35 | G53: 166.8*(2*0.35+0.3)+33.1*(2*0.35+0.2)
A55: L | B55: Columns | C55: =TAKEOFF!$H$4299 -> 321.3175 | D55: m2 | E55: =RATES!$D$37 -> 165 | F55: =C55*E55 -> 53017.387 | G55: 5*2*(0.75+0.5)*3.05+1*2*(0.75+0.5)*3.05+2*2*(0.75+0.5)*3.05+1*2*(0.75+0.5)*3.05+3*2*(1.2+0.3)*3.05+6*2*(1.2+0.3)*3.05+1*2*(1.2+0.3)*3.05+15*2*(1.2+0.3)*3.05+1*2*(2.85+1.075)*3.05
A57: M | B57: Concrete wall (both faces) | C57: =TAKEOFF!$H$4304 -> 423.6145 | D57: m2 | E57: =RATES!$D$36 -> 165 | F57: =C57*E57 -> 69896.393 | G57: 2*22.05*3.05+2*21.825*3.05+2*25.57*3.05
A59: N | B59: Soffits of stair flights, landings and risers | C59: =TAKEOFF!$H$4312 -> 66.5328 | D59: m2 | E59: =RATES!$D$42 -> 165 | F59: =C59*E59 -> 10977.912 | G59: (2*3.424*1.8+15.0+22*0.15*1.8)+(2*3.424*1.8+15.0+22*0.15*1.8)
A61: P | B61: Side and soffits of lintel / coping | C61: =TAKEOFF!$H$4349 -> 122.13 | D61: m2 | E61: =RATES!$D$43 -> 165 | F61: =C61*E61 -> 20151.45 | G61: (8*(1+0.3)+15*(0.9+0.3)+21*(0.75+0.3)+1*(0.7+0.3)+2*(1.2+0.3)+3*(1+0.3)+2*(1+0.3)+1*(0.9+0.3)+1*(1.5+0.3)+2*(0.9+0.3)+4*(0.75+0.3)+1*(0.45+0.3)+3*(0.6+0.3)+1*(3+0.3)+4*(1.6+0.3)+2*(1.3+0.3)+4*(1.8+0.3)+1*(1.2+0.3)+6*(1.8+0.3)+10*(0.9+0.3)+2*(1.8+0...
B65: E30 REINFORCEMENT - High tensile yield round bar reinforcement (standard) to BS 4449:
A66: Q | B66: 10mm diameter in columns | C66: =TAKEOFF!$H$4353 -> 4.509 | D66: t | E66: =RATES!$D$29 -> 14300 | F66: =C66*E66 -> 64478.7 | G66: 4.509
A68: R | B68: 20mm diameter in columns | C68: =TAKEOFF!$H$4356 -> 6.299 | D68: t | E68: =RATES!$D$32 -> 14300 | F68: =C68*E68 -> 90075.7 | G68: 6.299
A70: S | B70: 25mm diameter in columns | C70: =TAKEOFF!$H$4359 -> 0.624 | D70: t | E70: =RATES!$D$33 -> 14300 | F70: =C70*E70 -> 8923.2 | G70: 0.624
A72: T | B72: 10mm diameter in beams (links) | C72: =TAKEOFF!$H$4362 -> 1.806 | D72: t | E72: =RATES!$D$29 -> 14300 | F72: =C72*E72 -> 25825.8 | G72: 1.806
A74: U | B74: 16mm diameter in beams | C74: =TAKEOFF!$H$4365 -> 1.248 | D74: t | E74: =RATES!$D$31 -> 14300 | F74: =C74*E74 -> 17846.4 | G74: 1.248
...

Sheet 9TH FLR    
A1: ='PRELIMS & GEN. ITEMS'!A1 -> PROJECT: BLOCK N REDEVELOPMENT
A2: ='PRELIMS & GEN. ITEMS'!A2 -> LOCATION: KANESHIE
A3: ='PRELIMS & GEN. ITEMS'!A3 -> CLIENT: STATE HOUSING LIMITED
A4: ='PRELIMS & GEN. ITEMS'!A4 -> DATE:9/30/2026
A5: ITEM | B5: DESCRIPTION | C5: QTY | D5: UNIT | E5: RATE | F5: AMOUNT - GHC | G5: Measurement basis / calculation
B7: MAIN BUILDING
B9: NINTH FLOOR
B11: BILL SUMMARY
A13: A | B13: ELEMENT NO. 1: IN SITU CONCRETE/LARGE PRECAST CONCRETE | F13: =F92 -> 2564952.1
A15: B | B15: ELEMENT NO. 2: MASONRY | F15: =F102 -> 310127.3
A17: C | B17: ELEMENT NO. 3: WATERPROOFING | F17: =F112 -> 79963.8
A19: D | B19: ELEMENT NO. 4: WINDOWS/DOORS | F19: =F193 -> 357735.95
A21: E | B21: ELEMENT NO. 5: FLOOR FINISHES | F21: =F216 -> 357394.34
A23: F | B23: ELEMENT NO. 6: WALL FINISHES | F23: =F233 -> 272188.02
A25: G | B25: ELEMENT NO. 7: PAINTING AND DECORATING | F25: =F254 -> 154620.02
B27: =B9 -> NINTH FLOOR | E27: GHC | F27: =SUM(F13:F26) -> 4096981.5
B28: To Bill General Summary
B31: BILL NR. 12 - NINTH FLOOR
B33: ELEMENT NO. 1: IN SITU CONCRETE/LARGE PRECAST CONCRETE
B35: Vibrated in-situ concrete C40 as described in:
A36: A | B36: Suspended slab 250mm thick | C36: =TAKEOFF!$H$4826 -> 283.6 | D36: m3 | E36: =RATES!$D$22 -> 2310 | F36: =C36*E36 -> 655116 | G36: 1134.4*0.25
A38: B | B38: Beams (downstands below slab) | C38: =TAKEOFF!$H$4830 -> 21.8995 | D38: m3 | E38: =RATES!$D$23 -> 2310 | F38: =C38*E38 -> 50587.845 | G38: 186.5*0.3*0.35+33.1*0.2*0.35
A40: C | B40: Columns | C40: =TAKEOFF!$H$4838 -> 28.731 | D40: m3 | E40: =RATES!$D$21 -> 2310 | F40: =C40*E40 -> 66368.61 | G40: 1*0.75*0.5*3.05+2*0.75*0.5*3.05+1*0.75*0.5*3.05+6*1.2*0.3*3.05+1*1.2*0.3*3.05+15*1.2*0.3*3.05
A42: D | B42: Concrete wall - shear walls to main & emergency stair cores, 250mm thick | C42: =TAKEOFF!$H$4842 -> 36.31025 | D42: m3 | E42: =RATES!$D$20 -> 2310 | F42: =C42*E42 -> 83876.677 | G42: 22.05*3.05*0.25+25.57*3.05*0.25
A44: E | B44: Concrete wall - lift walls, 250mm thick | C44: =TAKEOFF!$H$4845 -> 16.641562 | D44: m3 | E44: =RATES!$D$20 -> 2310 | F44: =C44*E44 -> 38442.009 | G44: 21.825*3.05*0.25
A46: F | B46: Stairs | C46: =TAKEOFF!$H$4851 -> 11.182 | D46: m3 | E46: =RATES!$D$24 -> 2310 | F46: =C46*E46 -> 25830.42 | G46: (2.966*3.3/3.3+2.625)+(2.966*3.3/3.3+2.625)
