Workbook

Sheet Verification Notes
A1: BOQ VERIFICATION - PROPOSED KANESHIE BLOCK N REDEVELOPMENT
A2: Drawings used: Structural SHC-KANESHIE-STR-000 to 107 (108 sheets); Architectural SHC-NORTH K-ARCH-101 to 606 (59 sheets).
A4: HOW TO READ THE BOQ SHEETS
A5: Column C = original BOQ quantity (unchanged). Column D "Verified Qty" (green) = quantity measured from the drawings; it links to the Verification Take-off sheet where every calculation is shown.
A6: Column F "Verified Unit": red where the unit has been corrected (e.g. edges of bed m2 -> m; hinges nr -> pairs; provisional sums -> item).
A7: Description text in red "[PER DRAWINGS: ...]" = the drawings describe the item differently; the original description is kept above it.
A8: Rows shaded yellow (item codes N1..N12, A1, D1, W, X) are ADDED items omitted from the BOQ. They sit inside the existing page totals.
A9: Column H "Amount" now = Rate x Verified Qty. Column I gives remarks.
A11: KEY FINDINGS
A12: 1. Superstructure columns: BOQ multiplies concrete, formwork and reinforcement by 5. The base figures already represent all floors - the x5 overstates them five-fold.
A13: 2. Concrete walls (306 m3) understate the shear/lift/emergency core walls (c.667 m3 measured). The formwork formula refers to the column line.
A14: 3. Beams (c.211 m3 concrete, c.111 t steel, c.2,100 m2 formwork), Y20 wall bars (82 t), raft edge formwork, slab edges and stair formwork are not in the BOQ - added.
... A31: e) Wall-tile height in washrooms, roof drainage layout and burglar-proofing extent are not dimensioned.

Sheet Prelims
A1: Item | B1: Description | C1: Qty | D1: Unit | E1: Rate | F1: Amount
B2: BILL NO. 1- PRELIMINARIES AND GENERAL CONDITIONS
B4: NAME: PROPOSED KANESHIE BLOCK N REDEVELOPMENT
B5: CLIENT/ CONSULTANTS: STATE HOUSING PROJECT
B6: CONTRACTOR: FBC PARTNERS GHANA LTD
B7: DRAWING: STRUCTURAL, ARCHITECTURAL, MEP DRAWINGS - KANESHIE BLOCK N REDEVELOPMENT
B9: (The Contractor is free to price for additional items under Preliminaries not included in the List below)
A11: A | B11: Performance Security
A13: B | B13: Offices for use by Contractor
A15: C | B15: Offices for use by the Engineer
A17: D | B17: Watching and Protection of the Works
A19: E | B19: Transport for Workpeople
A21: F | B21: First Aid Equipment
A23: G | B23: Project Signboard
A25: H | B25: Setting Out of the Works
A27: J | B27: Agent or Foreman-in-Charge
A29: K | B29: Plant, tools and Vehicles
A31: L | B31: Branded PPEs
A33: M | B33: Security and protection
... A37: P | B37: Allow for providing all scaffolding, and apparatus
B38: profiles and apparatus generraly required for the
B39: proper execution of the Works. The Contractor
B40: shall provide without extra charge all labour and
B41: equipment or apparatus required by the Engineer
B42: for the testing and measuring the Works and for
B43: weighing, proving or testing the efficiency of any
B44: portion of the Works
A46: Q | B46: Water for the works
B48: BILL NO. 1
B49: GENERAL ITEMS (PRELIMINARIES)
B50: Carried to General Summay

Sheet structural works
A1: Item | B1: Description | C1: Qty | D1: Verified Qty | E1: Unit | F1: Verified Unit | G1: Rate | H1: Amount | I1: Verification remarks
B2: PROPOSED KANESHIE BLOCK N REDEVELOPMENT
B3: SUBSTRUCTURE
B4: D GROUNDWORK (D20 EXCAVATION)
B6: Site Preparation
A8: A | B8: Clear site of all vegetation, grub up their roots and dispose-off | C8: 2369 | D8: ='Verification Take-off'!E6 -> 2299.0095 | E8: m2 | F8: m2 | H8: =G8*D8 -> 0 | I8: Plot + Parking-22 forecourt
A10: B | B10: Excavate oversite to remove vegetable soil average 150mm deep and deposit on site for re-use average 50m from excavation. | C10: 1477 | D10: ='Verification Take-off'!E7 -> 1800 | E10: m2 | F10: m2 | H10: =G10*D10 -> 0 | I10: BOQ 1,477 m2 = raft only; excavation footprint 45 x 40 m
A12: C | B12: Excavate raft foundation to reduce levels maximum depth 4.00m | C12: =C10*4.1 -> 6055.7 | D12: ='Verification Take-off'!E8 -> 7200 | E12: m3 | F12: m3 | H12: =G12*D12 -> 0
A14: D | B14: Fill to make up levels thickness 1300mm with waterproof external membrane with high strength biaxial geogridover geotextile 300mm thick [PER DRAWINGS: fill over raft is c.1.0m thick (raft top -1.000 to underside of hardcore -0.000)] | C14: =C10*1.1 -> 1624.7 | D14: ='Verification Take-off'!E9 -> 1445.3447 | E14: m3 | F14: m3 | H14: =G14*D14 -> 0 | I14: BOQ uses 1.1 x oversite area
A16: E | B16: Fill to make up levels thickness 1300mm with 300mm thick compacted crushed rock layers between layers until formation level and well compacted [PER DRAWINGS: crushed rock/geogrid layers are c.1,700 thick between raft underside (-2.300) and formation (-4.000)] | C16: =C10*1.3 -> 1920.1 | D16: ='Verification Take-off'!E10 -> 3060 | E16: m3 | F16: m3 | H16: =G16*D16 -> 0 | I16: RFI: Section A-A dims show 2,700
B18: Backfill and compact selected material around
A19: F | B19: foundations | C19: 1255 | D19: ='Verification Take-off'!E11 -> 745.2 | E19: m3 | F19: m3 | H19: =G19*D19 -> 0
B21: Load up surplus excavated material
A22: G | B22: and remove from site | C22: =C12-C16-C48-C52-C37-C34 -> 3799.2 | D22: ='Verification Take-off'!E12 -> 6454.8 | E22: m3 | F22: m3 | H22: =G22*D22 -> 0
B24: Hardcore Filling
A25: H | B25: Approved imported granular material
B26: Filling to make up levels: depositing and
B27: compacting in layers 150mm maximum
B28: thickness | C28: =C10*0.15 -> 221.55 | D28: ='Verification Take-off'!E13 -> 221.4 | E28: m3 | F28: m3 | H28: =G28*D28 -> 0
B30: E10 IN SITU CONCRETE
B31: Concreteworks
B32: Plain in-situ concrete(1:4:8-38mmAggre)
B33: as described in:
A34: J | B34: Blinding [PER DRAWINGS: blinding minimum 100mm thick (General Notes item 1.0/3)] | C34: =C10*0.05 -> 73.85 | D34: ='Verification Take-off'!E14 -> 147.6 | E34: m3 | F34: m3 | H34: =G34*D34 -> 0
A37: K | B37: 150mm thick Bed | C37: =0.15*C10 -> 221.55 | D37: ='Verification Take-off'!E15 -> 221.4 | E37: m3 | F37: m3 | H37: =G37*D37 -> 0 | I37: No GF slab detail issued - RFI
B42: TO COLLECTION | H42: =SUM(H2:H35) -> 0
A44: Item | B44: Description | C44: Qty | D44: Verified Qty | E44: Unit | F44: Verified Unit | G44: Rate | H44: Amount | I44: Verification remarks
B45: E10 IN SITU CONCRETE
B46: Vibrated in situ concrete C40
B47: as described in:
A48: A | B48: Concrete walls | C48: 34 | D48: ='Verification Take-off'!E17 -> 22.569625 | E48: m3 | F48: m3 | H48: =G48*D48 -> 0
A50: B | B50: Concrete in raft | C50: =C10*1.3 -> 1920.1 | D50: ='Verification Take-off'!E18 -> 1918.8 | E50: m3 | F50: m3 | H50: =G50*D50 -> 0
A52: C | B52: Concrete in columns | C52: 7 | D52: ='Verification Take-off'!E19 -> 17.281875 | E52: m3 | F52: m3 | H52: =G52*D52 -> 0 | I52: BOQ 7 m3 too low: 35 columns x 1.3m
B54: E30 REINFORCEMENT
B55: High Tensile yield round bar reinforcement (standard)
A56: D | B56: 20mm in raft | C56: 2.467 | D56: ='Verification Take-off'!E20 -> 2.466 | E56: t | F56: t | H56: =G56*D56 -> 0
A58: E | B58: 25mm diameter in raft | C58: 180 | D58: ='Verification Take-off'!E21 -> 184.672 | E58: t | F58: t | H58: =G58*D58 -> 0
A60: F | B60: 10mm diamter for concrete [PER DRAWINGS: Y10 links to columns & walls (raft to GF)] | C60: 2.574 | D60: ='Verification Take-off'!E22 -> 4.029 | E60: t | F60: t | H60: =G60*D60 -> 0
A62: G | B62: 12mm diamter for concrete [PER DRAWINGS: Y12 to walls (raft to GF)] | C62: 1.566 | D62: ='Verification Take-off'!E23 -> 1.253 | E62: t | F62: t | H62: =G62*D62 -> 0
A64: H | B64: 25mm diamter for concrete [PER DRAWINGS: Y25 to columns & walls (raft to GF)] | C64: 1.414 | D64: ='Verification Take-off'!E24 -> 21.306 | E64: t | F64: t | H64: =G64*D64 -> 0
...

Sheet architectural works
A1: Item | B1: Description | C1: Qty | D1: Verified Qty | E1: Unit | F1: Verified Unit | G1: Rate | H1: Amount | I1: Verification remarks
B2: PROPOSED KANESHIE BLOCK N REDEVELOPMENT
B3: SUPERSTRUCTURE
B5: F10 BRICK/BLOCK WALL
B6: Blockwork
B7: Walls and Partitions
B9: Solid sancrete blockwork in Cement and Sand
B10: (1:4) mortar as described in:
A12: A | B12: 150mm thick wall | C12: 17500 | D12: ='Verification Take-off'!E67 -> 14110.532 | E12: m2 | F12: m2 | H12: =G12*D12 -> 0
A13: A1 | B13: 200mm thick wall | D13: ='Verification Take-off'!E68 -> 1744.1391 | E13: - | F13: m2 | H13: =G13*D13 -> 0 | I13: ADDED - 200/225 walls on plans
B15: Finishing
B16: Walls and Ceilings
B17: 12.5mm Cement and sand (1:3) rendering
B18: as described on blockwork or concrete to
A19: B | B19: Interior walls | C19: 26400 | D19: ='Verification Take-off'!E73 -> 17036.533 | E19: m2 | F19: m2 | H19: =G19*D19 -> 0
A21: C | B21: Interior partitions and washrooms | C21: 950 | D21: ='Verification Take-off'!E74 -> 2964.8897 | E21: m2 | F21: m2 | H21: =G21*D21 -> 0
B23: Cement and Sand(1:3) mortar as described
A24: D | B24: 25mm Screeded finish laid level on concrete and
B25: finished smooth with steel trowel | C25: 17600 | D25: ='Verification Take-off'!E85 -> 7644.2 | E25: m2 | F25: m2 | H25: =G25*D25 -> 0 | I25: BOQ 17,600 m2 appears to be gross slab area; screed measured to tiled floors
A27: D1 | B27: 12.5mm cement & sand (1:3) rendering to external walls | D27: ='Verification Take-off'!E75 -> 7081.575 | E27: - | F27: m2 | H27: =G27*D27 -> 0 | I27: ADDED - no external render item in BOQ
B29: Painting and decorating
B30: Prepare and apply two undercoat and finishing
B31: coat of Emulsion Paint on:
A32: E | B32: Interior walls | C32: 26400 | D32: ='Verification Take-off'!E90 -> 17036.533 | E32: m2 | F32: m2 | H32: =G32*D32 -> 0
A34: F | B34: Interior partitions and washrooms | C34: 950 | D34: ='Verification Take-off'!E91 -> 688.00816 | E34: m2 | F34: m2 | H34: =G34*D34 -> 0
A36: G | B36: Exterior walls | C36: 5200 | D36: ='Verification Take-off'!E92 -> 7081.575 | E36: m2 | F36: m2 | H36: =G36*D36 -> 0
A38: H | B38: Ditto to columns and walls not exceeding 300mm girth [PER DRAWINGS: columns are girth exceeding 300mm - measured in m2 (exposed faces GF & parking levels)] | C38: 700 | D38: ='Verification Take-off'!E93 -> 948.5 | E38: m2 | F38: m2 | H38: =G38*D38 -> 0
A40: J | B40: Ditto soffit of plaster board | C40: 6800 | D40: ='Verification Take-off'!E94 -> 7109 | E40: m2 | F40: m2 | H40: =G40*D40 -> 0
A42: K | B42: Ditto soffit of plaster board for washrooms | C42: 900 | D42: ='Verification Take-off'!E95 -> 493 | E42: m2 | F42: m2 | H42: =G42*D42 -> 0
B46: Prepare and apply one coat of Aluminum Primer on
B47: Joinery before fixing to:
B48: Knot, Prime, Stop and apply two undercoats and
B49: one finishing coat of Gloss Oil Paint on:
A51: L | B51: General surfaces of woodwork | C51: =1078 -> 1078 | D51: ='Verification Take-off'!E96 -> 1517.115 | E51: m2 | F51: m2 | H51: =G51*D51 -> 0
B53: Primer
B54: Mild steel burglar proof bars not exceeding
A55: M | B55: 300mm girth [PER DRAWINGS: measured over area of window openings] | C55: 2102 | D55: ='Verification Take-off'!E97 -> 809.4 | E55: m2 | F55: m2 | H55: =G55*D55 -> 0
B58: BEDS AND BACKINGS
B59: Cement and sand (1:4) as discribed
A60: N | B60: 12mm Screeded backing to receive wall tiles(m/s) | C60: 1846 | D60: ='Verification Take-off'!E87 -> 2276.8816 | E60: m² | F60: m² | H60: =G60*D60 -> 0 | I60: Wall tiling height assumed 2.4m
...

Sheet general summary
A1: Item | B1: Description | C1: Qty | D1: Unit | E1: Rate | F1: Amount
B3: GENERAL SUMMARY
A5: A | B5: PRELIMINARIES | F5: =Prelims!F50 -> 0
A7: B | B7: STRUCTURAL | F7: ='structural works'!H166 -> 0 | L7: =SUM(F6:F10)*0.045 -> 0
A9: C | B9: ARCHITECTURAL | F9: ='architectural works'!H287 -> 0
B12: SUB TOTAL | F12: =F9+F7+F5 -> 0
B15: CONTIGENCY (10%) | F15: =0.1*F12 -> 0
B19: TOTAL | F19: =SUM(F12:F18) -> 0

Sheet Verification Take-off
A1: VERIFICATION TAKE-OFF - PROPOSED KANESHIE BLOCK N REDEVELOPMENT
A2: Every verified quantity in the BOQ links to the Result column of this sheet. Calculations are shown as formulas (dimensions in metres unless noted). Blue = dimensions taken from drawings.
A4: Ref | B4: BOQ sheet / item | C4: Description | D4: Calculation (dimensions) | E4: Result | F4: Unit | G4: Source / basis
A5: A. SUBSTRUCTURE - EARTHWORKS (STR-001 raft GA & Section A-A; ARCH-101/102 site & block plan)
A6: S1 | B6: STR A | C6: Site clearance: Block N plot + Parking-22 forecourt | D6: '=40.85*38.27+35.2*20.9 | E6: =40.85*38.27+35.2*20.9 -> 2299.0095 | F6: m2 | G6: ARCH-102 block plan: plot 3945+36900 wide x 38272 deep; Parking-22 5549+28051+1619 x (4900+5000+6000+5000)
A7: S2 | B7: STR B | C7: Strip topsoil 150mm over excavation footprint (raft 41.0 x 36.0 + 2.0m working space each side) | D7: '=(41.0+2*2.0)*(36.0+2*2.0) | E7: =(41.0+2*2.0)*(36.0+2*2.0) -> 1800 | F7: m2 | G7: STR-001 Section A-A: raft width 41,000; width of excavation 45,000 (2,000 allowance each side). Raft depth 36.0 m measured on STR-001 at 1:100
A8: S3 | B8: STR C | C8: Excavate to reduce levels, max depth 4.00m | D8: '=(45.0*40.0)*4.0 | E8: =(45.0*40.0)*4.0 -> 7200 | F8: m3 | G8: STR-001: bottom of excavation -4,000mm
A9: S4 | B9: STR D | C9: Fill to make up levels over raft to underside of hardcore (raft top -1.000 to -0.000) | D9: '=41.0*36.0*1.0-(69.445*0.25*1.0)-(13.294*1.0) | E9: =41.0*36.0*1.0-(69.445*0.25*1.0)-(13.294*1.0) -> 1445.3447 | F9: m3 | G9: Raft top SSL -1.000 (STR-007/017), GF +0.300 less 150 bed & 150 hardcore; core walls (69.445m x 0.25) and columns (13.294 m2 plan) deducted
A10: S5 | B10: STR E | C10: Crushed rock / geogrid layers between raft underside (-2.300) and formation (-4.000), full excavation width | D10: '=(45.0*40.0)*1.7 | E10: =(45.0*40.0)*1.7 -> 3060 | F10: m3 | G10: STR-001 Section A-A layer build-up. NB section dims show 2,700 below raft; levels give 1,700 - RFI
A11: S6 | B11: STR F | C11: Backfill around raft in working space (outside raft, above crushed-rock layer) | D11: '=((45.0*40.0)-(41.0*36.0))*(4.0-1.7) | E11: =((45.0*40.0)-(41.0*36.0))*(4.0-1.7) -> 745.2 | F11: m3 | G11: Working-space area x depth from NGL to top of crushed rock
A12: S7 | B12: STR G | C12: Disposal of surplus excavated material | D12: '=(45.0*40.0)*4.0-((45.0*40.0)-(41.0*36.0))*(4.0-1.7) | E12: =(45.0*40.0)*4.0-((45.0*40.0)-(41.0*36.0))*(4.0-1.7) -> 6454.8 | F12: m3 | G12: Excavation less re-used backfill (fills D/E/H are imported)
A13: S8 | B13: STR H | C13: Hardcore 150mm under GF bed | D13: '=41.0*36.0*0.15 | E13: =41.0*36.0*0.15 -> 221.4 | F13: m3 | G13: GF bed footprint taken as raft footprint
A14: S9 | B14: STR J | C14: Blinding under raft - 100mm min. (General Notes 1.0 item 3) | D14: '=41.0*36.0*0.10 | E14: =41.0*36.0*0.10 -> 147.6 | F14: m3 | G14: STR-000: "minimum 100mm thick blinding" - BOQ describes 50mm
A15: S10 | B15: STR K | C15: 150mm thick bed (GF slab on fill) | D15: '=41.0*36.0*0.15 | E15: =41.0*36.0*0.15 -> 221.4 | F15: m3 | G15: No GF slab detail on structural drawings - RFI
A16: B. SUBSTRUCTURE - CONCRETE, REINFORCEMENT, FORMWORK, BLOCKWORK
A17: S11 | B17: STR A (p2) | C17: Concrete walls from raft top (-1.000) to GF (+0.300): main core shear 22.05m + lift 21.825m + emergency core 25.57m, 250 thk | D17: '=(22.05+21.825+25.57)*0.25*1.3 | E17: =(22.05+21.825+25.57)*0.25*1.3 -> 22.569625 | F17: m3 | G17: Wall lengths from raft GA STR-002 dims; walls 250 thk
A18: S12 | B18: STR B (p2) | C18: Raft 1300 thick | D18: '=41.0*36.0*1.3 | E18: =41.0*36.0*1.3 -> 1918.8 | F18: m3 | G18: Sump/lift-pit transitions (STR-003) not adjusted - same thickness folded
A19: S13 | B19: STR C (p2) | C19: Columns raft to GF: 9 nr type-01 (750x500) + 25 nr type-02 (1200x300) + SWC-01A L-shape | D19: '=(9*0.75*0.5+25*1.2*0.3+(2.85*0.25+(1.075-0.25)*0.25))*1.3 | E19: =(9*0.75*0.5+25*1.2*0.3+(2.85*0.25+(1.075-0.25)*0.25))*1.3 -> 17.281875 | F19: m3 | G19: STR-007..012 sections; counts STR-002
A20: S14 | B20: STR D (p2) | C20: Y20 in raft | D20: '=2.466 | E20: =2.466 -> 2.466 | F20: t | G20: Reinforcement take-off (raft BBS STR-004..006)
A21: S15 | B21: STR E (p2) | C21: Y25 in raft | D21: '=184.672 | E21: =184.672 -> 184.672 | F21: t | G21: Reinforcement take-off (raft BBS)
A22: S16 | B22: STR F (p2) | C22: Y10 links - columns & walls (substructure) | D22: '=3.252+0.26+0.517 | E22: =3.252+0.26+0.517 -> 4.029 | F22: t | G22: Columns + lift walls + shear walls, Foundation-GF storey
A23: S17 | B23: STR G (p2) | C23: Y12 - walls (substructure) | D23: '=0.39+0.863 | E23: =0.39+0.863 -> 1.253 | F23: t | G23: Wall horizontal bars
A24: S18 | B24: STR H (p2) | C24: Y25 - columns & walls (substructure starters) | D24: '=6.531+4.935+9.84 | E24: =6.531+4.935+9.84 -> 21.306 | F24: t | G24: Column & wall vertical starters
A25: S19 | B25: STR NEW | C25: Y20 - columns (substructure, SWC/type-02 starters) | D25: '=0.338 | E25: =0.338 -> 0.338 | F25: t | G25: Not in BOQ
A26: S20 | B26: STR (p2) Walls fwk | C26: Formwork to concrete walls (substructure), both faces | D26: '=2*(22.05+21.825+25.57)*1.3 | E26: =2*(22.05+21.825+25.57)*1.3 -> 180.557 | F26: m2
A27: S21 | B27: STR J (p2) | C27: Edges of GF bed 150mm high (perimeter) | D27: '=2*(41.0+36.0) | E27: =2*(41.0+36.0) -> 154 | F27: m | G27: Edge <=250 high - measured linear (m), not m2
A28: S22 | B28: STR NEW | C28: Formwork to edges of raft 1300 high | D28: '=2*(41.0+36.0)*1.3 | E28: =2*(41.0+36.0)*1.3 -> 200.2 | F28: m2 | G28: Not in BOQ
A29: S23 | B29: STR NEW | C29: Formwork to columns raft to GF | D29: '=(9*2*(0.75+0.5)+25*2*(1.2+0.3)+2*(2.85+1.075))*1.3 | E29: =(9*2*(0.75+0.5)+25*2*(1.2+0.3)+2*(2.85+1.075))*1.3 -> 136.955 | F29: m2 | G29: Not in BOQ
A30: S24 | B30: STR K (p2) | C30: 150mm blockwork to plinth (GF perimeter, -1.000 to +0.300) | D30: '=2*(41.0+36.0)*1.3 | E30: =2*(41.0+36.0)*1.3 -> 200.2 | F30: m2 | G30: Perimeter of raft x plinth height
A31: C. SUPERSTRUCTURE - CONCRETE (C40)
A32: C1 | B32: STR A (sup) | C32: Lintels 150x225 over all door & window openings (opening width + 150 bearing each end) | D32: '=(1*(1.8+0.3)+59*(1+0.3)+126*(0.9+0.3)+1*(0.9+0.3)+1*(3.2+0.3)+172*(0.75+0.3)+12*(0.7+0.3)+21*(1.2+0.3)+36*(1+0.3)+20*(1+0.3)+13*(0.9+0.3)+3*(1.8+0.3)+7*(1.5+0.3)+18*(0.9+0.3)+36*(0.75+0.3)+8*(0.45+0.3)+24*(0.6+0.3)+2*(1.8+0.3)+2*(2.4+0.3)+1*(5.05+0.3)+8*(3+0.3)+28*(1.6+0.3)+16*(1.3+0.3)+30*(1.8+0.3)+7*(1.2+0.3)+2*(4.2+0.3)+1*(3.6+0.3)+44*(1.8+0.3)+1*(1.8+0.3)+77*(0.9+0.3)+1*(1.8+0.3)+1*(3.5+0.3)+12*(1.8+0.3)+22*(1.2+0.3)+61*(1.2+0.3)+8*(1.2+0.3)+47*(1.5+0.3)+27*(1.5+0.3)+6*(2.4+0.3)+3*(3.6+0.3)+8*(3+0.3)+2*(2.4+0.3)+22*(1.8+0.3)+7*(0.75+0.3)+2*(2.1+0.3)+6*(1.45+0.3)+104*(0.9+0.3)+40*(0.75+0.3)+12*(0.6+0.3)+12*(1.2+0.3))*0.15*0.225 | E32: =(1*(1.8+0.3)+59*(1+0.3)+126*(0.9+0.3)+1*(0.9+0.3)+1*(3.2+0.3)+172*(0.75+0.3)+12*(0.7+0.3)+21*(1.2+0.3)+36*(1+0.3)+20*(1+0.3)+13*(0.9+0.3)+3*(1.8+0.3)+7*(1.5+0.3)+18*(0.9+0.3)+36*(0.75+0.3)+8*(0.45+0.3)+24*(0.6+0.3)+2*(1.8+0.3)+2*(2.4+0.3)+1*(5.05+0.3)+8*(3+0.3)+28*(1.6+0.3)+16*(1.3+0.3)+30*(1.8+0.3)+7*(1.2+0.3)+2*(4.2+0.3)+1*(3.6+0.3)+44*(1.8+0.3)+1*(1.8+0.3)+77*(0.9+0.3)+1*(1.8+0.3)+1*(3.5+0.3)+12*(1.8+0.3)+22*(1.2+0.3)+61*(1.2+0.3)+8*(1.2+0.3)+47*(1.5+0.3)+27*(1.5+0.3)+6*(2.4+0.3)+3*(3.6+0.3)+8*(3+0.3)+2*(2.4+0.3)+22*(1.8+0.3)+7*(0.75+0.3)+2*(2.1+0.3)+6*(1.45+0.3)+104*(0.9+0.3)+40*(0.75+0.3)+12*(0.6+0.3)+12*(1.2+0.3))*0.15*0.225 -> 56.413125 | F32: m3 | G32: Door schedule ARCH-501, window schedule ARCH-502
A33: C2 | B33: STR B (sup) | C33: Columns GF to top: nos x section area x sum of clear storey heights (storey - 0.25 slab) | D33: '=5*0.75*0.5*28.15+1*0.75*0.5*34.25+2*0.75*0.5*37.15+1*0.75*0.5*34+3*1.2*0.3*28.15+6*1.2*0.3*34.25+1*1.2*0.3*37.15+15*1.2*0.3*34+1*(2.85*0.25+0.825*0.25)*28.15 | E33: =5*0.75*0.5*28.15+1*0.75*0.5*34.25+2*0.75*0.5*37.15+1*0.75*0.5*34+3*1.2*0.3*28.15+6*1.2*0.3*34.25+1*1.2*0.3*37.15+15*1.2*0.3*34+1*(2.85*0.25+0.825*0.25)*28.15 -> 433.45631 | F33: m3 | G33: Clear heights per column type from elevations STR-007..012: COL-01A 5 nr 28.15m; COL-01B 1 nr 34.25m; COL-01C 2 nr 37.15m; COL-01D 1 nr 34.00m; COL-02A 3 nr 28.15m; COL-02B 6 nr 34.25m; COL-02C 1 nr 37.15m; COL-02D 15 nr 34.00m; SWC-01A 1 nr 28.15m
A34: C3 | B34: STR C (sup) | C34: Concrete walls GF-roof: main stair core 22.05m x 37.15m clear; lift walls 21.825m x 41.20m; emergency core 25.57m x 37.20m; 250 thk | D34: '=(22.05*37.15+21.825*41.2+25.57*37.2)*0.25 | E34: =(22.05*37.15+21.825*41.2+25.57*37.2)*0.25 -> 667.38788 | F34: m3 | G34: Clear heights = sum(storey heights) - 0.25 per slab (STR-014/016/017 elevations)
A35: C4 | B35: STR D (sup) | C35: Stairs: per storey 2 flights (waist 175, 1800 wide, 3.0m going) + 2 landings; scaled to storey height. Main 10 storeys (sum H 37.0m), emergency 12 storeys (sum H 37.3m) | D35: '=2.966*(37.0+37.3)/3.3+2.625*(10+12) | E35: =2.966*(37.0+37.3)/3.3+2.625*(10+12) -> 124.52994 | F35: m3 | G35: STR-018..039 GA: waist 175, treads 300, risers 150-160; per 3.3m storey: flights 2.966 m3, landings 2.625 m3
A36: C5 | B36: STR E (sup) | C36: Suspended slabs 250 thk (areas measured from GA sheets, voids/stair & lift openings excluded) + roof 150 thk (176.3 m2) + lift-core top 150 thk (16.3 m2) | D36: '=(689.1+737.6+650.6+737.5+554.9+1273.9+1134.6*5+1134.4+868.4+868.1)*0.25+(176.3+16.3)*0.15 | E36: =(689.1+737.6+650.6+737.5+554.9+1273.9+1134.6*5+1134.4+868.4+868.1)*0.25+(176.3+16.3)*0.15 -> 3325.765 | F36: m3 | G36: Slab areas measured on STR-040/046/052/058/064/070/076/083/091/097/104/107 (scale calibrated on gridlines 1-12 = 36,500)
A37: C6 | B37: STR F (sup) | C37: Copings 300x150 to parapets: roof terrace perimeter 182.5 + roof 105.0 + lift core 17.3 | D37: '=(182.5+105.0+17.3)*0.3*0.15 | E37: =(182.5+105.0+17.3)*0.3*0.15 -> 13.716 | F37: m3 | G37: Slab outer perimeters measured on GA sheets
A38: C7 | B38: STR NEW | C38: Beams (downstands below 250 slab): 300x600 = (67.8+81.1+63.6+79.9+64.3+97.4+166.8*5+186.5+122.2+125.7) m; 200x600 = (43.5+43.0+33.1+33.1*5+33.1+14.2+14.2) m; roof 250x600 31.4m & 200x450 34.0m below 150 slab | D38: '=(67.8+81.1+63.6+79.9+64.3+97.4+166.8*5+186.5+122.2+125.7)*0.3*0.35+(43.5+43.0+33.1+33.1*5+33.1+14.2+14.2)*0.2*0.35+31.4*0.25*0.45+34.0*0.2*0.3 | E38: =(67.8+81.1+63.6+79.9+64.3+97.4+166.8*5+186.5+122.2+125.7)*0.3*0.35+(43.5+43.0+33.1+33.1*5+33.1+14.2+14.2)*0.2*0.35+31.4*0.25*0.45+34.0*0.2*0.3 -> 210.697 | F38: m3 | G38: Beam lengths measured from dashed beam outlines on GA sheets. NOT IN BOQ
A39: D. SUPERSTRUCTURE - REINFORCEMENT (from Reinforcement Take-off workbook)
A40: R1 | B40: STR G (sup) | C40: Y10 in columns | D40: '=48.472 | E40: =48.472 -> 48.472 | F40: t
A41: R2 | B41: STR H (sup) | C41: Y20 in columns | D41: '=56.589 | E41: =56.589 -> 56.589 | F41: t
...
