Workbook

Sheet Notes & Assumptions
A1: PROPOSED KANESHIE BLOCK N REDEVELOPMENT - REINFORCEMENT TAKE-OFF
A2: Source: Structural drawings SHC-KANESHIE-STR-000 to STR-107 (108 sheets, Documents.pdf). Take-off prepared floor by floor; all quantities in tonnes.
A4: METHOD OF MEASUREMENT
A5: 1. Every take-off line shows: No. of members x No. of bars per member = Total bars; Total bars x Cut length = Total length; Total length x Unit mass = kg; kg / 1000 = tonnes.
A6: 2. Unit mass of bar (kg/m) = d^2 / 162 (d in mm), calculated by formula in column L of every floor sheet (0.617 kg/m Y10, 0.888 Y12, 1.580 Y16, 2.469 Y20, 3.858 Y25).
A7: 3. Raft, floor slabs, beams, staircases and lift-core slab are taken from the Bar Bending Schedules (BBS) on the drawings (bar mark, diameter, quantity, cut length). Cut lengths already include laps/bends as scheduled.
A8: 4. Floors 4th to 8th are typical (STR-076 to STR-082): the typical schedules are measured once on each of the five floor sheets.
A9: 5. Main staircase typical flight (STR-027, 4th-10th) measured on 4th, 5th, 6th, 7th, 8th and 9th floors (6 storeys). Emergency stair typical flight M1-3rd (STR-033) measured at M1, M2 and Mezzanine; typical 4th-10th (STR-037) on 6 storeys. Staircase BBS quantities are per storey (e.g. 1201: 30 no = 2x15 in plan).
A10: 6. Elements are allocated to the floor they rise FROM: columns, walls and stair flights between level X and the level above are measured under level X. Column/wall starters from the raft to Ground level are measured under Substructure.
A11: 7. Structural levels used (SSL): Raft top -1000, NGL 0, GF +300, M1 +2500, 1st +4150, M2 +5200, 2nd +6850, Mezz +7900, 3rd +10900, 4th +14200 then +3300 per floor to 10th +34000, Roof top terrace +37300, Roof +40450, Top of lift core +44650.
A13: COLUMNS (STR-007 to STR-012)
A14: 8. Number of links and main bars per storey taken from the column elevations (text callouts) x number of columns of each type; cut lengths from the column BBS. Column count confirmed on raft GA STR-002: 01A x5, 01B x1, 01C x2, 01D x1, 02A x3, 02B x6, 02C x1, 02D x15, SWC-01A x1 (35 no.).
... A33: Colour code: blue text = figures transcribed from drawings (inputs); black = formulas.

Sheet Summary
A1: REINFORCEMENT SUMMARY - FLOOR BY FLOOR (TONNES)
A2: Proposed Kaneshie Block N Redevelopment - High yield steel BS4449 grade 500. Values link to the floor sheets (green).
A4: Ref | B4: Floor / level | C4: Raft Foundation | D4: Columns | E4: Shear Walls | F4: Lift Walls | G4: Retaining / Ramp Walls | H4: Beams | I4: Floor Slabs | J4: Staircases | K4: Lift Core Roof Slab | L4: TOTAL (t)
A5: F00 | B5: Raft foundation & starters (Foundation to Ground) | C5: =SUMIF('F00 Substructure'!$B$6:$B$154,"Raft Foundation",'F00 Substructure'!$N$6:$N$154) -> 187.13848 | D5: =SUMIF('F00 Substructure'!$B$6:$B$154,"Columns",'F00 Substructure'!$N$6:$N$154) -> 10.121227 | E5: =SUMIF('F00 Substructure'!$B$6:$B$154,"Shear Walls",'F00 Substructure'!$N$6:$N$154) -> 11.219664 | F5: =SUMIF('F00 Substructure'!$B$6:$B$154,"Lift Walls",'F00 Substructure'!$N$6:$N$154) -> 5.5847052 | G5: =SUMIF('F00 Substructure'!$B$6:$B$154,"Retaining / Ramp Walls",'F00 Substructure'!$N$6:$N$154) -> 0 | H5: =SUMIF('F00 Substructure'!$B$6:$B$154,"Beams",'F00 Substructure'!$N$6:$N$154) -> 0 | I5: =SUMIF('F00 Substructure'!$B$6:$B$154,"Floor Slabs",'F00 Substructure'!$N$6:$N$154) -> 0 | J5: =SUMIF('F00 Substructure'!$B$6:$B$154,"Staircases",'F00 Substructure'!$N$6:$N$154) -> 0 | K5: =SUMIF('F00 Substructure'!$B$6:$B$154,"Lift Core Roof Slab",'F00 Substructure'!$N$6:$N$154) -> 0 | L5: =SUM(C5:K5) -> 214.06407
A6: F01 | B6: Ground floor (+300) - elements rising to next level | C6: =SUMIF('F01 Ground Floor'!$B$6:$B$107,"Raft Foundation",'F01 Ground Floor'!$N$6:$N$107) -> 0 | D6: =SUMIF('F01 Ground Floor'!$B$6:$B$107,"Columns",'F01 Ground Floor'!$N$6:$N$107) -> 15.054202 | E6: =SUMIF('F01 Ground Floor'!$B$6:$B$107,"Shear Walls",'F01 Ground Floor'!$N$6:$N$107) -> 14.507586 | F6: =SUMIF('F01 Ground Floor'!$B$6:$B$107,"Lift Walls",'F01 Ground Floor'!$N$6:$N$107) -> 8.3599768 | G6: =SUMIF('F01 Ground Floor'!$B$6:$B$107,"Retaining / Ramp Walls",'F01 Ground Floor'!$N$6:$N$107) -> 0.83957333 | H6: =SUMIF('F01 Ground Floor'!$B$6:$B$107,"Beams",'F01 Ground Floor'!$N$6:$N$107) -> 0 | I6: =SUMIF('F01 Ground Floor'!$B$6:$B$107,"Floor Slabs",'F01 Ground Floor'!$N$6:$N$107) -> 0 | J6: =SUMIF('F01 Ground Floor'!$B$6:$B$107,"Staircases",'F01 Ground Floor'!$N$6:$N$107) -> 2.0712691 | K6: =SUMIF('F01 Ground Floor'!$B$6:$B$107,"Lift Core Roof Slab",'F01 Ground Floor'!$N$6:$N$107) -> 0 | L6: =SUM(C6:K6) -> 40.832608
A7: F02 | B7: M1 Level 1B Parking (+2500) | C7: =SUMIF('F02 M1 Level'!$B$6:$B$141,"Raft Foundation",'F02 M1 Level'!$N$6:$N$141) -> 0 | D7: =SUMIF('F02 M1 Level'!$B$6:$B$141,"Columns",'F02 M1 Level'!$N$6:$N$141) -> 5.9595617 | E7: =SUMIF('F02 M1 Level'!$B$6:$B$141,"Shear Walls",'F02 M1 Level'!$N$6:$N$141) -> 6.6908321 | F7: =SUMIF('F02 M1 Level'!$B$6:$B$141,"Lift Walls",'F02 M1 Level'!$N$6:$N$141) -> 0 | G7: =SUMIF('F02 M1 Level'!$B$6:$B$141,"Retaining / Ramp Walls",'F02 M1 Level'!$N$6:$N$141) -> 0 | H7: =SUMIF('F02 M1 Level'!$B$6:$B$141,"Beams",'F02 M1 Level'!$N$6:$N$141) -> 4.9530066 | I7: =SUMIF('F02 M1 Level'!$B$6:$B$141,"Floor Slabs",'F02 M1 Level'!$N$6:$N$141) -> 29.315805 | J7: =SUMIF('F02 M1 Level'!$B$6:$B$141,"Staircases",'F02 M1 Level'!$N$6:$N$141) -> 1.1338272 | K7: =SUMIF('F02 M1 Level'!$B$6:$B$141,"Lift Core Roof Slab",'F02 M1 Level'!$N$6:$N$141) -> 0 | L7: =SUM(C7:K7) -> 48.053033
A8: F03 | B8: First Floor Level 2A Parking (+4150) | C8: =SUMIF('F03 First Floor'!$B$6:$B$169,"Raft Foundation",'F03 First Floor'!$N$6:$N$169) -> 0 | D8: =SUMIF('F03 First Floor'!$B$6:$B$169,"Columns",'F03 First Floor'!$N$6:$N$169) -> 7.8130222 | E8: =SUMIF('F03 First Floor'!$B$6:$B$169,"Shear Walls",'F03 First Floor'!$N$6:$N$169) -> 5.7582319 | F8: =SUMIF('F03 First Floor'!$B$6:$B$169,"Lift Walls",'F03 First Floor'!$N$6:$N$169) -> 5.8945788 | G8: =SUMIF('F03 First Floor'!$B$6:$B$169,"Retaining / Ramp Walls",'F03 First Floor'!$N$6:$N$169) -> 0 | H8: =SUMIF('F03 First Floor'!$B$6:$B$169,"Beams",'F03 First Floor'!$N$6:$N$169) -> 5.5100807 | I8: =SUMIF('F03 First Floor'!$B$6:$B$169,"Floor Slabs",'F03 First Floor'!$N$6:$N$169) -> 30.475444 | J8: =SUMIF('F03 First Floor'!$B$6:$B$169,"Staircases",'F03 First Floor'!$N$6:$N$169) -> 1.1798914 | K8: =SUMIF('F03 First Floor'!$B$6:$B$169,"Lift Core Roof Slab",'F03 First Floor'!$N$6:$N$169) -> 0 | L8: =SUM(C8:K8) -> 56.631249
A9: F04 | B9: M2 Level 2B Parking (+5200) | C9: =SUMIF('F04 M2 Level'!$B$6:$B$127,"Raft Foundation",'F04 M2 Level'!$N$6:$N$127) -> 0 | D9: =SUMIF('F04 M2 Level'!$B$6:$B$127,"Columns",'F04 M2 Level'!$N$6:$N$127) -> 5.8728951 | E9: =SUMIF('F04 M2 Level'!$B$6:$B$127,"Shear Walls",'F04 M2 Level'!$N$6:$N$127) -> 6.6908321 | F9: =SUMIF('F04 M2 Level'!$B$6:$B$127,"Lift Walls",'F04 M2 Level'!$N$6:$N$127) -> 0 | G9: =SUMIF('F04 M2 Level'!$B$6:$B$127,"Retaining / Ramp Walls",'F04 M2 Level'!$N$6:$N$127) -> 0 | H9: =SUMIF('F04 M2 Level'!$B$6:$B$127,"Beams",'F04 M2 Level'!$N$6:$N$127) -> 3.530211 | I9: =SUMIF('F04 M2 Level'!$B$6:$B$127,"Floor Slabs",'F04 M2 Level'!$N$6:$N$127) -> 27.517938 | J9: =SUMIF('F04 M2 Level'!$B$6:$B$127,"Staircases",'F04 M2 Level'!$N$6:$N$127) -> 1.1338272 | K9: =SUMIF('F04 M2 Level'!$B$6:$B$127,"Lift Core Roof Slab",'F04 M2 Level'!$N$6:$N$127) -> 0 | L9: =SUM(C9:K9) -> 44.745704
A10: F05 | B10: Second Floor Level 3A Parking (+6850) | C10: =SUMIF('F05 Second Floor'!$B$6:$B$171,"Raft Foundation",'F05 Second Floor'!$N$6:$N$171) -> 0 | D10: =SUMIF('F05 Second Floor'!$B$6:$B$171,"Columns",'F05 Second Floor'!$N$6:$N$171) -> 10.099315 | E10: =SUMIF('F05 Second Floor'!$B$6:$B$171,"Shear Walls",'F05 Second Floor'!$N$6:$N$171) -> 8.0676019 | F10: =SUMIF('F05 Second Floor'!$B$6:$B$171,"Lift Walls",'F05 Second Floor'!$N$6:$N$171) -> 8.2524321 | G10: =SUMIF('F05 Second Floor'!$B$6:$B$171,"Retaining / Ramp Walls",'F05 Second Floor'!$N$6:$N$171) -> 0 | H10: =SUMIF('F05 Second Floor'!$B$6:$B$171,"Beams",'F05 Second Floor'!$N$6:$N$171) -> 4.8648063 | I10: =SUMIF('F05 Second Floor'!$B$6:$B$171,"Floor Slabs",'F05 Second Floor'!$N$6:$N$171) -> 35.155422 | J10: =SUMIF('F05 Second Floor'!$B$6:$B$171,"Staircases",'F05 Second Floor'!$N$6:$N$171) -> 1.1798914 | K10: =SUMIF('F05 Second Floor'!$B$6:$B$171,"Lift Core Roof Slab",'F05 Second Floor'!$N$6:$N$171) -> 0 | L10: =SUM(C10:K10) -> 67.619469
A11: F06 | B11: Mezzanine Floor 3B Parking (+7900) | C11: =SUMIF('F06 Mezzanine Floor'!$B$6:$B$118,"Raft Foundation",'F06 Mezzanine Floor'!$N$6:$N$118) -> 0 | D11: =SUMIF('F06 Mezzanine Floor'!$B$6:$B$118,"Columns",'F06 Mezzanine Floor'!$N$6:$N$118) -> 4.8222469 | E11: =SUMIF('F06 Mezzanine Floor'!$B$6:$B$118,"Shear Walls",'F06 Mezzanine Floor'!$N$6:$N$118) -> 7.2898173 | F11: =SUMIF('F06 Mezzanine Floor'!$B$6:$B$118,"Lift Walls",'F06 Mezzanine Floor'!$N$6:$N$118) -> 0 | G11: =SUMIF('F06 Mezzanine Floor'!$B$6:$B$118,"Retaining / Ramp Walls",'F06 Mezzanine Floor'!$N$6:$N$118) -> 0 | H11: =SUMIF('F06 Mezzanine Floor'!$B$6:$B$118,"Beams",'F06 Mezzanine Floor'!$N$6:$N$118) -> 3.0414878 | I11: =SUMIF('F06 Mezzanine Floor'!$B$6:$B$118,"Floor Slabs",'F06 Mezzanine Floor'!$N$6:$N$118) -> 33.929356 | J11: =SUMIF('F06 Mezzanine Floor'!$B$6:$B$118,"Staircases",'F06 Mezzanine Floor'!$N$6:$N$118) -> 1.1338272 | K11: =SUMIF('F06 Mezzanine Floor'!$B$6:$B$118,"Lift Core Roof Slab",'F06 Mezzanine Floor'!$N$6:$N$118) -> 0 | L11: =SUM(C11:K11) -> 50.216735
A12: F07 | B12: Third Floor (+10900) | C12: =SUMIF('F07 Third Floor'!$B$6:$B$230,"Raft Foundation",'F07 Third Floor'!$N$6:$N$230) -> 0 | D12: =SUMIF('F07 Third Floor'!$B$6:$B$230,"Columns",'F07 Third Floor'!$N$6:$N$230) -> 11.683963 | E12: =SUMIF('F07 Third Floor'!$B$6:$B$230,"Shear Walls",'F07 Third Floor'!$N$6:$N$230) -> 14.673421 | F12: =SUMIF('F07 Third Floor'!$B$6:$B$230,"Lift Walls",'F07 Third Floor'!$N$6:$N$230) -> 6.9425136 | G12: =SUMIF('F07 Third Floor'!$B$6:$B$230,"Retaining / Ramp Walls",'F07 Third Floor'!$N$6:$N$230) -> 0 | H12: =SUMIF('F07 Third Floor'!$B$6:$B$230,"Beams",'F07 Third Floor'!$N$6:$N$230) -> 6.3449904 | I12: =SUMIF('F07 Third Floor'!$B$6:$B$230,"Floor Slabs",'F07 Third Floor'!$N$6:$N$230) -> 56.97337 | J12: =SUMIF('F07 Third Floor'!$B$6:$B$230,"Staircases",'F07 Third Floor'!$N$6:$N$230) -> 2.3137185 | K12: =SUMIF('F07 Third Floor'!$B$6:$B$230,"Lift Core Roof Slab",'F07 Third Floor'!$N$6:$N$230) -> 0 | L12: =SUM(C12:K12) -> 98.931977
A13: F08 | B13: Fourth Floor (+14200) - typical 4th-8th | C13: =SUMIF('F08 Fourth Floor'!$B$6:$B$281,"Raft Foundation",'F08 Fourth Floor'!$N$6:$N$281) -> 0 | D13: =SUMIF('F08 Fourth Floor'!$B$6:$B$281,"Columns",'F08 Fourth Floor'!$N$6:$N$281) -> 11.683963 | E13: =SUMIF('F08 Fourth Floor'!$B$6:$B$281,"Shear Walls",'F08 Fourth Floor'!$N$6:$N$281) -> 10.263575 | F13: =SUMIF('F08 Fourth Floor'!$B$6:$B$281,"Lift Walls",'F08 Fourth Floor'!$N$6:$N$281) -> 6.9425136 | G13: =SUMIF('F08 Fourth Floor'!$B$6:$B$281,"Retaining / Ramp Walls",'F08 Fourth Floor'!$N$6:$N$281) -> 0 | H13: =SUMIF('F08 Fourth Floor'!$B$6:$B$281,"Beams",'F08 Fourth Floor'!$N$6:$N$281) -> 10.695925 | I13: =SUMIF('F08 Fourth Floor'!$B$6:$B$281,"Floor Slabs",'F08 Fourth Floor'!$N$6:$N$281) -> 49.954959 | J13: =SUMIF('F08 Fourth Floor'!$B$6:$B$281,"Staircases",'F08 Fourth Floor'!$N$6:$N$281) -> 2.3137185 | K13: =SUMIF('F08 Fourth Floor'!$B$6:$B$281,"Lift Core Roof Slab",'F08 Fourth Floor'!$N$6:$N$281) -> 0 | L13: =SUM(C13:K13) -> 91.854654
A14: F09 | B14: Fifth Floor (+17500) - typical 4th-8th | C14: =SUMIF('F09 Fifth Floor'!$B$6:$B$281,"Raft Foundation",'F09 Fifth Floor'!$N$6:$N$281) -> 0 | D14: =SUMIF('F09 Fifth Floor'!$B$6:$B$281,"Columns",'F09 Fifth Floor'!$N$6:$N$281) -> 11.683963 | E14: =SUMIF('F09 Fifth Floor'!$B$6:$B$281,"Shear Walls",'F09 Fifth Floor'!$N$6:$N$281) -> 10.263575 | F14: =SUMIF('F09 Fifth Floor'!$B$6:$B$281,"Lift Walls",'F09 Fifth Floor'!$N$6:$N$281) -> 4.8216494 | G14: =SUMIF('F09 Fifth Floor'!$B$6:$B$281,"Retaining / Ramp Walls",'F09 Fifth Floor'!$N$6:$N$281) -> 0 | H14: =SUMIF('F09 Fifth Floor'!$B$6:$B$281,"Beams",'F09 Fifth Floor'!$N$6:$N$281) -> 10.695925 | I14: =SUMIF('F09 Fifth Floor'!$B$6:$B$281,"Floor Slabs",'F09 Fifth Floor'!$N$6:$N$281) -> 49.954959 | J14: =SUMIF('F09 Fifth Floor'!$B$6:$B$281,"Staircases",'F09 Fifth Floor'!$N$6:$N$281) -> 2.3137185 | K14: =SUMIF('F09 Fifth Floor'!$B$6:$B$281,"Lift Core Roof Slab",'F09 Fifth Floor'!$N$6:$N$281) -> 0 | L14: =SUM(C14:K14) -> 89.73379
A15: F10 | B15: Sixth Floor (+20800) - typical 4th-8th | C15: =SUMIF('F10 Sixth Floor'!$B$6:$B$281,"Raft Foundation",'F10 Sixth Floor'!$N$6:$N$281) -> 0 | D15: =SUMIF('F10 Sixth Floor'!$B$6:$B$281,"Columns",'F10 Sixth Floor'!$N$6:$N$281) -> 11.683963 | E15: =SUMIF('F10 Sixth Floor'!$B$6:$B$281,"Shear Walls",'F10 Sixth Floor'!$N$6:$N$281) -> 10.263575 | F15: =SUMIF('F10 Sixth Floor'!$B$6:$B$281,"Lift Walls",'F10 Sixth Floor'!$N$6:$N$281) -> 4.8216494 | G15: =SUMIF('F10 Sixth Floor'!$B$6:$B$281,"Retaining / Ramp Walls",'F10 Sixth Floor'!$N$6:$N$281) -> 0 | H15: =SUMIF('F10 Sixth Floor'!$B$6:$B$281,"Beams",'F10 Sixth Floor'!$N$6:$N$281) -> 10.695925 | I15: =SUMIF('F10 Sixth Floor'!$B$6:$B$281,"Floor Slabs",'F10 Sixth Floor'!$N$6:$N$281) -> 49.954959 | J15: =SUMIF('F10 Sixth Floor'!$B$6:$B$281,"Staircases",'F10 Sixth Floor'!$N$6:$N$281) -> 2.3137185 | K15: =SUMIF('F10 Sixth Floor'!$B$6:$B$281,"Lift Core Roof Slab",'F10 Sixth Floor'!$N$6:$N$281) -> 0 | L15: =SUM(C15:K15) -> 89.73379
A16: F11 | B16: Seventh Floor (+24100) - typical 4th-8th | C16: =SUMIF('F11 Seventh Floor'!$B$6:$B$281,"Raft Foundation",'F11 Seventh Floor'!$N$6:$N$281) -> 0 | D16: =SUMIF('F11 Seventh Floor'!$B$6:$B$281,"Columns",'F11 Seventh Floor'!$N$6:$N$281) -> 11.683963 | E16: =SUMIF('F11 Seventh Floor'!$B$6:$B$281,"Shear Walls",'F11 Seventh Floor'!$N$6:$N$281) -> 10.263575 | F16: =SUMIF('F11 Seventh Floor'!$B$6:$B$281,"Lift Walls",'F11 Seventh Floor'!$N$6:$N$281) -> 4.8216494 | G16: =SUMIF('F11 Seventh Floor'!$B$6:$B$281,"Retaining / Ramp Walls",'F11 Seventh Floor'!$N$6:$N$281) -> 0 | H16: =SUMIF('F11 Seventh Floor'!$B$6:$B$281,"Beams",'F11 Seventh Floor'!$N$6:$N$281) -> 10.695925 | I16: =SUMIF('F11 Seventh Floor'!$B$6:$B$281,"Floor Slabs",'F11 Seventh Floor'!$N$6:$N$281) -> 49.954959 | J16: =SUMIF('F11 Seventh Floor'!$B$6:$B$281,"Staircases",'F11 Seventh Floor'!$N$6:$N$281) -> 2.3137185 | K16: =SUMIF('F11 Seventh Floor'!$B$6:$B$281,"Lift Core Roof Slab",'F11 Seventh Floor'!$N$6:$N$281) -> 0 | L16: =SUM(C16:K16) -> 89.73379
A17: F12 | B17: Eighth Floor (+27400) - typical 4th-8th | C17: =SUMIF('F12 Eighth Floor'!$B$6:$B$281,"Raft Foundation",'F12 Eighth Floor'!$N$6:$N$281) -> 0 | D17: =SUMIF('F12 Eighth Floor'!$B$6:$B$281,"Columns",'F12 Eighth Floor'!$N$6:$N$281) -> 11.431928 | E17: =SUMIF('F12 Eighth Floor'!$B$6:$B$281,"Shear Walls",'F12 Eighth Floor'!$N$6:$N$281) -> 10.263575 | F17: =SUMIF('F12 Eighth Floor'!$B$6:$B$281,"Lift Walls",'F12 Eighth Floor'!$N$6:$N$281) -> 4.8216494 | G17: =SUMIF('F12 Eighth Floor'!$B$6:$B$281,"Retaining / Ramp Walls",'F12 Eighth Floor'!$N$6:$N$281) -> 0 | H17: =SUMIF('F12 Eighth Floor'!$B$6:$B$281,"Beams",'F12 Eighth Floor'!$N$6:$N$281) -> 10.695925 | I17: =SUMIF('F12 Eighth Floor'!$B$6:$B$281,"Floor Slabs",'F12 Eighth Floor'!$N$6:$N$281) -> 49.954959 | J17: =SUMIF('F12 Eighth Floor'!$B$6:$B$281,"Staircases",'F12 Eighth Floor'!$N$6:$N$281) -> 2.3137185 | K17: =SUMIF('F12 Eighth Floor'!$B$6:$B$281,"Lift Core Roof Slab",'F12 Eighth Floor'!$N$6:$N$281) -> 0 | L17: =SUM(C17:K17) -> 89.481756
A18: F13 | B18: Ninth Floor (+30700) | C18: =SUMIF('F13 Ninth Floor'!$B$6:$B$291,"Raft Foundation",'F13 Ninth Floor'!$N$6:$N$291) -> 0 | D18: =SUMIF('F13 Ninth Floor'!$B$6:$B$291,"Columns",'F13 Ninth Floor'!$N$6:$N$291) -> 8.3459037 | E18: =SUMIF('F13 Ninth Floor'!$B$6:$B$291,"Shear Walls",'F13 Ninth Floor'!$N$6:$N$291) -> 10.455291 | F18: =SUMIF('F13 Ninth Floor'!$B$6:$B$291,"Lift Walls",'F13 Ninth Floor'!$N$6:$N$291) -> 4.9082094 | G18: =SUMIF('F13 Ninth Floor'!$B$6:$B$291,"Retaining / Ramp Walls",'F13 Ninth Floor'!$N$6:$N$291) -> 0 | H18: =SUMIF('F13 Ninth Floor'!$B$6:$B$291,"Beams",'F13 Ninth Floor'!$N$6:$N$291) -> 12.147079 | I18: =SUMIF('F13 Ninth Floor'!$B$6:$B$291,"Floor Slabs",'F13 Ninth Floor'!$N$6:$N$291) -> 50.157359 | J18: =SUMIF('F13 Ninth Floor'!$B$6:$B$291,"Staircases",'F13 Ninth Floor'!$N$6:$N$291) -> 2.3137185 | K18: =SUMIF('F13 Ninth Floor'!$B$6:$B$291,"Lift Core Roof Slab",'F13 Ninth Floor'!$N$6:$N$291) -> 0 | L18: =SUM(C18:K18) -> 88.327561
A19: F14 | B19: Tenth Floor (+34000) | C19: =SUMIF('F14 Tenth Floor'!$B$6:$B$253,"Raft Foundation",'F14 Tenth Floor'!$N$6:$N$253) -> 0 | D19: =SUMIF('F14 Tenth Floor'!$B$6:$B$253,"Columns",'F14 Tenth Floor'!$N$6:$N$253) -> 6.5526457 | E19: =SUMIF('F14 Tenth Floor'!$B$6:$B$253,"Shear Walls",'F14 Tenth Floor'!$N$6:$N$253) -> 10.263575 | F19: =SUMIF('F14 Tenth Floor'!$B$6:$B$253,"Lift Walls",'F14 Tenth Floor'!$N$6:$N$253) -> 4.8216494 | G19: =SUMIF('F14 Tenth Floor'!$B$6:$B$253,"Retaining / Ramp Walls",'F14 Tenth Floor'!$N$6:$N$253) -> 0 | H19: =SUMIF('F14 Tenth Floor'!$B$6:$B$253,"Beams",'F14 Tenth Floor'!$N$6:$N$253) -> 7.312361 | I19: =SUMIF('F14 Tenth Floor'!$B$6:$B$253,"Floor Slabs",'F14 Tenth Floor'!$N$6:$N$253) -> 36.423919 | J19: =SUMIF('F14 Tenth Floor'!$B$6:$B$253,"Staircases",'F14 Tenth Floor'!$N$6:$N$253) -> 2.3137185 | K19: =SUMIF('F14 Tenth Floor'!$B$6:$B$253,"Lift Core Roof Slab",'F14 Tenth Floor'!$N$6:$N$253) -> 0 | L19: =SUM(C19:K19) -> 67.687868
A20: F15 | B20: Roof Top Terrace (+37300) | C20: =SUMIF('F15 Roof Top Terrace'!$B$6:$B$216,"Raft Foundation",'F15 Roof Top Terrace'!$N$6:$N$216) -> 0 | D20: =SUMIF('F15 Roof Top Terrace'!$B$6:$B$216,"Columns",'F15 Roof Top Terrace'!$N$6:$N$216) -> 0.63584198 | E20: =SUMIF('F15 Roof Top Terrace'!$B$6:$B$216,"Shear Walls",'F15 Roof Top Terrace'!$N$6:$N$216) -> 9.8495694 | F20: =SUMIF('F15 Roof Top Terrace'!$B$6:$B$216,"Lift Walls",'F15 Roof Top Terrace'!$N$6:$N$216) -> 4.627999 | G20: =SUMIF('F15 Roof Top Terrace'!$B$6:$B$216,"Retaining / Ramp Walls",'F15 Roof Top Terrace'!$N$6:$N$216) -> 0 | H20: =SUMIF('F15 Roof Top Terrace'!$B$6:$B$216,"Beams",'F15 Roof Top Terrace'!$N$6:$N$216) -> 7.254319 | I20: =SUMIF('F15 Roof Top Terrace'!$B$6:$B$216,"Floor Slabs",'F15 Roof Top Terrace'!$N$6:$N$216) -> 43.024607 | J20: =SUMIF('F15 Roof Top Terrace'!$B$6:$B$216,"Staircases",'F15 Roof Top Terrace'!$N$6:$N$216) -> 0 | K20: =SUMIF('F15 Roof Top Terrace'!$B$6:$B$216,"Lift Core Roof Slab",'F15 Roof Top Terrace'!$N$6:$N$216) -> 0 | L20: =SUM(C20:K20) -> 65.392337
A21: F16 | B21: Roof Level (+40450) | C21: =SUMIF('F16 Roof Level'!$B$6:$B$84,"Raft Foundation",'F16 Roof Level'!$N$6:$N$84) -> 0 | D21: =SUMIF('F16 Roof Level'!$B$6:$B$84,"Columns",'F16 Roof Level'!$N$6:$N$84) -> 0 | E21: =SUMIF('F16 Roof Level'!$B$6:$B$84,"Shear Walls",'F16 Roof Level'!$N$6:$N$84) -> 0 | F21: =SUMIF('F16 Roof Level'!$B$6:$B$84,"Lift Walls",'F16 Roof Level'!$N$6:$N$84) -> 5.2477916 | G21: =SUMIF('F16 Roof Level'!$B$6:$B$84,"Retaining / Ramp Walls",'F16 Roof Level'!$N$6:$N$84) -> 0 | H21: =SUMIF('F16 Roof Level'!$B$6:$B$84,"Beams",'F16 Roof Level'!$N$6:$N$84) -> 2.9873941 | I21: =SUMIF('F16 Roof Level'!$B$6:$B$84,"Floor Slabs",'F16 Roof Level'!$N$6:$N$84) -> 4.5732 | J21: =SUMIF('F16 Roof Level'!$B$6:$B$84,"Staircases",'F16 Roof Level'!$N$6:$N$84) -> 0 | K21: =SUMIF('F16 Roof Level'!$B$6:$B$84,"Lift Core Roof Slab",'F16 Roof Level'!$N$6:$N$84) -> 0 | L21: =SUM(C21:K21) -> 12.808386
A22: F17 | B22: Top of Lift Core (+44650) | C22: =SUMIF('F17 Top of Lift Core'!$B$6:$B$9,"Raft Foundation",'F17 Top of Lift Core'!$N$6:$N$9) -> 0 | D22: =SUMIF('F17 Top of Lift Core'!$B$6:$B$9,"Columns",'F17 Top of Lift Core'!$N$6:$N$9) -> 0 | E22: =SUMIF('F17 Top of Lift Core'!$B$6:$B$9,"Shear Walls",'F17 Top of Lift Core'!$N$6:$N$9) -> 0 | F22: =SUMIF('F17 Top of Lift Core'!$B$6:$B$9,"Lift Walls",'F17 Top of Lift Core'!$N$6:$N$9) -> 0 | G22: =SUMIF('F17 Top of Lift Core'!$B$6:$B$9,"Retaining / Ramp Walls",'F17 Top of Lift Core'!$N$6:$N$9) -> 0 | H22: =SUMIF('F17 Top of Lift Core'!$B$6:$B$9,"Beams",'F17 Top of Lift Core'!$N$6:$N$9) -> 0 | I22: =SUMIF('F17 Top of Lift Core'!$B$6:$B$9,"Floor Slabs",'F17 Top of Lift Core'!$N$6:$N$9) -> 0 | J22: =SUMIF('F17 Top of Lift Core'!$B$6:$B$9,"Staircases",'F17 Top of Lift Core'!$N$6:$N$9) -> 0 | K22: =SUMIF('F17 Top of Lift Core'!$B$6:$B$9,"Lift Core Roof Slab",'F17 Top of Lift Core'!$N$6:$N$9) -> 0.36591111 | L22: =SUM(C22:K22) -> 0.36591111
B23: GRAND TOTAL | C23: =SUM(C5:C22) -> 187.13848 | D23: =SUM(D5:D22) -> 145.1286 | E23: =SUM(E5:E22) -> 156.7843 | F23: =SUM(F5:F22) -> 80.868967 | G23: =SUM(G5:G22) -> 0.83957333 | H23: =SUM(H5:H22) -> 111.42536 | I23: =SUM(I5:I22) -> 597.32122 | J23: =SUM(J5:J22) -> 26.342281 | ... L23: =SUM(L5:L22) -> 1306.2147
A26: SUMMARY BY BAR DIAMETER (TONNES)
A27: Ref | B27: Floor / level | C27: Y10 | D27: Y12 | E27: Y16 | F27: Y20 | G27: Y25 | H27: TOTAL (t)
A28: F00 | B28: Raft foundation & starters (Foundation to Ground) | C28: =SUMIF('F00 Substructure'!$F$6:$F$154,10,'F00 Substructure'!$N$6:$N$154) -> 4.0288654 | D28: =SUMIF('F00 Substructure'!$F$6:$F$154,12,'F00 Substructure'!$N$6:$N$154) -> 1.25224 | E28: =SUMIF('F00 Substructure'!$F$6:$F$154,16,'F00 Substructure'!$N$6:$N$154) -> 0 | F28: =SUMIF('F00 Substructure'!$F$6:$F$154,20,'F00 Substructure'!$N$6:$N$154) -> 2.8040741 | G28: =SUMIF('F00 Substructure'!$F$6:$F$154,25,'F00 Substructure'!$N$6:$N$154) -> 205.97889 | H28: =SUM(C28:G28) -> 214.06407
A29: F01 | B29: Ground floor (+300) - elements rising to next level | C29: =SUMIF('F01 Ground Floor'!$F$6:$F$107,10,'F01 Ground Floor'!$N$6:$N$107) -> 6.4979062 | D29: =SUMIF('F01 Ground Floor'!$F$6:$F$107,12,'F01 Ground Floor'!$N$6:$N$107) -> 5.4585244 | E29: =SUMIF('F01 Ground Floor'!$F$6:$F$107,16,'F01 Ground Floor'!$N$6:$N$107) -> 1.1916247 | F29: =SUMIF('F01 Ground Floor'!$F$6:$F$107,20,'F01 Ground Floor'!$N$6:$N$107) -> 0.59851852 | G29: =SUMIF('F01 Ground Floor'!$F$6:$F$107,25,'F01 Ground Floor'!$N$6:$N$107) -> 27.086034 | H29: =SUM(C29:G29) -> 40.832608
A30: F02 | B30: M1 Level 1B Parking (+2500) | C30: =SUMIF('F02 M1 Level'!$F$6:$F$141,10,'F02 M1 Level'!$N$6:$N$141) -> 3.4423086 | D30: =SUMIF('F02 M1 Level'!$F$6:$F$141,12,'F02 M1 Level'!$N$6:$N$141) -> 26.848644 | E30: =SUMIF('F02 M1 Level'!$F$6:$F$141,16,'F02 M1 Level'!$N$6:$N$141) -> 5.011358 | F30: =SUMIF('F02 M1 Level'!$F$6:$F$141,20,'F02 M1 Level'!$N$6:$N$141) -> 0.8137037 | G30: =SUMIF('F02 M1 Level'!$F$6:$F$141,25,'F02 M1 Level'!$N$6:$N$141) -> 11.937018 | H30: =SUM(C30:G30) -> 48.053033
A31: F03 | B31: First Floor Level 2A Parking (+4150) | C31: =SUMIF('F03 First Floor'!$F$6:$F$169,10,'F03 First Floor'!$N$6:$N$169) -> 4.733763 | D31: =SUMIF('F03 First Floor'!$F$6:$F$169,12,'F03 First Floor'!$N$6:$N$169) -> 29.778627 | E31: =SUMIF('F03 First Floor'!$F$6:$F$169,16,'F03 First Floor'!$N$6:$N$169) -> 4.0308543 | F31: =SUMIF('F03 First Floor'!$F$6:$F$169,20,'F03 First Floor'!$N$6:$N$169) -> 1.2590123 | G31: =SUMIF('F03 First Floor'!$F$6:$F$169,25,'F03 First Floor'!$N$6:$N$169) -> 16.828993 | H31: =SUM(C31:G31) -> 56.631249
A32: F04 | B32: M2 Level 2B Parking (+5200) | C32: =SUMIF('F04 M2 Level'!$F$6:$F$127,10,'F04 M2 Level'!$N$6:$N$127) -> 2.960642 | D32: =SUMIF('F04 M2 Level'!$F$6:$F$127,12,'F04 M2 Level'!$N$6:$N$127) -> 25.050778 | E32: =SUMIF('F04 M2 Level'!$F$6:$F$127,16,'F04 M2 Level'!$N$6:$N$127) -> 4.8953679 | F32: =SUMIF('F04 M2 Level'!$F$6:$F$127,20,'F04 M2 Level'!$N$6:$N$127) -> 0.9562963 | G32: =SUMIF('F04 M2 Level'!$F$6:$F$127,25,'F04 M2 Level'!$N$6:$N$127) -> 10.88262 | H32: =SUM(C32:G32) -> 44.745704
A33: F05 | B33: Second Floor Level 3A Parking (+6850) | C33: =SUMIF('F05 Second Floor'!$F$6:$F$171,10,'F05 Second Floor'!$N$6:$N$171) -> 5.7003333 | D33: =SUMIF('F05 Second Floor'!$F$6:$F$171,12,'F05 Second Floor'!$N$6:$N$171) -> 37.7408 | E33: =SUMIF('F05 Second Floor'!$F$6:$F$171,16,'F05 Second Floor'!$N$6:$N$171) -> 1.5080691 | F33: =SUMIF('F05 Second Floor'!$F$6:$F$171,20,'F05 Second Floor'!$N$6:$N$171) -> 1.4190123 | G33: =SUMIF('F05 Second Floor'!$F$6:$F$171,25,'F05 Second Floor'!$N$6:$N$171) -> 21.251254 | H33: =SUM(C33:G33) -> 67.619469
A34: F06 | B34: Mezzanine Floor 3B Parking (+7900) | C34: =SUMIF('F06 Mezzanine Floor'!$F$6:$F$118,10,'F06 Mezzanine Floor'!$N$6:$N$118) -> 2.9689136 | D34: =SUMIF('F06 Mezzanine Floor'!$F$6:$F$118,12,'F06 Mezzanine Floor'!$N$6:$N$118) -> 35.308378 | E34: =SUMIF('F06 Mezzanine Floor'!$F$6:$F$118,16,'F06 Mezzanine Floor'!$N$6:$N$118) -> 1.1003654 | F34: =SUMIF('F06 Mezzanine Floor'!$F$6:$F$118,20,'F06 Mezzanine Floor'!$N$6:$N$118) -> 4.3366667 | G34: =SUMIF('F06 Mezzanine Floor'!$F$6:$F$118,25,'F06 Mezzanine Floor'!$N$6:$N$118) -> 6.5024113 | H34: =SUM(C34:G34) -> 50.216735
A35: F07 | B35: Third Floor (+10900) | C35: =SUMIF('F07 Third Floor'!$F$6:$F$230,10,'F07 Third Floor'!$N$6:$N$230) -> 7.7926667 | D35: =SUMIF('F07 Third Floor'!$F$6:$F$230,12,'F07 Third Floor'!$N$6:$N$230) -> 60.490111 | E35: =SUMIF('F07 Third Floor'!$F$6:$F$230,16,'F07 Third Floor'!$N$6:$N$230) -> 2.5831111 | F35: =SUMIF('F07 Third Floor'!$F$6:$F$230,20,'F07 Third Floor'!$N$6:$N$230) -> 9.2950617 | G35: =SUMIF('F07 Third Floor'!$F$6:$F$230,25,'F07 Third Floor'!$N$6:$N$230) -> 18.771026 | H35: =SUM(C35:G35) -> 98.931977
A36: F08 | B36: Fourth Floor (+14200) - typical 4th-8th | C36: =SUMIF('F08 Fourth Floor'!$F$6:$F$281,10,'F08 Fourth Floor'!$N$6:$N$281) -> 8.434642 | D36: =SUMIF('F08 Fourth Floor'!$F$6:$F$281,12,'F08 Fourth Floor'!$N$6:$N$281) -> 53.466841 | E36: =SUMIF('F08 Fourth Floor'!$F$6:$F$281,16,'F08 Fourth Floor'!$N$6:$N$281) -> 2.8322765 | F36: =SUMIF('F08 Fourth Floor'!$F$6:$F$281,20,'F08 Fourth Floor'!$N$6:$N$281) -> 16.172593 | G36: =SUMIF('F08 Fourth Floor'!$F$6:$F$281,25,'F08 Fourth Floor'!$N$6:$N$281) -> 10.948302 | H36: =SUM(C36:G36) -> 91.854654
A37: F09 | B37: Fifth Floor (+17500) - typical 4th-8th | C37: =SUMIF('F09 Fifth Floor'!$F$6:$F$281,10,'F09 Fifth Floor'!$N$6:$N$281) -> 8.434642 | D37: =SUMIF('F09 Fifth Floor'!$F$6:$F$281,12,'F09 Fifth Floor'!$N$6:$N$281) -> 53.466841 | E37: =SUMIF('F09 Fifth Floor'!$F$6:$F$281,16,'F09 Fifth Floor'!$N$6:$N$281) -> 2.8322765 | F37: =SUMIF('F09 Fifth Floor'!$F$6:$F$281,20,'F09 Fifth Floor'!$N$6:$N$281) -> 19.493086 | G37: =SUMIF('F09 Fifth Floor'!$F$6:$F$281,25,'F09 Fifth Floor'!$N$6:$N$281) -> 5.5069444 | H37: =SUM(C37:G37) -> 89.73379
A38: F10 | B38: Sixth Floor (+20800) - typical 4th-8th | C38: =SUMIF('F10 Sixth Floor'!$F$6:$F$281,10,'F10 Sixth Floor'!$N$6:$N$281) -> 8.434642 | D38: =SUMIF('F10 Sixth Floor'!$F$6:$F$281,12,'F10 Sixth Floor'!$N$6:$N$281) -> 53.466841 | E38: =SUMIF('F10 Sixth Floor'!$F$6:$F$281,16,'F10 Sixth Floor'!$N$6:$N$281) -> 2.8322765 | F38: =SUMIF('F10 Sixth Floor'!$F$6:$F$281,20,'F10 Sixth Floor'!$N$6:$N$281) -> 19.493086 | G38: =SUMIF('F10 Sixth Floor'!$F$6:$F$281,25,'F10 Sixth Floor'!$N$6:$N$281) -> 5.5069444 | H38: =SUM(C38:G38) -> 89.73379
A39: F11 | B39: Seventh Floor (+24100) - typical 4th-8th | C39: =SUMIF('F11 Seventh Floor'!$F$6:$F$281,10,'F11 Seventh Floor'!$N$6:$N$281) -> 8.434642 | D39: =SUMIF('F11 Seventh Floor'!$F$6:$F$281,12,'F11 Seventh Floor'!$N$6:$N$281) -> 53.466841 | E39: =SUMIF('F11 Seventh Floor'!$F$6:$F$281,16,'F11 Seventh Floor'!$N$6:$N$281) -> 2.8322765 | F39: =SUMIF('F11 Seventh Floor'!$F$6:$F$281,20,'F11 Seventh Floor'!$N$6:$N$281) -> 19.493086 | G39: =SUMIF('F11 Seventh Floor'!$F$6:$F$281,25,'F11 Seventh Floor'!$N$6:$N$281) -> 5.5069444 | H39: =SUM(C39:G39) -> 89.73379
A40: F12 | B40: Eighth Floor (+27400) - typical 4th-8th | C40: =SUMIF('F12 Eighth Floor'!$F$6:$F$281,10,'F12 Eighth Floor'!$N$6:$N$281) -> 8.3931506 | D40: =SUMIF('F12 Eighth Floor'!$F$6:$F$281,12,'F12 Eighth Floor'!$N$6:$N$281) -> 53.466841 | E40: =SUMIF('F12 Eighth Floor'!$F$6:$F$281,16,'F12 Eighth Floor'!$N$6:$N$281) -> 2.8322765 | F40: =SUMIF('F12 Eighth Floor'!$F$6:$F$281,20,'F12 Eighth Floor'!$N$6:$N$281) -> 18.658469 | G40: =SUMIF('F12 Eighth Floor'!$F$6:$F$281,25,'F12 Eighth Floor'!$N$6:$N$281) -> 6.1310185 | H40: =SUM(C40:G40) -> 89.481756
A41: F13 | B41: Ninth Floor (+30700) | C41: =SUMIF('F13 Ninth Floor'!$F$6:$F$291,10,'F13 Ninth Floor'!$N$6:$N$291) -> 7.3442988 | D41: =SUMIF('F13 Ninth Floor'!$F$6:$F$291,12,'F13 Ninth Floor'!$N$6:$N$291) -> 53.947516 | E41: =SUMIF('F13 Ninth Floor'!$F$6:$F$291,16,'F13 Ninth Floor'!$N$6:$N$291) -> 2.7480494 | F41: =SUMIF('F13 Ninth Floor'!$F$6:$F$291,20,'F13 Ninth Floor'!$N$6:$N$291) -> 17.796667 | G41: =SUMIF('F13 Ninth Floor'!$F$6:$F$291,25,'F13 Ninth Floor'!$N$6:$N$291) -> 6.4910301 | H41: =SUM(C41:G41) -> 88.327561
A42: F14 | B42: Tenth Floor (+34000) | C42: =SUMIF('F14 Tenth Floor'!$F$6:$F$253,10,'F14 Tenth Floor'!$N$6:$N$253) -> 5.7719049 | D42: =SUMIF('F14 Tenth Floor'!$F$6:$F$253,12,'F14 Tenth Floor'!$N$6:$N$253) -> 39.938644 | E42: =SUMIF('F14 Tenth Floor'!$F$6:$F$253,16,'F14 Tenth Floor'!$N$6:$N$253) -> 2.8006716 | F42: =SUMIF('F14 Tenth Floor'!$F$6:$F$253,20,'F14 Tenth Floor'!$N$6:$N$253) -> 15.119259 | G42: =SUMIF('F14 Tenth Floor'!$F$6:$F$253,25,'F14 Tenth Floor'!$N$6:$N$253) -> 4.0573881 | H42: =SUM(C42:G42) -> 67.687868
A43: F15 | B43: Roof Top Terrace (+37300) | C43: =SUMIF('F15 Roof Top Terrace'!$F$6:$F$216,10,'F15 Roof Top Terrace'!$N$6:$N$216) -> 3.5047926 | D43: =SUMIF('F15 Roof Top Terrace'!$F$6:$F$216,12,'F15 Roof Top Terrace'!$N$6:$N$216) -> 45.484284 | E43: =SUMIF('F15 Roof Top Terrace'!$F$6:$F$216,16,'F15 Roof Top Terrace'!$N$6:$N$216) -> 1.440316 | F43: =SUMIF('F15 Roof Top Terrace'!$F$6:$F$216,20,'F15 Roof Top Terrace'!$N$6:$N$216) -> 11.340741 | G43: =SUMIF('F15 Roof Top Terrace'!$F$6:$F$216,25,'F15 Roof Top Terrace'!$N$6:$N$216) -> 3.6222029 | H43: =SUM(C43:G43) -> 65.392337
...

Sheet Element x Size by Floor
A1: EACH ELEMENT BY FLOOR AND BAR SIZE (TONNES) - with totals for all floors
A2: Values link to the element/bar-size summary at the foot of each floor sheet (green).
A4: RAFT FOUNDATION
A5: Ref | B5: Floor / level | C5: Y10 | D5: Y12 | E5: Y16 | F5: Y20 | G5: Y25 | H5: TOTAL (t)
A6: F00 | B6: Raft foundation & starters (Foundation to Ground) | C6: ='F00 Substructure'!E158 -> 0 | D6: ='F00 Substructure'!F158 -> 0 | E6: ='F00 Substructure'!G158 -> 0 | F6: ='F00 Substructure'!H158 -> 2.4662963 | G6: ='F00 Substructure'!I158 -> 184.67218 | H6: =SUM(C6:G6) -> 187.13848
A7: F01 | B7: Ground floor (+300) - elements rising to next level | C7: ='F01 Ground Floor'!E111 -> 0 | D7: ='F01 Ground Floor'!F111 -> 0 | E7: ='F01 Ground Floor'!G111 -> 0 | F7: ='F01 Ground Floor'!H111 -> 0 | G7: ='F01 Ground Floor'!I111 -> 0 | H7: =SUM(C7:G7) -> 0
A8: F02 | B8: M1 Level 1B Parking (+2500) | C8: ='F02 M1 Level'!E145 -> 0 | D8: ='F02 M1 Level'!F145 -> 0 | E8: ='F02 M1 Level'!G145 -> 0 | F8: ='F02 M1 Level'!H145 -> 0 | G8: ='F02 M1 Level'!I145 -> 0 | H8: =SUM(C8:G8) -> 0
A9: F03 | B9: First Floor Level 2A Parking (+4150) | C9: ='F03 First Floor'!E173 -> 0 | D9: ='F03 First Floor'!F173 -> 0 | E9: ='F03 First Floor'!G173 -> 0 | F9: ='F03 First Floor'!H173 -> 0 | G9: ='F03 First Floor'!I173 -> 0 | H9: =SUM(C9:G9) -> 0
A10: F04 | B10: M2 Level 2B Parking (+5200) | C10: ='F04 M2 Level'!E131 -> 0 | D10: ='F04 M2 Level'!F131 -> 0 | E10: ='F04 M2 Level'!G131 -> 0 | F10: ='F04 M2 Level'!H131 -> 0 | G10: ='F04 M2 Level'!I131 -> 0 | H10: =SUM(C10:G10) -> 0
A11: F05 | B11: Second Floor Level 3A Parking (+6850) | C11: ='F05 Second Floor'!E175 -> 0 | D11: ='F05 Second Floor'!F175 -> 0 | E11: ='F05 Second Floor'!G175 -> 0 | F11: ='F05 Second Floor'!H175 -> 0 | G11: ='F05 Second Floor'!I175 -> 0 | H11: =SUM(C11:G11) -> 0
A12: F06 | B12: Mezzanine Floor 3B Parking (+7900) | C12: ='F06 Mezzanine Floor'!E122 -> 0 | D12: ='F06 Mezzanine Floor'!F122 -> 0 | E12: ='F06 Mezzanine Floor'!G122 -> 0 | F12: ='F06 Mezzanine Floor'!H122 -> 0 | G12: ='F06 Mezzanine Floor'!I122 -> 0 | H12: =SUM(C12:G12) -> 0
A13: F07 | B13: Third Floor (+10900) | C13: ='F07 Third Floor'!E234 -> 0 | D13: ='F07 Third Floor'!F234 -> 0 | E13: ='F07 Third Floor'!G234 -> 0 | F13: ='F07 Third Floor'!H234 -> 0 | G13: ='F07 Third Floor'!I234 -> 0 | H13: =SUM(C13:G13) -> 0
A14: F08 | B14: Fourth Floor (+14200) - typical 4th-8th | C14: ='F08 Fourth Floor'!E285 -> 0 | D14: ='F08 Fourth Floor'!F285 -> 0 | E14: ='F08 Fourth Floor'!G285 -> 0 | F14: ='F08 Fourth Floor'!H285 -> 0 | G14: ='F08 Fourth Floor'!I285 -> 0 | H14: =SUM(C14:G14) -> 0
A15: F09 | B15: Fifth Floor (+17500) - typical 4th-8th | C15: ='F09 Fifth Floor'!E285 -> 0 | D15: ='F09 Fifth Floor'!F285 -> 0 | E15: ='F09 Fifth Floor'!G285 -> 0 | F15: ='F09 Fifth Floor'!H285 -> 0 | G15: ='F09 Fifth Floor'!I285 -> 0 | H15: =SUM(C15:G15) -> 0
A16: F10 | B16: Sixth Floor (+20800) - typical 4th-8th | C16: ='F10 Sixth Floor'!E285 -> 0 | D16: ='F10 Sixth Floor'!F285 -> 0 | E16: ='F10 Sixth Floor'!G285 -> 0 | F16: ='F10 Sixth Floor'!H285 -> 0 | G16: ='F10 Sixth Floor'!I285 -> 0 | H16: =SUM(C16:G16) -> 0
A17: F11 | B17: Seventh Floor (+24100) - typical 4th-8th | C17: ='F11 Seventh Floor'!E285 -> 0 | D17: ='F11 Seventh Floor'!F285 -> 0 | E17: ='F11 Seventh Floor'!G285 -> 0 | F17: ='F11 Seventh Floor'!H285 -> 0 | G17: ='F11 Seventh Floor'!I285 -> 0 | H17: =SUM(C17:G17) -> 0
A18: F12 | B18: Eighth Floor (+27400) - typical 4th-8th | C18: ='F12 Eighth Floor'!E285 -> 0 | D18: ='F12 Eighth Floor'!F285 -> 0 | E18: ='F12 Eighth Floor'!G285 -> 0 | F18: ='F12 Eighth Floor'!H285 -> 0 | G18: ='F12 Eighth Floor'!I285 -> 0 | H18: =SUM(C18:G18) -> 0
A19: F13 | B19: Ninth Floor (+30700) | C19: ='F13 Ninth Floor'!E295 -> 0 | D19: ='F13 Ninth Floor'!F295 -> 0 | E19: ='F13 Ninth Floor'!G295 -> 0 | F19: ='F13 Ninth Floor'!H295 -> 0 | G19: ='F13 Ninth Floor'!I295 -> 0 | H19: =SUM(C19:G19) -> 0
A20: F14 | B20: Tenth Floor (+34000) | C20: ='F14 Tenth Floor'!E257 -> 0 | D20: ='F14 Tenth Floor'!F257 -> 0 | E20: ='F14 Tenth Floor'!G257 -> 0 | F20: ='F14 Tenth Floor'!H257 -> 0 | G20: ='F14 Tenth Floor'!I257 -> 0 | H20: =SUM(C20:G20) -> 0
A21: F15 | B21: Roof Top Terrace (+37300) | C21: ='F15 Roof Top Terrace'!E220 -> 0 | D21: ='F15 Roof Top Terrace'!F220 -> 0 | E21: ='F15 Roof Top Terrace'!G220 -> 0 | F21: ='F15 Roof Top Terrace'!H220 -> 0 | G21: ='F15 Roof Top Terrace'!I220 -> 0 | H21: =SUM(C21:G21) -> 0
A22: F16 | B22: Roof Level (+40450) | C22: ='F16 Roof Level'!E88 -> 0 | D22: ='F16 Roof Level'!F88 -> 0 | E22: ='F16 Roof Level'!G88 -> 0 | F22: ='F16 Roof Level'!H88 -> 0 | G22: ='F16 Roof Level'!I88 -> 0 | H22: =SUM(C22:G22) -> 0
A23: F17 | B23: Top of Lift Core (+44650) | C23: ='F17 Top of Lift Core'!E13 -> 0 | D23: ='F17 Top of Lift Core'!F13 -> 0 | E23: ='F17 Top of Lift Core'!G13 -> 0 | F23: ='F17 Top of Lift Core'!H13 -> 0 | G23: ='F17 Top of Lift Core'!I13 -> 0 | H23: =SUM(C23:G23) -> 0
B24: TOTAL RAFT FOUNDATION - ALL FLOORS | C24: =SUM(C6:C23) -> 0 | D24: =SUM(D6:D23) -> 0 | E24: =SUM(E6:E23) -> 0 | F24: =SUM(F6:F23) -> 2.4662963 | G24: =SUM(G6:G23) -> 184.67218 | H24: =SUM(H6:H23) -> 187.13848
A27: COLUMNS
A28: Ref | B28: Floor / level | C28: Y10 | D28: Y12 | E28: Y16 | F28: Y20 | G28: Y25 | H28: TOTAL (t)
A29: F00 | B29: Raft foundation & starters (Foundation to Ground) | C29: ='F00 Substructure'!E159 -> 3.2521988 | D29: ='F00 Substructure'!F159 -> 0 | E29: ='F00 Substructure'!G159 -> 0 | F29: ='F00 Substructure'!H159 -> 0.33777778 | G29: ='F00 Substructure'!I159 -> 6.53125 | H29: =SUM(C29:G29) -> 10.121227
A30: F01 | B30: Ground floor (+300) - elements rising to next level | C30: ='F01 Ground Floor'!E112 -> 4.3723506 | D30: ='F01 Ground Floor'!F112 -> 0 | E30: ='F01 Ground Floor'!G112 -> 0 | F30: ='F01 Ground Floor'!H112 -> 0.59851852 | G30: ='F01 Ground Floor'!I112 -> 10.083333 | H30: =SUM(C30:G30) -> 15.054202
A31: F02 | B31: M1 Level 1B Parking (+2500) | C31: ='F02 M1 Level'!E146 -> 1.656321 | D31: ='F02 M1 Level'!F146 -> 0 | E31: ='F02 M1 Level'!G146 -> 0 | F31: ='F02 M1 Level'!H146 -> 0 | G31: ='F02 M1 Level'!I146 -> 4.3032407 | H31: =SUM(C31:G31) -> 5.9595617
A32: F03 | B32: First Floor Level 2A Parking (+4150) | C32: ='F03 First Floor'!E174 -> 2.7165407 | D32: ='F03 First Floor'!F174 -> 0 | E32: ='F03 First Floor'!G174 -> 0 | F32: ='F03 First Floor'!H174 -> 0.46222222 | G32: ='F03 First Floor'!I174 -> 4.6342593 | H32: =SUM(C32:G32) -> 7.8130222
A33: F04 | B33: M2 Level 2B Parking (+5200) | C33: ='F04 M2 Level'!E132 -> 1.656321 | D33: ='F04 M2 Level'!F132 -> 0 | E33: ='F04 M2 Level'!G132 -> 0 | F33: ='F04 M2 Level'!H132 -> 0.15407407 | G33: ='F04 M2 Level'!I132 -> 4.0625 | H33: =SUM(C33:G33) -> 5.8728951
A34: F05 | B34: Second Floor Level 3A Parking (+6850) | C34: ='F05 Second Floor'!E176 -> 3.2386667 | D34: ='F05 Second Floor'!F176 -> 0 | E34: ='F05 Second Floor'!G176 -> 0 | F34: ='F05 Second Floor'!H176 -> 0.62222222 | G34: ='F05 Second Floor'!I176 -> 6.2384259 | H34: =SUM(C34:G34) -> 10.099315
A35: F06 | B35: Mezzanine Floor 3B Parking (+7900) | C35: ='F06 Mezzanine Floor'!E123 -> 1.656321 | D35: ='F06 Mezzanine Floor'!F123 -> 0 | E35: ='F06 Mezzanine Floor'!G123 -> 0 | F35: ='F06 Mezzanine Floor'!H123 -> 3.1659259 | G35: ='F06 Mezzanine Floor'!I123 -> 0 | H35: =SUM(C35:G35) -> 4.8222469
A36: F07 | B36: Third Floor (+10900) | C36: ='F07 Third Floor'!E235 -> 4.5506296 | D36: ='F07 Third Floor'!F235 -> 0 | E36: ='F07 Third Floor'!G235 -> 0 | F36: ='F07 Third Floor'!H235 -> 7.1333333 | G36: ='F07 Third Floor'!I235 -> 0 | H36: =SUM(C36:G36) -> 11.683963
A37: F08 | B37: Fourth Floor (+14200) - typical 4th-8th | C37: ='F08 Fourth Floor'!E286 -> 4.5506296 | D37: ='F08 Fourth Floor'!F286 -> 0 | E37: ='F08 Fourth Floor'!G286 -> 0 | F37: ='F08 Fourth Floor'!H286 -> 7.1333333 | G37: ='F08 Fourth Floor'!I286 -> 0 | H37: =SUM(C37:G37) -> 11.683963
A38: F09 | B38: Fifth Floor (+17500) - typical 4th-8th | C38: ='F09 Fifth Floor'!E286 -> 4.5506296 | D38: ='F09 Fifth Floor'!F286 -> 0 | E38: ='F09 Fifth Floor'!G286 -> 0 | F38: ='F09 Fifth Floor'!H286 -> 7.1333333 | G38: ='F09 Fifth Floor'!I286 -> 0 | H38: =SUM(C38:G38) -> 11.683963
A39: F10 | B39: Sixth Floor (+20800) - typical 4th-8th | C39: ='F10 Sixth Floor'!E286 -> 4.5506296 | D39: ='F10 Sixth Floor'!F286 -> 0 | E39: ='F10 Sixth Floor'!G286 -> 0 | F39: ='F10 Sixth Floor'!H286 -> 7.1333333 | G39: ='F10 Sixth Floor'!I286 -> 0 | H39: =SUM(C39:G39) -> 11.683963
A40: F11 | B40: Seventh Floor (+24100) - typical 4th-8th | C40: ='F11 Seventh Floor'!E286 -> 4.5506296 | D40: ='F11 Seventh Floor'!F286 -> 0 | E40: ='F11 Seventh Floor'!G286 -> 0 | F40: ='F11 Seventh Floor'!H286 -> 7.1333333 | G40: ='F11 Seventh Floor'!I286 -> 0 | H40: =SUM(C40:G40) -> 11.683963
A41: F12 | B41: Eighth Floor (+27400) - typical 4th-8th | C41: ='F12 Eighth Floor'!E286 -> 4.5091383 | D41: ='F12 Eighth Floor'!F286 -> 0 | E41: ='F12 Eighth Floor'!G286 -> 0 | F41: ='F12 Eighth Floor'!H286 -> 6.298716 | G41: ='F12 Eighth Floor'!I286 -> 0.62407407 | H41: =SUM(C41:G41) -> 11.431928
A42: F13 | B42: Ninth Floor (+30700) | C42: ='F13 Ninth Floor'!E296 -> 3.2347926 | D42: ='F13 Ninth Floor'!F296 -> 0 | E42: ='F13 Ninth Floor'!G296 -> 0 | F42: ='F13 Ninth Floor'!H296 -> 5.1111111 | G42: ='F13 Ninth Floor'!I296 -> 0 | H42: =SUM(C42:G42) -> 8.3459037
A43: F14 | B43: Tenth Floor (+34000) | C43: ='F14 Tenth Floor'!E258 -> 2.4684481 | D43: ='F14 Tenth Floor'!F258 -> 0 | E43: ='F14 Tenth Floor'!G258 -> 0 | F43: ='F14 Tenth Floor'!H258 -> 4.0841975 | G43: ='F14 Tenth Floor'!I258 -> 0 | H43: =SUM(C43:G43) -> 6.5526457
...

Sheet F00 Substructure
A1: REINFORCEMENT TAKE-OFF - RAFT FOUNDATION & STARTERS (FOUNDATION TO GROUND)
A2: Proposed Kaneshie Block N Redevelopment
A3: Calculation per line: Total bars = members x bars/member; Total length = bars x cut length; kg = length x d^2/162; t = kg/1000
A5: Item | B5: Element | C5: Drawing | D5: Description / location | E5: Bar mark | F5: Dia (mm) | G5: No. of members | H5: No. of bars per member | I5: Total no. of bars | J5: Cut length per bar (m) | K5: Total length (m) | L5: Unit mass (kg/m) | M5: Weight (kg) | N5: Weight (t) | O5: Source
A6: 1 | B6: Raft Foundation | C6: STR-004 | D6: Raft - bottom reinforcement | E6: 2501 | F6: 25 | G6: 1 | H6: 272 | I6: =G6*H6 -> 272 | J6: =8725/1000 -> 8.725 | K6: =I6*J6 -> 2373.2 | L6: =F6^2/162 -> 3.8580247 | M6: =K6*L6 -> 9155.8642 | N6: =M6/1000 -> 9.1558642 | O6: BBS
A7: 2 | B7: Raft Foundation | C7: STR-004 | D7: Raft - bottom reinforcement | E7: 2502 | F7: 25 | G7: 1 | H7: 88 | I7: =G7*H7 -> 88 | J7: =8375/1000 -> 8.375 | K7: =I7*J7 -> 737 | L7: =F7^2/162 -> 3.8580247 | M7: =K7*L7 -> 2843.3642 | N7: =M7/1000 -> 2.8433642 | O7: BBS
A8: 3 | B8: Raft Foundation | C8: STR-004 | D8: Raft - bottom reinforcement | E8: 2503 | F8: 25 | G8: 1 | H8: 92 | I8: =G8*H8 -> 92 | J8: =10387/1000 -> 10.387 | K8: =I8*J8 -> 955.604 | L8: =F8^2/162 -> 3.8580247 | M8: =K8*L8 -> 3686.7438 | N8: =M8/1000 -> 3.6867438 | O8: BBS
A9: 4 | B9: Raft Foundation | C9: STR-004 | D9: Raft - bottom reinforcement | E9: 2504 | F9: 25 | G9: 1 | H9: 84 | I9: =G9*H9 -> 84 | J9: =11025/1000 -> 11.025 | K9: =I9*J9 -> 926.1 | L9: =F9^2/162 -> 3.8580247 | M9: =K9*L9 -> 3572.9167 | N9: =M9/1000 -> 3.5729167 | O9: BBS
A10: 5 | B10: Raft Foundation | C10: STR-004 | D10: Raft - bottom reinforcement | E10: 2504A | F10: 25 | G10: 1 | H10: 84 | I10: =G10*H10 -> 84 | J10: =10600/1000 -> 10.6 | K10: =I10*J10 -> 890.4 | L10: =F10^2/162 -> 3.8580247 | M10: =K10*L10 -> 3435.1852 | N10: =M10/1000 -> 3.4351852 | O10: BBS
A11: 6 | B11: Raft Foundation | C11: STR-004 | D11: Raft - bottom reinforcement | E11: 2505 | F11: 25 | G11: 1 | H11: 62 | I11: =G11*H11 -> 62 | J11: =11375/1000 -> 11.375 | K11: =I11*J11 -> 705.25 | L11: =F11^2/162 -> 3.8580247 | M11: =K11*L11 -> 2720.8719 | N11: =M11/1000 -> 2.7208719 | O11: BBS
A12: 7 | B12: Raft Foundation | C12: STR-004 | D12: Raft - bottom reinforcement | E12: 2506 | F12: 25 | G12: 1 | H12: 25 | I12: =G12*H12 -> 25 | J12: =7425/1000 -> 7.425 | K12: =I12*J12 -> 185.625 | L12: =F12^2/162 -> 3.8580247 | M12: =K12*L12 -> 716.14583 | N12: =M12/1000 -> 0.71614583 | O12: BBS
A13: 8 | B13: Raft Foundation | C13: STR-004 | D13: Raft - bottom reinforcement | E13: 2507 | F13: 25 | G13: 1 | H13: 88 | I13: =G13*H13 -> 88 | J13: =12000/1000 -> 12 | K13: =I13*J13 -> 1056 | L13: =F13^2/162 -> 3.8580247 | M13: =K13*L13 -> 4074.0741 | N13: =M13/1000 -> 4.0740741 | O13: BBS
A14: 9 | B14: Raft Foundation | C14: STR-004 | D14: Raft - bottom reinforcement | E14: 2508 | F14: 25 | G14: 1 | H14: 84 | I14: =G14*H14 -> 84 | J14: =8125/1000 -> 8.125 | K14: =I14*J14 -> 682.5 | L14: =F14^2/162 -> 3.8580247 | M14: =K14*L14 -> 2633.1019 | N14: =M14/1000 -> 2.6331019 | O14: BBS
A15: 10 | B15: Raft Foundation | C15: STR-004 | D15: Raft - bottom reinforcement | E15: 2509 | F15: 25 | G15: 1 | H15: 23 | I15: =G15*H15 -> 23 | J15: =10875/1000 -> 10.875 | K15: =I15*J15 -> 250.125 | L15: =F15^2/162 -> 3.8580247 | M15: =K15*L15 -> 964.98843 | N15: =M15/1000 -> 0.96498843 | O15: BBS
A16: 11 | B16: Raft Foundation | C16: STR-004 | D16: Raft - bottom reinforcement | E16: 2509A | F16: 25 | G16: 1 | H16: 23 | I16: =G16*H16 -> 23 | J16: =10555/1000 -> 10.555 | K16: =I16*J16 -> 242.765 | L16: =F16^2/162 -> 3.8580247 | M16: =K16*L16 -> 936.59336 | N16: =M16/1000 -> 0.93659336 | O16: BBS
A17: 12 | B17: Raft Foundation | C17: STR-004 | D17: Raft - bottom reinforcement | E17: 2510 | F17: 25 | G17: 1 | H17: 23 | I17: =G17*H17 -> 23 | J17: =10650/1000 -> 10.65 | K17: =I17*J17 -> 244.95 | L17: =F17^2/162 -> 3.8580247 | M17: =K17*L17 -> 945.02315 | N17: =M17/1000 -> 0.94502315 | O17: BBS
A18: 13 | B18: Raft Foundation | C18: STR-004 | D18: Raft - bottom reinforcement | E18: 2511 | F18: 25 | G18: 1 | H18: 240 | I18: =G18*H18 -> 240 | J18: =10400/1000 -> 10.4 | K18: =I18*J18 -> 2496 | L18: =F18^2/162 -> 3.8580247 | M18: =K18*L18 -> 9629.6296 | N18: =M18/1000 -> 9.6296296 | O18: BBS
A19: 14 | B19: Raft Foundation | C19: STR-004 | D19: Raft - bottom reinforcement | E19: 2512 | F19: 25 | G19: 1 | H19: 305 | I19: =G19*H19 -> 305 | J19: =6325/1000 -> 6.325 | K19: =I19*J19 -> 1929.125 | L19: =F19^2/162 -> 3.8580247 | M19: =K19*L19 -> 7442.6119 | N19: =M19/1000 -> 7.4426119 | O19: BBS
A20: 15 | B20: Raft Foundation | C20: STR-004 | D20: Raft - bottom reinforcement | E20: 2513 | F20: 25 | G20: 1 | H20: 177 | I20: =G20*H20 -> 177 | J20: =12000/1000 -> 12 | K20: =I20*J20 -> 2124 | L20: =F20^2/162 -> 3.8580247 | M20: =K20*L20 -> 8194.4444 | N20: =M20/1000 -> 8.1944444 | O20: BBS
A21: 16 | B21: Raft Foundation | C21: STR-004 | D21: Raft - bottom reinforcement | E21: 2514 | F21: 25 | G21: 1 | H21: 58 | I21: =G21*H21 -> 58 | J21: =5675/1000 -> 5.675 | K21: =I21*J21 -> 329.15 | L21: =F21^2/162 -> 3.8580247 | M21: =K21*L21 -> 1269.8688 | N21: =M21/1000 -> 1.2698688 | O21: BBS
A22: 17 | B22: Raft Foundation | C22: STR-004 | D22: Raft - bottom reinforcement | E22: 2514A | F22: 25 | G22: 1 | H22: 58 | I22: =G22*H22 -> 58 | J22: =10550/1000 -> 10.55 | K22: =I22*J22 -> 611.9 | L22: =F22^2/162 -> 3.8580247 | M22: =K22*L22 -> 2360.7253 | N22: =M22/1000 -> 2.3607253 | O22: BBS
A23: 18 | B23: Raft Foundation | C23: STR-004 | D23: Raft - bottom reinforcement | E23: 2515 | F23: 25 | G23: 1 | H23: 177 | I23: =G23*H23 -> 177 | J23: =5750/1000 -> 5.75 | K23: =I23*J23 -> 1017.75 | L23: =F23^2/162 -> 3.8580247 | M23: =K23*L23 -> 3926.5046 | N23: =M23/1000 -> 3.9265046 | O23: BBS
A24: 19 | B24: Raft Foundation | C24: STR-004 | D24: Raft - bottom reinforcement | E24: 2516 | F24: 25 | G24: 1 | H24: 58 | I24: =G24*H24 -> 58 | J24: =5800/1000 -> 5.8 | K24: =I24*J24 -> 336.4 | L24: =F24^2/162 -> 3.8580247 | M24: =K24*L24 -> 1297.8395 | N24: =M24/1000 -> 1.2978395 | O24: BBS
A25: 20 | B25: Raft Foundation | C25: STR-004 | D25: Raft - bottom reinforcement | E25: 2516A | F25: 25 | G25: 1 | H25: 58 | I25: =G25*H25 -> 58 | J25: =11075/1000 -> 11.075 | K25: =I25*J25 -> 642.35 | L25: =F25^2/162 -> 3.8580247 | M25: =K25*L25 -> 2478.2022 | N25: =M25/1000 -> 2.4782022 | O25: BBS
A26: 21 | B26: Raft Foundation | C26: STR-004 | D26: Raft - bottom reinforcement | E26: 2517 | F26: 25 | G26: 1 | H26: 177 | I26: =G26*H26 -> 177 | J26: =9000/1000 -> 9 | K26: =I26*J26 -> 1593 | L26: =F26^2/162 -> 3.8580247 | M26: =K26*L26 -> 6145.8333 | N26: =M26/1000 -> 6.1458333 | O26: BBS
A27: 22 | B27: Raft Foundation | C27: STR-004 | D27: Raft - bottom reinforcement | E27: 2518 | F27: 25 | G27: 1 | H27: 39 | I27: =G27*H27 -> 39 | J27: =9050/1000 -> 9.05 | K27: =I27*J27 -> 352.95 | L27: =F27^2/162 -> 3.8580247 | M27: =K27*L27 -> 1361.6898 | N27: =M27/1000 -> 1.3616898 | O27: BBS
A28: 23 | B28: Raft Foundation | C28: STR-004 | D28: Raft - bottom reinforcement | E28: 2519 | F28: 25 | G28: 1 | H28: 161 | I28: =G28*H28 -> 161 | J28: =2175/1000 -> 2.175 | K28: =I28*J28 -> 350.175 | L28: =F28^2/162 -> 3.8580247 | M28: =K28*L28 -> 1350.9838 | N28: =M28/1000 -> 1.3509838 | O28: BBS
A29: 24 | B29: Raft Foundation | C29: STR-004 | D29: Raft - bottom reinforcement | E29: 2520 | F29: 25 | G29: 1 | H29: 33 | I29: =G29*H29 -> 33 | J29: =9000/1000 -> 9 | K29: =I29*J29 -> 297 | L29: =F29^2/162 -> 3.8580247 | M29: =K29*L29 -> 1145.8333 | N29: =M29/1000 -> 1.1458333 | O29: BBS
A30: 25 | B30: Raft Foundation | C30: STR-004 | D30: Raft - bottom reinforcement | E30: 2521 | F30: 25 | G30: 1 | H30: 33 | I30: =G30*H30 -> 33 | J30: =12000/1000 -> 12 | K30: =I30*J30 -> 396 | L30: =F30^2/162 -> 3.8580247 | M30: =K30*L30 -> 1527.7778 | N30: =M30/1000 -> 1.5277778 | O30: BBS
A31: 26 | B31: Raft Foundation | C31: STR-004 | D31: Raft - bottom reinforcement | E31: 2522 | F31: 25 | G31: 1 | H31: 33 | I31: =G31*H31 -> 33 | J31: =11887/1000 -> 11.887 | K31: =I31*J31 -> 392.271 | L31: =F31^2/162 -> 3.8580247 | M31: =K31*L31 -> 1513.3912 | N31: =M31/1000 -> 1.5133912 | O31: BBS
A32: 27 | B32: Raft Foundation | C32: STR-004 | D32: Raft - bottom reinforcement | E32: 2523 | F32: 25 | G32: 1 | H32: 201 | I32: =G32*H32 -> 201 | J32: =11525/1000 -> 11.525 | K32: =I32*J32 -> 2316.525 | L32: =F32^2/162 -> 3.8580247 | M32: =K32*L32 -> 8937.2106 | N32: =M32/1000 -> 8.9372106 | O32: BBS
A33: 28 | B33: Raft Foundation | C33: STR-005 | D33: Raft - additional bottom reinforcement | E33: 2001 | F33: 20 | G33: 1 | H33: 24 | I33: =G33*H33 -> 24 | J33: =2225/1000 -> 2.225 | K33: =I33*J33 -> 53.4 | L33: =F33^2/162 -> 2.4691358 | M33: =K33*L33 -> 131.85185 | N33: =M33/1000 -> 0.13185185 | O33: BBS
A34: 29 | B34: Raft Foundation | C34: STR-005 | D34: Raft - additional bottom reinforcement | E34: 2002 | F34: 20 | G34: 1 | H34: 27 | I34: =G34*H34 -> 27 | J34: =3200/1000 -> 3.2 | K34: =I34*J34 -> 86.4 | L34: =F34^2/162 -> 2.4691358 | M34: =K34*L34 -> 213.33333 | N34: =M34/1000 -> 0.21333333 | O34: BBS
A35: 30 | B35: Raft Foundation | C35: STR-005 | D35: Raft - additional bottom reinforcement | E35: 2003 | F35: 20 | G35: 1 | H35: 40 | I35: =G35*H35 -> 40 | J35: =5000/1000 -> 5 | K35: =I35*J35 -> 200 | L35: =F35^2/162 -> 2.4691358 | M35: =K35*L35 -> 493.82716 | N35: =M35/1000 -> 0.49382716 | O35: BBS
A36: 31 | B36: Raft Foundation | C36: STR-005 | D36: Raft - additional bottom reinforcement | E36: 2004 | F36: 20 | G36: 1 | H36: 34 | I36: =G36*H36 -> 34 | J36: =4100/1000 -> 4.1 | K36: =I36*J36 -> 139.4 | L36: =F36^2/162 -> 2.4691358 | M36: =K36*L36 -> 344.19753 | N36: =M36/1000 -> 0.34419753 | O36: BBS
A37: 32 | B37: Raft Foundation | C37: STR-005 | D37: Raft - additional bottom reinforcement | E37: 2005 | F37: 20 | G37: 1 | H37: 76 | I37: =G37*H37 -> 76 | J37: =6000/1000 -> 6 | K37: =I37*J37 -> 456 | L37: =F37^2/162 -> 2.4691358 | M37: =K37*L37 -> 1125.9259 | N37: =M37/1000 -> 1.1259259 | O37: BBS
A38: 33 | B38: Raft Foundation | C38: STR-005 | D38: Raft - additional bottom reinforcement | E38: 2006 | F38: 20 | G38: 1 | H38: 19 | I38: =G38*H38 -> 19 | J38: =3350/1000 -> 3.35 | K38: =I38*J38 -> 63.65 | L38: =F38^2/162 -> 2.4691358 | M38: =K38*L38 -> 157.16049 | N38: =M38/1000 -> 0.15716049 | O38: BBS
A39: 34 | B39: Raft Foundation | C39: STR-005 | D39: Raft - additional bottom reinforcement | E39: 2501 | F39: 25 | G39: 1 | H39: 80 | I39: =G39*H39 -> 80 | J39: =5000/1000 -> 5 | K39: =I39*J39 -> 400 | L39: =F39^2/162 -> 3.8580247 | M39: =K39*L39 -> 1543.2099 | N39: =M39/1000 -> 1.5432099 | O39: BBS
A40: 35 | B40: Raft Foundation | C40: STR-005 | D40: Raft - additional bottom reinforcement | E40: 2502 | F40: 25 | G40: 1 | H40: 67 | I40: =G40*H40 -> 67 | J40: =6650/1000 -> 6.65 | K40: =I40*J40 -> 445.55 | L40: =F40^2/162 -> 3.8580247 | M40: =K40*L40 -> 1718.9429 | N40: =M40/1000 -> 1.7189429 | O40: BBS
A41: 36 | B41: Raft Foundation | C41: STR-005 | D41: Raft - additional bottom reinforcement | E41: 2503 | F41: 25 | G41: 1 | H41: 111 | I41: =G41*H41 -> 111 | J41: =4100/1000 -> 4.1 | K41: =I41*J41 -> 455.1 | L41: =F41^2/162 -> 3.8580247 | M41: =K41*L41 -> 1755.787 | N41: =M41/1000 -> 1.755787 | O41: BBS
...

Sheet F01 Ground Floor
A1: REINFORCEMENT TAKE-OFF - GROUND FLOOR (+300) - ELEMENTS RISING TO NEXT LEVEL
A2: Proposed Kaneshie Block N Redevelopment
A3: Calculation per line: Total bars = members x bars/member; Total length = bars x cut length; kg = length x d^2/162; t = kg/1000
A5: Item | B5: Element | C5: Drawing | D5: Description / location | E5: Bar mark | F5: Dia (mm) | G5: No. of members | H5: No. of bars per member | I5: Total no. of bars | J5: Cut length per bar (m) | K5: Total length (m) | L5: Unit mass (kg/m) | M5: Weight (kg) | N5: Weight (t) | O5: Source
A6: 1 | B6: Columns | C6: STR-007 | D6: COL-01A (5 nos) GF to next level - links | E6: 1001 | F6: 10 | G6: 5 | H6: 32 | I6: =G6*H6 -> 160 | J6: =2330/1000 -> 2.33 | K6: =I6*J6 -> 372.8 | L6: =F6^2/162 -> 0.61728395 | M6: =K6*L6 -> 230.12346 | N6: =M6/1000 -> 0.23012346 | O6: Elevation + BBS length
A7: 2 | B7: Columns | C7: STR-007 | D7: COL-01A (5 nos) GF to next level - links | E7: 1002 | F7: 10 | G7: 5 | H7: 64 | I7: =G7*H7 -> 320 | J7: =1330/1000 -> 1.33 | K7: =I7*J7 -> 425.6 | L7: =F7^2/162 -> 0.61728395 | M7: =K7*L7 -> 262.71605 | N7: =M7/1000 -> 0.26271605 | O7: Elevation + BBS length
A8: 3 | B8: Columns | C8: STR-007 | D8: COL-01A (5 nos) GF to next level - links | E8: 1003 | F8: 10 | G8: 5 | H8: 32 | I8: =G8*H8 -> 160 | J8: =1830/1000 -> 1.83 | K8: =I8*J8 -> 292.8 | L8: =F8^2/162 -> 0.61728395 | M8: =K8*L8 -> 180.74074 | N8: =M8/1000 -> 0.18074074 | O8: Elevation + BBS length
A9: 4 | B9: Columns | C9: STR-007 | D9: COL-01A (5 nos) GF to next level - main bars | E9: 2502 | F9: 25 | G9: 5 | H9: 16 | I9: =G9*H9 -> 80 | J9: =5050/1000 -> 5.05 | K9: =I9*J9 -> 404 | L9: =F9^2/162 -> 3.8580247 | M9: =K9*L9 -> 1558.642 | N9: =M9/1000 -> 1.558642 | O9: Elevation + BBS length
A10: 5 | B10: Columns | C10: STR-007 | D10: COL-01B (1 nos) GF to next level - links | E10: 1001 | F10: 10 | G10: 1 | H10: 32 | I10: =G10*H10 -> 32 | J10: =2330/1000 -> 2.33 | K10: =I10*J10 -> 74.56 | L10: =F10^2/162 -> 0.61728395 | M10: =K10*L10 -> 46.024691 | N10: =M10/1000 -> 0.046024691 | O10: Elevation + BBS length
A11: 6 | B11: Columns | C11: STR-007 | D11: COL-01B (1 nos) GF to next level - links | E11: 1002 | F11: 10 | G11: 1 | H11: 64 | I11: =G11*H11 -> 64 | J11: =1330/1000 -> 1.33 | K11: =I11*J11 -> 85.12 | L11: =F11^2/162 -> 0.61728395 | M11: =K11*L11 -> 52.54321 | N11: =M11/1000 -> 0.05254321 | O11: Elevation + BBS length
A12: 7 | B12: Columns | C12: STR-007 | D12: COL-01B (1 nos) GF to next level - links | E12: 1003 | F12: 10 | G12: 1 | H12: 32 | I12: =G12*H12 -> 32 | J12: =1830/1000 -> 1.83 | K12: =I12*J12 -> 58.56 | L12: =F12^2/162 -> 0.61728395 | M12: =K12*L12 -> 36.148148 | N12: =M12/1000 -> 0.036148148 | O12: Elevation + BBS length
A13: 8 | B13: Columns | C13: STR-007 | D13: COL-01B (1 nos) GF to next level - main bars | E13: 2502 | F13: 25 | G13: 1 | H13: 16 | I13: =G13*H13 -> 16 | J13: =5050/1000 -> 5.05 | K13: =I13*J13 -> 80.8 | L13: =F13^2/162 -> 3.8580247 | M13: =K13*L13 -> 311.7284 | N13: =M13/1000 -> 0.3117284 | O13: Elevation + BBS length
A14: 9 | B14: Columns | C14: STR-008 | D14: COL-01C (2 nos) GF to next level - links | E14: 1001 | F14: 10 | G14: 2 | H14: 32 | I14: =G14*H14 -> 64 | J14: =2330/1000 -> 2.33 | K14: =I14*J14 -> 149.12 | L14: =F14^2/162 -> 0.61728395 | M14: =K14*L14 -> 92.049383 | N14: =M14/1000 -> 0.092049383 | O14: Elevation + BBS length
A15: 10 | B15: Columns | C15: STR-008 | D15: COL-01C (2 nos) GF to next level - links | E15: 1002 | F15: 10 | G15: 2 | H15: 64 | I15: =G15*H15 -> 128 | J15: =1330/1000 -> 1.33 | K15: =I15*J15 -> 170.24 | L15: =F15^2/162 -> 0.61728395 | M15: =K15*L15 -> 105.08642 | N15: =M15/1000 -> 0.10508642 | O15: Elevation + BBS length
A16: 11 | B16: Columns | C16: STR-008 | D16: COL-01C (2 nos) GF to next level - links | E16: 1003 | F16: 10 | G16: 2 | H16: 32 | I16: =G16*H16 -> 64 | J16: =1830/1000 -> 1.83 | K16: =I16*J16 -> 117.12 | L16: =F16^2/162 -> 0.61728395 | M16: =K16*L16 -> 72.296296 | N16: =M16/1000 -> 0.072296296 | O16: Elevation + BBS length
A17: 12 | B17: Columns | C17: STR-008 | D17: COL-01C (2 nos) GF to next level - main bars | E17: 2502 | F17: 25 | G17: 2 | H17: 16 | I17: =G17*H17 -> 32 | J17: =5050/1000 -> 5.05 | K17: =I17*J17 -> 161.6 | L17: =F17^2/162 -> 3.8580247 | M17: =K17*L17 -> 623.45679 | N17: =M17/1000 -> 0.62345679 | O17: Elevation + BBS length
A18: 13 | B18: Columns | C18: STR-008 | D18: COL-01D (1 nos) GF to next level - links | E18: 1001 | F18: 10 | G18: 1 | H18: 22 | I18: =G18*H18 -> 22 | J18: =2330/1000 -> 2.33 | K18: =I18*J18 -> 51.26 | L18: =F18^2/162 -> 0.61728395 | M18: =K18*L18 -> 31.641975 | N18: =M18/1000 -> 0.031641975 | O18: Elevation + BBS length
A19: 14 | B19: Columns | C19: STR-008 | D19: COL-01D (1 nos) GF to next level - links | E19: 1002 | F19: 10 | G19: 1 | H19: 44 | I19: =G19*H19 -> 44 | J19: =1330/1000 -> 1.33 | K19: =I19*J19 -> 58.52 | L19: =F19^2/162 -> 0.61728395 | M19: =K19*L19 -> 36.123457 | N19: =M19/1000 -> 0.036123457 | O19: Elevation + BBS length
A20: 15 | B20: Columns | C20: STR-008 | D20: COL-01D (1 nos) GF to next level - links | E20: 1003 | F20: 10 | G20: 1 | H20: 22 | I20: =G20*H20 -> 22 | J20: =1830/1000 -> 1.83 | K20: =I20*J20 -> 40.26 | L20: =F20^2/162 -> 0.61728395 | M20: =K20*L20 -> 24.851852 | N20: =M20/1000 -> 0.024851852 | O20: Elevation + BBS length
A21: 16 | B21: Columns | C21: STR-008 | D21: COL-01D (1 nos) GF to next level - main bars | E21: 2505 | F21: 25 | G21: 1 | H21: 16 | I21: =G21*H21 -> 16 | J21: =3700/1000 -> 3.7 | K21: =I21*J21 -> 59.2 | L21: =F21^2/162 -> 3.8580247 | M21: =K21*L21 -> 228.39506 | N21: =M21/1000 -> 0.22839506 | O21: Elevation + BBS length
A22: 17 | B22: Columns | C22: STR-010 | D22: COL-02A (3 nos) GF to next level - links | E22: 1004 | F22: 10 | G22: 3 | H22: 32 | I22: =G22*H22 -> 96 | J22: =2910/1000 -> 2.91 | K22: =I22*J22 -> 279.36 | L22: =F22^2/162 -> 0.61728395 | M22: =K22*L22 -> 172.44444 | N22: =M22/1000 -> 0.17244444 | O22: Elevation + BBS length
A23: 18 | B23: Columns | C23: STR-010 | D23: COL-02A (3 nos) GF to next level - links | E23: 1005 | F23: 10 | G23: 3 | H23: =5*32 -> 160 | I23: =G23*H23 -> 480 | J23: =1008/1000 -> 1.008 | K23: =I23*J23 -> 483.84 | L23: =F23^2/162 -> 0.61728395 | M23: =K23*L23 -> 298.66667 | N23: =M23/1000 -> 0.29866667 | O23: Elevation + BBS length
A24: 19 | B24: Columns | C24: STR-010 | D24: COL-02A (3 nos) GF to next level - main bars | E24: 2502 | F24: 25 | G24: 3 | H24: 18 | I24: =G24*H24 -> 54 | J24: =5050/1000 -> 5.05 | K24: =I24*J24 -> 272.7 | L24: =F24^2/162 -> 3.8580247 | M24: =K24*L24 -> 1052.0833 | N24: =M24/1000 -> 1.0520833 | O24: Elevation + BBS length
A25: 20 | B25: Columns | C25: STR-010 | D25: COL-02B (6 nos) GF to next level - links | E25: 1004 | F25: 10 | G25: 6 | H25: 32 | I25: =G25*H25 -> 192 | J25: =2910/1000 -> 2.91 | K25: =I25*J25 -> 558.72 | L25: =F25^2/162 -> 0.61728395 | M25: =K25*L25 -> 344.88889 | N25: =M25/1000 -> 0.34488889 | O25: Elevation + BBS length
A26: 21 | B26: Columns | C26: STR-010 | D26: COL-02B (6 nos) GF to next level - links | E26: 1005 | F26: 10 | G26: 6 | H26: =5*32 -> 160 | I26: =G26*H26 -> 960 | J26: =1008/1000 -> 1.008 | K26: =I26*J26 -> 967.68 | L26: =F26^2/162 -> 0.61728395 | M26: =K26*L26 -> 597.33333 | N26: =M26/1000 -> 0.59733333 | O26: Elevation + BBS length
A27: 22 | B27: Columns | C27: STR-010 | D27: COL-02B (6 nos) GF to next level - main bars | E27: 2502 | F27: 25 | G27: 6 | H27: 18 | I27: =G27*H27 -> 108 | J27: =5050/1000 -> 5.05 | K27: =I27*J27 -> 545.4 | L27: =F27^2/162 -> 3.8580247 | M27: =K27*L27 -> 2104.1667 | N27: =M27/1000 -> 2.1041667 | O27: Elevation + BBS length
A28: 23 | B28: Columns | C28: STR-011 | D28: COL-02C (1 nos) GF to next level - links | E28: 1004 | F28: 10 | G28: 1 | H28: 32 | I28: =G28*H28 -> 32 | J28: =2910/1000 -> 2.91 | K28: =I28*J28 -> 93.12 | L28: =F28^2/162 -> 0.61728395 | M28: =K28*L28 -> 57.481481 | N28: =M28/1000 -> 0.057481481 | O28: Elevation + BBS length
A29: 24 | B29: Columns | C29: STR-011 | D29: COL-02C (1 nos) GF to next level - links | E29: 1005 | F29: 10 | G29: 1 | H29: =3*32 -> 96 | I29: =G29*H29 -> 96 | J29: =1008/1000 -> 1.008 | K29: =I29*J29 -> 96.768 | L29: =F29^2/162 -> 0.61728395 | M29: =K29*L29 -> 59.733333 | N29: =M29/1000 -> 0.059733333 | O29: Elevation + BBS length
A30: 25 | B30: Columns | C30: STR-011 | D30: COL-02C (1 nos) GF to next level - main bars | E30: 2502 | F30: 25 | G30: 1 | H30: 18 | I30: =G30*H30 -> 18 | J30: =5050/1000 -> 5.05 | K30: =I30*J30 -> 90.9 | L30: =F30^2/162 -> 3.8580247 | M30: =K30*L30 -> 350.69444 | N30: =M30/1000 -> 0.35069444 | O30: Elevation + BBS length
A31: 26 | B31: Columns | C31: STR-011 | D31: COL-02D (15 nos) GF to next level - links | E31: 1004 | F31: 10 | G31: 15 | H31: 24 | I31: =G31*H31 -> 360 | J31: =2910/1000 -> 2.91 | K31: =I31*J31 -> 1047.6 | L31: =F31^2/162 -> 0.61728395 | M31: =K31*L31 -> 646.66667 | N31: =M31/1000 -> 0.64666667 | O31: Elevation + BBS length
A32: 27 | B32: Columns | C32: STR-011 | D32: COL-02D (15 nos) GF to next level - links | E32: 1005 | F32: 10 | G32: 15 | H32: =3*24 -> 72 | I32: =G32*H32 -> 1080 | J32: =1008/1000 -> 1.008 | K32: =I32*J32 -> 1088.64 | L32: =F32^2/162 -> 0.61728395 | M32: =K32*L32 -> 672 | N32: =M32/1000 -> 0.672 | O32: Elevation + BBS length
