Workbook

Sheet Cover Page .
A9: S | B9: CASHFLOW FORECAST FOR PROPOSED HEAD OFFICE FOR PRIORITY INSURANCE
F21: OCTOBER, 2026
C23: www.spektra.global // +233 30 321 7241 // | F23: SPEKTRA GLOBAL LTD
B182: GROUND TOTAL TO SUMMARY

Sheet CASHFLOW SUMMARY
A1: PROPOSED CASH FLOW AGGREGATED
A2: PAYMENT NO. | B2: MONTH, YEAR | C2: AMOUNT (US$)
A3: PMT 1 (ADV.) | B3: =' CASHFLOW'!E1 | C3: =SUM(' CASHFLOW'!E97:E97)
A4: PMT 2 | B4: =' CASHFLOW'!I1 | C4: =SUM(' CASHFLOW'!F97:I97)
A5: PMT 3 | B5: =' CASHFLOW'!M1 | C5: =SUM(' CASHFLOW'!J97:M97)
A6: PMT 4 | B6: =' CASHFLOW'!Q1 | C6: =SUM(' CASHFLOW'!N97:Q97)
A7: PMT 5 | B7: =' CASHFLOW'!U1 | C7: =SUM(' CASHFLOW'!R97:U97)
A8: PMT 6 | B8: =' CASHFLOW'!Y1 | C8: =SUM(' CASHFLOW'!V97:Y97)
A9: PMT 7 | B9: =' CASHFLOW'!AC1 | C9: =SUM(' CASHFLOW'!Z97:AC97)
A10: PMT 8 | B10: =' CASHFLOW'!AD1 | C10: =SUM(' CASHFLOW'!AD97:AD97)
A11: PMT 9 | B11: =' CASHFLOW'!AE1 | C11: =SUM(' CASHFLOW'!AE97:AE97)
A12: TOTAL PAYMENT | C12: =SUM(C3:C11)
A15: PROPOSED CASH FLOW MONTHLY
A16: PAYMENT NO. | B16: MONTH, YEAR | C16: AMOUNT (US$)
A17: PMT 1 (ADV) | B17: =' CASHFLOW'!E1 | C17: =' CASHFLOW'!E97 | D17: =' CASHFLOW'!E98
A18: PMT 2 | B18: =' CASHFLOW'!F1 | C18: =' CASHFLOW'!F97 | D18: =' CASHFLOW'!F98
A19: PMT 3 | B19: =' CASHFLOW'!G1 | C19: =' CASHFLOW'!G97 | D19: =' CASHFLOW'!G98
A20: PMT 4 | B20: =' CASHFLOW'!H1 | C20: =' CASHFLOW'!H97 | D20: =' CASHFLOW'!H98
A21: PMT 5 | B21: =' CASHFLOW'!I1 | C21: =' CASHFLOW'!I97 | D21: =' CASHFLOW'!I98
A22: PMT 6 | B22: =' CASHFLOW'!J1 | C22: =' CASHFLOW'!J97 | D22: =' CASHFLOW'!J98
A23: PMT 7 | B23: =' CASHFLOW'!K1 | C23: =' CASHFLOW'!K97 | D23: =' CASHFLOW'!K98
A24: PMT 8 | B24: =' CASHFLOW'!L1 | C24: =' CASHFLOW'!L97 | D24: =' CASHFLOW'!L98
A25: PMT 9 | B25: =' CASHFLOW'!M1 | C25: =' CASHFLOW'!M97 | D25: =' CASHFLOW'!M98
A26: PMT 10 | B26: =' CASHFLOW'!N1 | C26: =' CASHFLOW'!N97 | D26: =' CASHFLOW'!N98
A27: PMT 11 | B27: =' CASHFLOW'!O1 | C27: =' CASHFLOW'!O97 | D27: =' CASHFLOW'!O98
A28: PMT 12 | B28: =' CASHFLOW'!P1 | C28: =' CASHFLOW'!P97 | D28: =' CASHFLOW'!P98
A29: PMT 13 | B29: =' CASHFLOW'!Q1 | C29: =' CASHFLOW'!Q97 | D29: =' CASHFLOW'!Q98
A30: PMT 14 | B30: =' CASHFLOW'!R1 | C30: =' CASHFLOW'!R97 | D30: =' CASHFLOW'!R98
A31: PMT 15 | B31: =' CASHFLOW'!S1 | C31: =' CASHFLOW'!S97 | D31: =' CASHFLOW'!S98
A32: PMT 16 | B32: =' CASHFLOW'!T1 | C32: =' CASHFLOW'!T97 | D32: =' CASHFLOW'!T98
A33: PMT 17 | B33: =' CASHFLOW'!U1 | C33: =' CASHFLOW'!U97 | D33: =' CASHFLOW'!U98
A34: PMT 18 | B34: =' CASHFLOW'!V1 | C34: =' CASHFLOW'!V97 | D34: =' CASHFLOW'!V98
A35: PMT 19 | B35: =' CASHFLOW'!W1 | C35: =' CASHFLOW'!W97 | D35: =' CASHFLOW'!W98
A36: PMT 20 | B36: =' CASHFLOW'!X1 | C36: =' CASHFLOW'!X97 | D36: =' CASHFLOW'!X98
A37: PMT 21 | B37: =' CASHFLOW'!Y1 | C37: =' CASHFLOW'!Y97 | D37: =' CASHFLOW'!Y98
A38: PMT 22 | B38: =' CASHFLOW'!Z1 | C38: =' CASHFLOW'!Z97 | D38: =' CASHFLOW'!Z98
A39: PMT 23 | B39: =' CASHFLOW'!AA1 | C39: =' CASHFLOW'!AA97 | D39: =' CASHFLOW'!AA98
A40: PMT 24 | B40: =' CASHFLOW'!AB1 | C40: =' CASHFLOW'!AB97 | D40: =' CASHFLOW'!AB98
A41: PMT 25 | B41: =' CASHFLOW'!AC1 | C41: =' CASHFLOW'!AC97 | D41: =' CASHFLOW'!AC98
A42: PMT 26 | B42: =' CASHFLOW'!AD1 | C42: =' CASHFLOW'!AD97 | D42: =' CASHFLOW'!AD98
...

Sheet CASHFLOW SUMMARY CHART

Sheet  CASHFLOW
A1: ITEM | B1: DESCRIPTION | D1: TOTAL | E1: =EOMONTH($C$107,E2) | F1: =EOMONTH($C$107,F2) | G1: =EOMONTH($C$107,G2) | H1: =EOMONTH($C$107,H2) | I1: =EOMONTH($C$107,I2) | J1: =EOMONTH($C$107,J2) | K1: =EOMONTH($C$107,K2) | L1: =EOMONTH($C$107,L2) | ... AE1: =EOMONTH($C$107,AE2) | AF1: TOTAL | AH1: START MONTH | AI1: DURATION (MONTHS)
E2: 0 | F2: =E2+1 | G2: =F2+1 | H2: =G2+1 | I2: =H2+1 | J2: =I2+1 | K2: =J2+1 | L2: =K2+1 | M2: =L2+1 | ... AC2: =AB2+1 | AD2: =$C$108+1 | AE2: =$C$108+$C$110
A3: A | B3: ADVANCE MOBILIZATION | D3: =$C$103*$C$101 | E3: =IF(AND(E$2>=$AH4,E$2<$AH4+$AI4),$D4/$AI4,0) | F3: =IF(AND(F$2>=$AH4,F$2<$AH4+$AI4),$D4/$AI4,0) | G3: =IF(AND(G$2>=$AH4,G$2<$AH4+$AI4),$D4/$AI4,0) | H3: =IF(AND(H$2>=$AH4,H$2<$AH4+$AI4),$D4/$AI4,0) | I3: =IF(AND(I$2>=$AH4,I$2<$AH4+$AI4),$D4/$AI4,0) | J3: =IF(AND(J$2>=$AH4,J$2<$AH4+$AI4),$D4/$AI4,0) | K3: =IF(AND(K$2>=$AH4,K$2<$AH4+$AI4),$D4/$AI4,0) | L3: =IF(AND(L$2>=$AH4,L$2<$AH4+$AI4),$D4/$AI4,0) | ... AE3: =IF(AND(AE$2>=$AH4,AE$2<$AH4+$AI4),$D4/$AI4,0) | AF3: =SUM(E3:AE3)
B4: Contract Signing | C4: 1 | D4: =C4*$D$3 | AH4: 0 | AI4: 1
A6: B | B6: ='GEN SUMMARY.'!B7 | D6: ='GEN SUMMARY.'!E7 | E6: =IF(AND(E$2>=$AH7,E$2<$AH7+$AI7),$D7/$AI7,0)+IF(AND(E$2>=$AH8,E$2<$AH8+$AI8),$D8/$AI8,0)+IF(AND(E$2>=$AH9,E$2<$AH9+$AI9),$D9/$AI9,0) | F6: =IF(AND(F$2>=$AH7,F$2<$AH7+$AI7),$D7/$AI7,0)+IF(AND(F$2>=$AH8,F$2<$AH8+$AI8),$D8/$AI8,0)+IF(AND(F$2>=$AH9,F$2<$AH9+$AI9),$D9/$AI9,0) | G6: =IF(AND(G$2>=$AH7,G$2<$AH7+$AI7),$D7/$AI7,0)+IF(AND(G$2>=$AH8,G$2<$AH8+$AI8),$D8/$AI8,0)+IF(AND(G$2>=$AH9,G$2<$AH9+$AI9),$D9/$AI9,0) | H6: =IF(AND(H$2>=$AH7,H$2<$AH7+$AI7),$D7/$AI7,0)+IF(AND(H$2>=$AH8,H$2<$AH8+$AI8),$D8/$AI8,0)+IF(AND(H$2>=$AH9,H$2<$AH9+$AI9),$D9/$AI9,0) | I6: =IF(AND(I$2>=$AH7,I$2<$AH7+$AI7),$D7/$AI7,0)+IF(AND(I$2>=$AH8,I$2<$AH8+$AI8),$D8/$AI8,0)+IF(AND(I$2>=$AH9,I$2<$AH9+$AI9),$D9/$AI9,0) | J6: =IF(AND(J$2>=$AH7,J$2<$AH7+$AI7),$D7/$AI7,0)+IF(AND(J$2>=$AH8,J$2<$AH8+$AI8),$D8/$AI8,0)+IF(AND(J$2>=$AH9,J$2<$AH9+$AI9),$D9/$AI9,0) | K6: =IF(AND(K$2>=$AH7,K$2<$AH7+$AI7),$D7/$AI7,0)+IF(AND(K$2>=$AH8,K$2<$AH8+$AI8),$D8/$AI8,0)+IF(AND(K$2>=$AH9,K$2<$AH9+$AI9),$D9/$AI9,0) | L6: =IF(AND(L$2>=$AH7,L$2<$AH7+$AI7),$D7/$AI7,0)+IF(AND(L$2>=$AH8,L$2<$AH8+$AI8),$D8/$AI8,0)+IF(AND(L$2>=$AH9,L$2<$AH9+$AI9),$D9/$AI9,0) | ... AE6: =IF(AND(AE$2>=$AH7,AE$2<$AH7+$AI7),$D7/$AI7,0)+IF(AND(AE$2>=$AH8,AE$2<$AH8+$AI8),$D8/$AI8,0)+IF(AND(AE$2>=$AH9,AE$2<$AH9+$AI9),$D9/$AI9,0) | AF6: =SUM(E6:AE6)
B7: (100%) Site Possession and Hoarding | C7: 0.3 | D7: =C7*$D$6 | AH7: 1 | AI7: 1
B8: (100%) Site Setup and Mobilization | C8: 0.2 | D8: =C8*$D$6 | AH8: 2 | AI8: 1
B9: (100%) Site Maintenance | C9: 0.5 | D9: =C9*$D$6 | AH9: 3 | AI9: 22
A11: C | B11: ='GEN SUMMARY.'!B9 | D11: ='GEN SUMMARY.'!E9 | E11: =IF(AND(E$2>=$AH12,E$2<$AH12+$AI12),$D12/$AI12,0)+IF(AND(E$2>=$AH13,E$2<$AH13+$AI13),$D13/$AI13,0) | F11: =IF(AND(F$2>=$AH12,F$2<$AH12+$AI12),$D12/$AI12,0)+IF(AND(F$2>=$AH13,F$2<$AH13+$AI13),$D13/$AI13,0) | G11: =IF(AND(G$2>=$AH12,G$2<$AH12+$AI12),$D12/$AI12,0)+IF(AND(G$2>=$AH13,G$2<$AH13+$AI13),$D13/$AI13,0) | H11: =IF(AND(H$2>=$AH12,H$2<$AH12+$AI12),$D12/$AI12,0)+IF(AND(H$2>=$AH13,H$2<$AH13+$AI13),$D13/$AI13,0) | I11: =IF(AND(I$2>=$AH12,I$2<$AH12+$AI12),$D12/$AI12,0)+IF(AND(I$2>=$AH13,I$2<$AH13+$AI13),$D13/$AI13,0) | J11: =IF(AND(J$2>=$AH12,J$2<$AH12+$AI12),$D12/$AI12,0)+IF(AND(J$2>=$AH13,J$2<$AH13+$AI13),$D13/$AI13,0) | K11: =IF(AND(K$2>=$AH12,K$2<$AH12+$AI12),$D12/$AI12,0)+IF(AND(K$2>=$AH13,K$2<$AH13+$AI13),$D13/$AI13,0) | L11: =IF(AND(L$2>=$AH12,L$2<$AH12+$AI12),$D12/$AI12,0)+IF(AND(L$2>=$AH13,L$2<$AH13+$AI13),$D13/$AI13,0) | ... AE11: =IF(AND(AE$2>=$AH12,AE$2<$AH12+$AI12),$D12/$AI12,0)+IF(AND(AE$2>=$AH13,AE$2<$AH13+$AI13),$D13/$AI13,0) | AF11: =SUM(E11:AE11)
B12: (0%) Start of Demolition Works | C12: 0.8 | D12: =C12*$D$11 | AH12: 1 | AI12: 1
B13: (100%) End of Demolition Works | C13: 0.2 | D13: =C13*$D$11 | AH13: 2 | AI13: 1
A15: D | B15: ='GEN SUMMARY.'!B11 | D15: ='GEN SUMMARY.'!E11 | E15: =IF(AND(E$2>=$AH16,E$2<$AH16+$AI16),$D16/$AI16,0)+IF(AND(E$2>=$AH17,E$2<$AH17+$AI17),$D17/$AI17,0)+IF(AND(E$2>=$AH18,E$2<$AH18+$AI18),$D18/$AI18,0) | F15: =IF(AND(F$2>=$AH16,F$2<$AH16+$AI16),$D16/$AI16,0)+IF(AND(F$2>=$AH17,F$2<$AH17+$AI17),$D17/$AI17,0)+IF(AND(F$2>=$AH18,F$2<$AH18+$AI18),$D18/$AI18,0) | G15: =IF(AND(G$2>=$AH16,G$2<$AH16+$AI16),$D16/$AI16,0)+IF(AND(G$2>=$AH17,G$2<$AH17+$AI17),$D17/$AI17,0)+IF(AND(G$2>=$AH18,G$2<$AH18+$AI18),$D18/$AI18,0) | H15: =IF(AND(H$2>=$AH16,H$2<$AH16+$AI16),$D16/$AI16,0)+IF(AND(H$2>=$AH17,H$2<$AH17+$AI17),$D17/$AI17,0)+IF(AND(H$2>=$AH18,H$2<$AH18+$AI18),$D18/$AI18,0) | I15: =IF(AND(I$2>=$AH16,I$2<$AH16+$AI16),$D16/$AI16,0)+IF(AND(I$2>=$AH17,I$2<$AH17+$AI17),$D17/$AI17,0)+IF(AND(I$2>=$AH18,I$2<$AH18+$AI18),$D18/$AI18,0) | J15: =IF(AND(J$2>=$AH16,J$2<$AH16+$AI16),$D16/$AI16,0)+IF(AND(J$2>=$AH17,J$2<$AH17+$AI17),$D17/$AI17,0)+IF(AND(J$2>=$AH18,J$2<$AH18+$AI18),$D18/$AI18,0) | K15: =IF(AND(K$2>=$AH16,K$2<$AH16+$AI16),$D16/$AI16,0)+IF(AND(K$2>=$AH17,K$2<$AH17+$AI17),$D17/$AI17,0)+IF(AND(K$2>=$AH18,K$2<$AH18+$AI18),$D18/$AI18,0) | L15: =IF(AND(L$2>=$AH16,L$2<$AH16+$AI16),$D16/$AI16,0)+IF(AND(L$2>=$AH17,L$2<$AH17+$AI17),$D17/$AI17,0)+IF(AND(L$2>=$AH18,L$2<$AH18+$AI18),$D18/$AI18,0) | ... AE15: =IF(AND(AE$2>=$AH16,AE$2<$AH16+$AI16),$D16/$AI16,0)+IF(AND(AE$2>=$AH17,AE$2<$AH17+$AI17),$D17/$AI17,0)+IF(AND(AE$2>=$AH18,AE$2<$AH18+$AI18),$D18/$AI18,0) | AF15: =SUM(E15:AE15)
B16: Procurement Phase I (Substructure materials on site and in transit) (0%) | C16: 0.5 | D16: =C16*$D$15 | AH16: 1 | AI16: 2
B17: (50%) Completion of Ground Works | C17: 0.25 | D17: =C17*$D$15 | AH17: 3 | AI17: 1
B18: (100%) Completion of Substructure Concrete Works | C18: 0.25 | D18: =C18*$D$15 | AH18: 4 | AI18: 1
A20: E | B20: ='GEN SUMMARY.'!B13 | D20: ='GEN SUMMARY.'!E13 | E20: =IF(AND(E$2>=$AH21,E$2<$AH21+$AI21),$D21/$AI21,0)+IF(AND(E$2>=$AH22,E$2<$AH22+$AI22),$D22/$AI22,0)+IF(AND(E$2>=$AH23,E$2<$AH23+$AI23),$D23/$AI23,0)+IF(AND(E$2>=$AH24,E$2<$AH24+$AI24),$D24/$AI24,0) | F20: =IF(AND(F$2>=$AH21,F$2<$AH21+$AI21),$D21/$AI21,0)+IF(AND(F$2>=$AH22,F$2<$AH22+$AI22),$D22/$AI22,0)+IF(AND(F$2>=$AH23,F$2<$AH23+$AI23),$D23/$AI23,0)+IF(AND(F$2>=$AH24,F$2<$AH24+$AI24),$D24/$AI24,0) | G20: =IF(AND(G$2>=$AH21,G$2<$AH21+$AI21),$D21/$AI21,0)+IF(AND(G$2>=$AH22,G$2<$AH22+$AI22),$D22/$AI22,0)+IF(AND(G$2>=$AH23,G$2<$AH23+$AI23),$D23/$AI23,0)+IF(AND(G$2>=$AH24,G$2<$AH24+$AI24),$D24/$AI24,0) | H20: =IF(AND(H$2>=$AH21,H$2<$AH21+$AI21),$D21/$AI21,0)+IF(AND(H$2>=$AH22,H$2<$AH22+$AI22),$D22/$AI22,0)+IF(AND(H$2>=$AH23,H$2<$AH23+$AI23),$D23/$AI23,0)+IF(AND(H$2>=$AH24,H$2<$AH24+$AI24),$D24/$AI24,0) | I20: =IF(AND(I$2>=$AH21,I$2<$AH21+$AI21),$D21/$AI21,0)+IF(AND(I$2>=$AH22,I$2<$AH22+$AI22),$D22/$AI22,0)+IF(AND(I$2>=$AH23,I$2<$AH23+$AI23),$D23/$AI23,0)+IF(AND(I$2>=$AH24,I$2<$AH24+$AI24),$D24/$AI24,0) | J20: =IF(AND(J$2>=$AH21,J$2<$AH21+$AI21),$D21/$AI21,0)+IF(AND(J$2>=$AH22,J$2<$AH22+$AI22),$D22/$AI22,0)+IF(AND(J$2>=$AH23,J$2<$AH23+$AI23),$D23/$AI23,0)+IF(AND(J$2>=$AH24,J$2<$AH24+$AI24),$D24/$AI24,0) | K20: =IF(AND(K$2>=$AH21,K$2<$AH21+$AI21),$D21/$AI21,0)+IF(AND(K$2>=$AH22,K$2<$AH22+$AI22),$D22/$AI22,0)+IF(AND(K$2>=$AH23,K$2<$AH23+$AI23),$D23/$AI23,0)+IF(AND(K$2>=$AH24,K$2<$AH24+$AI24),$D24/$AI24,0) | L20: =IF(AND(L$2>=$AH21,L$2<$AH21+$AI21),$D21/$AI21,0)+IF(AND(L$2>=$AH22,L$2<$AH22+$AI22),$D22/$AI22,0)+IF(AND(L$2>=$AH23,L$2<$AH23+$AI23),$D23/$AI23,0)+IF(AND(L$2>=$AH24,L$2<$AH24+$AI24),$D24/$AI24,0) | ... AE20: =IF(AND(AE$2>=$AH21,AE$2<$AH21+$AI21),$D21/$AI21,0)+IF(AND(AE$2>=$AH22,AE$2<$AH22+$AI22),$D22/$AI22,0)+IF(AND(AE$2>=$AH23,AE$2<$AH23+$AI23),$D23/$AI23,0)+IF(AND(AE$2>=$AH24,AE$2<$AH24+$AI24),$D24/$AI24,0) | AF20: =SUM(E20:AE20)
B21: (0%) Start of Sub-Basement Floor Structure | C21: 0.3 | D21: =C21*$D$20 | AH21: 3 | AI21: 3
B22: (100%) Completion of Structure | C22: 0.2 | D22: =C22*$D$20 | AH22: 6 | AI22: 1
B23: (0%) Start of Finishings and MEP | C23: 0.3 | D23: =C23*$D$20 | AH23: 7 | AI23: 10
B24: (100%) Completion of Finishings and MEP | C24: 0.2 | D24: =C24*$D$20 | AH24: 17 | AI24: 2
A26: F | B26: ='GEN SUMMARY.'!B15 | D26: ='GEN SUMMARY.'!E15 | E26: =IF(AND(E$2>=$AH27,E$2<$AH27+$AI27),$D27/$AI27,0)+IF(AND(E$2>=$AH28,E$2<$AH28+$AI28),$D28/$AI28,0)+IF(AND(E$2>=$AH29,E$2<$AH29+$AI29),$D29/$AI29,0)+IF(AND(E$2>=$AH30,E$2<$AH30+$AI30),$D30/$AI30,0) | F26: =IF(AND(F$2>=$AH27,F$2<$AH27+$AI27),$D27/$AI27,0)+IF(AND(F$2>=$AH28,F$2<$AH28+$AI28),$D28/$AI28,0)+IF(AND(F$2>=$AH29,F$2<$AH29+$AI29),$D29/$AI29,0)+IF(AND(F$2>=$AH30,F$2<$AH30+$AI30),$D30/$AI30,0) | G26: =IF(AND(G$2>=$AH27,G$2<$AH27+$AI27),$D27/$AI27,0)+IF(AND(G$2>=$AH28,G$2<$AH28+$AI28),$D28/$AI28,0)+IF(AND(G$2>=$AH29,G$2<$AH29+$AI29),$D29/$AI29,0)+IF(AND(G$2>=$AH30,G$2<$AH30+$AI30),$D30/$AI30,0) | H26: =IF(AND(H$2>=$AH27,H$2<$AH27+$AI27),$D27/$AI27,0)+IF(AND(H$2>=$AH28,H$2<$AH28+$AI28),$D28/$AI28,0)+IF(AND(H$2>=$AH29,H$2<$AH29+$AI29),$D29/$AI29,0)+IF(AND(H$2>=$AH30,H$2<$AH30+$AI30),$D30/$AI30,0) | I26: =IF(AND(I$2>=$AH27,I$2<$AH27+$AI27),$D27/$AI27,0)+IF(AND(I$2>=$AH28,I$2<$AH28+$AI28),$D28/$AI28,0)+IF(AND(I$2>=$AH29,I$2<$AH29+$AI29),$D29/$AI29,0)+IF(AND(I$2>=$AH30,I$2<$AH30+$AI30),$D30/$AI30,0) | J26: =IF(AND(J$2>=$AH27,J$2<$AH27+$AI27),$D27/$AI27,0)+IF(AND(J$2>=$AH28,J$2<$AH28+$AI28),$D28/$AI28,0)+IF(AND(J$2>=$AH29,J$2<$AH29+$AI29),$D29/$AI29,0)+IF(AND(J$2>=$AH30,J$2<$AH30+$AI30),$D30/$AI30,0) | K26: =IF(AND(K$2>=$AH27,K$2<$AH27+$AI27),$D27/$AI27,0)+IF(AND(K$2>=$AH28,K$2<$AH28+$AI28),$D28/$AI28,0)+IF(AND(K$2>=$AH29,K$2<$AH29+$AI29),$D29/$AI29,0)+IF(AND(K$2>=$AH30,K$2<$AH30+$AI30),$D30/$AI30,0) | L26: =IF(AND(L$2>=$AH27,L$2<$AH27+$AI27),$D27/$AI27,0)+IF(AND(L$2>=$AH28,L$2<$AH28+$AI28),$D28/$AI28,0)+IF(AND(L$2>=$AH29,L$2<$AH29+$AI29),$D29/$AI29,0)+IF(AND(L$2>=$AH30,L$2<$AH30+$AI30),$D30/$AI30,0) | ... AE26: =IF(AND(AE$2>=$AH27,AE$2<$AH27+$AI27),$D27/$AI27,0)+IF(AND(AE$2>=$AH28,AE$2<$AH28+$AI28),$D28/$AI28,0)+IF(AND(AE$2>=$AH29,AE$2<$AH29+$AI29),$D29/$AI29,0)+IF(AND(AE$2>=$AH30,AE$2<$AH30+$AI30),$D30/$AI30,0) | AF26: =SUM(E26:AE26)
B27: (0%) Start of Ground Floor Structure | C27: 0.3 | D27: =C27*$D$26 | AH27: 5 | AI27: 2
B28: (100%) Completion of Structure | C28: 0.2 | D28: =C28*$D$26 | AH28: 7 | AI28: 1
B29: (0%) Start of Finishings and MEP | C29: 0.3 | D29: =C29*$D$26 | AH29: 8 | AI29: 11
B30: (100%) Completion of Finishings and MEP | C30: 0.2 | D30: =C30*$D$26 | AH30: 19 | AI30: 2
A32: G | B32: ='GEN SUMMARY.'!B17 | D32: ='GEN SUMMARY.'!E17 | E32: =IF(AND(E$2>=$AH33,E$2<$AH33+$AI33),$D33/$AI33,0)+IF(AND(E$2>=$AH34,E$2<$AH34+$AI34),$D34/$AI34,0)+IF(AND(E$2>=$AH35,E$2<$AH35+$AI35),$D35/$AI35,0)+IF(AND(E$2>=$AH36,E$2<$AH36+$AI36),$D36/$AI36,0) | F32: =IF(AND(F$2>=$AH33,F$2<$AH33+$AI33),$D33/$AI33,0)+IF(AND(F$2>=$AH34,F$2<$AH34+$AI34),$D34/$AI34,0)+IF(AND(F$2>=$AH35,F$2<$AH35+$AI35),$D35/$AI35,0)+IF(AND(F$2>=$AH36,F$2<$AH36+$AI36),$D36/$AI36,0) | G32: =IF(AND(G$2>=$AH33,G$2<$AH33+$AI33),$D33/$AI33,0)+IF(AND(G$2>=$AH34,G$2<$AH34+$AI34),$D34/$AI34,0)+IF(AND(G$2>=$AH35,G$2<$AH35+$AI35),$D35/$AI35,0)+IF(AND(G$2>=$AH36,G$2<$AH36+$AI36),$D36/$AI36,0) | H32: =IF(AND(H$2>=$AH33,H$2<$AH33+$AI33),$D33/$AI33,0)+IF(AND(H$2>=$AH34,H$2<$AH34+$AI34),$D34/$AI34,0)+IF(AND(H$2>=$AH35,H$2<$AH35+$AI35),$D35/$AI35,0)+IF(AND(H$2>=$AH36,H$2<$AH36+$AI36),$D36/$AI36,0) | I32: =IF(AND(I$2>=$AH33,I$2<$AH33+$AI33),$D33/$AI33,0)+IF(AND(I$2>=$AH34,I$2<$AH34+$AI34),$D34/$AI34,0)+IF(AND(I$2>=$AH35,I$2<$AH35+$AI35),$D35/$AI35,0)+IF(AND(I$2>=$AH36,I$2<$AH36+$AI36),$D36/$AI36,0) | J32: =IF(AND(J$2>=$AH33,J$2<$AH33+$AI33),$D33/$AI33,0)+IF(AND(J$2>=$AH34,J$2<$AH34+$AI34),$D34/$AI34,0)+IF(AND(J$2>=$AH35,J$2<$AH35+$AI35),$D35/$AI35,0)+IF(AND(J$2>=$AH36,J$2<$AH36+$AI36),$D36/$AI36,0) | K32: =IF(AND(K$2>=$AH33,K$2<$AH33+$AI33),$D33/$AI33,0)+IF(AND(K$2>=$AH34,K$2<$AH34+$AI34),$D34/$AI34,0)+IF(AND(K$2>=$AH35,K$2<$AH35+$AI35),$D35/$AI35,0)+IF(AND(K$2>=$AH36,K$2<$AH36+$AI36),$D36/$AI36,0) | L32: =IF(AND(L$2>=$AH33,L$2<$AH33+$AI33),$D33/$AI33,0)+IF(AND(L$2>=$AH34,L$2<$AH34+$AI34),$D34/$AI34,0)+IF(AND(L$2>=$AH35,L$2<$AH35+$AI35),$D35/$AI35,0)+IF(AND(L$2>=$AH36,L$2<$AH36+$AI36),$D36/$AI36,0) | ... AE32: =IF(AND(AE$2>=$AH33,AE$2<$AH33+$AI33),$D33/$AI33,0)+IF(AND(AE$2>=$AH34,AE$2<$AH34+$AI34),$D34/$AI34,0)+IF(AND(AE$2>=$AH35,AE$2<$AH35+$AI35),$D35/$AI35,0)+IF(AND(AE$2>=$AH36,AE$2<$AH36+$AI36),$D36/$AI36,0) | AF32: =SUM(E32:AE32)
B33: (0%) Start of First Floor Structure | C33: 0.3 | D33: =C33*$D$32 | AH33: 7 | AI33: 2
B34: (100%) Completion of Structure | C34: 0.2 | D34: =C34*$D$32 | AH34: 9 | AI34: 1
B35: (0%) Start of Finishings and MEP | C35: 0.3 | D35: =C35*$D$32 | AH35: 10 | AI35: 10
B36: (100%) Completion of Finishings and MEP | C36: 0.2 | D36: =C36*$D$32 | AH36: 20 | AI36: 2
A38: H | B38: ='GEN SUMMARY.'!B19 | D38: ='GEN SUMMARY.'!E19 | E38: =IF(AND(E$2>=$AH39,E$2<$AH39+$AI39),$D39/$AI39,0)+IF(AND(E$2>=$AH40,E$2<$AH40+$AI40),$D40/$AI40,0)+IF(AND(E$2>=$AH41,E$2<$AH41+$AI41),$D41/$AI41,0)+IF(AND(E$2>=$AH42,E$2<$AH42+$AI42),$D42/$AI42,0) | F38: =IF(AND(F$2>=$AH39,F$2<$AH39+$AI39),$D39/$AI39,0)+IF(AND(F$2>=$AH40,F$2<$AH40+$AI40),$D40/$AI40,0)+IF(AND(F$2>=$AH41,F$2<$AH41+$AI41),$D41/$AI41,0)+IF(AND(F$2>=$AH42,F$2<$AH42+$AI42),$D42/$AI42,0) | G38: =IF(AND(G$2>=$AH39,G$2<$AH39+$AI39),$D39/$AI39,0)+IF(AND(G$2>=$AH40,G$2<$AH40+$AI40),$D40/$AI40,0)+IF(AND(G$2>=$AH41,G$2<$AH41+$AI41),$D41/$AI41,0)+IF(AND(G$2>=$AH42,G$2<$AH42+$AI42),$D42/$AI42,0) | H38: =IF(AND(H$2>=$AH39,H$2<$AH39+$AI39),$D39/$AI39,0)+IF(AND(H$2>=$AH40,H$2<$AH40+$AI40),$D40/$AI40,0)+IF(AND(H$2>=$AH41,H$2<$AH41+$AI41),$D41/$AI41,0)+IF(AND(H$2>=$AH42,H$2<$AH42+$AI42),$D42/$AI42,0) | I38: =IF(AND(I$2>=$AH39,I$2<$AH39+$AI39),$D39/$AI39,0)+IF(AND(I$2>=$AH40,I$2<$AH40+$AI40),$D40/$AI40,0)+IF(AND(I$2>=$AH41,I$2<$AH41+$AI41),$D41/$AI41,0)+IF(AND(I$2>=$AH42,I$2<$AH42+$AI42),$D42/$AI42,0) | J38: =IF(AND(J$2>=$AH39,J$2<$AH39+$AI39),$D39/$AI39,0)+IF(AND(J$2>=$AH40,J$2<$AH40+$AI40),$D40/$AI40,0)+IF(AND(J$2>=$AH41,J$2<$AH41+$AI41),$D41/$AI41,0)+IF(AND(J$2>=$AH42,J$2<$AH42+$AI42),$D42/$AI42,0) | K38: =IF(AND(K$2>=$AH39,K$2<$AH39+$AI39),$D39/$AI39,0)+IF(AND(K$2>=$AH40,K$2<$AH40+$AI40),$D40/$AI40,0)+IF(AND(K$2>=$AH41,K$2<$AH41+$AI41),$D41/$AI41,0)+IF(AND(K$2>=$AH42,K$2<$AH42+$AI42),$D42/$AI42,0) | L38: =IF(AND(L$2>=$AH39,L$2<$AH39+$AI39),$D39/$AI39,0)+IF(AND(L$2>=$AH40,L$2<$AH40+$AI40),$D40/$AI40,0)+IF(AND(L$2>=$AH41,L$2<$AH41+$AI41),$D41/$AI41,0)+IF(AND(L$2>=$AH42,L$2<$AH42+$AI42),$D42/$AI42,0) | ... AE38: =IF(AND(AE$2>=$AH39,AE$2<$AH39+$AI39),$D39/$AI39,0)+IF(AND(AE$2>=$AH40,AE$2<$AH40+$AI40),$D40/$AI40,0)+IF(AND(AE$2>=$AH41,AE$2<$AH41+$AI41),$D41/$AI41,0)+IF(AND(AE$2>=$AH42,AE$2<$AH42+$AI42),$D42/$AI42,0) | AF38: =SUM(E38:AE38)
B39: (0%) Start of Second Floor Structure | C39: 0.3 | D39: =C39*$D$38 | AH39: 9 | AI39: 2
B40: (100%) Completion of Structure | C40: 0.2 | D40: =C40*$D$38 | AH40: 11 | AI40: 1
B41: (0%) Start of Finishings and MEP | C41: 0.3 | D41: =C41*$D$38 | AH41: 12 | AI41: 8
B42: (100%) Completion of Finishings and MEP | C42: 0.2 | D42: =C42*$D$38 | AH42: 20 | AI42: 2
A44: J | B44: ='GEN SUMMARY.'!B21 | D44: ='GEN SUMMARY.'!E21 | E44: =IF(AND(E$2>=$AH45,E$2<$AH45+$AI45),$D45/$AI45,0)+IF(AND(E$2>=$AH46,E$2<$AH46+$AI46),$D46/$AI46,0)+IF(AND(E$2>=$AH47,E$2<$AH47+$AI47),$D47/$AI47,0)+IF(AND(E$2>=$AH48,E$2<$AH48+$AI48),$D48/$AI48,0) | F44: =IF(AND(F$2>=$AH45,F$2<$AH45+$AI45),$D45/$AI45,0)+IF(AND(F$2>=$AH46,F$2<$AH46+$AI46),$D46/$AI46,0)+IF(AND(F$2>=$AH47,F$2<$AH47+$AI47),$D47/$AI47,0)+IF(AND(F$2>=$AH48,F$2<$AH48+$AI48),$D48/$AI48,0) | G44: =IF(AND(G$2>=$AH45,G$2<$AH45+$AI45),$D45/$AI45,0)+IF(AND(G$2>=$AH46,G$2<$AH46+$AI46),$D46/$AI46,0)+IF(AND(G$2>=$AH47,G$2<$AH47+$AI47),$D47/$AI47,0)+IF(AND(G$2>=$AH48,G$2<$AH48+$AI48),$D48/$AI48,0) | H44: =IF(AND(H$2>=$AH45,H$2<$AH45+$AI45),$D45/$AI45,0)+IF(AND(H$2>=$AH46,H$2<$AH46+$AI46),$D46/$AI46,0)+IF(AND(H$2>=$AH47,H$2<$AH47+$AI47),$D47/$AI47,0)+IF(AND(H$2>=$AH48,H$2<$AH48+$AI48),$D48/$AI48,0) | I44: =IF(AND(I$2>=$AH45,I$2<$AH45+$AI45),$D45/$AI45,0)+IF(AND(I$2>=$AH46,I$2<$AH46+$AI46),$D46/$AI46,0)+IF(AND(I$2>=$AH47,I$2<$AH47+$AI47),$D47/$AI47,0)+IF(AND(I$2>=$AH48,I$2<$AH48+$AI48),$D48/$AI48,0) | J44: =IF(AND(J$2>=$AH45,J$2<$AH45+$AI45),$D45/$AI45,0)+IF(AND(J$2>=$AH46,J$2<$AH46+$AI46),$D46/$AI46,0)+IF(AND(J$2>=$AH47,J$2<$AH47+$AI47),$D47/$AI47,0)+IF(AND(J$2>=$AH48,J$2<$AH48+$AI48),$D48/$AI48,0) | K44: =IF(AND(K$2>=$AH45,K$2<$AH45+$AI45),$D45/$AI45,0)+IF(AND(K$2>=$AH46,K$2<$AH46+$AI46),$D46/$AI46,0)+IF(AND(K$2>=$AH47,K$2<$AH47+$AI47),$D47/$AI47,0)+IF(AND(K$2>=$AH48,K$2<$AH48+$AI48),$D48/$AI48,0) | L44: =IF(AND(L$2>=$AH45,L$2<$AH45+$AI45),$D45/$AI45,0)+IF(AND(L$2>=$AH46,L$2<$AH46+$AI46),$D46/$AI46,0)+IF(AND(L$2>=$AH47,L$2<$AH47+$AI47),$D47/$AI47,0)+IF(AND(L$2>=$AH48,L$2<$AH48+$AI48),$D48/$AI48,0) | ... AE44: =IF(AND(AE$2>=$AH45,AE$2<$AH45+$AI45),$D45/$AI45,0)+IF(AND(AE$2>=$AH46,AE$2<$AH46+$AI46),$D46/$AI46,0)+IF(AND(AE$2>=$AH47,AE$2<$AH47+$AI47),$D47/$AI47,0)+IF(AND(AE$2>=$AH48,AE$2<$AH48+$AI48),$D48/$AI48,0) | AF44: =SUM(E44:AE44)
B45: (0%) Start of Third Floor Structure | C45: 0.3 | D45: =C45*$D$44 | AH45: 11 | AI45: 2
B46: (100%) Completion of Structure | C46: 0.2 | D46: =C46*$D$44 | AH46: 13 | AI46: 1
B47: (0%) Start of Finishings and MEP | C47: 0.3 | D47: =C47*$D$44 | AH47: 14 | AI47: 7
B48: (100%) Completion of Finishings and MEP | C48: 0.2 | D48: =C48*$D$44 | AH48: 21 | AI48: 2
...

Sheet GEN SUMMARY.
A1: PROJECT: PROPOSED HEAD OFFICE FOR PRIORITY INSURANCE
A2: LOCATION: RIDGE, ACCRA
A3: CLIENT: PRIORITY INSURANCE
A4: DATE: 07/10/2026 (PRELIMINARY ESTIMATE REV. 6)
A5: ITEM | B5: GENERAL SUMMARY | D5: AMOUNT USD | E5: DISCOUNTED AMOUNT USD
A7: A | B7: BILL NO. 1- PRELIMINARIES AND GENERAL ITEMS | D7: =366625+50000 | E7: =D7*$D$48/$D$44
A9: B | B9: BILL NO. 2- DEMOLITIONS AND ALTERATIONS | D9: 50000 | E9: =D9*$D$48/$D$44
A11: C | B11: BILL NO. 3 -SUBSTRUCTURE (ALL PROVISIONAL) | D11: =1585*350 | E11: =D11*$D$48/$D$44
A13: D | B13: BILL NO. 4 -SUB-BASEMENT FLOOR | D13: =1585*400 | E13: =D13*$D$48/$D$44
A15: E | B15: BILL NO. 5 - GROUND FLOOR | D15: =450*500 | E15: =D15*$D$48/$D$44
A17: F | B17: BILL NO. 6 - FIRST FLOOR | D17: =600*500 | E17: =D17*$D$48/$D$44
A19: G | B19: BILL NO. 7- SECOND FLOOR | D19: =600*500 | E19: =D19*$D$48/$D$44
A21: H | B21: BILL NO. 8 -THIRD FLOOR | D21: =600*500 | E21: =D21*$D$48/$D$44
A23: J | B23: BILL NO. 9 -FOURTH FLOOR | D23: =600*500 | E23: =D23*$D$48/$D$44
A25: K | B25: BILL NO. 10 - FIFTH FLOOR | D25: =600*500 | E25: =D25*$D$48/$D$44
A27: L | B27: BILL NO. 11 - KITCHEN CABINETRY/WALL CLADDING | D27: 134515.22 | E27: =D27*$D$48/$D$44
A29: M | B29: BILL NO. 12. PLUMBING, FIRE-FIGHTING AND MECHANICAL | D29: =659925+125000 | E29: =D29*$D$48/$D$44
A31: N | B31: BILL NO. 13: ELECTRICAL WORKS | D31: =1026550+50000 | E31: =D31*$D$48/$D$44
A33: P | B33: BILL NO. 14. EXTERNAL FAÇADE WORKS | D33: =606968.250712613+50000 | E33: =D33*$D$48/$D$44
A35: Q | B35: BILL NO. 15.- EXTERNAL WORKS (ALL PROVISIONAL) | D35: 47193.436 | E35: =D35*$D$48/$D$44
A37: R | B37: DESIGN FEES | D37: 194211.36 | E37: =D37*$D$48/$D$44
A39: S | B39: PROJECT MANAGEMENT FEES | D39: =623262.5-175000 | E39: =D39*$D$48/$D$44
B44: SUB - TOTAL (1) | C44: US $ | D44: =SUM(D7:D40) | E44: =SUM(E7:E40)
B46: LESS: DISCOUNT | D46: =D44-D48
B48: AGREED DISCOUNTED CONTRACT SUM | D48: 6250000
B51: TOTAL COST OF THE WORKS (EXCLUDING TAXES) | C51: US $ | D51: =D44-D46 | E51: =E44
B54: SIGNED: ……………………………………………………………
B57: DATE: ………………………………………...........………….
